Workbook

Sheet 01.20
A1: № | B1: Кўрсаткич | C1: жами | D1: Ал-Хоразмий | E1: Бахористон | F1: Бектўпи | G1: Гулистон | H1: Катта Хирмонтепа | I1: Тирсакобод | J1: Хайрабод | K1: Хирмон тепа | L1: Хонтўпи | M1: Шараф | N1: Шарқ | O1: Шарқ тонги | P1: Шухрат | Q1: 1-Чарх Камолон | R1: 2-Чарх Камолон | S1: 3-Чарх Камолон | T1: Бешёғоч | U1: Катта Козиробод | V1: Катта Олмазор | W1: Катта Чилонзор-1 | X1: Катта Чилонзор-2 | Y1: Катта Чилонзор-3 | Z1: Қозиробод | AA1: Новза | AB1: Чилонзор | AC1: 1-Қатортол | AD1: Бешчинор | AE1: Боғзор | AF1: Диёр | AG1: Дилобод | AH1: Катта Навбаҳор | AI1: Кўркам | AJ1: Кўтарма | AK1: Қатортол | AL1: Лутфий | AM1: Навбахор | AN1: Нафосат | AO1: Оқ-тепа | AP1: Халқлар Дўстлиги | AQ1: Чўпон-ота | AR1: 2-Қатортол | AS1: Ботирма | AT1: Бўрижар | AU1: Гавхар | AV1: Дўмбиробод | AW1: Зарқўрғон | AX1: Катта Дўмбиробод | AY1: Кичик Хирмонтепа | AZ1: Мевазор | BA1: Мехржон | BB1: Наққошлик | BC1: Фидокор | BD1: Яккабоғ | BE1: Яккатут | BF1: Бешқўрғон
A2: 1. | B2: Савдо ва маиший хизмат кўрсатиш объектларини техник қўриқловга олиш | C2: =+SUM(D2:BF2) -> 3 | D2: =+SUM(D3:D7) -> 0 | E2: =+SUM(E3:E7) -> 0 | F2: =+SUM(F3:F7) -> 0 | G2: =+SUM(G3:G7) -> 0 | H2: =+SUM(H3:H7) -> 0 | I2: =+SUM(I3:I7) -> 0 | J2: =+SUM(J3:J7) -> 0 | K2: =+SUM(K3:K7) -> 0 | ... BF2: =+SUM(BF3:BF7) -> 0
A3: шундан | B3: савдо дўконлари | C3: =+SUM(D3:BF3) -> 0
B4: спиртли ичимликлар дўконлари | C4: =+SUM(D4:BF4) -> 0
B5: умумий овқатланиш жойлари | C5: =+SUM(D5:BF5) -> 0
B6: компьютер-плейстейшн | C6: =+SUM(D6:BF6) -> 0
B7: бошқа турдаги объектлар | C7: =+SUM(D7:BF7) -> 3 | Z7: 1 | AN7: 1 | AX7: 1
A8: 2. | B8: Кўп қаватли ва якка тартибдаги хонадонларни техник қўриқловга олиш | C8: =+SUM(D8:BF8) -> 10 | G8: 2 | W8: 3 | AE8: 2 | AG8: 1 | AK8: 1 | AL8: 1
A9: 3. | B9: Кўп қаватли уйларнинг кириш йўлаклари олдига ташвиш тугмаларини ўрнатиш | C9: =+SUM(D9:BF9) -> 0
A10: 4. | B10: Кун давомида келиб тушган "ташвиш хабарлари" | C10: 39 | D10: 2 | E10: 1 | F10: 4 | G10: 2 | H10: 3 | I10: 3 | K10: 2 | M10: 1 | N10: 1 | Q10: 3 | U10: 1 | X10: 3 | Z10: 2 | AC10: 1 | AE10: 2 | AG10: 3 | AI10: 1 | AS10: 1 | AX10: 2 | BB10: 1
A11: 4.1. | B11: Чақирувга асосан ҳодиса жойига етиб борган тезкор ҳаракатланувчи гуруҳ | C11: 39 | D11: 2 | E11: 1 | F11: 4 | G11: 2 | H11: 3 | I11: 3 | K11: 2 | M11: 1 | N11: 1 | Q11: 3 | U11: 1 | X11: 3 | Z11: 2 | AC11: 1 | AE11: 2 | AG11: 3 | AI11: 1 | AS11: 1 | AX11: 2 | BB11: 1
A12: 5. | B12: тезкор ҳаракатланувчи гуруҳлар томонидан аниқланган жиноятлар | C12: =+SUM(D12:BF12) -> 2 | Y12: 1 | AG12: 1
A13: 6. | B13: тезкор ҳаракатланувчи гуруҳлар томонидан ушланган қидирувдаги шахслар | C13: =+SUM(D13:BF13) -> 2 | H13: 1 | AA13: 1
A14: 7. | B14: Қўриқлаш хизмати афзалликлари бўйича тарғибот учрашувлари ўтказиш | C14: =+SUM(D14:BF14) -> 100 | D14: 1 | E14: 2 | F14: 2 | G14: 3 | H14: 3 | I14: 2 | J14: 3 | K14: 2 | L14: 2 | M14: 1 | N14: 3 | O14: 2 | P14: 3 | Q14: 2 | R14: 2 | S14: 3 | T14: 2 | U14: 2 | V14: 3 | W14: 1 | X14: 2 | Y14: 3 | Z14: 3 | AA14: 3 | AB14: 1 | AC14: 2 | AD14: 1 | AE14: 1 | AF14: 2 | AG14: 1 | AH14: 1 | AI14: 1 | AJ14: 2 | AK14: 3 | AL14: 1 | AM14: 2 | AN14: 1 | AO14: 2 | AP14: 1 | AQ14: 2 | AR14: 1 | AS14: 2 | AT14: 1 | AU14: 2 | AV14: 2 | AW14: 2 | AX14: 1 | AY14: 2 | AZ14: 1 | BA14: 1 | BB14: 1 | BC14: 2 | BD14: 1 | BE14: 1 | BF14: 1
A15: 8. | B15: “Объект қўриқловда!” ва “Хонадон қўриқловда!” стикерларини жойлаштириш | C15: =+SUM(D15:BF15) -> 85 | D15: 2 | F15: 5 | G15: 3 | J15: 2 | K15: 3 | M15: 2 | N15: 1 | P15: 2 | Q15: 5 | R15: 1 | S15: 3 | U15: 3 | V15: 4 | W15: 1 | Y15: 1 | Z15: 3 | AA15: 2 | AB15: 5 | AC15: 2 | AD15: 2 | AF15: 2 | AH15: 1 | AI15: 1 | AJ15: 2 | AK15: 3 | AL15: 2 | AM15: 1 | AN15: 1 | AO15: 2 | AR15: 2 | AS15: 1 | AT15: 1 | AU15: 2 | AW15: 1 | AY15: 1 | AZ15: 2 | BB15: 2 | BD15: 3 | BF15: 3
A16: 9. | B16: Объектларни жисмоний қўриқловга олиш | C16: =+SUM(D16:BF16) -> 0 | D16: =+D17+D18+D19 -> 0 | E16: =+E17+E18+E19 -> 0 | F16: =+F17+F18+F19 -> 0 | G16: =+G17+G18+G19 -> 0 | H16: =+H17+H18+H19 -> 0 | I16: =+I17+I18+I19 -> 0 | J16: =+J17+J18+J19 -> 0 | K16: =+K17+K18+K19 -> 0 | ... BF16: =+BF17+BF18+BF19 -> 0
A17: шундан | B17: шаҳодатланган таркиб | C17: =+SUM(D17:BF17) -> 0
B18: ҳарбийлаштирилган соқчи | C18: =+SUM(D18:BF18) -> 0
B19: қоровуллик | C19: =+SUM(D19:BF19) -> 0
A21: 1. | B21: Савдо ва маиший хизмат кўрсатиш объектларини техник қўриқловга олиш | C21: 0 | D21: 0 | E21: -1 | F21: -1 | G21: 0 | H21: 2 | I21: 0 | J21: 0 | K21: 0 | L21: 0 | M21: -2 | N21: 2 | O21: 0 | P21: 0 | Q21: 0 | R21: -1 | S21: 1 | T21: 0 | U21: -2 | V21: 2 | W21: 0 | X21: -1 | Y21: 1 | Z21: 0 | AA21: 0 | AB21: 0 | AC21: 0 | AD21: -1 | AE21: 1 | AF21: -2 | AG21: 2 | AH21: 0 | AI21: -2 | AJ21: 1 | AK21: 1 | AL21: -9 | AM21: 9 | AN21: 0 | AO21: 0 | AP21: 0 | AQ21: 0 | AR21: 0 | AS21: -5 | AT21: 5 | AU21: 0 | AV21: 0 | AW21: -1 | AX21: 0 | AY21: 1 | AZ21: 0 | BA21: -1 | BB21: 1 | BC21: 0 | BD21: 0 | BE21: -1 | BF21: 1
A22: шундан | B22: савдо дўконлари | C22: 0 | D22: 0 | E22: -1 | F22: -1 | G22: 0 | H22: 2 | I22: 0 | J22: 0 | K22: 0 | L22: 0 | M22: -2 | N22: 2 | O22: 0 | P22: 0 | Q22: 0 | R22: -1 | S22: 1 | T22: 0 | U22: -2 | V22: 2 | W22: 0 | X22: -1 | Y22: 1 | Z22: 0 | AA22: 0 | AB22: 0 | AC22: 0 | AD22: -1 | AE22: 1 | AF22: -2 | AG22: 2 | AH22: 0 | AI22: -2 | AJ22: 1 | AK22: 1 | AL22: -9 | AM22: 9 | AN22: 0 | AO22: 0 | AP22: 0 | AQ22: 0 | AR22: 0 | AS22: -5 | AT22: 5 | AU22: 0 | AV22: 0 | AW22: -1 | AX22: 0 | AY22: 1 | AZ22: 0 | BA22: -1 | BB22: 1 | BC22: 0 | BD22: 0 | BE22: -1 | BF22: 1

Sheet 01.21
A1: № | B1: Кўрсаткич | C1: жами | D1: Ал-Хоразмий | E1: Бахористон | F1: Бектўпи | G1: Гулистон | H1: Катта Хирмонтепа | I1: Тирсакобод | J1: Хайрабод | K1: Хирмон тепа | L1: Хонтўпи | M1: Шараф | N1: Шарқ | O1: Шарқ тонги | P1: Шухрат | Q1: 1-Чарх Камолон | R1: 2-Чарх Камолон | S1: 3-Чарх Камолон | T1: Бешёғоч | U1: Катта Козиробод | V1: Катта Олмазор | W1: Катта Чилонзор-1 | X1: Катта Чилонзор-2 | Y1: Катта Чилонзор-3 | Z1: Қозиробод | AA1: Новза | AB1: Чилонзор | AC1: 1-Қатортол | AD1: Бешчинор | AE1: Боғзор | AF1: Диёр | AG1: Дилобод | AH1: Катта Навбаҳор | AI1: Кўркам | AJ1: Кўтарма | AK1: Қатортол | AL1: Лутфий | AM1: Навбахор | AN1: Нафосат | AO1: Оқ-тепа | AP1: Халқлар Дўстлиги | AQ1: Чўпон-ота | AR1: 2-Қатортол | AS1: Ботирма | AT1: Бўрижар | AU1: Гавхар | AV1: Дўмбиробод | AW1: Зарқўрғон | AX1: Катта Дўмбиробод | AY1: Кичик Хирмонтепа | AZ1: Мевазор | BA1: Мехржон | BB1: Наққошлик | BC1: Фидокор | BD1: Яккабоғ | BE1: Яккатут | BF1: Бешқўрғон
A2: 1. | B2: Савдо ва маиший хизмат кўрсатиш объектларини техник қўриқловга олиш | D2: =+SUM(D3:D7) -> 0 | E2: =+SUM(E3:E7) -> 0 | F2: =+SUM(F3:F7) -> 0 | G2: =+SUM(G3:G7) -> 0 | I2: =+SUM(I3:I7) -> 0 | J2: =+SUM(J3:J7) -> 0 | K2: =+SUM(K3:K7) -> 0 | L2: =+SUM(L3:L7) -> 0 | M2: =+SUM(M3:M7) -> 0 | N2: =+SUM(N3:N7) -> 0 | O2: =+SUM(O3:O7) -> 0 | Q2: =+SUM(Q3:Q7) -> 0 | R2: =+SUM(R3:R7) -> 0 | S2: =+SUM(S3:S7) -> 0 | T2: =+SUM(T3:T7) -> 0 | U2: =+SUM(U3:U7) -> 0 | V2: =+SUM(V3:V7) -> 0 | W2: =+SUM(W3:W7) -> 0 | X2: =+SUM(X3:X7) -> 0 | ... AD2: =+SUM(AD3:AD7) -> 0 | AF2: =+SUM(AF3:AF7) -> 0 | AG2: =+SUM(AG3:AG7) -> 0 | AH2: =+SUM(AH3:AH7) -> 0 | AI2: =+SUM(AI3:AI7) -> 0 | AJ2: =+SUM(AJ3:AJ7) -> 0 | AK2: =+SUM(AK3:AK7) -> 0 | AL2: =+SUM(AL3:AL7) -> 0 | AM2: =+SUM(AM3:AM7) -> 0 | ... AQ2: =+SUM(AQ3:AQ7) -> 0 | AS2: =+SUM(AS3:AS7) -> 0 | AT2: =+SUM(AT3:AT7) -> 0 | AU2: =+SUM(AU3:AU7) -> 0 | AV2: =+SUM(AV3:AV7) -> 0 | AX2: =+SUM(AX3:AX7) -> 0 | AY2: =+SUM(AY3:AY7) -> 0 | AZ2: =+SUM(AZ3:AZ7) -> 0 | BA2: =+SUM(BA3:BA7) -> 0 | BB2: =+SUM(BB3:BB7) -> 0 | BD2: =+SUM(BD3:BD7) -> 0 | BE2: =+SUM(BE3:BE7) -> 0 | BF2: =+SUM(BF3:BF7) -> 0
A3: шундан | B3: савдо дўконлари | C3: =+SUM(D3:BF3) -> 0
B4: спиртли ичимликлар дўконлари | C4: =+SUM(D4:BF4) -> 0
B5: умумий овқатланиш жойлари | C5: =+SUM(D5:BF5) -> 0
B6: компьютер-плейстейшн | C6: =+SUM(D6:BF6) -> 0
B7: бошқа турдаги объектлар | C7: =+SUM(D7:BF7) -> 0
A8: 2. | B8: Кўп қаватли ва якка тартибдаги хонадонларни техник қўриқловга олиш | C8: =+SUM(D8:BF8) -> 8 | H8: 1 | P8: 1 | AE8: 2 | AR8: 2 | AW8: 1 | BC8: 1
A9: 3. | B9: Кўп қаватли уйларнинг кириш йўлаклари олдига ташвиш тугмаларини ўрнатиш | C9: =+SUM(D9:BF9) -> 12 | W9: 12
A10: 4. | B10: Кун давомида келиб тушган "ташвиш хабарлари" | C10: =+SUM(D10:BF10) -> 30 | D10: 1 | F10: 1 | I10: 1 | L10: 1 | O10: 2 | Q10: 1 | R10: 1 | U10: 1 | W10: 1 | Y10: 1 | AB10: 1 | AD10: 1 | AH10: 2 | AJ10: 1 | AL10: 1 | AN10: 1 | AP10: 2 | AR10: 1 | AU10: 1 | AW10: 1 | AX10: 2 | AY10: 1 | BA10: 1 | BC10: 1 | BD10: 1 | BE10: 1
A11: 4.1. | B11: Чақирувга асосан ҳодиса жойига етиб борган тезкор ҳаракатланувчи гуруҳ | C11: =+SUM(D11:BF11) -> 30 | D11: 1 | F11: 1 | I11: 1 | L11: 1 | O11: 2 | Q11: 1 | R11: 1 | U11: 1 | W11: 1 | Y11: 1 | AB11: 1 | AD11: 1 | AH11: 2 | AJ11: 1 | AL11: 1 | AN11: 1 | AP11: 2 | AR11: 1 | AU11: 1 | AW11: 1 | AX11: 2 | AY11: 1 | BA11: 1 | BC11: 1 | BD11: 1 | BE11: 1
A12: 5. | B12: тезкор ҳаракатланувчи гуруҳлар томонидан аниқланган жиноятлар | C12: =+SUM(D12:BF12) -> 0
A13: 6. | B13: тезкор ҳаракатланувчи гуруҳлар томонидан ушланган қидирувдаги шахслар | C13: =+SUM(D13:BF13) -> 3 | AM13: 1 | AN13: 1 | AR13: 1
A14: 7. | B14: Қўриқлаш хизмати афзалликлари бўйича тарғибот учрашувлари ўтказиш | C14: =+SUM(D14:BF14) -> 90 | D14: 2 | E14: 3 | F14: 1 | G14: 2 | H14: 1 | I14: 2 | J14: 1 | K14: 2 | L14: 1 | M14: 2 | N14: 3 | O14: 2 | P14: 5 | Q14: 2 | R14: 3 | S14: 2 | T14: 1 | U14: 3 | V14: 4 | W14: 3 | X14: 5 | Y14: 2 | Z14: 1 | AA14: 1 | AB14: 2 | AC14: 1 | AD14: 2 | AE14: 3 | AF14: 1 | AG14: 2 | AH14: 1 | AI14: 2 | AJ14: 1 | AK14: 1 | AL14: 2 | AM14: 2 | AN14: 3 | AO14: 1 | AQ14: 2 | AR14: 3 | AS14: 1 | AT14: 2 | AU14: 1 | AV14: 2 | AW14: 1
A15: 8. | B15: “Объект қўриқловда!” ва “Хонадон қўриқловда!” стикерларини жойлаштириш | C15: =+SUM(D15:BF15) -> 65 | D15: 1 | E15: 1 | F15: 2 | G15: 1 | H15: 2 | I15: 1 | J15: 2 | K15: 1 | L15: 2 | M15: 1 | N15: 2 | O15: 1 | P15: 3 | Q15: 1 | R15: 2 | S15: 1 | T15: 2 | U15: 2 | V15: 1 | W15: 3 | X15: 1 | Y15: 2 | Z15: 1 | AA15: 2 | AB15: 1 | AC15: 2 | AD15: 1 | AE15: 1 | AF15: 2 | AG15: 2 | AH15: 1 | AI15: 1 | AL15: 1 | AN15: 1 | AQ15: 1 | AR15: 2 | AS15: 1 | AU15: 1 | AV15: 1 | AW15: 2 | AX15: 1 | AY15: 1 | AZ15: 2 | BA15: 1 | BD15: 1
A16: 9. | B16: Объектларни жисмоний қўриқловга олиш | C16: =+SUM(D16:BF16) -> 1 | AL16: 1
A17: шундан | B17: шаҳодатланган таркиб | C17: =+SUM(D17:BF17) -> 6 | AL17: 6
B18: ҳарбийлаштирилган соқчи | C18: =+SUM(D18:BF18) -> 0
B19: қоровуллик | C19: =+SUM(D19:BF19) -> 0

Sheet 01.22
A1: № | B1: Кўрсаткич | C1: жами | D1: Ал-Хоразмий | E1: Бахористон | F1: Бектўпи | G1: Гулистон | H1: Катта Хирмонтепа | I1: Тирсакобод | J1: Хайрабод | K1: Хирмон тепа | L1: Хонтўпи | M1: Шараф | N1: Шарқ | O1: Шарқ тонги | P1: Шухрат | Q1: 1-Чарх Камолон | R1: 2-Чарх Камолон | S1: 3-Чарх Камолон | T1: Бешёғоч | U1: Катта Козиробод | V1: Катта Олмазор | W1: Катта Чилонзор-1 | X1: Катта Чилонзор-2 | Y1: Катта Чилонзор-3 | Z1: Қозиробод | AA1: Новза | AB1: Чилонзор | AC1: 1-Қатортол | AD1: Бешчинор | AE1: Боғзор | AF1: Диёр | AG1: Дилобод | AH1: Катта Навбаҳор | AI1: Кўркам | AJ1: Кўтарма | AK1: Қатортол | AL1: Лутфий | AM1: Навбахор | AN1: Нафосат | AO1: Оқ-тепа | AP1: Халқлар Дўстлиги | AQ1: Чўпон-ота | AR1: 2-Қатортол | AS1: Ботирма | AT1: Бўрижар | AU1: Гавхар | AV1: Дўмбиробод | AW1: Зарқўрғон | AX1: Катта Дўмбиробод | AY1: Кичик Хирмонтепа | AZ1: Мевазор | BA1: Мехржон | BB1: Наққошлик | BC1: Фидокор | BD1: Яккабоғ | BE1: Яккатут | BF1: Бешқўрғон
A2: 1. | B2: Савдо ва маиший хизмат кўрсатиш объектларини техник қўриқловга олиш | C2: =+SUM(D2:BF2) -> 3 | D2: =+SUM(D3:D7) -> 0 | E2: =+SUM(E3:E7) -> 0 | F2: =+SUM(F3:F7) -> 0 | G2: =+SUM(G3:G7) -> 0 | H2: =+SUM(H3:H7) -> 0 | I2: =+SUM(I3:I7) -> 0 | J2: =+SUM(J3:J7) -> 0 | K2: =+SUM(K3:K7) -> 0 | ... BF2: =+SUM(BF3:BF7) -> 1
A3: шундан | B3: савдо дўконлари | C3: =+SUM(D3:BF3) -> 0
B4: спиртли ичимликлар дўконлари | C4: =+SUM(D4:BF4) -> 0
B5: умумий овқатланиш жойлари | C5: =+SUM(D5:BF5) -> 0
B6: компьютер-плейстейшн | C6: =+SUM(D6:BF6) -> 0
B7: бошқа турдаги объектлар | C7: =+SUM(D7:BF7) -> 3 | AU7: 2 | BF7: 1
A8: 2. | B8: Кўп қаватли ва якка тартибдаги хонадонларни техник қўриқловга олиш | C8: =+SUM(D8:BF8) -> 4 | L8: 1 | N8: 1 | AP8: 2
A9: 3. | B9: Кўп қаватли уйларнинг кириш йўлаклари олдига ташвиш тугмаларини ўрнатиш | C9: =+SUM(D9:BF9) -> 0
A10: 4. | B10: Кун давомида келиб тушган "ташвиш хабарлари" | C10: =+SUM(D10:BF10) -> 6 | O10: 1 | W10: 1 | AB10: 1 | AJ10: 1 | AW10: 1 | BF10: 1
A11: 4.1. | B11: Чақирувга асосан ҳодиса жойига етиб борган тезкор ҳаракатланувчи гуруҳ | C11: =+SUM(D11:BF11) -> 6 | O11: 1 | W11: 1 | AB11: 1 | AJ11: 1 | AW11: 1 | BF11: 1
A12: 5. | B12: тезкор ҳаракатланувчи гуруҳлар томонидан аниқланган жиноятлар | C12: =+SUM(D12:BF12) -> 0
A13: 6. | B13: тезкор ҳаракатланувчи гуруҳлар томонидан ушланган қидирувдаги шахслар | C13: =+SUM(D13:BF13) -> 0
A14: 7. | B14: Қўриқлаш хизмати афзалликлари бўйича тарғибот учрашувлари ўтказиш | C14: =+SUM(D14:BF14) -> 51 | D14: 5 | J14: 3 | N14: 10 | T14: 7 | Y14: 4 | AB14: 5 | AE14: 10 | AS14: 4 | AY14: 3
A15: 8. | B15: “Объект қўриқловда!” ва “Хонадон қўриқловда!” стикерларини жойлаштириш | C15: =+SUM(D15:BF15) -> 22 | D15: 2 | J15: 3 | R15: 4 | Z15: 2 | AE15: 4 | AK15: 4 | AV15: 3
A16: 9. | B16: Объектларни жисмоний қўриқловга олиш | C16: =+SUM(D16:BF16) -> 0
A17: шундан | B17: шаҳодатланган таркиб | C17: =+SUM(D17:BF17) -> 0
B18: ҳарбийлаштирилган соқчи | C18: =+SUM(D18:BF18) -> 0
B19: қоровуллик | C19: =+SUM(D19:BF19) -> 0

Sheet 01.23
A1: № | B1: Кўрсаткич | C1: жами | D1: Ал-Хоразмий | E1: Бахористон | F1: Бектўпи | G1: Гулистон | H1: Катта Хирмонтепа | I1: Тирсакобод | J1: Хайрабод | K1: Хирмон тепа | L1: Хонтўпи | M1: Шараф | N1: Шарқ | O1: Шарқ тонги | P1: Шухрат | Q1: 1-Чарх Камолон | R1: 2-Чарх Камолон | S1: 3-Чарх Камолон | T1: Бешёғоч | U1: Катта Козиробод | V1: Катта Олмазор | W1: Катта Чилонзор-1 | X1: Катта Чилонзор-2 | Y1: Катта Чилонзор-3 | Z1: Қозиробод | AA1: Новза | AB1: Чилонзор | AC1: 1-Қатортол | AD1: Бешчинор | AE1: Боғзор | AF1: Диёр | AG1: Дилобод | AH1: Катта Навбаҳор | AI1: Кўркам | AJ1: Кўтарма | AK1: Қатортол | AL1: Лутфий | AM1: Навбахор | AN1: Нафосат | AO1: Оқ-тепа | AP1: Халқлар Дўстлиги | AQ1: Чўпон-ота | AR1: 2-Қатортол | AS1: Ботирма | AT1: Бўрижар | AU1: Гавхар | AV1: Дўмбиробод | AW1: Зарқўрғон | AX1: Катта Дўмбиробод | AY1: Кичик Хирмонтепа | AZ1: Мевазор | BA1: Мехржон | BB1: Наққошлик | BC1: Фидокор | BD1: Яккабоғ | BE1: Яккатут | BF1: Бешқўрғон
A2: 1. | B2: Савдо ва маиший хизмат кўрсатиш объектларини техник қўриқловга олиш | C2: =+SUM(D2:BF2) -> 3 | D2: =+SUM(D3:D7) -> 0 | E2: =+SUM(E3:E7) -> 0 | F2: =+SUM(F3:F7) -> 0 | G2: =+SUM(G3:G7) -> 0 | H2: =+SUM(H3:H7) -> 0 | I2: =+SUM(I3:I7) -> 0 | J2: =+SUM(J3:J7) -> 0 | K2: =+SUM(K3:K7) -> 0 | ... BF2: =+SUM(BF3:BF7) -> 0
A3: шундан | B3: савдо дўконлари | C3: =+SUM(D3:BF3) -> 1 | BB3: 1
B4: спиртли ичимликлар дўконлари | C4: =+SUM(D4:BF4) -> 0
B5: умумий овқатланиш жойлари | C5: =+SUM(D5:BF5) -> 0
B6: компьютер-плейстейшн | C6: =+SUM(D6:BF6) -> 1 | AF6: 1
B7: бошқа турдаги объектлар | C7: =+SUM(D7:BF7) -> 1 | BA7: 1
A8: 2. | B8: Кўп қаватли ва якка тартибдаги хонадонларни техник қўриқловга олиш | C8: =+SUM(D8:BF8) -> 6 | F8: 1 | M8: 1 | W8: 1 | AB8: 1 | AH8: 1 | AS8: 1
A9: 3. | B9: Кўп қаватли уйларнинг кириш йўлаклари олдига ташвиш тугмаларини ўрнатиш | C9: =+SUM(D9:BF9) -> 5 | W9: 5
A10: 4. | B10: Кун давомида келиб тушган "ташвиш хабарлари" | C10: =+SUM(D10:BF10) -> 35 | D10: 3 | E10: 2 | H10: 1 | O10: 1 | T10: 1 | W10: 2 | X10: 1 | Y10: 2 | Z10: 1 | AB10: 2 | AG10: 2 | AJ10: 3 | AK10: 1 | AL10: 1 | AM10: 1 | AO10: 1 | AS10: 1 | AW10: 3 | AZ10: 1 | BC10: 2 | BF10: 3
A11: 4.1. | B11: Чақирувга асосан ҳодиса жойига етиб борган тезкор ҳаракатланувчи гуруҳ | C11: =+SUM(D11:BF11) -> 35 | D11: 3 | E11: 2 | H11: 1 | O11: 1 | T11: 1 | W11: 2 | X11: 1 | Y11: 2 | Z11: 1 | AB11: 2 | AG11: 2 | AJ11: 3 | AK11: 1 | AL11: 1 | AM11: 1 | AO11: 1 | AS11: 1 | AW11: 3 | AZ11: 1 | BC11: 2 | BF11: 3
A12: 5. | B12: тезкор ҳаракатланувчи гуруҳлар томонидан аниқланган жиноятлар | C12: =+SUM(D12:BF12) -> 0
A13: 6. | B13: тезкор ҳаракатланувчи гуруҳлар томонидан ушланган қидирувдаги шахслар | C13: =+SUM(D13:BF13) -> 0
A14: 7. | B14: Қўриқлаш хизмати афзалликлари бўйича тарғибот учрашувлари ўтказиш | C14: =+SUM(D14:BF14) -> 36 | L14: 2 | M14: 2 | U14: 1 | Z14: 2 | AC14: 4 | AD14: 3 | AF14: 2 | AG14: 4 | AH14: 5 | AX14: 3 | BB14: 3 | BE14: 2 | BF14: 3
A15: 8. | B15: “Объект қўриқловда!” ва “Хонадон қўриқловда!” стикерларини жойлаштириш | C15: =+SUM(D15:BF15) -> 18 | E15: 2 | I15: 3 | O15: 4 | X15: 3 | AP15: 2 | BC15: 1 | BE15: 3
A16: 9. | B16: Объектларни жисмоний қўриқловга олиш | C16: =+SUM(D16:BF16) -> 0
A17: шундан | B17: шаҳодатланган таркиб | C17: =+SUM(D17:BF17) -> 0
B18: ҳарбийлаштирилган соқчи | C18: =+SUM(D18:BF18) -> 0
B19: қоровуллик | C19: =+SUM(D19:BF19) -> 0

Sheet 01.24
A1: № | B1: Кўрсаткич | C1: жами | D1: Ал-Хоразмий | E1: Бахористон | F1: Бектўпи | G1: Гулистон | H1: Катта Хирмонтепа | I1: Тирсакобод | J1: Хайрабод | K1: Хирмон тепа | L1: Хонтўпи | M1: Шараф | N1: Шарқ | O1: Шарқ тонги | P1: Шухрат | Q1: 1-Чарх Камолон | R1: 2-Чарх Камолон | S1: 3-Чарх Камолон | T1: Бешёғоч | U1: Катта Козиробод | V1: Катта Олмазор | W1: Катта Чилонзор-1 | X1: Катта Чилонзор-2 | Y1: Катта Чилонзор-3 | Z1: Қозиробод | AA1: Новза | AB1: Чилонзор | AC1: 1-Қатортол | AD1: Бешчинор | AE1: Боғзор | AF1: Диёр | AG1: Дилобод | AH1: Катта Навбаҳор | AI1: Кўркам | AJ1: Кўтарма | AK1: Қатортол | AL1: Лутфий | AM1: Навбахор | AN1: Нафосат | AO1: Оқ-тепа | AP1: Халқлар Дўстлиги | AQ1: Чўпон-ота | AR1: 2-Қатортол | AS1: Ботирма | AT1: Бўрижар | AU1: Гавхар | AV1: Дўмбиробод | AW1: Зарқўрғон | AX1: Катта Дўмбиробод | AY1: Кичик Хирмонтепа | AZ1: Мевазор | BA1: Мехржон | BB1: Наққошлик | BC1: Фидокор | BD1: Яккабоғ | BE1: Яккатут | BF1: Бешқўрғон
A2: 1. | B2: Савдо ва маиший хизмат кўрсатиш объектларини техник қўриқловга олиш | C2: =+SUM(D2:BF2) -> 2 | D2: =+SUM(D3:D7) -> 0 | E2: =+SUM(E3:E7) -> 0 | F2: =+SUM(F3:F7) -> 0 | G2: =+SUM(G3:G7) -> 1 | H2: =+SUM(H3:H7) -> 0 | I2: =+SUM(I3:I7) -> 0 | J2: =+SUM(J3:J7) -> 0 | K2: =+SUM(K3:K7) -> 0 | ... BF2: =+SUM(BF3:BF7) -> 0
A3: шундан | B3: савдо дўконлари | C3: =+SUM(D3:BF3) -> 1 | G3: 1
B4: спиртли ичимликлар дўконлари | C4: =+SUM(D4:BF4) -> 0
B5: умумий овқатланиш жойлари | C5: =+SUM(D5:BF5) -> 0
B6: компьютер-плейстейшн | C6: =+SUM(D6:BF6) -> 0
B7: бошқа турдаги объектлар | C7: =+SUM(D7:BF7) -> 1 | AL7: 1
A8: 2. | B8: Кўп қаватли ва якка тартибдаги хонадонларни техник қўриқловга олиш | C8: =+SUM(D8:BF8) -> 12 | G8: 2 | O8: 1 | Z8: 1 | AA8: 2 | AK8: 1 | AP8: 1 | AW8: 3 | BF8: 1
A9: 3. | B9: Кўп қаватли уйларнинг кириш йўлаклари олдига ташвиш тугмаларини ўрнатиш | C9: =+SUM(D9:BF9) -> 8 | W9: 8
A10: 4. | B10: Кун давомида келиб тушган "ташвиш хабарлари" | C10: =+SUM(D10:BF10) -> 20 | D10: 1 | E10: 2 | H10: 1 | I10: 1 | T10: 1 | V10: 1 | AA10: 1 | AG10: 2 | AJ10: 2 | AK10: 1 | AO10: 1 | AQ10: 1 | AU10: 1 | AZ10: 2 | BA10: 1 | BF10: 1
A11: 4.1. | B11: Чақирувга асосан ҳодиса жойига етиб борган тезкор ҳаракатланувчи гуруҳ | C11: =+SUM(D11:BF11) -> 20 | D11: 1 | E11: 2 | H11: 1 | I11: 1 | T11: 1 | V11: 1 | AA11: 1 | AG11: 2 | AJ11: 2 | AK11: 1 | AO11: 1 | AQ11: 1 | AU11: 1 | AZ11: 2 | BA11: 1 | BF11: 1
A12: 5. | B12: тезкор ҳаракатланувчи гуруҳлар томонидан аниқланган жиноятлар | C12: =+SUM(D12:BF12) -> 0
A13: 6. | B13: тезкор ҳаракатланувчи гуруҳлар томонидан ушланган қидирувдаги шахслар | C13: =+SUM(D13:BF13) -> 0
A14: 7. | B14: Қўриқлаш хизмати афзалликлари бўйича тарғибот учрашувлари ўтказиш | C14: =+SUM(D14:BF14) -> 67 | F14: 5 | L14: 3 | O14: 4 | AI14: 5 | AJ14: 3 | AL14: 6 | AP14: 5 | AT14: 4 | AU14: 2 | AW14: 4 | AZ14: 5 | BA14: 5 | BC14: 5 | BD14: 5 | BE14: 4 | BF14: 2
A15: 8. | B15: “Объект қўриқловда!” ва “Хонадон қўриқловда!” стикерларини жойлаштириш | C15: =+SUM(D15:BF15) -> 36 | E15: 2 | H15: 2 | L15: 1 | T15: 2 | Y15: 2 | AD15: 1 | AM15: 3 | AQ15: 2 | AS15: 1 | AT15: 2 | AU15: 2 | AX15: 2 | AY15: 2 | BA15: 3 | BB15: 3 | BC15: 3 | BE15: 2 | BF15: 1
A16: 9. | B16: Объектларни жисмоний қўриқловга олиш | C16: =+SUM(D16:BF16) -> 0
A17: шундан | B17: шаҳодатланган таркиб | C17: =+SUM(D17:BF17) -> 0
B18: ҳарбийлаштирилган соқчи | C18: =+SUM(D18:BF18) -> 0
B19: қоровуллик | C19: =+SUM(D19:BF19) -> 0

Sheet 01.25
A1: № | B1: Кўрсаткич | C1: жами | D1: Ал-Хоразмий | E1: Бахористон | F1: Бектўпи | G1: Гулистон | H1: Катта Хирмонтепа | I1: Тирсакобод | J1: Хайрабод | K1: Хирмон тепа | L1: Хонтўпи | M1: Шараф | N1: Шарқ | O1: Шарқ тонги | P1: Шухрат | Q1: 1-Чарх Камолон | R1: 2-Чарх Камолон | S1: 3-Чарх Камолон | T1: Бешёғоч | U1: Катта Козиробод | V1: Катта Олмазор | W1: Катта Чилонзор-1 | X1: Катта Чилонзор-2 | Y1: Катта Чилонзор-3 | Z1: Қозиробод | AA1: Новза | AB1: Чилонзор | AC1: 1-Қатортол | AD1: Бешчинор | AE1: Боғзор | AF1: Диёр | AG1: Дилобод | AH1: Катта Навбаҳор | AI1: Кўркам | AJ1: Кўтарма | AK1: Қатортол | AL1: Лутфий | AM1: Навбахор | AN1: Нафосат | AO1: Оқ-тепа | AP1: Халқлар Дўстлиги | AQ1: Чўпон-ота | AR1: 2-Қатортол | AS1: Ботирма | AT1: Бўрижар | AU1: Гавхар | AV1: Дўмбиробод | AW1: Зарқўрғон | AX1: Катта Дўмбиробод | AY1: Кичик Хирмонтепа | AZ1: Мевазор | BA1: Мехржон | BB1: Наққошлик | BC1: Фидокор | BD1: Яккабоғ | BE1: Яккатут | BF1: Бешқўрғон
A2: 1. | B2: Савдо ва маиший хизмат кўрсатиш объектларини техник қўриқловга олиш | C2: =+SUM(D2:BF2) -> 3 | D2: =+SUM(D3:D7) -> 0 | E2: =+SUM(E3:E7) -> 0 | F2: =+SUM(F3:F7) -> 3 | G2: =+SUM(G3:G7) -> 0 | H2: =+SUM(H3:H7) -> 0 | I2: =+SUM(I3:I7) -> 0 | J2: =+SUM(J3:J7) -> 0 | K2: =+SUM(K3:K7) -> 0 | ... BF2: =+SUM(BF3:BF7) -> 0
A3: шундан | B3: савдо дўконлари | C3: =+SUM(D3:BF3) -> 0
B4: спиртли ичимликлар дўконлари | C4: =+SUM(D4:BF4) -> 0
B5: умумий овқатланиш жойлари | C5: =+SUM(D5:BF5) -> 1 | F5: 1
B6: компьютер-плейстейшн | C6: =+SUM(D6:BF6) -> 0
B7: бошқа турдаги объектлар | C7: =+SUM(D7:BF7) -> 2 | F7: 2
A8: 2. | B8: Кўп қаватли ва якка тартибдаги хонадонларни техник қўриқловга олиш | C8: =+SUM(D8:BF8) -> 7 | G8: 1 | AL8: 1 | AM8: 1 | AS8: 2 | AW8: 2
A9: 3. | B9: Кўп қаватли уйларнинг кириш йўлаклари олдига ташвиш тугмаларини ўрнатиш | C9: =+SUM(D9:BF9) -> 0
A10: 4. | B10: Кун давомида келиб тушган "ташвиш хабарлари" | C10: =+SUM(D10:BF10) -> 35 | D10: 1 | I10: 2 | U10: 1 | X10: 2 | Z10: 4 | AB10: 1 | AG10: 1 | AJ10: 4 | AK10: 2 | AL10: 1 | AM10: 2 | AP10: 1 | AQ10: 2 | AS10: 3 | AW10: 2 | AZ10: 2 | BB10: 1 | BF10: 3
A11: 4.1. | B11: Чақирувга асосан ҳодиса жойига етиб борган тезкор ҳаракатланувчи гуруҳ | C11: =+SUM(D11:BF11) -> 35 | D11: 1 | I11: 2 | U11: 1 | X11: 2 | Z11: 4 | AB11: 1 | AG11: 1 | AJ11: 4 | AK11: 2 | AL11: 1 | AM11: 2 | AP11: 1 | AQ11: 2 | AS11: 3 | AW11: 2 | AZ11: 2 | BB11: 1 | BF11: 3
A12: 5. | B12: тезкор ҳаракатланувчи гуруҳлар томонидан аниқланган жиноятлар | C12: =+SUM(D12:BF12) -> 0
A13: 6. | B13: тезкор ҳаракатланувчи гуруҳлар томонидан ушланган қидирувдаги шахслар | C13: =+SUM(D13:BF13) -> 0
A14: 7. | B14: Қўриқлаш хизмати афзалликлари бўйича тарғибот учрашувлари ўтказиш | C14: =+SUM(D14:BF14) -> 68 | E14: 2 | G14: 3 | H14: 3 | I14: 2 | K14: 2 | M14: 3 | Q14: 3 | R14: 2 | S14: 2 | V14: 1 | W14: 1 | Z14: 2 | AA14: 2 | AD14: 1 | AF14: 2 | AH14: 3 | AJ14: 4 | AK14: 3 | AM14: 3 | AN14: 3 | AO14: 5 | AR14: 2 | AU14: 2 | AV14: 1 | AX14: 3 | AY14: 1 | BB14: 3 | BD14: 2 | BE14: 1 | BF14: 1
A15: 8. | B15: “Объект қўриқловда!” ва “Хонадон қўриқловда!” стикерларини жойлаштириш | C15: =+SUM(D15:BF15) -> 51 | G15: 2 | H15: 3 | L15: 2 | N15: 2 | W15: 3 | X15: 3 | Y15: 2 | AC15: 3 | AD15: 3 | AG15: 3 | AJ15: 3 | AL15: 2 | AM15: 2 | AN15: 1 | AO15: 1 | AP15: 2 | AQ15: 4 | AR15: 3 | AS15: 2 | AW15: 1 | AX15: 1 | AZ15: 1 | BA15: 1 | BF15: 1
A16: 9. | B16: Объектларни жисмоний қўриқловга олиш | C16: =+SUM(D16:BF16) -> 0
A17: шундан | B17: шаҳодатланган таркиб | C17: =+SUM(D17:BF17) -> 0
B18: ҳарбийлаштирилган соқчи | C18: =+SUM(D18:BF18) -> 0
B19: қоровуллик | C19: =+SUM(D19:BF19) -> 0

Sheet 01.26
A1: № | B1: Кўрсаткич | C1: жами | D1: Ал-Хоразмий | E1: Бахористон | F1: Бектўпи | G1: Гулистон | H1: Катта Хирмонтепа | I1: Тирсакобод | J1: Хайрабод | K1: Хирмон тепа | L1: Хонтўпи | M1: Шараф | N1: Шарқ | O1: Шарқ тонги | P1: Шухрат | Q1: 1-Чарх Камолон | R1: 2-Чарх Камолон | S1: 3-Чарх Камолон | T1: Бешёғоч | U1: Катта Козиробод | V1: Катта Олмазор | W1: Катта Чилонзор-1 | X1: Катта Чилонзор-2 | Y1: Катта Чилонзор-3 | Z1: Қозиробод | AA1: Новза | AB1: Чилонзор | AC1: 1-Қатортол | AD1: Бешчинор | AE1: Боғзор | AF1: Диёр | AG1: Дилобод | AH1: Катта Навбаҳор | AI1: Кўркам | AJ1: Кўтарма | AK1: Қатортол | AL1: Лутфий | AM1: Навбахор | AN1: Нафосат | AO1: Оқ-тепа | AP1: Халқлар Дўстлиги | AQ1: Чўпон-ота | AR1: 2-Қатортол | AS1: Ботирма | AT1: Бўрижар | AU1: Гавхар | AV1: Дўмбиробод | AW1: Зарқўрғон | AX1: Катта Дўмбиробод | AY1: Кичик Хирмонтепа | AZ1: Мевазор | BA1: Мехржон | BB1: Наққошлик | BC1: Фидокор | BD1: Яккабоғ | BE1: Яккатут | BF1: Бешқўрғон
A2: 1. | B2: Савдо ва маиший хизмат кўрсатиш объектларини техник қўриқловга олиш | C2: =+SUM(D2:BF2) -> 0 | D2: =+SUM(D3:D7) -> 0 | E2: =+SUM(E3:E7) -> 0 | F2: =+SUM(F3:F7) -> 0 | G2: =+SUM(G3:G7) -> 0 | H2: =+SUM(H3:H7) -> 0 | I2: =+SUM(I3:I7) -> 0 | J2: =+SUM(J3:J7) -> 0 | K2: =+SUM(K3:K7) -> 0 | ... BF2: =+SUM(BF3:BF7) -> 0
A3: шундан | B3: савдо дўконлари | C3: =+SUM(D3:BF3) -> 0
B4: спиртли ичимликлар дўконлари | C4: =+SUM(D4:BF4) -> 0
B5: умумий овқатланиш жойлари | C5: =+SUM(D5:BF5) -> 0
B6: компьютер-плейстейшн | C6: =+SUM(D6:BF6) -> 0
B7: бошқа турдаги объектлар | C7: =+SUM(D7:BF7) -> 0
A8: 2. | B8: Кўп қаватли ва якка тартибдаги хонадонларни техник қўриқловга олиш | C8: =+SUM(D8:BF8) -> 10 | AE8: 3 | AS8: 1 | AW8: 2 | AY8: 2 | AZ8: 1 | BF8: 1
A9: 3. | B9: Кўп қаватли уйларнинг кириш йўлаклари олдига ташвиш тугмаларини ўрнатиш | C9: =+SUM(D9:BF9) -> 0
A10: 4. | B10: Кун давомида келиб тушган "ташвиш хабарлари" | C10: =+SUM(D10:BF10) -> 11 | I10: 1 | Y10: 1 | AB10: 1 | AH10: 1 | AI10: 3 | AQ10: 2 | AS10: 1 | AZ10: 1
A11: 4.1. | B11: Чақирувга асосан ҳодиса жойига етиб борган тезкор ҳаракатланувчи гуруҳ | C11: =+SUM(D11:BF11) -> 11 | I11: 1 | Y11: 1 | AB11: 1 | AH11: 1 | AI11: 3 | AQ11: 2 | AS11: 1 | AZ11: 1
A12: 5. | B12: тезкор ҳаракатланувчи гуруҳлар томонидан аниқланган жиноятлар | C12: =+SUM(D12:BF12) -> 0
A13: 6. | B13: тезкор ҳаракатланувчи гуруҳлар томонидан ушланган қидирувдаги шахслар | C13: =+SUM(D13:BF13) -> 0
A14: 7. | B14: Қўриқлаш хизмати афзалликлари бўйича тарғибот учрашувлари ўтказиш | C14: =+SUM(D14:BF14) -> 49 | E14: 3 | H14: 3 | Q14: 4 | S14: 3 | W14: 5 | AC14: 3 | AF14: 1 | AG14: 1 | AK14: 3 | AM14: 3 | AQ14: 3 | AR14: 3 | AT14: 1 | AV14: 4 | AX14: 2 | BB14: 1 | BC14: 3 | BF14: 3
A15: 8. | B15: “Объект қўриқловда!” ва “Хонадон қўриқловда!” стикерларини жойлаштириш | C15: =+SUM(D15:BF15) -> 28 | I15: 1 | K15: 2 | S15: 2 | T15: 1 | AA15: 3 | AE15: 2 | AF15: 1 | AH15: 3 | AI15: 2 | AN15: 1 | AO15: 3 | AT15: 2 | AY15: 3 | BC15: 1 | BD15: 1
A16: 9. | B16: Объектларни жисмоний қўриқловга олиш | C16: =+SUM(D16:BF16) -> 0
A17: шундан | B17: шаҳодатланган таркиб | C17: =+SUM(D17:BF17) -> 0
B18: ҳарбийлаштирилган соқчи | C18: =+SUM(D18:BF18) -> 0
B19: қоровуллик | C19: =+SUM(D19:BF19) -> 0

Sheet 01.27
A1: № | B1: Кўрсаткич | C1: жами | D1: Ал-Хоразмий | E1: Бахористон | F1: Бектўпи | G1: Гулистон | H1: Катта Хирмонтепа | I1: Тирсакобод | J1: Хайрабод | K1: Хирмон тепа | L1: Хонтўпи | M1: Шараф | N1: Шарқ | O1: Шарқ тонги | P1: Шухрат | Q1: 1-Чарх Камолон | R1: 2-Чарх Камолон | S1: 3-Чарх Камолон | T1: Бешёғоч | U1: Катта Козиробод | V1: Катта Олмазор | W1: Катта Чилонзор-1 | X1: Катта Чилонзор-2 | Y1: Катта Чилонзор-3 | Z1: Қозиробод | AA1: Новза | AB1: Чилонзор | AC1: 1-Қатортол | AD1: Бешчинор | AE1: Боғзор | AF1: Диёр | AG1: Дилобод | AH1: Катта Навбаҳор | AI1: Кўркам | AJ1: Кўтарма | AK1: Қатортол | AL1: Лутфий | AM1: Навбахор | AN1: Нафосат | AO1: Оқ-тепа | AP1: Халқлар Дўстлиги | AQ1: Чўпон-ота | AR1: 2-Қатортол | AS1: Ботирма | AT1: Бўрижар | AU1: Гавхар | AV1: Дўмбиробод | AW1: Зарқўрғон | AX1: Катта Дўмбиробод | AY1: Кичик Хирмонтепа | AZ1: Мевазор | BA1: Мехржон | BB1: Наққошлик | BC1: Фидокор | BD1: Яккабоғ | BE1: Яккатут | BF1: Бешқўрғон
A2: 1. | B2: Савдо ва маиший хизмат кўрсатиш объектларини техник қўриқловга олиш | C2: =+SUM(D2:BF2) -> 3 | D2: =+SUM(D3:D7) -> 0 | E2: =+SUM(E3:E7) -> 0 | F2: =+SUM(F3:F7) -> 1 | G2: =+SUM(G3:G7) -> 0 | H2: =+SUM(H3:H7) -> 0 | I2: =+SUM(I3:I7) -> 0 | J2: =+SUM(J3:J7) -> 0 | K2: =+SUM(K3:K7) -> 0 | ... BF2: =+SUM(BF3:BF7) -> 0
A3: шундан | B3: савдо дўконлари | C3: =+SUM(D3:BF3) -> 0
B4: спиртли ичимликлар дўконлари | C4: =+SUM(D4:BF4) -> 1 | AH4: 1
B5: умумий овқатланиш жойлари | C5: =+SUM(D5:BF5) -> 1 | N5: 1
B6: компьютер-плейстейшн | C6: =+SUM(D6:BF6) -> 0
B7: бошқа турдаги объектлар | C7: =+SUM(D7:BF7) -> 1 | F7: 1
A8: 2. | B8: Кўп қаватли ва якка тартибдаги хонадонларни техник қўриқловга олиш | C8: =+SUM(D8:BF8) -> 13 | F8: 2 | Q8: 1 | AJ8: 1 | AL8: 2 | AS8: 2 | AT8: 3 | AY8: 2
A9: 3. | B9: Кўп қаватли уйларнинг кириш йўлаклари олдига ташвиш тугмаларини ўрнатиш | C9: =+SUM(D9:BF9) -> 9 | W9: 9
A10: 4. | B10: Кун давомида келиб тушган "ташвиш хабарлари" | C10: =+SUM(D10:BF10) -> 21 | I10: 2 | U10: 1 | Z10: 3 | AB10: 1 | AJ10: 3 | AK10: 1 | AQ10: 1 | AS10: 3 | AV10: 1 | AW10: 1 | BB10: 1 | BD10: 1 | BF10: 2
A11: 4.1. | B11: Чақирувга асосан ҳодиса жойига етиб борган тезкор ҳаракатланувчи гуруҳ | C11: =+SUM(D11:BF11) -> 21 | I11: 2 | U11: 1 | Z11: 3 | AB11: 1 | AJ11: 3 | AK11: 1 | AQ11: 1 | AS11: 3 | AV11: 1 | AW11: 1 | BB11: 1 | BD11: 1 | BF11: 2
A12: 5. | B12: тезкор ҳаракатланувчи гуруҳлар томонидан аниқланган жиноятлар | C12: =+SUM(D12:BF12) -> 0
A13: 6. | B13: тезкор ҳаракатланувчи гуруҳлар томонидан ушланган қидирувдаги шахслар | C13: =+SUM(D13:BF13) -> 0
A14: 7. | B14: Қўриқлаш хизмати афзалликлари бўйича тарғибот учрашувлари ўтказиш | C14: =+SUM(D14:BF14) -> 61 | J14: 5 | K14: 5 | L14: 4 | O14: 5 | Q14: 5 | U14: 4 | X14: 5 | Z14: 5 | AD14: 5 | AN14: 5 | AP14: 4 | AS14: 4 | AY14: 1 | BA14: 4
A15: 8. | B15: “Объект қўриқловда!” ва “Хонадон қўриқловда!” стикерларини жойлаштириш | C15: =+SUM(D15:BF15) -> 37 | E15: 2 | H15: 2 | L15: 2 | M15: 1 | O15: 2 | Q15: 2 | T15: 2 | V15: 2 | Z15: 2 | AB15: 3 | AF15: 2 | AG15: 2 | AI15: 2 | AJ15: 2 | AN15: 3 | AP15: 2 | AX15: 1 | AZ15: 1 | BB15: 1 | BD15: 1
A16: 9. | B16: Объектларни жисмоний қўриқловга олиш | C16: =+SUM(D16:BF16) -> 0
A17: шундан | B17: шаҳодатланган таркиб | C17: =+SUM(D17:BF17) -> 0
B18: ҳарбийлаштирилган соқчи | C18: =+SUM(D18:BF18) -> 0
B19: қоровуллик | C19: =+SUM(D19:BF19) -> 0

Sheet 01.28
A1: № | B1: Кўрсаткич | C1: жами | D1: Ал-Хоразмий | E1: Бахористон | F1: Бектўпи | G1: Гулистон | H1: Катта Хирмонтепа | I1: Тирсакобод | J1: Хайрабод | K1: Хирмон тепа | L1: Хонтўпи | M1: Шараф | N1: Шарқ | O1: Шарқ тонги | P1: Шухрат | Q1: 1-Чарх Камолон | R1: 2-Чарх Камолон | S1: 3-Чарх Камолон | T1: Бешёғоч | U1: Катта Козиробод | V1: Катта Олмазор | W1: Катта Чилонзор-1 | X1: Катта Чилонзор-2 | Y1: Катта Чилонзор-3 | Z1: Қозиробод | AA1: Новза | AB1: Чилонзор | AC1: 1-Қатортол | AD1: Бешчинор | AE1: Боғзор | AF1: Диёр | AG1: Дилобод | AH1: Катта Навбаҳор | AI1: Кўркам | AJ1: Кўтарма | AK1: Қатортол | AL1: Лутфий | AM1: Навбахор | AN1: Нафосат | AO1: Оқ-тепа | AP1: Халқлар Дўстлиги | AQ1: Чўпон-ота | AR1: 2-Қатортол | AS1: Ботирма | AT1: Бўрижар | AU1: Гавхар | AV1: Дўмбиробод | AW1: Зарқўрғон | AX1: Катта Дўмбиробод | AY1: Кичик Хирмонтепа | AZ1: Мевазор | BA1: Мехржон | BB1: Наққошлик | BC1: Фидокор | BD1: Яккабоғ | BE1: Яккатут | BF1: Бешқўрғон
A2: 1. | B2: Савдо ва маиший хизмат кўрсатиш объектларини техник қўриқловга олиш | C2: =+SUM(D2:BF2) -> 0 | D2: =+SUM(D3:D7) -> 0 | E2: =+SUM(E3:E7) -> 0 | F2: =+SUM(F3:F7) -> 0 | G2: =+SUM(G3:G7) -> 0 | H2: =+SUM(H3:H7) -> 0 | I2: =+SUM(I3:I7) -> 0 | J2: =+SUM(J3:J7) -> 0 | K2: =+SUM(K3:K7) -> 0 | ... BF2: =+SUM(BF3:BF7) -> 0
A3: шундан | B3: савдо дўконлари | C3: =+SUM(D3:BF3) -> 0
B4: спиртли ичимликлар дўконлари | C4: =+SUM(D4:BF4) -> 0
B5: умумий овқатланиш жойлари | C5: =+SUM(D5:BF5) -> 0
B6: компьютер-плейстейшн | C6: =+SUM(D6:BF6) -> 0
B7: бошқа турдаги объектлар | C7: =+SUM(D7:BF7) -> 0
A8: 2. | B8: Кўп қаватли ва якка тартибдаги хонадонларни техник қўриқловга олиш | C8: =+SUM(D8:BF8) -> 0
A9: 3. | B9: Кўп қаватли уйларнинг кириш йўлаклари олдига ташвиш тугмаларини ўрнатиш | C9: =+SUM(D9:BF9) -> 0
A10: 4. | B10: Кун давомида келиб тушган "ташвиш хабарлари" | C10: =+SUM(D10:BF10) -> 24 | I10: 1 | W10: 1 | Z10: 4 | AB10: 1 | AD10: 1 | AJ10: 3 | AL10: 1 | AQ10: 1 | AS10: 3 | AU10: 1 | BB10: 1 | BD10: 1 | BE10: 1 | BF10: 4
A11: 4.1. | B11: Чақирувга асосан ҳодиса жойига етиб борган тезкор ҳаракатланувчи гуруҳ | C11: =+SUM(D11:BF11) -> 24 | I11: 1 | W11: 1 | Z11: 4 | AB11: 1 | AD11: 1 | AJ11: 3 | AL11: 1 | AQ11: 1 | AS11: 3 | AU11: 1 | BB11: 1 | BD11: 1 | BE11: 1 | BF11: 4
A12: 5. | B12: тезкор ҳаракатланувчи гуруҳлар томонидан аниқланган жиноятлар | C12: =+SUM(D12:BF12) -> 0
A13: 6. | B13: тезкор ҳаракатланувчи гуруҳлар томонидан ушланган қидирувдаги шахслар | C13: =+SUM(D13:BF13) -> 0
A14: 7. | B14: Қўриқлаш хизмати афзалликлари бўйича тарғибот учрашувлари ўтказиш | C14: =+SUM(D14:BF14) -> 29 | I14: 4 | R14: 5 | AA14: 4 | AG14: 4 | AQ14: 5 | AU14: 2 | AZ14: 5
A15: 8. | B15: “Объект қўриқловда!” ва “Хонадон қўриқловда!” стикерларини жойлаштириш | C15: =+SUM(D15:BF15) -> 21 | P15: 2 | U15: 2 | AI15: 4 | AV15: 5 | AW15: 3 | BC15: 5
A16: 9. | B16: Объектларни жисмоний қўриқловга олиш | C16: =+SUM(D16:BF16) -> 0
A17: шундан | B17: шаҳодатланган таркиб | C17: =+SUM(D17:BF17) -> 0
B18: ҳарбийлаштирилган соқчи | C18: =+SUM(D18:BF18) -> 0
B19: қоровуллик | C19: =+SUM(D19:BF19) -> 0

Sheet 01.29
A1: № | B1: Кўрсаткич | C1: жами | D1: Ал-Хоразмий | E1: Бахористон | F1: Бектўпи | G1: Гулистон | H1: Катта Хирмонтепа | I1: Тирсакобод | J1: Хайрабод | K1: Хирмон тепа | L1: Хонтўпи | M1: Шараф | N1: Шарқ | O1: Шарқ тонги | P1: Шухрат | Q1: 1-Чарх Камолон | R1: 2-Чарх Камолон | S1: 3-Чарх Камолон | T1: Бешёғоч | U1: Катта Козиробод | V1: Катта Олмазор | W1: Катта Чилонзор-1 | X1: Катта Чилонзор-2 | Y1: Катта Чилонзор-3 | Z1: Қозиробод | AA1: Новза | AB1: Чилонзор | AC1: 1-Қатортол | AD1: Бешчинор | AE1: Боғзор | AF1: Диёр | AG1: Дилобод | AH1: Катта Навбаҳор | AI1: Кўркам | AJ1: Кўтарма | AK1: Қатортол | AL1: Лутфий | AM1: Навбахор | AN1: Нафосат | AO1: Оқ-тепа | AP1: Халқлар Дўстлиги | AQ1: Чўпон-ота | AR1: 2-Қатортол | AS1: Ботирма | AT1: Бўрижар | AU1: Гавхар | AV1: Дўмбиробод | AW1: Зарқўрғон | AX1: Катта Дўмбиробод | AY1: Кичик Хирмонтепа | AZ1: Мевазор | BA1: Мехржон | BB1: Наққошлик | BC1: Фидокор | BD1: Яккабоғ | BE1: Яккатут | BF1: Бешқўрғон
A2: 1. | B2: Савдо ва маиший хизмат кўрсатиш объектларини техник қўриқловга олиш | C2: =+SUM(D2:BF2) -> 0 | D2: =+SUM(D3:D7) -> 0 | E2: =+SUM(E3:E7) -> 0 | F2: =+SUM(F3:F7) -> 0 | G2: =+SUM(G3:G7) -> 0 | H2: =+SUM(H3:H7) -> 0 | I2: =+SUM(I3:I7) -> 0 | J2: =+SUM(J3:J7) -> 0 | K2: =+SUM(K3:K7) -> 0 | ... BF2: =+SUM(BF3:BF7) -> 0
A3: шундан | B3: савдо дўконлари | C3: =+SUM(D3:BF3) -> 0
B4: спиртли ичимликлар дўконлари | C4: =+SUM(D4:BF4) -> 0
B5: умумий овқатланиш жойлари | C5: =+SUM(D5:BF5) -> 0
B6: компьютер-плейстейшн | C6: =+SUM(D6:BF6) -> 0
B7: бошқа турдаги объектлар | C7: =+SUM(D7:BF7) -> 0
A8: 2. | B8: Кўп қаватли ва якка тартибдаги хонадонларни техник қўриқловга олиш | C8: =+SUM(D8:BF8) -> 5 | AO8: 2 | AT8: 1 | AU8: 1 | AW8: 1
A9: 3. | B9: Кўп қаватли уйларнинг кириш йўлаклари олдига ташвиш тугмаларини ўрнатиш | C9: =+SUM(D9:BF9) -> 14 | W9: 14
A10: 4. | B10: Кун давомида келиб тушган "ташвиш хабарлари" | C10: =+SUM(D10:BF10) -> 23 | Z10: 4 | AB10: 1 | AJ10: 5 | AL10: 1 | AM10: 2 | AQ10: 1 | AS10: 3 | AU10: 1 | BB10: 1 | BD10: 1 | BE10: 1 | BF10: 2
A11: 4.1. | B11: Чақирувга асосан ҳодиса жойига етиб борган тезкор ҳаракатланувчи гуруҳ | C11: =+SUM(D11:BF11) -> 23 | Z11: 4 | AB11: 1 | AJ11: 5 | AL11: 1 | AM11: 2 | AQ11: 1 | AS11: 3 | AU11: 1 | BB11: 1 | BD11: 1 | BE11: 1 | BF11: 2
A12: 5. | B12: тезкор ҳаракатланувчи гуруҳлар томонидан аниқланган жиноятлар | C12: =+SUM(D12:BF12) -> 0
A13: 6. | B13: тезкор ҳаракатланувчи гуруҳлар томонидан ушланган қидирувдаги шахслар | C13: =+SUM(D13:BF13) -> 0
A14: 7. | B14: Қўриқлаш хизмати афзалликлари бўйича тарғибот учрашувлари ўтказиш | C14: =+SUM(D14:BF14) -> 68 | G14: 5 | M14: 5 | T14: 5 | Y14: 4 | AB14: 6 | AI14: 4 | AL14: 7 | AO14: 7 | AU14: 5 | AW14: 6 | AY14: 8 | BB14: 5 | BF14: 1
A15: 8. | B15: “Объект қўриқловда!” ва “Хонадон қўриқловда!” стикерларини жойлаштириш | C15: =+SUM(D15:BF15) -> 28 | I15: 5 | M15: 5 | S15: 5 | AD15: 5 | AH15: 5 | BA15: 3
A16: 9. | B16: Объектларни жисмоний қўриқловга олиш | C16: =+SUM(D16:BF16) -> 0
A17: шундан | B17: шаҳодатланган таркиб | C17: =+SUM(D17:BF17) -> 0
B18: ҳарбийлаштирилган соқчи | C18: =+SUM(D18:BF18) -> 0
B19: қоровуллик | C19: =+SUM(D19:BF19) -> 0

Sheet 01.30
A1: № | B1: Кўрсаткич | C1: жами | D1: Ал-Хоразмий | E1: Бахористон | F1: Бектўпи | G1: Гулистон | H1: Катта Хирмонтепа | I1: Тирсакобод | J1: Хайрабод | K1: Хирмон тепа | L1: Хонтўпи | M1: Шараф | N1: Шарқ | O1: Шарқ тонги | P1: Шухрат | Q1: 1-Чарх Камолон | R1: 2-Чарх Камолон | S1: 3-Чарх Камолон | T1: Бешёғоч | U1: Катта Козиробод | V1: Катта Олмазор | W1: Катта Чилонзор-1 | X1: Катта Чилонзор-2 | Y1: Катта Чилонзор-3 | Z1: Қозиробод | AA1: Новза | AB1: Чилонзор | AC1: 1-Қатортол | AD1: Бешчинор | AE1: Боғзор | AF1: Диёр | AG1: Дилобод | AH1: Катта Навбаҳор | AI1: Кўркам | AJ1: Кўтарма | AK1: Қатортол | AL1: Лутфий | AM1: Навбахор | AN1: Нафосат | AO1: Оқ-тепа | AP1: Халқлар Дўстлиги | AQ1: Чўпон-ота | AR1: 2-Қатортол | AS1: Ботирма | AT1: Бўрижар | AU1: Гавхар | AV1: Дўмбиробод | AW1: Зарқўрғон | AX1: Катта Дўмбиробод | AY1: Кичик Хирмонтепа | AZ1: Мевазор | BA1: Мехржон | BB1: Наққошлик | BC1: Фидокор | BD1: Яккабоғ | BE1: Яккатут | BF1: Бешқўрғон
A2: 1. | B2: Савдо ва маиший хизмат кўрсатиш объектларини техник қўриқловга олиш | C2: =+SUM(D2:BF2) -> 5 | D2: =+SUM(D3:D7) -> 0 | E2: =+SUM(E3:E7) -> 0 | F2: =+SUM(F3:F7) -> 0 | G2: =+SUM(G3:G7) -> 0 | H2: =+SUM(H3:H7) -> 0 | I2: =+SUM(I3:I7) -> 0 | J2: =+SUM(J3:J7) -> 0 | K2: =+SUM(K3:K7) -> 0 | ... BF2: =+SUM(BF3:BF7) -> 1
A3: шундан | B3: савдо дўконлари | C3: =+SUM(D3:BF3) -> 0
B4: спиртли ичимликлар дўконлари | C4: =+SUM(D4:BF4) -> 0
B5: умумий овқатланиш жойлари | C5: =+SUM(D5:BF5) -> 0
B6: компьютер-плейстейшн | C6: =+SUM(D6:BF6) -> 1 | AC6: 1
B7: бошқа турдаги объектлар | C7: =+SUM(D7:BF7) -> 4 | AB7: 2 | AF7: 1 | BF7: 1
A8: 2. | B8: Кўп қаватли ва якка тартибдаги хонадонларни техник қўриқловга олиш | C8: =+SUM(D8:BF8) -> 9 | F8: 1 | H8: 1 | AH8: 1 | AJ8: 1 | AO8: 2 | AT8: 1 | AY8: 2
A9: 3. | B9: Кўп қаватли уйларнинг кириш йўлаклари олдига ташвиш тугмаларини ўрнатиш | C9: =+SUM(D9:BF9) -> 4 | W9: 4
A10: 4. | B10: Кун давомида келиб тушган "ташвиш хабарлари" | C10: =+SUM(D10:BF10) -> 15 | G10: 1 | T10: 1 | W10: 1 | Y10: 1 | Z10: 1 | AA10: 1 | AI10: 1 | AJ10: 4 | AM10: 1 | AO10: 1 | AP10: 2
A11: 4.1. | B11: Чақирувга асосан ҳодиса жойига етиб борган тезкор ҳаракатланувчи гуруҳ | C11: =+SUM(D11:BF11) -> 15 | G11: 1 | T11: 1 | W11: 1 | Y11: 1 | Z11: 1 | AA11: 1 | AI11: 1 | AJ11: 4 | AM11: 1 | AO11: 1 | AP11: 2
A12: 5. | B12: тезкор ҳаракатланувчи гуруҳлар томонидан аниқланган жиноятлар | C12: =+SUM(D12:BF12) -> 0
A13: 6. | B13: тезкор ҳаракатланувчи гуруҳлар томонидан ушланган қидирувдаги шахслар | C13: =+SUM(D13:BF13) -> 0
A14: 7. | B14: Қўриқлаш хизмати афзалликлари бўйича тарғибот учрашувлари ўтказиш | C14: =+SUM(D14:BF14) -> 73 | E14: 4 | F14: 1 | G14: 3 | H14: 2 | J14: 3 | K14: 4 | N14: 5 | P14: 4 | Q14: 1 | S14: 3 | T14: 4 | U14: 3 | V14: 5 | W14: 2 | AC14: 5 | AD14: 2 | AF14: 5 | AR14: 3 | AT14: 5 | AV14: 2 | AX14: 2 | BD14: 3 | BE14: 2
A15: 8. | B15: “Объект қўриқловда!” ва “Хонадон қўриқловда!” стикерларини жойлаштириш | C15: =+SUM(D15:BF15) -> 15 | D15: 3 | G15: 1 | X15: 1 | AC15: 1 | AL15: 1 | AX15: 2 | AZ15: 2 | BB15: 2 | BD15: 1 | BF15: 1
A16: 9. | B16: Объектларни жисмоний қўриқловга олиш | C16: =+SUM(D16:BF16) -> 0
A17: шундан | B17: шаҳодатланган таркиб | C17: =+SUM(D17:BF17) -> 0
B18: ҳарбийлаштирилган соқчи | C18: =+SUM(D18:BF18) -> 0
B19: қоровуллик | C19: =+SUM(D19:BF19) -> 0

Sheet 01.31
A1: № | B1: Кўрсаткич | C1: жами | D1: Ал-Хоразмий | E1: Бахористон | F1: Бектўпи | G1: Гулистон | H1: Катта Хирмонтепа | I1: Тирсакобод | J1: Хайрабод | K1: Хирмон тепа | L1: Хонтўпи | M1: Шараф | N1: Шарқ | O1: Шарқ тонги | P1: Шухрат | Q1: 1-Чарх Камолон | R1: 2-Чарх Камолон | S1: 3-Чарх Камолон | T1: Бешёғоч | U1: Катта Козиробод | V1: Катта Олмазор | W1: Катта Чилонзор-1 | X1: Катта Чилонзор-2 | Y1: Катта Чилонзор-3 | Z1: Қозиробод | AA1: Новза | AB1: Чилонзор | AC1: 1-Қатортол | AD1: Бешчинор | AE1: Боғзор | AF1: Диёр | AG1: Дилобод | AH1: Катта Навбаҳор | AI1: Кўркам | AJ1: Кўтарма | AK1: Қатортол | AL1: Лутфий | AM1: Навбахор | AN1: Нафосат | AO1: Оқ-тепа | AP1: Халқлар Дўстлиги | AQ1: Чўпон-ота | AR1: 2-Қатортол | AS1: Ботирма | AT1: Бўрижар | AU1: Гавхар | AV1: Дўмбиробод | AW1: Зарқўрғон | AX1: Катта Дўмбиробод | AY1: Кичик Хирмонтепа | AZ1: Мевазор | BA1: Мехржон | BB1: Наққошлик | BC1: Фидокор | BD1: Яккабоғ | BE1: Яккатут | BF1: Бешқўрғон
A2: 1. | B2: Савдо ва маиший хизмат кўрсатиш объектларини техник қўриқловга олиш | C2: =+SUM(D2:BF2) -> 11 | D2: =+SUM(D3:D7) -> 0 | E2: =+SUM(E3:E7) -> 1 | F2: =+SUM(F3:F7) -> 0 | G2: =+SUM(G3:G7) -> 0 | H2: =+SUM(H3:H7) -> 0 | I2: =+SUM(I3:I7) -> 0 | J2: =+SUM(J3:J7) -> 0 | K2: =+SUM(K3:K7) -> 0 | ... BF2: =+SUM(BF3:BF7) -> 0
A3: шундан | B3: савдо дўконлари | C3: =+SUM(D3:BF3) -> 1 | AJ3: 1
B4: спиртли ичимликлар дўконлари | C4: =+SUM(D4:BF4) -> 1 | AN4: 1
B5: умумий овқатланиш жойлари | C5: =+SUM(D5:BF5) -> 1 | BD5: 1
B6: компьютер-плейстейшн | C6: =+SUM(D6:BF6) -> 2 | O6: 1 | Y6: 1
B7: бошқа турдаги объектлар | C7: =+SUM(D7:BF7) -> 6 | E7: 1 | AB7: 1 | AJ7: 1 | AO7: 1 | AT7: 1 | BD7: 1
A8: 2. | B8: Кўп қаватли ва якка тартибдаги хонадонларни техник қўриқловга олиш | C8: =+SUM(D8:BF8) -> 32 | E8: 6 | F8: 1 | H8: 6 | I8: 2 | N8: 6 | P8: 1 | T8: 2 | Y8: 1 | AK8: 4 | AS8: 1 | AT8: 1 | AW8: 1
A9: 3. | B9: Кўп қаватли уйларнинг кириш йўлаклари олдига ташвиш тугмаларини ўрнатиш | C9: =+SUM(D9:BF9) -> 2 | W9: 2
A10: 4. | B10: Кун давомида келиб тушган "ташвиш хабарлари" | C10: =+SUM(D10:BF10) -> 33 | F10: 1 | G10: 1 | T10: 2 | Y10: 2 | Z10: 4 | AA10: 1 | AB10: 1 | AI10: 1 | AJ10: 5 | AM10: 3 | AO10: 1 | AP10: 2 | AQ10: 1 | AS10: 3 | AU10: 1 | BD10: 1 | BE10: 1 | BF10: 2
A11: 4.1. | B11: Чақирувга асосан ҳодиса жойига етиб борган тезкор ҳаракатланувчи гуруҳ | C11: =+SUM(D11:BF11) -> 33 | F11: 1 | G11: 1 | T11: 2 | Y11: 2 | Z11: 4 | AA11: 1 | AB11: 1 | AI11: 1 | AJ11: 5 | AM11: 3 | AO11: 1 | AP11: 2 | AQ11: 1 | AS11: 3 | AU11: 1 | BD11: 1 | BE11: 1 | BF11: 2
A12: 5. | B12: тезкор ҳаракатланувчи гуруҳлар томонидан аниқланган жиноятлар | C12: =+SUM(D12:BF12) -> 0
A13: 6. | B13: тезкор ҳаракатланувчи гуруҳлар томонидан ушланган қидирувдаги шахслар | C13: =+SUM(D13:BF13) -> 0
A14: 7. | B14: Қўриқлаш хизмати афзалликлари бўйича тарғибот учрашувлари ўтказиш | C14: =+SUM(D14:BF14) -> 110 | D14: 3 | F14: 2 | G14: 2 | H14: 2 | I14: 2 | J14: 2 | L14: 2 | M14: 2 | P14: 3 | R14: 3 | S14: 2 | U14: 4 | V14: 2 | W14: 3 | X14: 5 | Y14: 2 | Z14: 3 | AA14: 5 | AB14: 2 | AC14: 3 | AD14: 2 | AE14: 2 | AF14: 2 | AH14: 3 | AJ14: 2 | AK14: 3 | AM14: 3 | AN14: 2 | AO14: 5 | AP14: 2 | AR14: 2 | AS14: 3 | AT14: 2 | AV14: 3 | AW14: 2 | AX14: 1 | AY14: 2 | AZ14: 2 | BA14: 3 | BB14: 2 | BC14: 3 | BD14: 2 | BE14: 1 | BF14: 2
A15: 8. | B15: “Объект қўриқловда!” ва “Хонадон қўриқловда!” стикерларини жойлаштириш | C15: =+SUM(D15:BF15) -> 12 | N15: 1 | AE15: 1 | AJ15: 1 | AL15: 1 | AM15: 2 | AS15: 2 | AT15: 2 | BE15: 2
A16: 9. | B16: Объектларни жисмоний қўриқловга олиш | C16: =+SUM(D16:BF16) -> 1 | AQ16: 1
A17: шундан | B17: шаҳодатланган таркиб | C17: =+SUM(D17:BF17) -> 0
B18: ҳарбийлаштирилган соқчи | C18: =+SUM(D18:BF18) -> 0
B19: қоровуллик | C19: =+SUM(D19:BF19) -> 1 | AQ19: 1

Sheet 02.01
A1: № | B1: Кўрсаткич | C1: жами | D1: Ал-Хоразмий | E1: Бахористон | F1: Бектўпи | G1: Гулистон | H1: Катта Хирмонтепа | I1: Тирсакобод | J1: Хайрабод | K1: Хирмон тепа | L1: Хонтўпи | M1: Шараф | N1: Шарқ | O1: Шарқ тонги | P1: Шухрат | Q1: 1-Чарх Камолон | R1: 2-Чарх Камолон | S1: 3-Чарх Камолон | T1: Бешёғоч | U1: Катта Козиробод | V1: Катта Олмазор | W1: Катта Чилонзор-1 | X1: Катта Чилонзор-2 | Y1: Катта Чилонзор-3 | Z1: Қозиробод | AA1: Новза | AB1: Чилонзор | AC1: 1-Қатортол | AD1: Бешчинор | AE1: Боғзор | AF1: Диёр | AG1: Дилобод | AH1: Катта Навбаҳор | AI1: Кўркам | AJ1: Кўтарма | AK1: Қатортол | AL1: Лутфий | AM1: Навбахор | AN1: Нафосат | AO1: Оқ-тепа | AP1: Халқлар Дўстлиги | AQ1: Чўпон-ота | AR1: 2-Қатортол | AS1: Ботирма | AT1: Бўрижар | AU1: Гавхар | AV1: Дўмбиробод | AW1: Зарқўрғон | AX1: Катта Дўмбиробод | AY1: Кичик Хирмонтепа | AZ1: Мевазор | BA1: Мехржон | BB1: Наққошлик | BC1: Фидокор | BD1: Яккабоғ | BE1: Яккатут | BF1: Бешқўрғон
A2: 1. | B2: Савдо ва маиший хизмат кўрсатиш объектларини техник қўриқловга олиш | C2: =+SUM(D2:BF2) -> 1 | D2: =+SUM(D3:D7) -> 0 | E2: =+SUM(E3:E7) -> 0 | F2: =+SUM(F3:F7) -> 0 | G2: =+SUM(G3:G7) -> 0 | H2: =+SUM(H3:H7) -> 0 | I2: =+SUM(I3:I7) -> 0 | J2: =+SUM(J3:J7) -> 0 | K2: =+SUM(K3:K7) -> 0 | ... BF2: =+SUM(BF3:BF7) -> 0
A3: шундан | B3: савдо дўконлари | C3: =+SUM(D3:BF3) -> 0
B4: спиртли ичимликлар дўконлари | C4: =+SUM(D4:BF4) -> 1 | AD4: 1
B5: умумий овқатланиш жойлари | C5: =+SUM(D5:BF5) -> 0
B6: компьютер-плейстейшн | C6: =+SUM(D6:BF6) -> 0
B7: бошқа турдаги объектлар | C7: =+SUM(D7:BF7) -> 0
A8: 2. | B8: Кўп қаватли ва якка тартибдаги хонадонларни техник қўриқловга олиш | C8: =+SUM(D8:BF8) -> 35 | Q8: 4 | R8: 1 | S8: 1 | AA8: 2 | AB8: 2 | AC8: 1 | AD8: 2 | AG8: 2 | AH8: 5 | AJ8: 2 | AK8: 4 | AM8: 2 | AN8: 3 | AP8: 1 | AQ8: 3
A9: 3. | B9: Кўп қаватли уйларнинг кириш йўлаклари олдига ташвиш тугмаларини ўрнатиш | C9: =+SUM(D9:BF9) -> 0
A10: 4. | B10: Кун давомида келиб тушган "ташвиш хабарлари" | C10: =+SUM(D10:BF10) -> 23 | P10: 1 | Q10: 1 | T10: 1 | W10: 1 | X10: 2 | AA10: 1 | AC10: 2 | AI10: 1 | AK10: 4 | AM10: 1 | AN10: 1 | AO10: 1 | AP10: 1 | AQ10: 1 | AT10: 1 | AW10: 1 | BA10: 1 | BE10: 1
A11: 4.1. | B11: Чақирувга асосан ҳодиса жойига етиб борган тезкор ҳаракатланувчи гуруҳ | C11: =+SUM(D11:BF11) -> 23 | P11: 1 | Q11: 1 | T11: 1 | W11: 1 | X11: 2 | AA11: 1 | AC11: 2 | AI11: 1 | AK11: 4 | AM11: 1 | AN11: 1 | AO11: 1 | AP11: 1 | AQ11: 1 | AT11: 1 | AW11: 1 | BA11: 1 | BE11: 1
A12: 5. | B12: тезкор ҳаракатланувчи гуруҳлар томонидан аниқланган жиноятлар | C12: =+SUM(D12:BF12) -> 0
A13: 6. | B13: тезкор ҳаракатланувчи гуруҳлар томонидан ушланган қидирувдаги шахслар | C13: =+SUM(D13:BF13) -> 0
A14: 7. | B14: Қўриқлаш хизмати афзалликлари бўйича тарғибот учрашувлари ўтказиш | C14: =+SUM(D14:BF14) -> 98 | D14: 2 | F14: 3 | I14: 3 | L14: 2 | O14: 5 | P14: 3 | R14: 2 | S14: 2 | V14: 3 | W14: 1 | Y14: 2 | AA14: 3 | AF14: 3 | AG14: 4 | AH14: 5 | AI14: 3 | AJ14: 2 | AK14: 2 | AL14: 1 | AM14: 5 | AN14: 2 | AP14: 5 | AQ14: 3 | AR14: 1 | AS14: 3 | AT14: 2 | AV14: 2 | AX14: 5 | AZ14: 1 | BA14: 3 | BB14: 3 | BC14: 2 | BD14: 3 | BE14: 5 | BF14: 2
A15: 8. | B15: “Объект қўриқловда!” ва “Хонадон қўриқловда!” стикерларини жойлаштириш | C15: =+SUM(D15:BF15) -> 30 | E15: 1 | G15: 1 | K15: 2 | L15: 2 | N15: 3 | O15: 1 | P15: 1 | R15: 2 | T15: 1 | U15: 1 | W15: 1 | Y15: 1 | AA15: 2 | AF15: 1 | AN15: 1 | AR15: 2 | AU15: 1 | AW15: 2 | AY15: 1 | BD15: 1 | BF15: 2
A16: 9. | B16: Объектларни жисмоний қўриқловга олиш | C16: =+SUM(D16:BF16) -> 0
A17: шундан | B17: шаҳодатланган таркиб | C17: =+SUM(D17:BF17) -> 0
B18: ҳарбийлаштирилган соқчи | C18: =+SUM(D18:BF18) -> 0
B19: қоровуллик | C19: =+SUM(D19:BF19) -> 0

Sheet 02.02
A1: № | B1: Кўрсаткич | C1: жами | D1: Ал-Хоразмий | E1: Бахористон | F1: Бектўпи | G1: Гулистон | H1: Катта Хирмонтепа | I1: Тирсакобод | J1: Хайрабод | K1: Хирмон тепа | L1: Хонтўпи | M1: Шараф | N1: Шарқ | O1: Шарқ тонги | P1: Шухрат | Q1: 1-Чарх Камолон | R1: 2-Чарх Камолон | S1: 3-Чарх Камолон | T1: Бешёғоч | U1: Катта Козиробод | V1: Катта Олмазор | W1: Катта Чилонзор-1 | X1: Катта Чилонзор-2 | Y1: Катта Чилонзор-3 | Z1: Қозиробод | AA1: Новза | AB1: Чилонзор | AC1: 1-Қатортол | AD1: Бешчинор | AE1: Боғзор | AF1: Диёр | AG1: Дилобод | AH1: Катта Навбаҳор | AI1: Кўркам | AJ1: Кўтарма | AK1: Қатортол | AL1: Лутфий | AM1: Навбахор | AN1: Нафосат | AO1: Оқ-тепа | AP1: Халқлар Дўстлиги | AQ1: Чўпон-ота | AR1: 2-Қатортол | AS1: Ботирма | AT1: Бўрижар | AU1: Гавхар | AV1: Дўмбиробод | AW1: Зарқўрғон | AX1: Катта Дўмбиробод | AY1: Кичик Хирмонтепа | AZ1: Мевазор | BA1: Мехржон | BB1: Наққошлик | BC1: Фидокор | BD1: Яккабоғ | BE1: Яккатут | BF1: Бешқўрғон
A2: 1. | B2: Савдо ва маиший хизмат кўрсатиш объектларини техник қўриқловга олиш | C2: =+SUM(D2:BF2) -> 5 | D2: =+SUM(D3:D7) -> 1 | E2: =+SUM(E3:E7) -> 0 | F2: =+SUM(F3:F7) -> 0 | G2: =+SUM(G3:G7) -> 0 | H2: =+SUM(H3:H7) -> 0 | I2: =+SUM(I3:I7) -> 0 | J2: =+SUM(J3:J7) -> 0 | K2: =+SUM(K3:K7) -> 0 | ... BF2: =+SUM(BF3:BF7) -> 0
A3: шундан | B3: савдо дўконлари | C3: =+SUM(D3:BF3) -> 0
B4: спиртли ичимликлар дўконлари | C4: =+SUM(D4:BF4) -> 0
B5: умумий овқатланиш жойлари | C5: =+SUM(D5:BF5) -> 2 | AR5: 1 | BE5: 1
B6: компьютер-плейстейшн | C6: =+SUM(D6:BF6) -> 0
B7: бошқа турдаги объектлар | C7: =+SUM(D7:BF7) -> 3 | D7: 1 | AC7: 1 | AU7: 1
A8: 2. | B8: Кўп қаватли ва якка тартибдаги хонадонларни техник қўриқловга олиш | C8: =+SUM(D8:BF8) -> 14 | D8: 1 | K8: 1 | M8: 1 | P8: 1 | Y8: 1 | AK8: 2 | AP8: 1 | AR8: 1 | AT8: 2 | AV8: 1 | AW8: 1 | BF8: 1
A9: 3. | B9: Кўп қаватли уйларнинг кириш йўлаклари олдига ташвиш тугмаларини ўрнатиш | C9: =+SUM(D9:BF9) -> 0
A10: 4. | B10: Кун давомида келиб тушган "ташвиш хабарлари" | C10: =+SUM(D10:BF10) -> 25 | F10: 1 | H10: 1 | P10: 1 | T10: 2 | Y10: 1 | Z10: 1 | AB10: 1 | AD10: 1 | AJ10: 4 | AK10: 1 | AL10: 1 | AM10: 1 | AR10: 2 | AS10: 3 | AU10: 1 | BA10: 1 | BC10: 1 | BF10: 1
A11: 4.1. | B11: Чақирувга асосан ҳодиса жойига етиб борган тезкор ҳаракатланувчи гуруҳ | C11: =+SUM(D11:BF11) -> 25 | F11: 1 | H11: 1 | P11: 1 | T11: 2 | Y11: 1 | Z11: 1 | AB11: 1 | AD11: 1 | AJ11: 4 | AK11: 1 | AL11: 1 | AM11: 1 | AR11: 2 | AS11: 3 | AU11: 1 | BA11: 1 | BC11: 1 | BF11: 1
A12: 5. | B12: тезкор ҳаракатланувчи гуруҳлар томонидан аниқланган жиноятлар | C12: =+SUM(D12:BF12) -> 0
A13: 6. | B13: тезкор ҳаракатланувчи гуруҳлар томонидан ушланган қидирувдаги шахслар | C13: =+SUM(D13:BF13) -> 0
A14: 7. | B14: Қўриқлаш хизмати афзалликлари бўйича тарғибот учрашувлари ўтказиш | C14: =+SUM(D14:BF14) -> 131 | D14: 3 | E14: 14 | F14: 2 | H14: 3 | J14: 10 | L14: 6 | M14: 12 | P14: 3 | S14: 3 | U14: 8 | W14: 15 | AB14: 3 | AE14: 17 | AG14: 2 | AJ14: 3 | AQ14: 1 | AR14: 5 | AW14: 2 | AZ14: 3 | BC14: 3 | BD14: 11 | BF14: 2
A15: 8. | B15: “Объект қўриқловда!” ва “Хонадон қўриқловда!” стикерларини жойлаштириш | C15: =+SUM(D15:BF15) -> 11 | J15: 2 | L15: 1 | W15: 1 | AE15: 3 | AR15: 2 | BD15: 2
A16: 9. | B16: Объектларни жисмоний қўриқловга олиш | C16: =+SUM(D16:BF16) -> 0
A17: шундан | B17: шаҳодатланган таркиб | C17: =+SUM(D17:BF17) -> 0
B18: ҳарбийлаштирилган соқчи | C18: =+SUM(D18:BF18) -> 0
B19: қоровуллик | C19: =+SUM(D19:BF19) -> 0

Sheet 02.03
A1: № | B1: Кўрсаткич | C1: жами | D1: Ал-Хоразмий | E1: Бахористон | F1: Бектўпи | G1: Гулистон | H1: Катта Хирмонтепа | I1: Тирсакобод | J1: Хайрабод | K1: Хирмон тепа | L1: Хонтўпи | M1: Шараф | N1: Шарқ | O1: Шарқ тонги | P1: Шухрат | Q1: 1-Чарх Камолон | R1: 2-Чарх Камолон | S1: 3-Чарх Камолон | T1: Бешёғоч | U1: Катта Козиробод | V1: Катта Олмазор | W1: Катта Чилонзор-1 | X1: Катта Чилонзор-2 | Y1: Катта Чилонзор-3 | Z1: Қозиробод | AA1: Новза | AB1: Чилонзор | AC1: 1-Қатортол | AD1: Бешчинор | AE1: Боғзор | AF1: Диёр | AG1: Дилобод | AH1: Катта Навбаҳор | AI1: Кўркам | AJ1: Кўтарма | AK1: Қатортол | AL1: Лутфий | AM1: Навбахор | AN1: Нафосат | AO1: Оқ-тепа | AP1: Халқлар Дўстлиги | AQ1: Чўпон-ота | AR1: 2-Қатортол | AS1: Ботирма | AT1: Бўрижар | AU1: Гавхар | AV1: Дўмбиробод | AW1: Зарқўрғон | AX1: Катта Дўмбиробод | AY1: Кичик Хирмонтепа | AZ1: Мевазор | BA1: Мехржон | BB1: Наққошлик | BC1: Фидокор | BD1: Яккабоғ | BE1: Яккатут | BF1: Бешқўрғон
A2: 1. | B2: Савдо ва маиший хизмат кўрсатиш объектларини техник қўриқловга олиш | C2: =+SUM(D2:BF2) -> 48 | D2: =+SUM(D3:D7) -> 0 | E2: =+SUM(E3:E7) -> 0 | F2: =+SUM(F3:F7) -> 0 | G2: =+SUM(G3:G7) -> 0 | H2: =+SUM(H3:H7) -> 0 | I2: =+SUM(I3:I7) -> 0 | J2: =+SUM(J3:J7) -> 0 | K2: =+SUM(K3:K7) -> 0 | ... BF2: =+SUM(BF3:BF7) -> 0
A3: шундан | B3: савдо дўконлари | C3: =+SUM(D3:BF3) -> 1 | AG3: 1
B4: спиртли ичимликлар дўконлари | C4: =+SUM(D4:BF4) -> 0
B5: умумий овқатланиш жойлари | C5: =+SUM(D5:BF5) -> 0
B6: компьютер-плейстейшн | C6: =+SUM(D6:BF6) -> 0
B7: бошқа турдаги объектлар | C7: =+SUM(D7:BF7) -> 47 | W7: 47
A8: 2. | B8: Кўп қаватли ва якка тартибдаги хонадонларни техник қўриқловга олиш | C8: =+SUM(D8:BF8) -> 8 | G8: 1 | S8: 1 | AG8: 1 | AK8: 2 | AX8: 1 | AZ8: 1 | BF8: 1
A9: 3. | B9: Кўп қаватли уйларнинг кириш йўлаклари олдига ташвиш тугмаларини ўрнатиш | C9: =+SUM(D9:BF9) -> 0
A10: 4. | B10: Кун давомида келиб тушган "ташвиш хабарлари" | C10: =+SUM(D10:BF10) -> 11 | F10: 3 | Y10: 1 | AJ10: 4 | AM10: 1 | AV10: 1 | AX10: 1
A11: 4.1. | B11: Чақирувга асосан ҳодиса жойига етиб борган тезкор ҳаракатланувчи гуруҳ | C11: =+SUM(D11:BF11) -> 11 | F11: 3 | Y11: 1 | AJ11: 4 | AM11: 1 | AV11: 1 | AX11: 1
A12: 5. | B12: тезкор ҳаракатланувчи гуруҳлар томонидан аниқланган жиноятлар | C12: =+SUM(D12:BF12) -> 0
A13: 6. | B13: тезкор ҳаракатланувчи гуруҳлар томонидан ушланган қидирувдаги шахслар | C13: =+SUM(D13:BF13) -> 1 | AN13: 1
A14: 7. | B14: Қўриқлаш хизмати афзалликлари бўйича тарғибот учрашувлари ўтказиш | C14: =+SUM(D14:BF14) -> 104 | D14: 5 | E14: 11 | F14: 3 | H14: 1 | I14: 5 | K14: 2 | M14: 3 | O14: 3 | Q14: 1 | R14: 2 | X14: 4 | Z14: 5 | AA14: 3 | AC14: 2 | AD14: 5 | AF14: 2 | AI14: 6 | AJ14: 3 | AK14: 4 | AL14: 3 | AN14: 5 | AQ14: 5 | AT14: 4 | AV14: 3 | AW14: 2 | AY14: 3 | BA14: 1 | BB14: 2 | BC14: 3 | BE14: 1 | BF14: 2
A15: 8. | B15: “Объект қўриқловда!” ва “Хонадон қўриқловда!” стикерларини жойлаштириш | C15: =+SUM(D15:BF15) -> 15 | E15: 1 | G15: 1 | J15: 1 | L15: 1 | P15: 1 | S15: 1 | T15: 1 | Y15: 1 | AB15: 1 | AG15: 1 | AR15: 3 | AZ15: 1 | BD15: 1
A16: 9. | B16: Объектларни жисмоний қўриқловга олиш | C16: =+SUM(D16:BF16) -> 0
A17: шундан | B17: шаҳодатланган таркиб | C17: =+SUM(D17:BF17) -> 0
B18: ҳарбийлаштирилган соқчи | C18: =+SUM(D18:BF18) -> 0
B19: қоровуллик | C19: =+SUM(D19:BF19) -> 0

Sheet 02.04
A1: № | B1: Кўрсаткич | C1: жами | D1: Ал-Хоразмий | E1: Бахористон | F1: Бектўпи | G1: Гулистон | H1: Катта Хирмонтепа | I1: Тирсакобод | J1: Хайрабод | K1: Хирмон тепа | L1: Хонтўпи | M1: Шараф | N1: Шарқ | O1: Шарқ тонги | P1: Шухрат | Q1: 1-Чарх Камолон | R1: 2-Чарх Камолон | S1: 3-Чарх Камолон | T1: Бешёғоч | U1: Катта Козиробод | V1: Катта Олмазор | W1: Катта Чилонзор-1 | X1: Катта Чилонзор-2 | Y1: Катта Чилонзор-3 | Z1: Қозиробод | AA1: Новза | AB1: Чилонзор | AC1: 1-Қатортол | AD1: Бешчинор | AE1: Боғзор | AF1: Диёр | AG1: Дилобод | AH1: Катта Навбаҳор | AI1: Кўркам | AJ1: Кўтарма | AK1: Қатортол | AL1: Лутфий | AM1: Навбахор | AN1: Нафосат | AO1: Оқ-тепа | AP1: Халқлар Дўстлиги | AQ1: Чўпон-ота | AR1: 2-Қатортол | AS1: Ботирма | AT1: Бўрижар | AU1: Гавхар | AV1: Дўмбиробод | AW1: Зарқўрғон | AX1: Катта Дўмбиробод | AY1: Кичик Хирмонтепа | AZ1: Мевазор | BA1: Мехржон | BB1: Наққошлик | BC1: Фидокор | BD1: Яккабоғ | BE1: Яккатут | BF1: Бешқўрғон
A2: 1. | B2: Савдо ва маиший хизмат кўрсатиш объектларини техник қўриқловга олиш | C2: =+SUM(D2:BF2) -> 17 | D2: =+SUM(D3:D7) -> 0 | E2: =+SUM(E3:E7) -> 0 | F2: =+SUM(F3:F7) -> 2 | G2: =+SUM(G3:G7) -> 0 | H2: =+SUM(H3:H7) -> 0 | I2: =+SUM(I3:I7) -> 0 | J2: =+SUM(J3:J7) -> 1 | K2: =+SUM(K3:K7) -> 0 | ... BF2: =+SUM(BF3:BF7) -> 0
A3: шундан | B3: савдо дўконлари | C3: =+SUM(D3:BF3) -> 2 | AK3: 1 | AT3: 1
B4: спиртли ичимликлар дўконлари | C4: =+SUM(D4:BF4) -> 0
B5: умумий овқатланиш жойлари | C5: =+SUM(D5:BF5) -> 2 | J5: 1 | BD5: 1
B6: компьютер-плейстейшн | C6: =+SUM(D6:BF6) -> 0
B7: бошқа турдаги объектлар | C7: =+SUM(D7:BF7) -> 13 | F7: 2 | X7: 2 | Z7: 1 | AA7: 2 | AG7: 1 | AM7: 1 | AN7: 1 | AU7: 1 | AZ7: 1 | BD7: 1
A8: 2. | B8: Кўп қаватли ва якка тартибдаги хонадонларни техник қўриқловга олиш | C8: =+SUM(D8:BF8) -> 12 | N8: 1 | S8: 1 | X8: 1 | AM8: 2 | AQ8: 1 | AS8: 3 | AV8: 1 | BC8: 2
A9: 3. | B9: Кўп қаватли уйларнинг кириш йўлаклари олдига ташвиш тугмаларини ўрнатиш | C9: =+SUM(D9:BF9) -> 0
A10: 4. | B10: Кун давомида келиб тушган "ташвиш хабарлари" | C10: =+SUM(D10:BF10) -> 32 | F10: 4 | I10: 1 | T10: 2 | W10: 1 | Y10: 2 | Z10: 2 | AB10: 1 | AG10: 1 | AJ10: 6 | AL10: 1 | AM10: 4 | AP10: 2 | AT10: 2 | AV10: 1 | AX10: 1 | BF10: 1
A11: 4.1. | B11: Чақирувга асосан ҳодиса жойига етиб борган тезкор ҳаракатланувчи гуруҳ | C11: =+SUM(D11:BF11) -> 32 | F11: 4 | I11: 1 | T11: 2 | W11: 1 | Y11: 2 | Z11: 2 | AB11: 1 | AG11: 1 | AJ11: 6 | AL11: 1 | AM11: 4 | AP11: 2 | AT11: 2 | AV11: 1 | AX11: 1 | BF11: 1
A12: 5. | B12: тезкор ҳаракатланувчи гуруҳлар томонидан аниқланган жиноятлар | C12: =+SUM(D12:BF12) -> 0
A13: 6. | B13: тезкор ҳаракатланувчи гуруҳлар томонидан ушланган қидирувдаги шахслар | C13: =+SUM(D13:BF13) -> 0
A14: 7. | B14: Қўриқлаш хизмати афзалликлари бўйича тарғибот учрашувлари ўтказиш | C14: =+SUM(D14:BF14) -> 130 | D14: 3 | E14: 2 | F14: 3 | G14: 1 | H14: 3 | I14: 1 | J14: 2 | K14: 3 | L14: 3 | N14: 2 | O14: 11 | P14: 2 | Q14: 5 | R14: 4 | S14: 1 | T14: 2 | V14: 5 | W14: 3 | Y14: 5 | Z14: 3 | AA14: 2 | AC14: 5 | AD14: 5 | AH14: 2 | AJ14: 3 | AK14: 5 | AM14: 5 | AN14: 3 | AP14: 3 | AT14: 14 | AU14: 5 | AX14: 3 | BA14: 5 | BE14: 2 | BF14: 4
A15: 8. | B15: “Объект қўриқловда!” ва “Хонадон қўриқловда!” стикерларини жойлаштириш | C15: =+SUM(D15:BF15) -> 13 | K15: 2 | Q15: 3 | V15: 2 | AG15: 2 | AO15: 1 | AP15: 1 | AU15: 2
A16: 9. | B16: Объектларни жисмоний қўриқловга олиш | C16: =+SUM(D16:BF16) -> 0
A17: шундан | B17: шаҳодатланган таркиб | C17: =+SUM(D17:BF17) -> 0
B18: ҳарбийлаштирилган соқчи | C18: =+SUM(D18:BF18) -> 0
B19: қоровуллик | C19: =+SUM(D19:BF19) -> 0

Sheet 02.05
A1: № | B1: Кўрсаткич | C1: жами | D1: Ал-Хоразмий | E1: Бахористон | F1: Бектўпи | G1: Гулистон | H1: Катта Хирмонтепа | I1: Тирсакобод | J1: Хайрабод | K1: Хирмон тепа | L1: Хонтўпи | M1: Шараф | N1: Шарқ | O1: Шарқ тонги | P1: Шухрат | Q1: 1-Чарх Камолон | R1: 2-Чарх Камолон | S1: 3-Чарх Камолон | T1: Бешёғоч | U1: Катта Козиробод | V1: Катта Олмазор | W1: Катта Чилонзор-1 | X1: Катта Чилонзор-2 | Y1: Катта Чилонзор-3 | Z1: Қозиробод | AA1: Новза | AB1: Чилонзор | AC1: 1-Қатортол | AD1: Бешчинор | AE1: Боғзор | AF1: Диёр | AG1: Дилобод | AH1: Катта Навбаҳор | AI1: Кўркам | AJ1: Кўтарма | AK1: Қатортол | AL1: Лутфий | AM1: Навбахор | AN1: Нафосат | AO1: Оқ-тепа | AP1: Халқлар Дўстлиги | AQ1: Чўпон-ота | AR1: 2-Қатортол | AS1: Ботирма | AT1: Бўрижар | AU1: Гавхар | AV1: Дўмбиробод | AW1: Зарқўрғон | AX1: Катта Дўмбиробод | AY1: Кичик Хирмонтепа | AZ1: Мевазор | BA1: Мехржон | BB1: Наққошлик | BC1: Фидокор | BD1: Яккабоғ | BE1: Яккатут | BF1: Бешқўрғон
A2: 1. | B2: Савдо ва маиший хизмат кўрсатиш объектларини техник қўриқловга олиш | C2: =+SUM(D2:BF2) -> 9 | D2: =+SUM(D3:D7) -> 0 | E2: =+SUM(E3:E7) -> 0 | F2: =+SUM(F3:F7) -> 0 | G2: =+SUM(G3:G7) -> 1 | H2: =+SUM(H3:H7) -> 0 | I2: =+SUM(I3:I7) -> 0 | J2: =+SUM(J3:J7) -> 0 | K2: =+SUM(K3:K7) -> 0 | ... BF2: =+SUM(BF3:BF7) -> 1
A3: шундан | B3: савдо дўконлари | C3: =+SUM(D3:BF3) -> 1 | BF3: 1
B4: спиртли ичимликлар дўконлари | C4: =+SUM(D4:BF4) -> 0
B5: умумий овқатланиш жойлари | C5: =+SUM(D5:BF5) -> 3 | T5: 2 | AJ5: 1
B6: компьютер-плейстейшн | C6: =+SUM(D6:BF6) -> 0
B7: бошқа турдаги объектлар | C7: =+SUM(D7:BF7) -> 5 | G7: 1 | O7: 1 | T7: 1 | AV7: 1 | BC7: 1
A8: 2. | B8: Кўп қаватли ва якка тартибдаги хонадонларни техник қўриқловга олиш | C8: =+SUM(D8:BF8) -> 9 | G8: 3 | R8: 1 | AH8: 1 | AK8: 3 | BF8: 1
A9: 3. | B9: Кўп қаватли уйларнинг кириш йўлаклари олдига ташвиш тугмаларини ўрнатиш | C9: =+SUM(D9:BF9) -> 0
