Workbook

Sheet 01.20
A1: № | B1: Кўрсаткич | C1: Жами | D1: Ал-Хоразмий | E1: Бахористон | F1: Бектўпи | G1: Гулистон | H1: Катта Хирмонтепа | I1: Тирсакобод | J1: Хайрабод | K1: Хирмон тепа | L1: Хонтўпи | M1: Шараф | N1: Шарқ | O1: Шарқ тонги | P1: Шухрат | Q1: 1-Чарх Камолон | R1: 2-Чарх Камолон | S1: 3-Чарх Камолон | T1: Бешёғоч | U1: Катта Козиробод | V1: Катта Олмазор | W1: Катта Чилонзор-1 | X1: Катта Чилонзор-2 | Y1: Катта Чилонзор-3 | Z1: Қозиробод | AA1: Новза | AB1: Чилонзор | AC1: 1-Қатортол | AD1: Бешчинор | AE1: Боғзор | AF1: Диёр | AG1: Дилобод | AH1: Катта Навбаҳор | AI1: Кўркам | AJ1: Кўтарма | AK1: Қатортол | AL1: Лутфий | AM1: Навбахор | AN1: Нафосат | AO1: Оқ-тепа | AP1: Халқлар Дўстлиги | AQ1: Чўпон-ота | AR1: 2-Қатортол | AS1: Ботирма | AT1: Бўрижар | AU1: Гавхар | AV1: Дўмбиробод | AW1: Зарқўрғон | AX1: Катта Дўмбиробод | AY1: Кичик Хирмонтепа | AZ1: Мевазор | BA1: Мехржон | BB1: Наққошлик | BC1: Фидокор | BD1: Яккабоғ | BE1: Яккатут | BF1: Бешқўрғон
A2: 1. | B2: Автомобиль йўллари четига барпо этилган пиёдалар йўлаклари (тротуарлар)
A3: 1.1. | B3: шундан, мактаб ҳудуди ва унинг атрофида ташкил этилган хавфсиз пиёдалар йўлаклари
A4: 2. | B4: Мактаб ҳудуди ва унинг атрофида ташкил этилган қавариқ пиёдалар ўтиш жойлари
A5: 3. | B5: шундан, серқатнов автомобиль йўлларида жойлашган мактаблар олдида ташкил этилган қавариқ пиёдалар
A6: 4. | B6: Йўл ёқасида жойлашган мактаблар олдида ўрнатилган сунъий нотекисликлар (тезлик пасайтиргичлар)
A7: 5. | B7: Ўрнатилган йўлларни ажратувчи махсус темир панжаралар (метр) | C7: =+D7+E7+F7+G7+H7+I7+J7+K7+L7+M7+N7+O7+P7+Q7+R7+S7+T7+U7+V7+W7+X7+Y7+Z7+AA7+AB7+AC7+AD7+AE7+AF7+AG7+AH7+AI7+AJ7+AK7+AL7+AM7+AN7+AO7+AP7+AQ7+AR7+AS7+AT7+AU7+AV7+AW7+AX7+AY7+AZ7+BA7+BB7+BC7+BD7+BE7+BF7 -> 0
A8: 6. | B8: Алмаштирилган эскирган ва талабга жавоб бермайдиган йўл белгилари | C8: 6 | D8: 2 | F8: 4
A9: 7. | B9: Жами ўрнатилган светофорлар
A10: 7.1. | B10: шундан, ТХАЙ йўлида ўрнатилган светофорлар
A11: 8. | B11: Жами ўрнатилган тугмали светофорлар
A12: 8.1. | B12: шундан, ТХАЙ йўлида ўрнатилган тугмали светофорлар
A13: 9. | B13: Жами ўрнатилган янги йўл белгилари | C13: 2 | F13: 2
A14: 9.1. | B14: шундан, ТХАЙ йўлида ўрнатилганлари
A15: 10. | B15: Чизилган йўл чизиқлари (м2) | C15: 600 | F15: 600
A16: 11. | B16: Мактабларда ташкил этилган махсус ўқув синфхоналари | C16: =+D16+E16+F16+G16+H16+I16+J16+K16+L16+M16+N16+O16+P16+Q16+R16+S16+T16+U16+V16+W16+X16+Y16+Z16+AA16+AB16+AC16+AD16+AE16+AF16+AG16+AH16+AI16+AJ16+AK16+AL16+AM16+AN16+AO16+AP16+AQ16+AR16+AS16+AT16+AU16+AV16+AW16+AX16+AY16+AZ16+BA16+BB16+BC16+BD16+BE16+BF16 -> 16 | D16: 1 | P16: 1 | R16: 1 | V16: 1 | W16: 1 | Z16: 1 | AE16: 1 | AG16: 1 | AI16: 1 | AJ16: 1 | AN16: 1 | AO16: 1 | AW16: 1 | AX16: 1 | BE16: 2
A17: 12. | B17: “Йўл қоидаси – умр фойдаси” шиори остида ўтказилган тарғибот тадбирлари
A18: 13. | B18: йўл ҳаракати қоидалари бўйича "Ёш тарғиботчи клублари" | C18: 5 | D18: 2 | H18: 2 | V18: 1
A19: 14. | B19: Яроқсиз ҳолга келган транспорт воситаларини рўйхатдан чиқариш
A20: 15. | B20: Аниқланган жами қоидабузарликлар | C20: =SUM(D20+E20+F20+G20+H20+I20+J20+K20+L20+M20+N20+O20+P20+Q20+R20+S20+T20+U20+V20+W20+X20+Y20+Z20+AA20+AB20+AC20+AD20+AE20+AF20+AG20+AH20+AI20+AJ20+AK20+AL20+AM20+AN20+AO20+AP20+AQ20+AR20+AS20+AT20+AU20+AV20+AW20+AX20+AY20+AZ20+BA20+BB20+BC20+BD20+BE20+BF20) -> 370 | D20: 5 | T20: 20 | U20: 10 | AM20: 5 | AZ20: 10 | BB20: 20 | BF20: 300
A21: шундан | B21: Қўпол турдаги қоидабузарликлар | C21: =SUM(D21+E21+F21+G21+H21+I21+J21+K21+L21+M21+N21+O21+P21+Q21+R21+S21+T21+U21+V21+W21+X21+Y21+Z21+AA21+AB21+AC21+AD21+AE21+AF21+AG21+AH21+AI21+AJ21+AK21+AL21+AM21+AN21+AO21+AP21+AQ21+AR21+AS21+AT21+AU21+AV21+AW21+AX21+AY21+AZ21+BA21+BB21+BC21+BD21+BE21+BF21) -> 63 | D21: 1 | T21: 4 | U21: 1 | AM21: 1 | AZ21: 2 | BB21: 3 | BF21: 51
B22: Қарама-қарши ҳаракатланиш (МЖтКнинг 128 прим 5-моддаси) | C22: =SUM(D22+E22+F22+G22+H22+I22+J22+K22+L22+M22+N22+O22+P22+Q22+R22+S22+T22+U22+V22+W22+X22+Y22+Z22+AA22+AB22+AC22+AD22+AE22+AF22+AG22+AH22+AI22+AJ22+AK22+AL22+AM22+AN22+AO22+AP22+AQ22+AR22+AS22+AT22+AU22+AV22+AW22+AX22+AY22+AZ22+BA22+BB22+BC22+BD22+BE22+BF22) -> 0
B23: Светофорнинг қизил чироғида ҳаракатланиш (МЖтКнинг 128 прим 4-моддаси) | C23: =SUM(D23+E23+F23+G23+H23+I23+J23+K23+L23+M23+N23+O23+P23+Q23+R23+S23+T23+U23+V23+W23+X23+Y23+Z23+AA23+AB23+AC23+AD23+AE23+AF23+AG23+AH23+AI23+AJ23+AK23+AL23+AM23+AN23+AO23+AP23+AQ23+AR23+AS23+AT23+AU23+AV23+AW23+AX23+AY23+AZ23+BA23+BB23+BC23+BD23+BE23+BF23) -> 1 | T23: 1
B24: Пиёдага йўл бермаслик (МЖтКнинг 128-моддаси) | C24: =SUM(D24+E24+F24+G24+H24+I24+J24+K24+L24+M24+N24+O24+P24+Q24+R24+S24+T24+U24+V24+W24+X24+Y24+Z24+AA24+AB24+AC24+AD24+AE24+AF24+AG24+AH24+AI24+AJ24+AK24+AL24+AM24+AN24+AO24+AP24+AQ24+AR24+AS24+AT24+AU24+AV24+AW24+AX24+AY24+AZ24+BA24+BB24+BC24+BD24+BE24+BF24) -> 2 | U24: 1 | BB24: 1
B25: Ноқонуний тонировка | C25: =SUM(D25+E25+F25+G25+H25+I25+J25+K25+L25+M25+N25+O25+P25+Q25+R25+S25+T25+U25+V25+W25+X25+Y25+Z25+AA25+AB25+AC25+AD25+AE25+AF25+AG25+AH25+AI25+AJ25+AK25+AL25+AM25+AN25+AO25+AP25+AQ25+AR25+AS25+AT25+AU25+AV25+AW25+AX25+AY25+AZ25+BA25+BB25+BC25+BD25+BE25+BF25) -> 2 | T25: 1 | BF25: 1
B26: Маст ҳолатда транспорт воситасини бошқариш | C26: =SUM(D26+E26+F26+G26+H26+I26+J26+K26+L26+M26+N26+O26+P26+Q26+R26+S26+T26+U26+V26+W26+X26+Y26+Z26+AA26+AB26+AC26+AD26+AE26+AF26+AG26+AH26+AI26+AJ26+AK26+AL26+AM26+AN26+AO26+AP26+AQ26+AR26+AS26+AT26+AU26+AV26+AW26+AX26+AY26+AZ26+BA26+BB26+BC26+BD26+BE26+BF26) -> 2 | D26: 1 | T26: 1
B27: Тегишли ҳужжатларсиз транспорт воситаларини бошқариш | C27: =SUM(D27+E27+F27+G27+H27+I27+J27+K27+L27+M27+N27+O27+P27+Q27+R27+S27+T27+U27+V27+W27+X27+Y27+Z27+AA27+AB27+AC27+AD27+AE27+AF27+AG27+AH27+AI27+AJ27+AK27+AL27+AM27+AN27+AO27+AP27+AQ27+AR27+AS27+AT27+AU27+AV27+AW27+AX27+AY27+AZ27+BA27+BB27+BC27+BD27+BE27+BF27) -> 4 | AZ27: 1 | BB27: 1 | BF27: 2
B28: Давлат рақам белгисини ўзбошимчалик билан ечиб олиш | C28: =SUM(D28+E28+F28+G28+H28+I28+J28+K28+L28+M28+N28+O28+P28+Q28+R28+S28+T28+U28+V28+W28+X28+Y28+Z28+AA28+AB28+AC28+AD28+AE28+AF28+AG28+AH28+AI28+AJ28+AK28+AL28+AM28+AN28+AO28+AP28+AQ28+AR28+AS28+AT28+AU28+AV28+AW28+AX28+AY28+AZ28+BA28+BB28+BC28+BD28+BE28+BF28) -> 0
B29: Глушител, товуш чиқарувчи, мигалка ва бошқа қурилмалар | C29: =SUM(D29+E29+F29+G29+H29+I29+J29+K29+L29+M29+N29+O29+P29+Q29+R29+S29+T29+U29+V29+W29+X29+Y29+Z29+AA29+AB29+AC29+AD29+AE29+AF29+AG29+AH29+AI29+AJ29+AK29+AL29+AM29+AN29+AO29+AP29+AQ29+AR29+AS29+AT29+AU29+AV29+AW29+AX29+AY29+AZ29+BA29+BB29+BC29+BD29+BE29+BF29) -> 0
A30: 16. | B30: Жарима майдонига жойлаштирилган транспорт воситалари | C30: =SUM(D30+E30+F30+G30+H30+I30+J30+K30+L30+M30+N30+O30+P30+Q30+R30+S30+T30+U30+V30+W30+X30+Y30+Z30+AA30+AB30+AC30+AD30+AE30+AF30+AG30+AH30+AI30+AJ30+AK30+AL30+AM30+AN30+AO30+AP30+AQ30+AR30+AS30+AT30+AU30+AV30+AW30+AX30+AY30+AZ30+BA30+BB30+BC30+BD30+BE30+BF30) -> 10 | D30: 2 | T30: 4 | AM30: 1 | AZ30: 1 | BF30: 2
A31: 17. | B31: Мактабларда ўтказилган "Авторейд" тадбирлари сони | C31: =SUM(D31+E31+F31+G31+H31+I31+J31+K31+L31+M31+N31+O31+P31+Q31+R31+S31+T31+U31+V31+W31+X31+Y31+Z31+AA31+AB31+AC31+AD31+AE31+AF31+AG31+AH31+AI31+AJ31+AK31+AL31+AM31+AN31+AO31+AP31+AQ31+AR31+AS31+AT31+AU31+AV31+AW31+AX31+AY31+AZ31+BA31+BB31+BC31+BD31+BE31+BF31) -> 5 | D31: 2 | F31: 2 | K31: 1
A32: 17.1. | B32: Мактабларда ўтказилган "Авторейд" тадбирларида аниқланган қоидабузарликлар сони | C32: =SUM(D32+E32+F32+G32+H32+I32+J32+K32+L32+M32+N32+O32+P32+Q32+R32+S32+T32+U32+V32+W32+X32+Y32+Z32+AA32+AB32+AC32+AD32+AE32+AF32+AG32+AH32+AI32+AJ32+AK32+AL32+AM32+AN32+AO32+AP32+AQ32+AR32+AS32+AT32+AU32+AV32+AW32+AX32+AY32+AZ32+BA32+BB32+BC32+BD32+BE32+BF32) -> 8 | D32: 2 | F32: 2 | T32: 2 | AK32: 1 | AU32: 1
A33: 18. | B33: Ашаддий қоидабузар ҳайдовчилар бўйича уларнинг яшаш маҳаллаларида ўтказилган муҳокамалар | C33: =SUM(D33+E33+F33+G33+H33+I33+J33+K33+L33+M33+N33+O33+P33+Q33+R33+S33+T33+U33+V33+W33+X33+Y33+Z33+AA33+AB33+AC33+AD33+AE33+AF33+AG33+AH33+AI33+AJ33+AK33+AL33+AM33+AN33+AO33+AP33+AQ33+AR33+AS33+AT33+AU33+AV33+AW33+AX33+AY33+AZ33+BA33+BB33+BC33+BD33+BE33+BF33) -> 9 | D33: 1 | G33: 1 | I33: 1 | L33: 1 | P33: 1 | T33: 1 | V33: 1 | Z33: 1 | AB33: 1
A34: 19. | B34: Содир этилган жами йўл транспорт ҳодисалари (жиноий ҳолатлардан ташқари) | C34: =+D34+E34+F34+G34+H34+I34+J34+K34+L34+M34+N34+O34+P34+Q34+R34+S34+T34+U34+V34+W34+X34+Y34+Z34+AA34+AB34+AC34+AD34+AE34+AF34+AG34+AH34+AI34+AJ34+AK34+AL34+AM34+AN34+AO34+AP34+AQ34+AR34+AS34+AT34+AU34+AV34+AW34+AX34+AY34+AZ34+BA34+BB34+BC34+BD34+BE34+BF34 -> 0
A35: 20. | B35: Содир этилган жами ЙТҲлари билан боғлиқ жиноятлар (ЖК 266-модда 1-қисми) | C35: =+D35+E35+F35+G35+H35+I35+J35+K35+L35+M35+N35+O35+P35+Q35+R35+S35+T35+U35+V35+W35+X35+Y35+Z35+AA35+AB35+AC35+AD35+AE35+AF35+AG35+AH35+AI35+AJ35+AK35+AL35+AM35+AN35+AO35+AP35+AQ35+AR35+AS35+AT35+AU35+AV35+AW35+AX35+AY35+AZ35+BA35+BB35+BC35+BD35+BE35+BF35 -> 0
A36: 20.1. | B36: шундан, инсон ўлими билан боғлиқ жиноий ҳолатлар | C36: =+D36+E36+F36+G36+H36+I36+J36+K36+L36+M36+N36+O36+P36+Q36+R36+S36+T36+U36+V36+W36+X36+Y36+Z36+AA36+AB36+AC36+AD36+AE36+AF36+AG36+AH36+AI36+AJ36+AK36+AL36+AM36+AN36+AO36+AP36+AQ36+AR36+AS36+AT36+AU36+AV36+AW36+AX36+AY36+AZ36+BA36+BB36+BC36+BD36+BE36+BF36 -> 0
A37: 21. | B37: Автомобилни олиб қочиш (ЖК 267-модда) | C37: =+D37+E37+F37+G37+H37+I37+J37+K37+L37+M37+N37+O37+P37+Q37+R37+S37+T37+U37+V37+W37+X37+Y37+Z37+AA37+AB37+AC37+AD37+AE37+AF37+AG37+AH37+AI37+AJ37+AK37+AL37+AM37+AN37+AO37+AP37+AQ37+AR37+AS37+AT37+AU37+AV37+AW37+AX37+AY37+AZ37+BA37+BB37+BC37+BD37+BE37+BF37 -> 0

Sheet 01.21
A1: № | B1: Кўрсаткич | C1: Жами | D1: Ал-Хоразмий | E1: Бахористон | F1: Бектўпи | G1: Гулистон | H1: Катта Хирмонтепа | I1: Тирсакобод | J1: Хайрабод | K1: Хирмон тепа | L1: Хонтўпи | M1: Шараф | N1: Шарқ | O1: Шарқ тонги | P1: Шухрат | Q1: 1-Чарх Камолон | R1: 2-Чарх Камолон | S1: 3-Чарх Камолон | T1: Бешёғоч | U1: Катта Козиробод | V1: Катта Олмазор | W1: Катта Чилонзор-1 | X1: Катта Чилонзор-2 | Y1: Катта Чилонзор-3 | Z1: Қозиробод | AA1: Новза | AB1: Чилонзор | AC1: 1-Қатортол | AD1: Бешчинор | AE1: Боғзор | AF1: Диёр | AG1: Дилобод | AH1: Катта Навбаҳор | AI1: Кўркам | AJ1: Кўтарма | AK1: Қатортол | AL1: Лутфий | AM1: Навбахор | AN1: Нафосат | AO1: Оқ-тепа | AP1: Халқлар Дўстлиги | AQ1: Чўпон-ота | AR1: 2-Қатортол | AS1: Ботирма | AT1: Бўрижар | AU1: Гавхар | AV1: Дўмбиробод | AW1: Зарқўрғон | AX1: Катта Дўмбиробод | AY1: Кичик Хирмонтепа | AZ1: Мевазор | BA1: Мехржон | BB1: Наққошлик | BC1: Фидокор | BD1: Яккабоғ | BE1: Яккатут | BF1: Бешқўрғон
A2: 1. | B2: Автомобиль йўллари четига барпо этилган пиёдалар йўлаклари (тротуарлар) | C2: =+D2+E2+F2+G2+H2+I2+J2+K2+L2+M2+N2+O2+P2+Q2+R2+S2+T2+U2+V2+W2+X2+Y2+Z2+AA2+AB2+AC2+AD2+AE2+AF2+AG2+AH2+AI2+AJ2+AK2+AL2+AM2+AN2+AO2+AP2+AQ2+AR2+AS2+AT2+AU2+AV2+AW2+AX2+AY2+AZ2+BA2+BB2+BC2+BD2+BE2+BF2 -> 0
A3: 1.1. | B3: шундан, мактаб ҳудуди ва унинг атрофида ташкил этилган хавфсиз пиёдалар йўлаклари | C3: =+D3+E3+F3+G3+H3+I3+J3+K3+L3+M3+N3+O3+P3+Q3+R3+S3+T3+U3+V3+W3+X3+Y3+Z3+AA3+AB3+AC3+AD3+AE3+AF3+AG3+AH3+AI3+AJ3+AK3+AL3+AM3+AN3+AO3+AP3+AQ3+AR3+AS3+AT3+AU3+AV3+AW3+AX3+AY3+AZ3+BA3+BB3+BC3+BD3+BE3+BF3 -> 0
A4: 2. | B4: Мактаб ҳудуди ва унинг атрофида ташкил этилган қавариқ пиёдалар ўтиш жойлари | C4: =+D4+E4+F4+G4+H4+I4+J4+K4+L4+M4+N4+O4+P4+Q4+R4+S4+T4+U4+V4+W4+X4+Y4+Z4+AA4+AB4+AC4+AD4+AE4+AF4+AG4+AH4+AI4+AJ4+AK4+AL4+AM4+AN4+AO4+AP4+AQ4+AR4+AS4+AT4+AU4+AV4+AW4+AX4+AY4+AZ4+BA4+BB4+BC4+BD4+BE4+BF4 -> 0
A5: 3. | B5: шундан, серқатнов автомобиль йўлларида жойлашган мактаблар олдида ташкил этилган қавариқ пиёдалар | C5: =+D5+E5+F5+G5+H5+I5+J5+K5+L5+M5+N5+O5+P5+Q5+R5+S5+T5+U5+V5+W5+X5+Y5+Z5+AA5+AB5+AC5+AD5+AE5+AF5+AG5+AH5+AI5+AJ5+AK5+AL5+AM5+AN5+AO5+AP5+AQ5+AR5+AS5+AT5+AU5+AV5+AW5+AX5+AY5+AZ5+BA5+BB5+BC5+BD5+BE5+BF5 -> 0
A6: 4. | B6: Йўл ёқасида жойлашган мактаблар олдида ўрнатилган сунъий нотекисликлар (тезлик пасайтиргичлар) | C6: =+D6+E6+F6+G6+H6+I6+J6+K6+L6+M6+N6+O6+P6+Q6+R6+S6+T6+U6+V6+W6+X6+Y6+Z6+AA6+AB6+AC6+AD6+AE6+AF6+AG6+AH6+AI6+AJ6+AK6+AL6+AM6+AN6+AO6+AP6+AQ6+AR6+AS6+AT6+AU6+AV6+AW6+AX6+AY6+AZ6+BA6+BB6+BC6+BD6+BE6+BF6 -> 0
A7: 5. | B7: Ўрнатилган йўлларни ажратувчи махсус темир панжаралар (метр) | C7: =+D7+E7+F7+G7+H7+I7+J7+K7+L7+M7+N7+O7+P7+Q7+R7+S7+T7+U7+V7+W7+X7+Y7+Z7+AA7+AB7+AC7+AD7+AE7+AF7+AG7+AH7+AI7+AJ7+AK7+AL7+AM7+AN7+AO7+AP7+AQ7+AR7+AS7+AT7+AU7+AV7+AW7+AX7+AY7+AZ7+BA7+BB7+BC7+BD7+BE7+BF7 -> 0
A8: 6. | B8: Алмаштирилган эскирган ва талабга жавоб бермайдиган йўл белгилари | C8: =+D8+E8+F8+G8+H8+I8+J8+K8+L8+M8+N8+O8+P8+Q8+R8+S8+T8+U8+V8+W8+X8+Y8+Z8+AA8+AB8+AC8+AD8+AE8+AF8+AG8+AH8+AI8+AJ8+AK8+AL8+AM8+AN8+AO8+AP8+AQ8+AR8+AS8+AT8+AU8+AV8+AW8+AX8+AY8+AZ8+BA8+BB8+BC8+BD8+BE8+BF8 -> 20 | D8: 2 | F8: 4 | H8: 2 | K8: 4 | L8: 3 | O8: 2 | P8: 1 | Z8: 2
A9: 7. | B9: Жами ўрнатилган светофорлар | C9: =+D9+E9+F9+G9+H9+I9+J9+K9+L9+M9+N9+O9+P9+Q9+R9+S9+T9+U9+V9+W9+X9+Y9+Z9+AA9+AB9+AC9+AD9+AE9+AF9+AG9+AH9+AI9+AJ9+AK9+AL9+AM9+AN9+AO9+AP9+AQ9+AR9+AS9+AT9+AU9+AV9+AW9+AX9+AY9+AZ9+BA9+BB9+BC9+BD9+BE9+BF9 -> 1 | BF9: 1
A10: 7.1. | B10: шундан, ТХАЙ йўлида ўрнатилган светофорлар | C10: =+D10+E10+F10+G10+H10+I10+J10+K10+L10+M10+N10+O10+P10+Q10+R10+S10+T10+U10+V10+W10+X10+Y10+Z10+AA10+AB10+AC10+AD10+AE10+AF10+AG10+AH10+AI10+AJ10+AK10+AL10+AM10+AN10+AO10+AP10+AQ10+AR10+AS10+AT10+AU10+AV10+AW10+AX10+AY10+AZ10+BA10+BB10+BC10+BD10+BE10+BF10 -> 1 | BF10: 1
A11: 8. | B11: Жами ўрнатилган тугмали светофорлар | C11: =+D11+E11+F11+G11+H11+I11+J11+K11+L11+M11+N11+O11+P11+Q11+R11+S11+T11+U11+V11+W11+X11+Y11+Z11+AA11+AB11+AC11+AD11+AE11+AF11+AG11+AH11+AI11+AJ11+AK11+AL11+AM11+AN11+AO11+AP11+AQ11+AR11+AS11+AT11+AU11+AV11+AW11+AX11+AY11+AZ11+BA11+BB11+BC11+BD11+BE11+BF11 -> 0
A12: 8.1. | B12: шундан, ТХАЙ йўлида ўрнатилган тугмали светофорлар
A13: 9. | B13: Жами ўрнатилган янги йўл белгилари | C13: =+D13+E13+F13+G13+H13+I13+J13+K13+L13+M13+N13+O13+P13+Q13+R13+S13+T13+U13+V13+W13+X13+Y13+Z13+AA13+AB13+AC13+AD13+AE13+AF13+AG13+AH13+AI13+AJ13+AK13+AL13+AM13+AN13+AO13+AP13+AQ13+AR13+AS13+AT13+AU13+AV13+AW13+AX13+AY13+AZ13+BA13+BB13+BC13+BD13+BE13+BF13 -> 10 | F13: 2 | K13: 2 | O13: 2 | AY13: 4
A14: 9.1. | B14: шундан, ТХАЙ йўлида ўрнатилганлари
A15: 10. | B15: Чизилган йўл чизиқлари (м2) | C15: =+D15+E15+F15+G15+H15+I15+J15+K15+L15+M15+N15+O15+P15+Q15+R15+S15+T15+U15+V15+W15+X15+Y15+Z15+AA15+AB15+AC15+AD15+AE15+AF15+AG15+AH15+AI15+AJ15+AK15+AL15+AM15+AN15+AO15+AP15+AQ15+AR15+AS15+AT15+AU15+AV15+AW15+AX15+AY15+AZ15+BA15+BB15+BC15+BD15+BE15+BF15 -> 1900 | F15: 1900
A16: 11. | B16: Мактабларда ташкил этилган махсус ўқув синфхоналари | C16: =+D16+E16+F16+G16+H16+I16+J16+K16+L16+M16+N16+O16+P16+Q16+R16+S16+T16+U16+V16+W16+X16+Y16+Z16+AA16+AB16+AC16+AD16+AE16+AF16+AG16+AH16+AI16+AJ16+AK16+AL16+AM16+AN16+AO16+AP16+AQ16+AR16+AS16+AT16+AU16+AV16+AW16+AX16+AY16+AZ16+BA16+BB16+BC16+BD16+BE16+BF16 -> 0
A17: 12. | B17: “Йўл қоидаси – умр фойдаси” шиори остида ўтказилган тарғибот тадбирлари | C17: =+D17+E17+F17+G17+H17+I17+J17+K17+L17+M17+N17+O17+P17+Q17+R17+S17+T17+U17+V17+W17+X17+Y17+Z17+AA17+AB17+AC17+AD17+AE17+AF17+AG17+AH17+AI17+AJ17+AK17+AL17+AM17+AN17+AO17+AP17+AQ17+AR17+AS17+AT17+AU17+AV17+AW17+AX17+AY17+AZ17+BA17+BB17+BC17+BD17+BE17+BF17 -> 0
A18: 13. | B18: Ташкил этилган йўл ҳаракати қоидалари бўйича "Ёш тарғиботчи клублари" | C18: =+D18+E18+F18+G18+H18+I18+J18+K18+L18+M18+N18+O18+P18+Q18+R18+S18+T18+U18+V18+W18+X18+Y18+Z18+AA18+AB18+AC18+AD18+AE18+AF18+AG18+AH18+AI18+AJ18+AK18+AL18+AM18+AN18+AO18+AP18+AQ18+AR18+AS18+AT18+AU18+AV18+AW18+AX18+AY18+AZ18+BA18+BB18+BC18+BD18+BE18+BF18 -> 0
A19: 14. | B19: Яроқсиз ҳолга келган транспорт воситаларини рўйхатдан чиқариш
A20: 15. | B20: Аниқланган жами қоидабузарликлар | C20: 612 | D20: 15 | E20: 2 | F20: 10 | G20: 3 | H20: 4 | I20: 5 | J20: 2 | K20: 10 | L20: 5 | M20: 5 | N20: 5 | O20: 2 | P20: 5 | Q20: 4 | R20: 7 | S20: 10 | T20: 35 | U20: 30 | V20: 10 | W20: 2 | X20: 5 | Y20: 1 | Z20: 7 | AA20: 25 | AB20: 4 | AC20: 4 | AD20: 4 | AE20: 2 | AF20: 1 | AG20: 5 | AH20: 6 | AI20: 4 | AJ20: 3 | AK20: 7 | AL20: 7 | AM20: 30 | AN20: 10 | AO20: 5 | AP20: 7 | AQ20: 5 | AR20: 4 | AS20: 9 | AT20: 7 | AU20: 6 | AV20: 8 | AW20: 14 | AX20: 5 | AY20: 3 | AZ20: 15 | BA20: 3 | BB20: 17 | BC20: 11 | BD20: 4 | BE20: 3 | BF20: 190
A21: шундан | B21: Қўпол турдаги қоидабузарликлар | C21: 64 | D21: 1 | F21: 1 | K21: 1 | M21: 1 | R21: 1 | S21: 1 | T21: 4 | U21: 3 | V21: 1 | W21: 2 | X21: 1 | Z21: 2 | AA21: 2 | AB21: 1 | AC21: 1 | AG21: 1 | AJ21: 1 | AK21: 1 | AM21: 3 | AN21: 2 | AO21: 1 | AP21: 1 | AQ21: 1 | AS21: 2 | AT21: 1 | AU21: 1 | AV21: 2 | AW21: 1 | AX21: 1 | AZ21: 2 | BA21: 1 | BB21: 2 | BC21: 1 | BD21: 1 | BF21: 15
B22: Қарама-қарши ҳаракатланиш (МЖтКнинг 128 прим 5-моддаси)
B23: Светофорнинг қизил чироғида ҳаракатланиш (МЖтКнинг 128 прим 4-моддаси) | C23: 2 | F23: 1 | BF23: 1
B24: Пиёдага йўл бермаслик (МЖтКнинг 128-моддаси) | C24: 10 | D24: 2 | BF24: 8
B25: Ноқонуний тонировка | C25: 1 | T25: 1
B26: Маст ҳолатда транспорт воситасини бошқариш | C26: 3 | H26: 1 | BB26: 1 | BF26: 1
B27: Тегишли ҳужжатларсиз транспорт воситаларини бошқариш | C27: 8 | T27: 1 | Y27: 1 | AH27: 1 | AO27: 1 | AX27: 1 | BF27: 3
B28: Давлат рақам белгисини ўзбошимчалик билан ечиб олиш | C28: 1 | T28: 1
B29: Глушител, товуш чиқарувчи, мигалка ва бошқа қурилмалар
A30: 16. | B30: Жарима майдонига жойлаштирилган транспорт воситалари | C30: 15 | F30: 1 | T30: 2 | Y30: 1 | AH30: 1 | AO30: 1 | AX30: 1 | BF30: 8
A31: 17. | B31: Мактабларда ўтказилган "Авторейд" тадбирлари сони | C31: =+D31+E31+F31+G31+H31+I31+J31+K31+L31+M31+N31+O31+P31+Q31+R31+S31+T31+U31+V31+W31+X31+Y31+Z31+AA31+AB31+AC31+AD31+AE31+AF31+AG31+AH31+AI31+AJ31+AK31+AL31+AM31+AN31+AO31+AP31+AQ31+AR31+AS31+AT31+AU31+AV31+AW31+AX31+AY31+AZ31+BA31+BB31+BC31+BD31+BE31+BF31 -> 4 | D31: 2 | AA31: 1 | BF31: 1
A32: 17.1. | B32: Мактабларда ўтказилган "Авторейд" тадбирларида аниқланган қоидабузарликлар сони | C32: =+D32+E32+F32+G32+H32+I32+J32+K32+L32+M32+N32+O32+P32+Q32+R32+S32+T32+U32+V32+W32+X32+Y32+Z32+AA32+AB32+AC32+AD32+AE32+AF32+AG32+AH32+AI32+AJ32+AK32+AL32+AM32+AN32+AO32+AP32+AQ32+AR32+AS32+AT32+AU32+AV32+AW32+AX32+AY32+AZ32+BA32+BB32+BC32+BD32+BE32+BF32 -> 0
A33: 18. | B33: Ашаддий қоидабузар ҳайдовчилар бўйича уларнинг яшаш маҳаллаларида ўтказилган муҳокамалар | C33: =+D33+E33+F33+G33+H33+I33+J33+K33+L33+M33+N33+O33+P33+Q33+R33+S33+T33+U33+V33+W33+X33+Y33+Z33+AA33+AB33+AC33+AD33+AE33+AF33+AG33+AH33+AI33+AJ33+AK33+AL33+AM33+AN33+AO33+AP33+AQ33+AR33+AS33+AT33+AU33+AV33+AW33+AX33+AY33+AZ33+BA33+BB33+BC33+BD33+BE33+BF33 -> 0
A34: 19. | B34: Содир этилган жами йўл транспорт ҳодисалари (жиноий ҳолатлардан ташқари) | C34: =+D34+E34+F34+G34+H34+I34+J34+K34+L34+M34+N34+O34+P34+Q34+R34+S34+T34+U34+V34+W34+X34+Y34+Z34+AA34+AB34+AC34+AD34+AE34+AF34+AG34+AH34+AI34+AJ34+AK34+AL34+AM34+AN34+AO34+AP34+AQ34+AR34+AS34+AT34+AU34+AV34+AW34+AX34+AY34+AZ34+BA34+BB34+BC34+BD34+BE34+BF34 -> 0
A35: 20. | B35: Содир этилган жами ЙТҲлари билан боғлиқ жиноятлар (ЖК 266-модда 1-қисми) | C35: =+D35+E35+F35+G35+H35+I35+J35+K35+L35+M35+N35+O35+P35+Q35+R35+S35+T35+U35+V35+W35+X35+Y35+Z35+AA35+AB35+AC35+AD35+AE35+AF35+AG35+AH35+AI35+AJ35+AK35+AL35+AM35+AN35+AO35+AP35+AQ35+AR35+AS35+AT35+AU35+AV35+AW35+AX35+AY35+AZ35+BA35+BB35+BC35+BD35+BE35+BF35 -> 0
A36: 20.1. | B36: шундан, инсон ўлими билан боғлиқ жиноий ҳолатлар | C36: =+D36+E36+F36+G36+H36+I36+J36+K36+L36+M36+N36+O36+P36+Q36+R36+S36+T36+U36+V36+W36+X36+Y36+Z36+AA36+AB36+AC36+AD36+AE36+AF36+AG36+AH36+AI36+AJ36+AK36+AL36+AM36+AN36+AO36+AP36+AQ36+AR36+AS36+AT36+AU36+AV36+AW36+AX36+AY36+AZ36+BA36+BB36+BC36+BD36+BE36+BF36 -> 0
A37: 21. | B37: Автомобилни олиб қочиш (ЖК 267-модда) | C37: =+D37+E37+F37+G37+H37+I37+J37+K37+L37+M37+N37+O37+P37+Q37+R37+S37+T37+U37+V37+W37+X37+Y37+Z37+AA37+AB37+AC37+AD37+AE37+AF37+AG37+AH37+AI37+AJ37+AK37+AL37+AM37+AN37+AO37+AP37+AQ37+AR37+AS37+AT37+AU37+AV37+AW37+AX37+AY37+AZ37+BA37+BB37+BC37+BD37+BE37+BF37 -> 0

Sheet 01.22
A1: № | B1: Кўрсаткич | C1: Жами | D1: Ал-Хоразмий | E1: Бахористон | F1: Бектўпи | G1: Гулистон | H1: Катта Хирмонтепа | I1: Тирсакобод | J1: Хайрабод | K1: Хирмон тепа | L1: Хонтўпи | M1: Шараф | N1: Шарқ | O1: Шарқ тонги | P1: Шухрат | Q1: 1-Чарх Камолон | R1: 2-Чарх Камолон | S1: 3-Чарх Камолон | T1: Бешёғоч | U1: Катта Козиробод | V1: Катта Олмазор | W1: Катта Чилонзор-1 | X1: Катта Чилонзор-2 | Y1: Катта Чилонзор-3 | Z1: Қозиробод | AA1: Новза | AB1: Чилонзор | AC1: 1-Қатортол | AD1: Бешчинор | AE1: Боғзор | AF1: Диёр | AG1: Дилобод | AH1: Катта Навбаҳор | AI1: Кўркам | AJ1: Кўтарма | AK1: Қатортол | AL1: Лутфий | AM1: Навбахор | AN1: Нафосат | AO1: Оқ-тепа | AP1: Халқлар Дўстлиги | AQ1: Чўпон-ота | AR1: 2-Қатортол | AS1: Ботирма | AT1: Бўрижар | AU1: Гавхар | AV1: Дўмбиробод | AW1: Зарқўрғон | AX1: Катта Дўмбиробод | AY1: Кичик Хирмонтепа | AZ1: Мевазор | BA1: Мехржон | BB1: Наққошлик | BC1: Фидокор | BD1: Яккабоғ | BE1: Яккатут | BF1: Бешқўрғон
A2: 1. | B2: Автомобиль йўллари четига барпо этилган пиёдалар йўлаклари (тротуарлар) | C2: =+D2+E2+F2+G2+H2+I2+J2+K2+L2+M2+N2+O2+P2+Q2+R2+S2+T2+U2+V2+W2+X2+Y2+Z2+AA2+AB2+AC2+AD2+AE2+AF2+AG2+AH2+AI2+AJ2+AK2+AL2+AM2+AN2+AO2+AP2+AQ2+AR2+AS2+AT2+AU2+AV2+AW2+AX2+AY2+AZ2+BA2+BB2+BC2+BD2+BE2+BF2 -> 0
A3: 1.1. | B3: шундан, мактаб ҳудуди ва унинг атрофида ташкил этилган хавфсиз пиёдалар йўлаклари | C3: =+D3+E3+F3+G3+H3+I3+J3+K3+L3+M3+N3+O3+P3+Q3+R3+S3+T3+U3+V3+W3+X3+Y3+Z3+AA3+AB3+AC3+AD3+AE3+AF3+AG3+AH3+AI3+AJ3+AK3+AL3+AM3+AN3+AO3+AP3+AQ3+AR3+AS3+AT3+AU3+AV3+AW3+AX3+AY3+AZ3+BA3+BB3+BC3+BD3+BE3+BF3 -> 0
A4: 2. | B4: Мактаб ҳудуди ва унинг атрофида ташкил этилган қавариқ пиёдалар ўтиш жойлари | C4: =+D4+E4+F4+G4+H4+I4+J4+K4+L4+M4+N4+O4+P4+Q4+R4+S4+T4+U4+V4+W4+X4+Y4+Z4+AA4+AB4+AC4+AD4+AE4+AF4+AG4+AH4+AI4+AJ4+AK4+AL4+AM4+AN4+AO4+AP4+AQ4+AR4+AS4+AT4+AU4+AV4+AW4+AX4+AY4+AZ4+BA4+BB4+BC4+BD4+BE4+BF4 -> 0
A5: 3. | B5: шундан, серқатнов автомобиль йўлларида жойлашган мактаблар олдида ташкил этилган қавариқ пиёдалар | C5: =+D5+E5+F5+G5+H5+I5+J5+K5+L5+M5+N5+O5+P5+Q5+R5+S5+T5+U5+V5+W5+X5+Y5+Z5+AA5+AB5+AC5+AD5+AE5+AF5+AG5+AH5+AI5+AJ5+AK5+AL5+AM5+AN5+AO5+AP5+AQ5+AR5+AS5+AT5+AU5+AV5+AW5+AX5+AY5+AZ5+BA5+BB5+BC5+BD5+BE5+BF5 -> 0
A6: 4. | B6: Йўл ёқасида жойлашган мактаблар олдида ўрнатилган сунъий нотекисликлар (тезлик пасайтиргичлар) | C6: =+D6+E6+F6+G6+H6+I6+J6+K6+L6+M6+N6+O6+P6+Q6+R6+S6+T6+U6+V6+W6+X6+Y6+Z6+AA6+AB6+AC6+AD6+AE6+AF6+AG6+AH6+AI6+AJ6+AK6+AL6+AM6+AN6+AO6+AP6+AQ6+AR6+AS6+AT6+AU6+AV6+AW6+AX6+AY6+AZ6+BA6+BB6+BC6+BD6+BE6+BF6 -> 0
A7: 5. | B7: Ўрнатилган йўлларни ажратувчи махсус темир панжаралар (метр) | C7: =+D7+E7+F7+G7+H7+I7+J7+K7+L7+M7+N7+O7+P7+Q7+R7+S7+T7+U7+V7+W7+X7+Y7+Z7+AA7+AB7+AC7+AD7+AE7+AF7+AG7+AH7+AI7+AJ7+AK7+AL7+AM7+AN7+AO7+AP7+AQ7+AR7+AS7+AT7+AU7+AV7+AW7+AX7+AY7+AZ7+BA7+BB7+BC7+BD7+BE7+BF7 -> 0
A8: 6. | B8: Алмаштирилган эскирган ва талабга жавоб бермайдиган йўл белгилари | C8: =+D8+E8+F8+G8+H8+I8+J8+K8+L8+M8+N8+O8+P8+Q8+R8+S8+T8+U8+V8+W8+X8+Y8+Z8+AA8+AB8+AC8+AD8+AE8+AF8+AG8+AH8+AI8+AJ8+AK8+AL8+AM8+AN8+AO8+AP8+AQ8+AR8+AS8+AT8+AU8+AV8+AW8+AX8+AY8+AZ8+BA8+BB8+BC8+BD8+BE8+BF8 -> 2 | AD8: 2
A9: 7. | B9: Жами ўрнатилган светофорлар | C9: =+D9+E9+F9+G9+H9+I9+J9+K9+L9+M9+N9+O9+P9+Q9+R9+S9+T9+U9+V9+W9+X9+Y9+Z9+AA9+AB9+AC9+AD9+AE9+AF9+AG9+AH9+AI9+AJ9+AK9+AL9+AM9+AN9+AO9+AP9+AQ9+AR9+AS9+AT9+AU9+AV9+AW9+AX9+AY9+AZ9+BA9+BB9+BC9+BD9+BE9+BF9 -> 0
A10: 7.1. | B10: шундан, ТХАЙ йўлида ўрнатилган светофорлар | C10: =+D10+E10+F10+G10+H10+I10+J10+K10+L10+M10+N10+O10+P10+Q10+R10+S10+T10+U10+V10+W10+X10+Y10+Z10+AA10+AB10+AC10+AD10+AE10+AF10+AG10+AH10+AI10+AJ10+AK10+AL10+AM10+AN10+AO10+AP10+AQ10+AR10+AS10+AT10+AU10+AV10+AW10+AX10+AY10+AZ10+BA10+BB10+BC10+BD10+BE10+BF10 -> 0
A11: 8. | B11: Жами ўрнатилган тугмали светофорлар | C11: =+D11+E11+F11+G11+H11+I11+J11+K11+L11+M11+N11+O11+P11+Q11+R11+S11+T11+U11+V11+W11+X11+Y11+Z11+AA11+AB11+AC11+AD11+AE11+AF11+AG11+AH11+AI11+AJ11+AK11+AL11+AM11+AN11+AO11+AP11+AQ11+AR11+AS11+AT11+AU11+AV11+AW11+AX11+AY11+AZ11+BA11+BB11+BC11+BD11+BE11+BF11 -> 0
A12: 8.1. | B12: шундан, ТХАЙ йўлида ўрнатилган тугмали светофорлар | C12: =+D12+E12+F12+G12+H12+I12+J12+K12+L12+M12+N12+O12+P12+Q12+R12+S12+T12+U12+V12+W12+X12+Y12+Z12+AA12+AB12+AC12+AD12+AE12+AF12+AG12+AH12+AI12+AJ12+AK12+AL12+AM12+AN12+AO12+AP12+AQ12+AR12+AS12+AT12+AU12+AV12+AW12+AX12+AY12+AZ12+BA12+BB12+BC12+BD12+BE12+BF12 -> 0
A13: 9. | B13: Жами ўрнатилган янги йўл белгилари | C13: =+D13+E13+F13+G13+H13+I13+J13+K13+L13+M13+N13+O13+P13+Q13+R13+S13+T13+U13+V13+W13+X13+Y13+Z13+AA13+AB13+AC13+AD13+AE13+AF13+AG13+AH13+AI13+AJ13+AK13+AL13+AM13+AN13+AO13+AP13+AQ13+AR13+AS13+AT13+AU13+AV13+AW13+AX13+AY13+AZ13+BA13+BB13+BC13+BD13+BE13+BF13 -> 2 | AD13: 2
A14: 9.1. | B14: шундан, ТХАЙ йўлида ўрнатилганлари | C14: =+D14+E14+F14+G14+H14+I14+J14+K14+L14+M14+N14+O14+P14+Q14+R14+S14+T14+U14+V14+W14+X14+Y14+Z14+AA14+AB14+AC14+AD14+AE14+AF14+AG14+AH14+AI14+AJ14+AK14+AL14+AM14+AN14+AO14+AP14+AQ14+AR14+AS14+AT14+AU14+AV14+AW14+AX14+AY14+AZ14+BA14+BB14+BC14+BD14+BE14+BF14 -> 0
A15: 10. | B15: Чизилган йўл чизиқлари (м2) | C15: =+D15+E15+F15+G15+H15+I15+J15+K15+L15+M15+N15+O15+P15+Q15+R15+S15+T15+U15+V15+W15+X15+Y15+Z15+AA15+AB15+AC15+AD15+AE15+AF15+AG15+AH15+AI15+AJ15+AK15+AL15+AM15+AN15+AO15+AP15+AQ15+AR15+AS15+AT15+AU15+AV15+AW15+AX15+AY15+AZ15+BA15+BB15+BC15+BD15+BE15+BF15 -> 0
A16: 11. | B16: Мактабларда ташкил этилган махсус ўқув синфхоналари | C16: =+D16+E16+F16+G16+H16+I16+J16+K16+L16+M16+N16+O16+P16+Q16+R16+S16+T16+U16+V16+W16+X16+Y16+Z16+AA16+AB16+AC16+AD16+AE16+AF16+AG16+AH16+AI16+AJ16+AK16+AL16+AM16+AN16+AO16+AP16+AQ16+AR16+AS16+AT16+AU16+AV16+AW16+AX16+AY16+AZ16+BA16+BB16+BC16+BD16+BE16+BF16 -> 0
A17: 12. | B17: “Йўл қоидаси – умр фойдаси” шиори остида ўтказилган тарғибот тадбирлари | C17: =+D17+E17+F17+G17+H17+I17+J17+K17+L17+M17+N17+O17+P17+Q17+R17+S17+T17+U17+V17+W17+X17+Y17+Z17+AA17+AB17+AC17+AD17+AE17+AF17+AG17+AH17+AI17+AJ17+AK17+AL17+AM17+AN17+AO17+AP17+AQ17+AR17+AS17+AT17+AU17+AV17+AW17+AX17+AY17+AZ17+BA17+BB17+BC17+BD17+BE17+BF17 -> 0
A18: 13. | B18: Ташкил этилган йўл ҳаракати қоидалари бўйича "Ёш тарғиботчи клублари" | C18: =+D18+E18+F18+G18+H18+I18+J18+K18+L18+M18+N18+O18+P18+Q18+R18+S18+T18+U18+V18+W18+X18+Y18+Z18+AA18+AB18+AC18+AD18+AE18+AF18+AG18+AH18+AI18+AJ18+AK18+AL18+AM18+AN18+AO18+AP18+AQ18+AR18+AS18+AT18+AU18+AV18+AW18+AX18+AY18+AZ18+BA18+BB18+BC18+BD18+BE18+BF18 -> 0
A19: 14. | B19: Яроқсиз ҳолга келган транспорт воситаларини рўйхатдан чиқариш | C19: =+D19+E19+F19+G19+H19+I19+J19+K19+L19+M19+N19+O19+P19+Q19+R19+S19+T19+U19+V19+W19+X19+Y19+Z19+AA19+AB19+AC19+AD19+AE19+AF19+AG19+AH19+AI19+AJ19+AK19+AL19+AM19+AN19+AO19+AP19+AQ19+AR19+AS19+AT19+AU19+AV19+AW19+AX19+AY19+AZ19+BA19+BB19+BC19+BD19+BE19+BF19 -> 3 | J19: 1 | AE19: 1 | AI19: 1
A20: 15. | B20: Аниқланган жами қоидабузарликлар | C20: =+D20+E20+F20+G20+H20+I20+J20+K20+L20+M20+N20+O20+P20+Q20+R20+S20+T20+U20+V20+W20+X20+Y20+Z20+AA20+AB20+AC20+AD20+AE20+AF20+AG20+AH20+AI20+AJ20+AK20+AL20+AM20+AN20+AO20+AP20+AQ20+AR20+AS20+AT20+AU20+AV20+AW20+AX20+AY20+AZ20+BA20+BB20+BC20+BD20+BE20+BF20 -> 712 | D20: 20 | F20: 30 | H20: 10 | I20: 25 | K20: 12 | M20: 5 | R20: 5 | T20: 60 | U20: 40 | V20: 5 | Z20: 10 | AA20: 30 | AB20: 10 | AE20: 10 | AH20: 20 | AL20: 10 | AM20: 20 | AN20: 30 | AS20: 10 | AU20: 10 | AV20: 15 | AW20: 40 | AX20: 10 | AZ20: 20 | BB20: 25 | BF20: 230
A21: шундан | B21: Қўпол турдаги қоидабузарликлар | C21: =+D21+E21+F21+G21+H21+I21+J21+K21+L21+M21+N21+O21+P21+Q21+R21+S21+T21+U21+V21+W21+X21+Y21+Z21+AA21+AB21+AC21+AD21+AE21+AF21+AG21+AH21+AI21+AJ21+AK21+AL21+AM21+AN21+AO21+AP21+AQ21+AR21+AS21+AT21+AU21+AV21+AW21+AX21+AY21+AZ21+BA21+BB21+BC21+BD21+BE21+BF21 -> 62 | D21: 1 | F21: 2 | H21: 0 | I21: 2 | K21: 1 | M21: 1 | T21: 3 | U21: 3 | V21: 1 | Z21: 2 | AA21: 2 | AB21: 1 | AE21: 2 | AH21: 3 | AL21: 1 | AM21: 3 | AN21: 2 | AS21: 1 | AU21: 1 | AV21: 1 | AW21: 6 | AX21: 1 | AZ21: 1 | BB21: 2 | BF21: 19
B22: Қарама-қарши ҳаракатланиш (МЖтКнинг 128 прим 5-моддаси) | C22: =+D22+E22+F22+G22+H22+I22+J22+K22+L22+M22+N22+O22+P22+Q22+R22+S22+T22+U22+V22+W22+X22+Y22+Z22+AA22+AB22+AC22+AD22+AE22+AF22+AG22+AH22+AI22+AJ22+AK22+AL22+AM22+AN22+AO22+AP22+AQ22+AR22+AS22+AT22+AU22+AV22+AW22+AX22+AY22+AZ22+BA22+BB22+BC22+BD22+BE22+BF22 -> 0
B23: Светофорнинг қизил чироғида ҳаракатланиш (МЖтКнинг 128 прим 4-моддаси) | C23: =+D23+E23+F23+G23+H23+I23+J23+K23+L23+M23+N23+O23+P23+Q23+R23+S23+T23+U23+V23+W23+X23+Y23+Z23+AA23+AB23+AC23+AD23+AE23+AF23+AG23+AH23+AI23+AJ23+AK23+AL23+AM23+AN23+AO23+AP23+AQ23+AR23+AS23+AT23+AU23+AV23+AW23+AX23+AY23+AZ23+BA23+BB23+BC23+BD23+BE23+BF23 -> 3 | I23: 2 | BF23: 1
B24: Пиёдага йўл бермаслик (МЖтКнинг 128-моддаси) | C24: =+D24+E24+F24+G24+H24+I24+J24+K24+L24+M24+N24+O24+P24+Q24+R24+S24+T24+U24+V24+W24+X24+Y24+Z24+AA24+AB24+AC24+AD24+AE24+AF24+AG24+AH24+AI24+AJ24+AK24+AL24+AM24+AN24+AO24+AP24+AQ24+AR24+AS24+AT24+AU24+AV24+AW24+AX24+AY24+AZ24+BA24+BB24+BC24+BD24+BE24+BF24 -> 4 | T24: 1 | U24: 1 | BF24: 2
B25: Ноқонуний тонировка | C25: =+D25+E25+F25+G25+H25+I25+J25+K25+L25+M25+N25+O25+P25+Q25+R25+S25+T25+U25+V25+W25+X25+Y25+Z25+AA25+AB25+AC25+AD25+AE25+AF25+AG25+AH25+AI25+AJ25+AK25+AL25+AM25+AN25+AO25+AP25+AQ25+AR25+AS25+AT25+AU25+AV25+AW25+AX25+AY25+AZ25+BA25+BB25+BC25+BD25+BE25+BF25 -> 1 | AN25: 1
B26: Маст ҳолатда транспорт воситасини бошқариш | C26: =+D26+E26+F26+G26+H26+I26+J26+K26+L26+M26+N26+O26+P26+Q26+R26+S26+T26+U26+V26+W26+X26+Y26+Z26+AA26+AB26+AC26+AD26+AE26+AF26+AG26+AH26+AI26+AJ26+AK26+AL26+AM26+AN26+AO26+AP26+AQ26+AR26+AS26+AT26+AU26+AV26+AW26+AX26+AY26+AZ26+BA26+BB26+BC26+BD26+BE26+BF26 -> 2 | AS26: 1 | BF26: 1
B27: Тегишли ҳужжатларсиз транспорт воситаларини бошқариш | C27: =+D27+E27+F27+G27+H27+I27+J27+K27+L27+M27+N27+O27+P27+Q27+R27+S27+T27+U27+V27+W27+X27+Y27+Z27+AA27+AB27+AC27+AD27+AE27+AF27+AG27+AH27+AI27+AJ27+AK27+AL27+AM27+AN27+AO27+AP27+AQ27+AR27+AS27+AT27+AU27+AV27+AW27+AX27+AY27+AZ27+BA27+BB27+BC27+BD27+BE27+BF27 -> 6 | D27: 1 | T27: 1 | AZ27: 1 | BB27: 1 | BF27: 2
B28: Давлат рақам белгисини ўзбошимчалик билан ечиб олиш | C28: =+D28+E28+F28+G28+H28+I28+J28+K28+L28+M28+N28+O28+P28+Q28+R28+S28+T28+U28+V28+W28+X28+Y28+Z28+AA28+AB28+AC28+AD28+AE28+AF28+AG28+AH28+AI28+AJ28+AK28+AL28+AM28+AN28+AO28+AP28+AQ28+AR28+AS28+AT28+AU28+AV28+AW28+AX28+AY28+AZ28+BA28+BB28+BC28+BD28+BE28+BF28 -> 0
B29: Глушител, товуш чиқарувчи, мигалка ва бошқа қурилмалар | C29: =+D29+E29+F29+G29+H29+I29+J29+K29+L29+M29+N29+O29+P29+Q29+R29+S29+T29+U29+V29+W29+X29+Y29+Z29+AA29+AB29+AC29+AD29+AE29+AF29+AG29+AH29+AI29+AJ29+AK29+AL29+AM29+AN29+AO29+AP29+AQ29+AR29+AS29+AT29+AU29+AV29+AW29+AX29+AY29+AZ29+BA29+BB29+BC29+BD29+BE29+BF29 -> 0
A30: 16. | B30: Жарима майдонига жойлаштирилган транспорт воситалари | C30: =+D30+E30+F30+G30+H30+I30+J30+K30+L30+M30+N30+O30+P30+Q30+R30+S30+T30+U30+V30+W30+X30+Y30+Z30+AA30+AB30+AC30+AD30+AE30+AF30+AG30+AH30+AI30+AJ30+AK30+AL30+AM30+AN30+AO30+AP30+AQ30+AR30+AS30+AT30+AU30+AV30+AW30+AX30+AY30+AZ30+BA30+BB30+BC30+BD30+BE30+BF30 -> 12 | D30: 1 | I30: 1 | T30: 2 | U30: 1 | AZ30: 1 | BA30: 1 | BB30: 1 | BF30: 4
A31: 17. | B31: Мактабларда ўтказилган "Авторейд" тадбирлари сони | C31: =+D31+E31+F31+G31+H31+I31+J31+K31+L31+M31+N31+O31+P31+Q31+R31+S31+T31+U31+V31+W31+X31+Y31+Z31+AA31+AB31+AC31+AD31+AE31+AF31+AG31+AH31+AI31+AJ31+AK31+AL31+AM31+AN31+AO31+AP31+AQ31+AR31+AS31+AT31+AU31+AV31+AW31+AX31+AY31+AZ31+BA31+BB31+BC31+BD31+BE31+BF31 -> 0
A32: 17.1. | B32: Мактабларда ўтказилган "Авторейд" тадбирларида аниқланган қоидабузарликлар сони | C32: =+D32+E32+F32+G32+H32+I32+J32+K32+L32+M32+N32+O32+P32+Q32+R32+S32+T32+U32+V32+W32+X32+Y32+Z32+AA32+AB32+AC32+AD32+AE32+AF32+AG32+AH32+AI32+AJ32+AK32+AL32+AM32+AN32+AO32+AP32+AQ32+AR32+AS32+AT32+AU32+AV32+AW32+AX32+AY32+AZ32+BA32+BB32+BC32+BD32+BE32+BF32 -> 0
A33: 18. | B33: Ашаддий қоидабузар ҳайдовчилар бўйича уларнинг яшаш маҳаллаларида ўтказилган муҳокамалар | C33: =+D33+E33+F33+G33+H33+I33+J33+K33+L33+M33+N33+O33+P33+Q33+R33+S33+T33+U33+V33+W33+X33+Y33+Z33+AA33+AB33+AC33+AD33+AE33+AF33+AG33+AH33+AI33+AJ33+AK33+AL33+AM33+AN33+AO33+AP33+AQ33+AR33+AS33+AT33+AU33+AV33+AW33+AX33+AY33+AZ33+BA33+BB33+BC33+BD33+BE33+BF33 -> 0
A34: 19. | B34: Содир этилган жами йўл транспорт ҳодисалари (жиноий ҳолатлардан ташқари) | C34: =+D34+E34+F34+G34+H34+I34+J34+K34+L34+M34+N34+O34+P34+Q34+R34+S34+T34+U34+V34+W34+X34+Y34+Z34+AA34+AB34+AC34+AD34+AE34+AF34+AG34+AH34+AI34+AJ34+AK34+AL34+AM34+AN34+AO34+AP34+AQ34+AR34+AS34+AT34+AU34+AV34+AW34+AX34+AY34+AZ34+BA34+BB34+BC34+BD34+BE34+BF34 -> 0
A35: 20. | B35: Содир этилган жами ЙТҲлари билан боғлиқ жиноятлар (ЖК 266-модда 1-қисми) | C35: =+D35+E35+F35+G35+H35+I35+J35+K35+L35+M35+N35+O35+P35+Q35+R35+S35+T35+U35+V35+W35+X35+Y35+Z35+AA35+AB35+AC35+AD35+AE35+AF35+AG35+AH35+AI35+AJ35+AK35+AL35+AM35+AN35+AO35+AP35+AQ35+AR35+AS35+AT35+AU35+AV35+AW35+AX35+AY35+AZ35+BA35+BB35+BC35+BD35+BE35+BF35 -> 2 | AD35: 1 | BF35: 1
A36: 20.1. | B36: шундан, инсон ўлими билан боғлиқ жиноий ҳолатлар | C36: =+D36+E36+F36+G36+H36+I36+J36+K36+L36+M36+N36+O36+P36+Q36+R36+S36+T36+U36+V36+W36+X36+Y36+Z36+AA36+AB36+AC36+AD36+AE36+AF36+AG36+AH36+AI36+AJ36+AK36+AL36+AM36+AN36+AO36+AP36+AQ36+AR36+AS36+AT36+AU36+AV36+AW36+AX36+AY36+AZ36+BA36+BB36+BC36+BD36+BE36+BF36 -> 0
A37: 21. | B37: Автомобилни олиб қочиш (ЖК 267-модда) | C37: =+D37+E37+F37+G37+H37+I37+J37+K37+L37+M37+N37+O37+P37+Q37+R37+S37+T37+U37+V37+W37+X37+Y37+Z37+AA37+AB37+AC37+AD37+AE37+AF37+AG37+AH37+AI37+AJ37+AK37+AL37+AM37+AN37+AO37+AP37+AQ37+AR37+AS37+AT37+AU37+AV37+AW37+AX37+AY37+AZ37+BA37+BB37+BC37+BD37+BE37+BF37 -> 0

Sheet 01.23
A1: № | B1: Кўрсаткич | C1: Жами | D1: Ал-Хоразмий | E1: Бахористон | F1: Бектўпи | G1: Гулистон | H1: Катта Хирмонтепа | I1: Тирсакобод | J1: Хайрабод | K1: Хирмон тепа | L1: Хонтўпи | M1: Шараф | N1: Шарқ | O1: Шарқ тонги | P1: Шухрат | Q1: 1-Чарх Камолон | R1: 2-Чарх Камолон | S1: 3-Чарх Камолон | T1: Бешёғоч | U1: Катта Козиробод | V1: Катта Олмазор | W1: Катта Чилонзор-1 | X1: Катта Чилонзор-2 | Y1: Катта Чилонзор-3 | Z1: Қозиробод | AA1: Новза | AB1: Чилонзор | AC1: 1-Қатортол | AD1: Бешчинор | AE1: Боғзор | AF1: Диёр | AG1: Дилобод | AH1: Катта Навбаҳор | AI1: Кўркам | AJ1: Кўтарма | AK1: Қатортол | AL1: Лутфий | AM1: Навбахор | AN1: Нафосат | AO1: Оқ-тепа | AP1: Халқлар Дўстлиги | AQ1: Чўпон-ота | AR1: 2-Қатортол | AS1: Ботирма | AT1: Бўрижар | AU1: Гавхар | AV1: Дўмбиробод | AW1: Зарқўрғон | AX1: Катта Дўмбиробод | AY1: Кичик Хирмонтепа | AZ1: Мевазор | BA1: Мехржон | BB1: Наққошлик | BC1: Фидокор | BD1: Яккабоғ | BE1: Яккатут | BF1: Бешқўрғон
A2: 1. | B2: Автомобиль йўллари четига барпо этилган пиёдалар йўлаклари (тротуарлар) | C2: =+D2+E2+F2+G2+H2+I2+J2+K2+L2+M2+N2+O2+P2+Q2+R2+S2+T2+U2+V2+W2+X2+Y2+Z2+AA2+AB2+AC2+AD2+AE2+AF2+AG2+AH2+AI2+AJ2+AK2+AL2+AM2+AN2+AO2+AP2+AQ2+AR2+AS2+AT2+AU2+AV2+AW2+AX2+AY2+AZ2+BA2+BB2+BC2+BD2+BE2+BF2 -> 0
A3: 1.1. | B3: шундан, мактаб ҳудуди ва унинг атрофида ташкил этилган хавфсиз пиёдалар йўлаклари | C3: =+D3+E3+F3+G3+H3+I3+J3+K3+L3+M3+N3+O3+P3+Q3+R3+S3+T3+U3+V3+W3+X3+Y3+Z3+AA3+AB3+AC3+AD3+AE3+AF3+AG3+AH3+AI3+AJ3+AK3+AL3+AM3+AN3+AO3+AP3+AQ3+AR3+AS3+AT3+AU3+AV3+AW3+AX3+AY3+AZ3+BA3+BB3+BC3+BD3+BE3+BF3 -> 0
A4: 2. | B4: Мактаб ҳудуди ва унинг атрофида ташкил этилган қавариқ пиёдалар ўтиш жойлари | C4: =+D4+E4+F4+G4+H4+I4+J4+K4+L4+M4+N4+O4+P4+Q4+R4+S4+T4+U4+V4+W4+X4+Y4+Z4+AA4+AB4+AC4+AD4+AE4+AF4+AG4+AH4+AI4+AJ4+AK4+AL4+AM4+AN4+AO4+AP4+AQ4+AR4+AS4+AT4+AU4+AV4+AW4+AX4+AY4+AZ4+BA4+BB4+BC4+BD4+BE4+BF4 -> 0
A5: 3. | B5: шундан, серқатнов автомобиль йўлларида жойлашган мактаблар олдида ташкил этилган қавариқ пиёдалар | C5: =+D5+E5+F5+G5+H5+I5+J5+K5+L5+M5+N5+O5+P5+Q5+R5+S5+T5+U5+V5+W5+X5+Y5+Z5+AA5+AB5+AC5+AD5+AE5+AF5+AG5+AH5+AI5+AJ5+AK5+AL5+AM5+AN5+AO5+AP5+AQ5+AR5+AS5+AT5+AU5+AV5+AW5+AX5+AY5+AZ5+BA5+BB5+BC5+BD5+BE5+BF5 -> 0
A6: 4. | B6: Йўл ёқасида жойлашган мактаблар олдида ўрнатилган сунъий нотекисликлар (тезлик пасайтиргичлар) | C6: =+D6+E6+F6+G6+H6+I6+J6+K6+L6+M6+N6+O6+P6+Q6+R6+S6+T6+U6+V6+W6+X6+Y6+Z6+AA6+AB6+AC6+AD6+AE6+AF6+AG6+AH6+AI6+AJ6+AK6+AL6+AM6+AN6+AO6+AP6+AQ6+AR6+AS6+AT6+AU6+AV6+AW6+AX6+AY6+AZ6+BA6+BB6+BC6+BD6+BE6+BF6 -> 0
A7: 5. | B7: Ўрнатилган йўлларни ажратувчи махсус темир панжаралар (метр) | C7: =+D7+E7+F7+G7+H7+I7+J7+K7+L7+M7+N7+O7+P7+Q7+R7+S7+T7+U7+V7+W7+X7+Y7+Z7+AA7+AB7+AC7+AD7+AE7+AF7+AG7+AH7+AI7+AJ7+AK7+AL7+AM7+AN7+AO7+AP7+AQ7+AR7+AS7+AT7+AU7+AV7+AW7+AX7+AY7+AZ7+BA7+BB7+BC7+BD7+BE7+BF7 -> 0
A8: 6. | B8: Алмаштирилган эскирган ва талабга жавоб бермайдиган йўл белгилари | C8: =+D8+E8+F8+G8+H8+I8+J8+K8+L8+M8+N8+O8+P8+Q8+R8+S8+T8+U8+V8+W8+X8+Y8+Z8+AA8+AB8+AC8+AD8+AE8+AF8+AG8+AH8+AI8+AJ8+AK8+AL8+AM8+AN8+AO8+AP8+AQ8+AR8+AS8+AT8+AU8+AV8+AW8+AX8+AY8+AZ8+BA8+BB8+BC8+BD8+BE8+BF8 -> 0
A9: 7. | B9: Жами ўрнатилган светофорлар | C9: =+D9+E9+F9+G9+H9+I9+J9+K9+L9+M9+N9+O9+P9+Q9+R9+S9+T9+U9+V9+W9+X9+Y9+Z9+AA9+AB9+AC9+AD9+AE9+AF9+AG9+AH9+AI9+AJ9+AK9+AL9+AM9+AN9+AO9+AP9+AQ9+AR9+AS9+AT9+AU9+AV9+AW9+AX9+AY9+AZ9+BA9+BB9+BC9+BD9+BE9+BF9 -> 0
A10: 7.1. | B10: шундан, ТХАЙ йўлида ўрнатилган светофорлар | C10: =+D10+E10+F10+G10+H10+I10+J10+K10+L10+M10+N10+O10+P10+Q10+R10+S10+T10+U10+V10+W10+X10+Y10+Z10+AA10+AB10+AC10+AD10+AE10+AF10+AG10+AH10+AI10+AJ10+AK10+AL10+AM10+AN10+AO10+AP10+AQ10+AR10+AS10+AT10+AU10+AV10+AW10+AX10+AY10+AZ10+BA10+BB10+BC10+BD10+BE10+BF10 -> 0
A11: 8. | B11: Жами ўрнатилган тугмали светофорлар | C11: =+D11+E11+F11+G11+H11+I11+J11+K11+L11+M11+N11+O11+P11+Q11+R11+S11+T11+U11+V11+W11+X11+Y11+Z11+AA11+AB11+AC11+AD11+AE11+AF11+AG11+AH11+AI11+AJ11+AK11+AL11+AM11+AN11+AO11+AP11+AQ11+AR11+AS11+AT11+AU11+AV11+AW11+AX11+AY11+AZ11+BA11+BB11+BC11+BD11+BE11+BF11 -> 0
A12: 8.1. | B12: шундан, ТХАЙ йўлида ўрнатилган тугмали светофорлар | C12: =+D12+E12+F12+G12+H12+I12+J12+K12+L12+M12+N12+O12+P12+Q12+R12+S12+T12+U12+V12+W12+X12+Y12+Z12+AA12+AB12+AC12+AD12+AE12+AF12+AG12+AH12+AI12+AJ12+AK12+AL12+AM12+AN12+AO12+AP12+AQ12+AR12+AS12+AT12+AU12+AV12+AW12+AX12+AY12+AZ12+BA12+BB12+BC12+BD12+BE12+BF12 -> 0
A13: 9. | B13: Жами ўрнатилган янги йўл белгилари | C13: =+D13+E13+F13+G13+H13+I13+J13+K13+L13+M13+N13+O13+P13+Q13+R13+S13+T13+U13+V13+W13+X13+Y13+Z13+AA13+AB13+AC13+AD13+AE13+AF13+AG13+AH13+AI13+AJ13+AK13+AL13+AM13+AN13+AO13+AP13+AQ13+AR13+AS13+AT13+AU13+AV13+AW13+AX13+AY13+AZ13+BA13+BB13+BC13+BD13+BE13+BF13 -> 0
... A19: 14. | B19: Яроқсиз ҳолга келган транспорт воситаларини рўйхатдан чиқариш | C19: =+D19+E19+F19+G19+H19+I19+J19+K19+L19+M19+N19+O19+P19+Q19+R19+S19+T19+U19+V19+W19+X19+Y19+Z19+AA19+AB19+AC19+AD19+AE19+AF19+AG19+AH19+AI19+AJ19+AK19+AL19+AM19+AN19+AO19+AP19+AQ19+AR19+AS19+AT19+AU19+AV19+AW19+AX19+AY19+AZ19+BA19+BB19+BC19+BD19+BE19+BF19 -> 0
A20: 15. | B20: Аниқланган жами қоидабузарликлар | C20: =+D20+E20+F20+G20+H20+I20+J20+K20+L20+M20+N20+O20+P20+Q20+R20+S20+T20+U20+V20+W20+X20+Y20+Z20+AA20+AB20+AC20+AD20+AE20+AF20+AG20+AH20+AI20+AJ20+AK20+AL20+AM20+AN20+AO20+AP20+AQ20+AR20+AS20+AT20+AU20+AV20+AW20+AX20+AY20+AZ20+BA20+BB20+BC20+BD20+BE20+BF20 -> 98 | R20: 1 | T20: 15 | U20: 5 | AM20: 3 | AN20: 2 | AZ20: 2 | BB20: 5 | BF20: 65
A21: шундан | B21: Қўпол турдаги қоидабузарликлар | C21: =+D21+E21+F21+G21+H21+I21+J21+K21+L21+M21+N21+O21+P21+Q21+R21+S21+T21+U21+V21+W21+X21+Y21+Z21+AA21+AB21+AC21+AD21+AE21+AF21+AG21+AH21+AI21+AJ21+AK21+AL21+AM21+AN21+AO21+AP21+AQ21+AR21+AS21+AT21+AU21+AV21+AW21+AX21+AY21+AZ21+BA21+BB21+BC21+BD21+BE21+BF21 -> 10 | R21: 1 | T21: 1 | AM21: 1 | BB21: 2 | BF21: 5
B22: Қарама-қарши ҳаракатланиш (МЖтКнинг 128 прим 5-моддаси) | C22: =+D22+E22+F22+G22+H22+I22+J22+K22+L22+M22+N22+O22+P22+Q22+R22+S22+T22+U22+V22+W22+X22+Y22+Z22+AA22+AB22+AC22+AD22+AE22+AF22+AG22+AH22+AI22+AJ22+AK22+AL22+AM22+AN22+AO22+AP22+AQ22+AR22+AS22+AT22+AU22+AV22+AW22+AX22+AY22+AZ22+BA22+BB22+BC22+BD22+BE22+BF22 -> 0
B23: Светофорнинг қизил чироғида ҳаракатланиш (МЖтКнинг 128 прим 4-моддаси) | C23: =+D23+E23+F23+G23+H23+I23+J23+K23+L23+M23+N23+O23+P23+Q23+R23+S23+T23+U23+V23+W23+X23+Y23+Z23+AA23+AB23+AC23+AD23+AE23+AF23+AG23+AH23+AI23+AJ23+AK23+AL23+AM23+AN23+AO23+AP23+AQ23+AR23+AS23+AT23+AU23+AV23+AW23+AX23+AY23+AZ23+BA23+BB23+BC23+BD23+BE23+BF23 -> 0
B24: Пиёдага йўл бермаслик (МЖтКнинг 128-моддаси) | C24: =+D24+E24+F24+G24+H24+I24+J24+K24+L24+M24+N24+O24+P24+Q24+R24+S24+T24+U24+V24+W24+X24+Y24+Z24+AA24+AB24+AC24+AD24+AE24+AF24+AG24+AH24+AI24+AJ24+AK24+AL24+AM24+AN24+AO24+AP24+AQ24+AR24+AS24+AT24+AU24+AV24+AW24+AX24+AY24+AZ24+BA24+BB24+BC24+BD24+BE24+BF24 -> 2 | T24: 1 | BF24: 1
B25: Ноқонуний тонировка | C25: =+D25+E25+F25+G25+H25+I25+J25+K25+L25+M25+N25+O25+P25+Q25+R25+S25+T25+U25+V25+W25+X25+Y25+Z25+AA25+AB25+AC25+AD25+AE25+AF25+AG25+AH25+AI25+AJ25+AK25+AL25+AM25+AN25+AO25+AP25+AQ25+AR25+AS25+AT25+AU25+AV25+AW25+AX25+AY25+AZ25+BA25+BB25+BC25+BD25+BE25+BF25 -> 0
B26: Маст ҳолатда транспорт воситасини бошқариш | C26: =+D26+E26+F26+G26+H26+I26+J26+K26+L26+M26+N26+O26+P26+Q26+R26+S26+T26+U26+V26+W26+X26+Y26+Z26+AA26+AB26+AC26+AD26+AE26+AF26+AG26+AH26+AI26+AJ26+AK26+AL26+AM26+AN26+AO26+AP26+AQ26+AR26+AS26+AT26+AU26+AV26+AW26+AX26+AY26+AZ26+BA26+BB26+BC26+BD26+BE26+BF26 -> 1 | R26: 1
B27: Тегишли ҳужжатларсиз транспорт воситаларини бошқариш | C27: =+D27+E27+F27+G27+H27+I27+J27+K27+L27+M27+N27+O27+P27+Q27+R27+S27+T27+U27+V27+W27+X27+Y27+Z27+AA27+AB27+AC27+AD27+AE27+AF27+AG27+AH27+AI27+AJ27+AK27+AL27+AM27+AN27+AO27+AP27+AQ27+AR27+AS27+AT27+AU27+AV27+AW27+AX27+AY27+AZ27+BA27+BB27+BC27+BD27+BE27+BF27 -> 6 | T27: 2 | BB27: 1 | BF27: 3
B28: Давлат рақам белгисини ўзбошимчалик билан ечиб олиш | C28: =+D28+E28+F28+G28+H28+I28+J28+K28+L28+M28+N28+O28+P28+Q28+R28+S28+T28+U28+V28+W28+X28+Y28+Z28+AA28+AB28+AC28+AD28+AE28+AF28+AG28+AH28+AI28+AJ28+AK28+AL28+AM28+AN28+AO28+AP28+AQ28+AR28+AS28+AT28+AU28+AV28+AW28+AX28+AY28+AZ28+BA28+BB28+BC28+BD28+BE28+BF28 -> 0
B29: Глушител, товуш чиқарувчи, мигалка ва бошқа қурилмалар | C29: =+D29+E29+F29+G29+H29+I29+J29+K29+L29+M29+N29+O29+P29+Q29+R29+S29+T29+U29+V29+W29+X29+Y29+Z29+AA29+AB29+AC29+AD29+AE29+AF29+AG29+AH29+AI29+AJ29+AK29+AL29+AM29+AN29+AO29+AP29+AQ29+AR29+AS29+AT29+AU29+AV29+AW29+AX29+AY29+AZ29+BA29+BB29+BC29+BD29+BE29+BF29 -> 0
A30: 16. | B30: Жарима майдонига жойлаштирилган транспорт воситалари | C30: =+D30+E30+F30+G30+H30+I30+J30+K30+L30+M30+N30+O30+P30+Q30+R30+S30+T30+U30+V30+W30+X30+Y30+Z30+AA30+AB30+AC30+AD30+AE30+AF30+AG30+AH30+AI30+AJ30+AK30+AL30+AM30+AN30+AO30+AP30+AQ30+AR30+AS30+AT30+AU30+AV30+AW30+AX30+AY30+AZ30+BA30+BB30+BC30+BD30+BE30+BF30 -> 8 | R30: 1 | T30: 2 | BB30: 2 | BF30: 3
A31: 17. | B31: Мактабларда ўтказилган "Авторейд" тадбирлари сони | C31: =+D31+E31+F31+G31+H31+I31+J31+K31+L31+M31+N31+O31+P31+Q31+R31+S31+T31+U31+V31+W31+X31+Y31+Z31+AA31+AB31+AC31+AD31+AE31+AF31+AG31+AH31+AI31+AJ31+AK31+AL31+AM31+AN31+AO31+AP31+AQ31+AR31+AS31+AT31+AU31+AV31+AW31+AX31+AY31+AZ31+BA31+BB31+BC31+BD31+BE31+BF31 -> 0
A32: 17.1. | B32: Мактабларда ўтказилган "Авторейд" тадбирларида аниқланган қоидабузарликлар сони | C32: =+D32+E32+F32+G32+H32+I32+J32+K32+L32+M32+N32+O32+P32+Q32+R32+S32+T32+U32+V32+W32+X32+Y32+Z32+AA32+AB32+AC32+AD32+AE32+AF32+AG32+AH32+AI32+AJ32+AK32+AL32+AM32+AN32+AO32+AP32+AQ32+AR32+AS32+AT32+AU32+AV32+AW32+AX32+AY32+AZ32+BA32+BB32+BC32+BD32+BE32+BF32 -> 0
A33: 18. | B33: Ашаддий қоидабузар ҳайдовчилар бўйича уларнинг яшаш маҳаллаларида ўтказилган муҳокамалар | C33: =+D33+E33+F33+G33+H33+I33+J33+K33+L33+M33+N33+O33+P33+Q33+R33+S33+T33+U33+V33+W33+X33+Y33+Z33+AA33+AB33+AC33+AD33+AE33+AF33+AG33+AH33+AI33+AJ33+AK33+AL33+AM33+AN33+AO33+AP33+AQ33+AR33+AS33+AT33+AU33+AV33+AW33+AX33+AY33+AZ33+BA33+BB33+BC33+BD33+BE33+BF33 -> 0
A34: 19. | B34: Содир этилган жами йўл транспорт ҳодисалари (жиноий ҳолатлардан ташқари) | C34: =+D34+E34+F34+G34+H34+I34+J34+K34+L34+M34+N34+O34+P34+Q34+R34+S34+T34+U34+V34+W34+X34+Y34+Z34+AA34+AB34+AC34+AD34+AE34+AF34+AG34+AH34+AI34+AJ34+AK34+AL34+AM34+AN34+AO34+AP34+AQ34+AR34+AS34+AT34+AU34+AV34+AW34+AX34+AY34+AZ34+BA34+BB34+BC34+BD34+BE34+BF34 -> 0
A35: 20. | B35: Содир этилган жами ЙТҲлари билан боғлиқ жиноятлар (ЖК 266-модда 1-қисми) | C35: =+D35+E35+F35+G35+H35+I35+J35+K35+L35+M35+N35+O35+P35+Q35+R35+S35+T35+U35+V35+W35+X35+Y35+Z35+AA35+AB35+AC35+AD35+AE35+AF35+AG35+AH35+AI35+AJ35+AK35+AL35+AM35+AN35+AO35+AP35+AQ35+AR35+AS35+AT35+AU35+AV35+AW35+AX35+AY35+AZ35+BA35+BB35+BC35+BD35+BE35+BF35 -> 0
A36: 20.1. | B36: шундан, инсон ўлими билан боғлиқ жиноий ҳолатлар | C36: =+D36+E36+F36+G36+H36+I36+J36+K36+L36+M36+N36+O36+P36+Q36+R36+S36+T36+U36+V36+W36+X36+Y36+Z36+AA36+AB36+AC36+AD36+AE36+AF36+AG36+AH36+AI36+AJ36+AK36+AL36+AM36+AN36+AO36+AP36+AQ36+AR36+AS36+AT36+AU36+AV36+AW36+AX36+AY36+AZ36+BA36+BB36+BC36+BD36+BE36+BF36 -> 0
A37: 21. | B37: Автомобилни олиб қочиш (ЖК 267-модда) | C37: =+D37+E37+F37+G37+H37+I37+J37+K37+L37+M37+N37+O37+P37+Q37+R37+S37+T37+U37+V37+W37+X37+Y37+Z37+AA37+AB37+AC37+AD37+AE37+AF37+AG37+AH37+AI37+AJ37+AK37+AL37+AM37+AN37+AO37+AP37+AQ37+AR37+AS37+AT37+AU37+AV37+AW37+AX37+AY37+AZ37+BA37+BB37+BC37+BD37+BE37+BF37 -> 0

Sheet 01.24
A1: № | B1: Кўрсаткич | C1: Жами | D1: Ал-Хоразмий | E1: Бахористон | F1: Бектўпи | G1: Гулистон | H1: Катта Хирмонтепа | I1: Тирсакобод | J1: Хайрабод | K1: Хирмон тепа | L1: Хонтўпи | M1: Шараф | N1: Шарқ | O1: Шарқ тонги | P1: Шухрат | Q1: 1-Чарх Камолон | R1: 2-Чарх Камолон | S1: 3-Чарх Камолон | T1: Бешёғоч | U1: Катта Козиробод | V1: Катта Олмазор | W1: Катта Чилонзор-1 | X1: Катта Чилонзор-2 | Y1: Катта Чилонзор-3 | Z1: Қозиробод | AA1: Новза | AB1: Чилонзор | AC1: 1-Қатортол | AD1: Бешчинор | AE1: Боғзор | AF1: Диёр | AG1: Дилобод | AH1: Катта Навбаҳор | AI1: Кўркам | AJ1: Кўтарма | AK1: Қатортол | AL1: Лутфий | AM1: Навбахор | AN1: Нафосат | AO1: Оқ-тепа | AP1: Халқлар Дўстлиги | AQ1: Чўпон-ота | AR1: 2-Қатортол | AS1: Ботирма | AT1: Бўрижар | AU1: Гавхар | AV1: Дўмбиробод | AW1: Зарқўрғон | AX1: Катта Дўмбиробод | AY1: Кичик Хирмонтепа | AZ1: Мевазор | BA1: Мехржон | BB1: Наққошлик | BC1: Фидокор | BD1: Яккабоғ | BE1: Яккатут | BF1: Бешқўрғон
A2: 1. | B2: Автомобиль йўллари четига барпо этилган пиёдалар йўлаклари (тротуарлар) | C2: =+D2+E2+F2+G2+H2+I2+J2+K2+L2+M2+N2+O2+P2+Q2+R2+S2+T2+U2+V2+W2+X2+Y2+Z2+AA2+AB2+AC2+AD2+AE2+AF2+AG2+AH2+AI2+AJ2+AK2+AL2+AM2+AN2+AO2+AP2+AQ2+AR2+AS2+AT2+AU2+AV2+AW2+AX2+AY2+AZ2+BA2+BB2+BC2+BD2+BE2+BF2 -> 0
A3: 1.1. | B3: шундан, мактаб ҳудуди ва унинг атрофида ташкил этилган хавфсиз пиёдалар йўлаклари | C3: =+D3+E3+F3+G3+H3+I3+J3+K3+L3+M3+N3+O3+P3+Q3+R3+S3+T3+U3+V3+W3+X3+Y3+Z3+AA3+AB3+AC3+AD3+AE3+AF3+AG3+AH3+AI3+AJ3+AK3+AL3+AM3+AN3+AO3+AP3+AQ3+AR3+AS3+AT3+AU3+AV3+AW3+AX3+AY3+AZ3+BA3+BB3+BC3+BD3+BE3+BF3 -> 0
A4: 2. | B4: Мактаб ҳудуди ва унинг атрофида ташкил этилган қавариқ пиёдалар ўтиш жойлари | C4: =+D4+E4+F4+G4+H4+I4+J4+K4+L4+M4+N4+O4+P4+Q4+R4+S4+T4+U4+V4+W4+X4+Y4+Z4+AA4+AB4+AC4+AD4+AE4+AF4+AG4+AH4+AI4+AJ4+AK4+AL4+AM4+AN4+AO4+AP4+AQ4+AR4+AS4+AT4+AU4+AV4+AW4+AX4+AY4+AZ4+BA4+BB4+BC4+BD4+BE4+BF4 -> 0
A5: 3. | B5: шундан, серқатнов автомобиль йўлларида жойлашган мактаблар олдида ташкил этилган қавариқ пиёдалар | C5: =+D5+E5+F5+G5+H5+I5+J5+K5+L5+M5+N5+O5+P5+Q5+R5+S5+T5+U5+V5+W5+X5+Y5+Z5+AA5+AB5+AC5+AD5+AE5+AF5+AG5+AH5+AI5+AJ5+AK5+AL5+AM5+AN5+AO5+AP5+AQ5+AR5+AS5+AT5+AU5+AV5+AW5+AX5+AY5+AZ5+BA5+BB5+BC5+BD5+BE5+BF5 -> 0
A6: 4. | B6: Йўл ёқасида жойлашган мактаблар олдида ўрнатилган сунъий нотекисликлар (тезлик пасайтиргичлар) | C6: =+D6+E6+F6+G6+H6+I6+J6+K6+L6+M6+N6+O6+P6+Q6+R6+S6+T6+U6+V6+W6+X6+Y6+Z6+AA6+AB6+AC6+AD6+AE6+AF6+AG6+AH6+AI6+AJ6+AK6+AL6+AM6+AN6+AO6+AP6+AQ6+AR6+AS6+AT6+AU6+AV6+AW6+AX6+AY6+AZ6+BA6+BB6+BC6+BD6+BE6+BF6 -> 0
A7: 5. | B7: Ўрнатилган йўлларни ажратувчи махсус темир панжаралар (метр) | C7: =+D7+E7+F7+G7+H7+I7+J7+K7+L7+M7+N7+O7+P7+Q7+R7+S7+T7+U7+V7+W7+X7+Y7+Z7+AA7+AB7+AC7+AD7+AE7+AF7+AG7+AH7+AI7+AJ7+AK7+AL7+AM7+AN7+AO7+AP7+AQ7+AR7+AS7+AT7+AU7+AV7+AW7+AX7+AY7+AZ7+BA7+BB7+BC7+BD7+BE7+BF7 -> 0
A8: 6. | B8: Алмаштирилган эскирган ва талабга жавоб бермайдиган йўл белгилари | C8: =+D8+E8+F8+G8+H8+I8+J8+K8+L8+M8+N8+O8+P8+Q8+R8+S8+T8+U8+V8+W8+X8+Y8+Z8+AA8+AB8+AC8+AD8+AE8+AF8+AG8+AH8+AI8+AJ8+AK8+AL8+AM8+AN8+AO8+AP8+AQ8+AR8+AS8+AT8+AU8+AV8+AW8+AX8+AY8+AZ8+BA8+BB8+BC8+BD8+BE8+BF8 -> 9 | F8: 5 | H8: 2 | U8: 2
A9: 7. | B9: Жами ўрнатилган светофорлар | C9: =+D9+E9+F9+G9+H9+I9+J9+K9+L9+M9+N9+O9+P9+Q9+R9+S9+T9+U9+V9+W9+X9+Y9+Z9+AA9+AB9+AC9+AD9+AE9+AF9+AG9+AH9+AI9+AJ9+AK9+AL9+AM9+AN9+AO9+AP9+AQ9+AR9+AS9+AT9+AU9+AV9+AW9+AX9+AY9+AZ9+BA9+BB9+BC9+BD9+BE9+BF9 -> 0
A10: 7.1. | B10: шундан, ТХАЙ йўлида ўрнатилган светофорлар | C10: =+D10+E10+F10+G10+H10+I10+J10+K10+L10+M10+N10+O10+P10+Q10+R10+S10+T10+U10+V10+W10+X10+Y10+Z10+AA10+AB10+AC10+AD10+AE10+AF10+AG10+AH10+AI10+AJ10+AK10+AL10+AM10+AN10+AO10+AP10+AQ10+AR10+AS10+AT10+AU10+AV10+AW10+AX10+AY10+AZ10+BA10+BB10+BC10+BD10+BE10+BF10 -> 0
A11: 8. | B11: Жами ўрнатилган тугмали светофорлар | C11: =+D11+E11+F11+G11+H11+I11+J11+K11+L11+M11+N11+O11+P11+Q11+R11+S11+T11+U11+V11+W11+X11+Y11+Z11+AA11+AB11+AC11+AD11+AE11+AF11+AG11+AH11+AI11+AJ11+AK11+AL11+AM11+AN11+AO11+AP11+AQ11+AR11+AS11+AT11+AU11+AV11+AW11+AX11+AY11+AZ11+BA11+BB11+BC11+BD11+BE11+BF11 -> 0
A12: 8.1. | B12: шундан, ТХАЙ йўлида ўрнатилган тугмали светофорлар | C12: =+D12+E12+F12+G12+H12+I12+J12+K12+L12+M12+N12+O12+P12+Q12+R12+S12+T12+U12+V12+W12+X12+Y12+Z12+AA12+AB12+AC12+AD12+AE12+AF12+AG12+AH12+AI12+AJ12+AK12+AL12+AM12+AN12+AO12+AP12+AQ12+AR12+AS12+AT12+AU12+AV12+AW12+AX12+AY12+AZ12+BA12+BB12+BC12+BD12+BE12+BF12 -> 0
A13: 9. | B13: Жами ўрнатилган янги йўл белгилари | C13: =+D13+E13+F13+G13+H13+I13+J13+K13+L13+M13+N13+O13+P13+Q13+R13+S13+T13+U13+V13+W13+X13+Y13+Z13+AA13+AB13+AC13+AD13+AE13+AF13+AG13+AH13+AI13+AJ13+AK13+AL13+AM13+AN13+AO13+AP13+AQ13+AR13+AS13+AT13+AU13+AV13+AW13+AX13+AY13+AZ13+BA13+BB13+BC13+BD13+BE13+BF13 -> 9 | F13: 3 | G13: 4 | U13: 2
A14: 9.1. | B14: шундан, ТХАЙ йўлида ўрнатилганлари | C14: =+D14+E14+F14+G14+H14+I14+J14+K14+L14+M14+N14+O14+P14+Q14+R14+S14+T14+U14+V14+W14+X14+Y14+Z14+AA14+AB14+AC14+AD14+AE14+AF14+AG14+AH14+AI14+AJ14+AK14+AL14+AM14+AN14+AO14+AP14+AQ14+AR14+AS14+AT14+AU14+AV14+AW14+AX14+AY14+AZ14+BA14+BB14+BC14+BD14+BE14+BF14 -> 3 | F14: 3
A15: 10. | B15: Чизилган йўл чизиқлари (м2) | C15: =+D15+E15+F15+G15+H15+I15+J15+K15+L15+M15+N15+O15+P15+Q15+R15+S15+T15+U15+V15+W15+X15+Y15+Z15+AA15+AB15+AC15+AD15+AE15+AF15+AG15+AH15+AI15+AJ15+AK15+AL15+AM15+AN15+AO15+AP15+AQ15+AR15+AS15+AT15+AU15+AV15+AW15+AX15+AY15+AZ15+BA15+BB15+BC15+BD15+BE15+BF15 -> 0
A16: 11. | B16: Мактабларда ташкил этилган махсус ўқув синфхоналари | C16: =+D16+E16+F16+G16+H16+I16+J16+K16+L16+M16+N16+O16+P16+Q16+R16+S16+T16+U16+V16+W16+X16+Y16+Z16+AA16+AB16+AC16+AD16+AE16+AF16+AG16+AH16+AI16+AJ16+AK16+AL16+AM16+AN16+AO16+AP16+AQ16+AR16+AS16+AT16+AU16+AV16+AW16+AX16+AY16+AZ16+BA16+BB16+BC16+BD16+BE16+BF16 -> 0
A17: 12. | B17: “Йўл қоидаси – умр фойдаси” шиори остида ўтказилган тарғибот тадбирлари | C17: =+D17+E17+F17+G17+H17+I17+J17+K17+L17+M17+N17+O17+P17+Q17+R17+S17+T17+U17+V17+W17+X17+Y17+Z17+AA17+AB17+AC17+AD17+AE17+AF17+AG17+AH17+AI17+AJ17+AK17+AL17+AM17+AN17+AO17+AP17+AQ17+AR17+AS17+AT17+AU17+AV17+AW17+AX17+AY17+AZ17+BA17+BB17+BC17+BD17+BE17+BF17 -> 0
A18: 13. | B18: Ташкил этилган йўл ҳаракати қоидалари бўйича "Ёш тарғиботчи клублари" | C18: =+D18+E18+F18+G18+H18+I18+J18+K18+L18+M18+N18+O18+P18+Q18+R18+S18+T18+U18+V18+W18+X18+Y18+Z18+AA18+AB18+AC18+AD18+AE18+AF18+AG18+AH18+AI18+AJ18+AK18+AL18+AM18+AN18+AO18+AP18+AQ18+AR18+AS18+AT18+AU18+AV18+AW18+AX18+AY18+AZ18+BA18+BB18+BC18+BD18+BE18+BF18 -> 0
A19: 14. | B19: Яроқсиз ҳолга келган транспорт воситаларини рўйхатдан чиқариш | C19: =+D19+E19+F19+G19+H19+I19+J19+K19+L19+M19+N19+O19+P19+Q19+R19+S19+T19+U19+V19+W19+X19+Y19+Z19+AA19+AB19+AC19+AD19+AE19+AF19+AG19+AH19+AI19+AJ19+AK19+AL19+AM19+AN19+AO19+AP19+AQ19+AR19+AS19+AT19+AU19+AV19+AW19+AX19+AY19+AZ19+BA19+BB19+BC19+BD19+BE19+BF19 -> 0
A20: 15. | B20: Аниқланган жами қоидабузарликлар | C20: =+D20+E20+F20+G20+H20+I20+J20+K20+L20+M20+N20+O20+P20+Q20+R20+S20+T20+U20+V20+W20+X20+Y20+Z20+AA20+AB20+AC20+AD20+AE20+AF20+AG20+AH20+AI20+AJ20+AK20+AL20+AM20+AN20+AO20+AP20+AQ20+AR20+AS20+AT20+AU20+AV20+AW20+AX20+AY20+AZ20+BA20+BB20+BC20+BD20+BE20+BF20 -> 154 | D20: 2 | F20: 5 | H20: 5 | I20: 4 | J20: 2 | K20: 5 | Q20: 5 | T20: 12 | U20: 15 | AA20: 5 | AG20: 4 | AI20: 5 | AM20: 8 | AN20: 5 | AR20: 5 | AU20: 2 | AW20: 10 | AZ20: 2 | BB20: 6 | BC20: 2 | BF20: 45
A21: шундан | B21: Қўпол турдаги қоидабузарликлар | C21: =+D21+E21+F21+G21+H21+I21+J21+K21+L21+M21+N21+O21+P21+Q21+R21+S21+T21+U21+V21+W21+X21+Y21+Z21+AA21+AB21+AC21+AD21+AE21+AF21+AG21+AH21+AI21+AJ21+AK21+AL21+AM21+AN21+AO21+AP21+AQ21+AR21+AS21+AT21+AU21+AV21+AW21+AX21+AY21+AZ21+BA21+BB21+BC21+BD21+BE21+BF21 -> 16 | D21: 1 | F21: 1 | H21: 1 | K21: 1 | T21: 2 | U21: 3 | AR21: 1 | AW21: 2 | BB21: 1 | BF21: 3
B22: Қарама-қарши ҳаракатланиш (МЖтКнинг 128 прим 5-моддаси) | C22: =+D22+E22+F22+G22+H22+I22+J22+K22+L22+M22+N22+O22+P22+Q22+R22+S22+T22+U22+V22+W22+X22+Y22+Z22+AA22+AB22+AC22+AD22+AE22+AF22+AG22+AH22+AI22+AJ22+AK22+AL22+AM22+AN22+AO22+AP22+AQ22+AR22+AS22+AT22+AU22+AV22+AW22+AX22+AY22+AZ22+BA22+BB22+BC22+BD22+BE22+BF22 -> 1 | D22: 1
B23: Светофорнинг қизил чироғида ҳаракатланиш (МЖтКнинг 128 прим 4-моддаси) | C23: =+D23+E23+F23+G23+H23+I23+J23+K23+L23+M23+N23+O23+P23+Q23+R23+S23+T23+U23+V23+W23+X23+Y23+Z23+AA23+AB23+AC23+AD23+AE23+AF23+AG23+AH23+AI23+AJ23+AK23+AL23+AM23+AN23+AO23+AP23+AQ23+AR23+AS23+AT23+AU23+AV23+AW23+AX23+AY23+AZ23+BA23+BB23+BC23+BD23+BE23+BF23 -> 1 | I23: 1
B24: Пиёдага йўл бермаслик (МЖтКнинг 128-моддаси) | C24: =+D24+E24+F24+G24+H24+I24+J24+K24+L24+M24+N24+O24+P24+Q24+R24+S24+T24+U24+V24+W24+X24+Y24+Z24+AA24+AB24+AC24+AD24+AE24+AF24+AG24+AH24+AI24+AJ24+AK24+AL24+AM24+AN24+AO24+AP24+AQ24+AR24+AS24+AT24+AU24+AV24+AW24+AX24+AY24+AZ24+BA24+BB24+BC24+BD24+BE24+BF24 -> 4 | T24: 2 | BF24: 2
B25: Ноқонуний тонировка | C25: =+D25+E25+F25+G25+H25+I25+J25+K25+L25+M25+N25+O25+P25+Q25+R25+S25+T25+U25+V25+W25+X25+Y25+Z25+AA25+AB25+AC25+AD25+AE25+AF25+AG25+AH25+AI25+AJ25+AK25+AL25+AM25+AN25+AO25+AP25+AQ25+AR25+AS25+AT25+AU25+AV25+AW25+AX25+AY25+AZ25+BA25+BB25+BC25+BD25+BE25+BF25 -> 1 | U25: 1
B26: Маст ҳолатда транспорт воситасини бошқариш | C26: =+D26+E26+F26+G26+H26+I26+J26+K26+L26+M26+N26+O26+P26+Q26+R26+S26+T26+U26+V26+W26+X26+Y26+Z26+AA26+AB26+AC26+AD26+AE26+AF26+AG26+AH26+AI26+AJ26+AK26+AL26+AM26+AN26+AO26+AP26+AQ26+AR26+AS26+AT26+AU26+AV26+AW26+AX26+AY26+AZ26+BA26+BB26+BC26+BD26+BE26+BF26 -> 2 | D26: 1 | T26: 1
B27: Тегишли ҳужжатларсиз транспорт воситаларини бошқариш | C27: =+D27+E27+F27+G27+H27+I27+J27+K27+L27+M27+N27+O27+P27+Q27+R27+S27+T27+U27+V27+W27+X27+Y27+Z27+AA27+AB27+AC27+AD27+AE27+AF27+AG27+AH27+AI27+AJ27+AK27+AL27+AM27+AN27+AO27+AP27+AQ27+AR27+AS27+AT27+AU27+AV27+AW27+AX27+AY27+AZ27+BA27+BB27+BC27+BD27+BE27+BF27 -> 5 | D27: 1 | T27: 1 | AV27: 2 | BF27: 1
B28: Давлат рақам белгисини ўзбошимчалик билан ечиб олиш | C28: =+D28+E28+F28+G28+H28+I28+J28+K28+L28+M28+N28+O28+P28+Q28+R28+S28+T28+U28+V28+W28+X28+Y28+Z28+AA28+AB28+AC28+AD28+AE28+AF28+AG28+AH28+AI28+AJ28+AK28+AL28+AM28+AN28+AO28+AP28+AQ28+AR28+AS28+AT28+AU28+AV28+AW28+AX28+AY28+AZ28+BA28+BB28+BC28+BD28+BE28+BF28 -> 0
B29: Глушител, товуш чиқарувчи, мигалка ва бошқа қурилмалар | C29: =+D29+E29+F29+G29+H29+I29+J29+K29+L29+M29+N29+O29+P29+Q29+R29+S29+T29+U29+V29+W29+X29+Y29+Z29+AA29+AB29+AC29+AD29+AE29+AF29+AG29+AH29+AI29+AJ29+AK29+AL29+AM29+AN29+AO29+AP29+AQ29+AR29+AS29+AT29+AU29+AV29+AW29+AX29+AY29+AZ29+BA29+BB29+BC29+BD29+BE29+BF29 -> 0
A30: 16. | B30: Жарима майдонига жойлаштирилган транспорт воситалари | C30: =+D30+E30+F30+G30+H30+I30+J30+K30+L30+M30+N30+O30+P30+Q30+R30+S30+T30+U30+V30+W30+X30+Y30+Z30+AA30+AB30+AC30+AD30+AE30+AF30+AG30+AH30+AI30+AJ30+AK30+AL30+AM30+AN30+AO30+AP30+AQ30+AR30+AS30+AT30+AU30+AV30+AW30+AX30+AY30+AZ30+BA30+BB30+BC30+BD30+BE30+BF30 -> 13 | D30: 2 | T30: 2 | U30: 1 | AV30: 2 | AX30: 2 | BF30: 4
A31: 17. | B31: Мактабларда ўтказилган "Авторейд" тадбирлари сони | C31: =+D31+E31+F31+G31+H31+I31+J31+K31+L31+M31+N31+O31+P31+Q31+R31+S31+T31+U31+V31+W31+X31+Y31+Z31+AA31+AB31+AC31+AD31+AE31+AF31+AG31+AH31+AI31+AJ31+AK31+AL31+AM31+AN31+AO31+AP31+AQ31+AR31+AS31+AT31+AU31+AV31+AW31+AX31+AY31+AZ31+BA31+BB31+BC31+BD31+BE31+BF31 -> 0
A32: 17.1. | B32: Мактабларда ўтказилган "Авторейд" тадбирларида аниқланган қоидабузарликлар сони | C32: =+D32+E32+F32+G32+H32+I32+J32+K32+L32+M32+N32+O32+P32+Q32+R32+S32+T32+U32+V32+W32+X32+Y32+Z32+AA32+AB32+AC32+AD32+AE32+AF32+AG32+AH32+AI32+AJ32+AK32+AL32+AM32+AN32+AO32+AP32+AQ32+AR32+AS32+AT32+AU32+AV32+AW32+AX32+AY32+AZ32+BA32+BB32+BC32+BD32+BE32+BF32 -> 1 | K32: 1
A33: 18. | B33: Ашаддий қоидабузар ҳайдовчилар бўйича уларнинг яшаш маҳаллаларида ўтказилган муҳокамалар | C33: =+D33+E33+F33+G33+H33+I33+J33+K33+L33+M33+N33+O33+P33+Q33+R33+S33+T33+U33+V33+W33+X33+Y33+Z33+AA33+AB33+AC33+AD33+AE33+AF33+AG33+AH33+AI33+AJ33+AK33+AL33+AM33+AN33+AO33+AP33+AQ33+AR33+AS33+AT33+AU33+AV33+AW33+AX33+AY33+AZ33+BA33+BB33+BC33+BD33+BE33+BF33 -> 0
A34: 19. | B34: Содир этилган жами йўл транспорт ҳодисалари (жиноий ҳолатлардан ташқари) | C34: =+D34+E34+F34+G34+H34+I34+J34+K34+L34+M34+N34+O34+P34+Q34+R34+S34+T34+U34+V34+W34+X34+Y34+Z34+AA34+AB34+AC34+AD34+AE34+AF34+AG34+AH34+AI34+AJ34+AK34+AL34+AM34+AN34+AO34+AP34+AQ34+AR34+AS34+AT34+AU34+AV34+AW34+AX34+AY34+AZ34+BA34+BB34+BC34+BD34+BE34+BF34 -> 0
A35: 20. | B35: Содир этилган жами ЙТҲлари билан боғлиқ жиноятлар (ЖК 266-модда 1-қисми) | C35: =+D35+E35+F35+G35+H35+I35+J35+K35+L35+M35+N35+O35+P35+Q35+R35+S35+T35+U35+V35+W35+X35+Y35+Z35+AA35+AB35+AC35+AD35+AE35+AF35+AG35+AH35+AI35+AJ35+AK35+AL35+AM35+AN35+AO35+AP35+AQ35+AR35+AS35+AT35+AU35+AV35+AW35+AX35+AY35+AZ35+BA35+BB35+BC35+BD35+BE35+BF35 -> 0
A36: 20.1. | B36: шундан, инсон ўлими билан боғлиқ жиноий ҳолатлар | C36: =+D36+E36+F36+G36+H36+I36+J36+K36+L36+M36+N36+O36+P36+Q36+R36+S36+T36+U36+V36+W36+X36+Y36+Z36+AA36+AB36+AC36+AD36+AE36+AF36+AG36+AH36+AI36+AJ36+AK36+AL36+AM36+AN36+AO36+AP36+AQ36+AR36+AS36+AT36+AU36+AV36+AW36+AX36+AY36+AZ36+BA36+BB36+BC36+BD36+BE36+BF36 -> 0
A37: 21. | B37: Автомобилни олиб қочиш (ЖК 267-модда) | C37: =+D37+E37+F37+G37+H37+I37+J37+K37+L37+M37+N37+O37+P37+Q37+R37+S37+T37+U37+V37+W37+X37+Y37+Z37+AA37+AB37+AC37+AD37+AE37+AF37+AG37+AH37+AI37+AJ37+AK37+AL37+AM37+AN37+AO37+AP37+AQ37+AR37+AS37+AT37+AU37+AV37+AW37+AX37+AY37+AZ37+BA37+BB37+BC37+BD37+BE37+BF37 -> 0

Sheet 01.25
A1: № | B1: Кўрсаткич | C1: Жами | D1: Ал-Хоразмий | E1: Бахористон | F1: Бектўпи | G1: Гулистон | H1: Катта Хирмонтепа | I1: Тирсакобод | J1: Хайрабод | K1: Хирмон тепа | L1: Хонтўпи | M1: Шараф | N1: Шарқ | O1: Шарқ тонги | P1: Шухрат | Q1: 1-Чарх Камолон | R1: 2-Чарх Камолон | S1: 3-Чарх Камолон | T1: Бешёғоч | U1: Катта Козиробод | V1: Катта Олмазор | W1: Катта Чилонзор-1 | X1: Катта Чилонзор-2 | Y1: Катта Чилонзор-3 | Z1: Қозиробод | AA1: Новза | AB1: Чилонзор | AC1: 1-Қатортол | AD1: Бешчинор | AE1: Боғзор | AF1: Диёр | AG1: Дилобод | AH1: Катта Навбаҳор | AI1: Кўркам | AJ1: Кўтарма | AK1: Қатортол | AL1: Лутфий | AM1: Навбахор | AN1: Нафосат | AO1: Оқ-тепа | AP1: Халқлар Дўстлиги | AQ1: Чўпон-ота | AR1: 2-Қатортол | AS1: Ботирма | AT1: Бўрижар | AU1: Гавхар | AV1: Дўмбиробод | AW1: Зарқўрғон | AX1: Катта Дўмбиробод | AY1: Кичик Хирмонтепа | AZ1: Мевазор | BA1: Мехржон | BB1: Наққошлик | BC1: Фидокор | BD1: Яккабоғ | BE1: Яккатут | BF1: Бешқўрғон
A2: 1. | B2: Автомобиль йўллари четига барпо этилган пиёдалар йўлаклари (тротуарлар) | C2: =+D2+E2+F2+G2+H2+I2+J2+K2+L2+M2+N2+O2+P2+Q2+R2+S2+T2+U2+V2+W2+X2+Y2+Z2+AA2+AB2+AC2+AD2+AE2+AF2+AG2+AH2+AI2+AJ2+AK2+AL2+AM2+AN2+AO2+AP2+AQ2+AR2+AS2+AT2+AU2+AV2+AW2+AX2+AY2+AZ2+BA2+BB2+BC2+BD2+BE2+BF2 -> 0
A3: 1.1. | B3: шундан, мактаб ҳудуди ва унинг атрофида ташкил этилган хавфсиз пиёдалар йўлаклари | C3: =+D3+E3+F3+G3+H3+I3+J3+K3+L3+M3+N3+O3+P3+Q3+R3+S3+T3+U3+V3+W3+X3+Y3+Z3+AA3+AB3+AC3+AD3+AE3+AF3+AG3+AH3+AI3+AJ3+AK3+AL3+AM3+AN3+AO3+AP3+AQ3+AR3+AS3+AT3+AU3+AV3+AW3+AX3+AY3+AZ3+BA3+BB3+BC3+BD3+BE3+BF3 -> 0
A4: 2. | B4: Мактаб ҳудуди ва унинг атрофида ташкил этилган қавариқ пиёдалар ўтиш жойлари | C4: =+D4+E4+F4+G4+H4+I4+J4+K4+L4+M4+N4+O4+P4+Q4+R4+S4+T4+U4+V4+W4+X4+Y4+Z4+AA4+AB4+AC4+AD4+AE4+AF4+AG4+AH4+AI4+AJ4+AK4+AL4+AM4+AN4+AO4+AP4+AQ4+AR4+AS4+AT4+AU4+AV4+AW4+AX4+AY4+AZ4+BA4+BB4+BC4+BD4+BE4+BF4 -> 0
A5: 3. | B5: шундан, серқатнов автомобиль йўлларида жойлашган мактаблар олдида ташкил этилган қавариқ пиёдалар | C5: =+D5+E5+F5+G5+H5+I5+J5+K5+L5+M5+N5+O5+P5+Q5+R5+S5+T5+U5+V5+W5+X5+Y5+Z5+AA5+AB5+AC5+AD5+AE5+AF5+AG5+AH5+AI5+AJ5+AK5+AL5+AM5+AN5+AO5+AP5+AQ5+AR5+AS5+AT5+AU5+AV5+AW5+AX5+AY5+AZ5+BA5+BB5+BC5+BD5+BE5+BF5 -> 0
A6: 4. | B6: Йўл ёқасида жойлашган мактаблар олдида ўрнатилган сунъий нотекисликлар (тезлик пасайтиргичлар) | C6: =+D6+E6+F6+G6+H6+I6+J6+K6+L6+M6+N6+O6+P6+Q6+R6+S6+T6+U6+V6+W6+X6+Y6+Z6+AA6+AB6+AC6+AD6+AE6+AF6+AG6+AH6+AI6+AJ6+AK6+AL6+AM6+AN6+AO6+AP6+AQ6+AR6+AS6+AT6+AU6+AV6+AW6+AX6+AY6+AZ6+BA6+BB6+BC6+BD6+BE6+BF6 -> 0
