Workbook

Sheet 01.20
A1: № | B1: Кўрсаткич | C1: Жами | D1: Ал-Хоразмий | E1: Бахористон | F1: Бектўпи | G1: Гулистон | H1: Катта Хирмонтепа | I1: Тирсакобод | J1: Хайрабод | K1: Хирмон тепа | L1: Хонтўпи | M1: Шараф | N1: Шарқ | O1: Шарқ тонги | P1: Шухрат | Q1: 1-Чарх Камолон | R1: 2-Чарх Камолон | S1: 3-Чарх Камолон | T1: Бешёғоч | U1: Катта Козиробод | V1: Катта Олмазор | W1: Катта Чилонзор-1 | X1: Катта Чилонзор-2 | Y1: Катта Чилонзор-3 | Z1: Қозиробод | AA1: Новза | AB1: Чилонзор | AC1: 1-Қатортол | AD1: Бешчинор | AE1: Боғзор | AF1: Диёр | AG1: Дилобод | AH1: Катта Навбаҳор | AI1: Кўркам | AJ1: Кўтарма | AK1: Қатортол | AL1: Лутфий | AM1: Навбахор | AN1: Нафосат | AO1: Оқ-тепа | AP1: Халқлар Дўстлиги | AQ1: Чўпон-ота | AR1: 2-Қатортол | AS1: Ботирма | AT1: Бўрижар | AU1: Гавхар | AV1: Дўмбиробод | AW1: Зарқўрғон | AX1: Катта Дўмбиробод | AY1: Кичик Хирмонтепа | AZ1: Мевазор | BA1: Мехржон | BB1: Наққошлик | BC1: Фидокор | BD1: Яккабоғ | BE1: Яккатут | BF1: Бешқўрғон
A2: 1. | B2: Коммунал соҳада келиб тушган жами мурожаатлар | C2: =D2+E2+F2+G2+H2+I2+J2+K2+L2+M2+N2+O2+P2+Q2+R2+S2+T2+U2+V2+W2+X2+Y2+Z2+AA2+AB2+AC2+AD2+AE2+AF2+AG2+AH2+AI2+AJ2+AK2+AL2+AM2+AN2+AO2+AP2+AQ2+AR2+AS2+AT2+AU2+AV2+AW2+AX2+AY2+AZ2+BA2+BB2+BC2+BD2+BE2+BF2 -> 68 | D2: =+SUM(D3:D11) -> 0 | E2: =+SUM(E3:E11) -> 0 | F2: =+SUM(F3:F11) -> 1 | G2: =+SUM(G3:G11) -> 1 | H2: =+SUM(H3:H11) -> 4 | I2: =+SUM(I3:I11) -> 0 | J2: =+SUM(J3:J11) -> 0 | K2: =+SUM(K3:K11) -> 0 | ... BF2: =+SUM(BF3:BF11) -> 1
A3: шундан | B3: БСК йўналишида | C3: =D3+E3+F3+G3+H3+I3+J3+K3+L3+M3+N3+O3+P3+Q3+R3+S3+T3+U3+V3+W3+X3+Y3+Z3+AA3+AB3+AC3+AD3+AE3+AF3+AG3+AH3+AI3+AJ3+AK3+AL3+AM3+AN3+AO3+AP3+AQ3+AR3+AS3+AT3+AU3+AV3+AW3+AX3+AY3+AZ3+BA3+BB3+BC3+BD3+BE3+BF3 -> 47 | H3: 3 | M3: 2 | N3: 4 | O3: 1 | R3: 4 | S3: 3 | W3: 4 | X3: 3 | Y3: 5 | AF3: 3 | AG3: 2 | AI3: 2 | AJ3: 1 | AN3: 2 | AO3: 2 | AQ3: 3 | AV3: 1 | BC3: 2
B4: электр таъминоти | C4: =D4+E4+F4+G4+H4+I4+J4+K4+L4+M4+N4+O4+P4+Q4+R4+S4+T4+U4+V4+W4+X4+Y4+Z4+AA4+AB4+AC4+AD4+AE4+AF4+AG4+AH4+AI4+AJ4+AK4+AL4+AM4+AN4+AO4+AP4+AQ4+AR4+AS4+AT4+AU4+AV4+AW4+AX4+AY4+AZ4+BA4+BB4+BC4+BD4+BE4+BF4 -> 9 | F4: 1 | G4: 1 | T4: 3 | X4: 1 | AC4: 1 | AD4: 1 | AW4: 1
B5: газ таъминоти | C5: =D5+E5+F5+G5+H5+I5+J5+K5+L5+M5+N5+O5+P5+Q5+R5+S5+T5+U5+V5+W5+X5+Y5+Z5+AA5+AB5+AC5+AD5+AE5+AF5+AG5+AH5+AI5+AJ5+AK5+AL5+AM5+AN5+AO5+AP5+AQ5+AR5+AS5+AT5+AU5+AV5+AW5+AX5+AY5+AZ5+BA5+BB5+BC5+BD5+BE5+BF5 -> 5 | R5: 1 | Y5: 1 | AS5: 1 | BA5: 1 | BF5: 1 | BG5: 1
B6: совуқ сув таъминоти | C6: =D6+E6+F6+G6+H6+I6+J6+K6+L6+M6+N6+O6+P6+Q6+R6+S6+T6+U6+V6+W6+X6+Y6+Z6+AA6+AB6+AC6+AD6+AE6+AF6+AG6+AH6+AI6+AJ6+AK6+AL6+AM6+AN6+AO6+AP6+AQ6+AR6+AS6+AT6+AU6+AV6+AW6+AX6+AY6+AZ6+BA6+BB6+BC6+BD6+BE6+BF6 -> 1 | BB6: 1
B7: иссиқ сув ва иссиқлик таъминоти | C7: =D7+E7+F7+G7+H7+I7+J7+K7+L7+M7+N7+O7+P7+Q7+R7+S7+T7+U7+V7+W7+X7+Y7+Z7+AA7+AB7+AC7+AD7+AE7+AF7+AG7+AH7+AI7+AJ7+AK7+AL7+AM7+AN7+AO7+AP7+AQ7+AR7+AS7+AT7+AU7+AV7+AW7+AX7+AY7+AZ7+BA7+BB7+BC7+BD7+BE7+BF7 -> 6 | H7: 1 | M7: 1 | N7: 1 | AF7: 1 | AG7: 1 | AP7: 1
B8: ёритиш чироқлари (нур) | C8: =D8+E8+F8+G8+H8+I8+J8+K8+L8+M8+N8+O8+P8+Q8+R8+S8+T8+U8+V8+W8+X8+Y8+Z8+AA8+AB8+AC8+AD8+AE8+AF8+AG8+AH8+AI8+AJ8+AK8+AL8+AM8+AN8+AO8+AP8+AQ8+AR8+AS8+AT8+AU8+AV8+AW8+AX8+AY8+AZ8+BA8+BB8+BC8+BD8+BE8+BF8 -> 0
B9: чиқиндиларни олиб чиқиш | C9: =D9+E9+F9+G9+H9+I9+J9+K9+L9+M9+N9+O9+P9+Q9+R9+S9+T9+U9+V9+W9+X9+Y9+Z9+AA9+AB9+AC9+AD9+AE9+AF9+AG9+AH9+AI9+AJ9+AK9+AL9+AM9+AN9+AO9+AP9+AQ9+AR9+AS9+AT9+AU9+AV9+AW9+AX9+AY9+AZ9+BA9+BB9+BC9+BD9+BE9+BF9 -> 0
B10: ободонлаштириш бўйича | C10: =D10+E10+F10+G10+H10+I10+J10+K10+L10+M10+N10+O10+P10+Q10+R10+S10+T10+U10+V10+W10+X10+Y10+Z10+AA10+AB10+AC10+AD10+AE10+AF10+AG10+AH10+AI10+AJ10+AK10+AL10+AM10+AN10+AO10+AP10+AQ10+AR10+AS10+AT10+AU10+AV10+AW10+AX10+AY10+AZ10+BA10+BB10+BC10+BD10+BE10+BF10 -> 0
B11: бошқалар | C11: =D11+E11+F11+G11+H11+I11+J11+K11+L11+M11+N11+O11+P11+Q11+R11+S11+T11+U11+V11+W11+X11+Y11+Z11+AA11+AB11+AC11+AD11+AE11+AF11+AG11+AH11+AI11+AJ11+AK11+AL11+AM11+AN11+AO11+AP11+AQ11+AR11+AS11+AT11+AU11+AV11+AW11+AX11+AY11+AZ11+BA11+BB11+BC11+BD11+BE11+BF11 -> 0
A12: 2. | B12: Муаммоси ҳал этилган жами мурожаатлар | C12: =D12+E12+F12+G12+H12+I12+J12+K12+L12+M12+N12+O12+P12+Q12+R12+S12+T12+U12+V12+W12+X12+Y12+Z12+AA12+AB12+AC12+AD12+AE12+AF12+AG12+AH12+AI12+AJ12+AK12+AL12+AM12+AN12+AO12+AP12+AQ12+AR12+AS12+AT12+AU12+AV12+AW12+AX12+AY12+AZ12+BA12+BB12+BC12+BD12+BE12+BF12 -> 68 | D12: =+SUM(D13:D21) -> 0 | E12: =+SUM(E13:E21) -> 0 | F12: =+SUM(F13:F21) -> 1 | G12: =+SUM(G13:G21) -> 1 | H12: =+SUM(H13:H21) -> 4 | I12: =+SUM(I13:I21) -> 0 | J12: =+SUM(J13:J21) -> 0 | K12: =+SUM(K13:K21) -> 0 | ... BF12: =+SUM(BF13:BF21) -> 1
A13: шундан | B13: БСК йўналишида | C13: =D13+E13+F13+G13+H13+I13+J13+K13+L13+M13+N13+O13+P13+Q13+R13+S13+T13+U13+V13+W13+X13+Y13+Z13+AA13+AB13+AC13+AD13+AE13+AF13+AG13+AH13+AI13+AJ13+AK13+AL13+AM13+AN13+AO13+AP13+AQ13+AR13+AS13+AT13+AU13+AV13+AW13+AX13+AY13+AZ13+BA13+BB13+BC13+BD13+BE13+BF13 -> 47 | H13: 3 | M13: 2 | N13: 4 | O13: 1 | R13: 4 | S13: 3 | W13: 4 | X13: 3 | Y13: 5 | AF13: 3 | AG13: 2 | AI13: 2 | AJ13: 1 | AN13: 2 | AO13: 2 | AQ13: 3 | AV13: 1 | BC13: 2
B14: электр таъминоти | C14: =D14+E14+F14+G14+H14+I14+J14+K14+L14+M14+N14+O14+P14+Q14+R14+S14+T14+U14+V14+W14+X14+Y14+Z14+AA14+AB14+AC14+AD14+AE14+AF14+AG14+AH14+AI14+AJ14+AK14+AL14+AM14+AN14+AO14+AP14+AQ14+AR14+AS14+AT14+AU14+AV14+AW14+AX14+AY14+AZ14+BA14+BB14+BC14+BD14+BE14+BF14 -> 9 | F14: 1 | G14: 1 | T14: 3 | X14: 1 | AC14: 1 | AD14: 1 | AW14: 1
B15: газ таъминоти | C15: =D15+E15+F15+G15+H15+I15+J15+K15+L15+M15+N15+O15+P15+Q15+R15+S15+T15+U15+V15+W15+X15+Y15+Z15+AA15+AB15+AC15+AD15+AE15+AF15+AG15+AH15+AI15+AJ15+AK15+AL15+AM15+AN15+AO15+AP15+AQ15+AR15+AS15+AT15+AU15+AV15+AW15+AX15+AY15+AZ15+BA15+BB15+BC15+BD15+BE15+BF15 -> 5 | R15: 1 | Y15: 1 | AS15: 1 | BA15: 1 | BF15: 1 | BG15: 1
B16: совуқ сув таъминоти | C16: =D16+E16+F16+G16+H16+I16+J16+K16+L16+M16+N16+O16+P16+Q16+R16+S16+T16+U16+V16+W16+X16+Y16+Z16+AA16+AB16+AC16+AD16+AE16+AF16+AG16+AH16+AI16+AJ16+AK16+AL16+AM16+AN16+AO16+AP16+AQ16+AR16+AS16+AT16+AU16+AV16+AW16+AX16+AY16+AZ16+BA16+BB16+BC16+BD16+BE16+BF16 -> 1 | BB16: 1
B17: иссиқ сув ва иссиқлик таъминоти | C17: =D17+E17+F17+G17+H17+I17+J17+K17+L17+M17+N17+O17+P17+Q17+R17+S17+T17+U17+V17+W17+X17+Y17+Z17+AA17+AB17+AC17+AD17+AE17+AF17+AG17+AH17+AI17+AJ17+AK17+AL17+AM17+AN17+AO17+AP17+AQ17+AR17+AS17+AT17+AU17+AV17+AW17+AX17+AY17+AZ17+BA17+BB17+BC17+BD17+BE17+BF17 -> 6 | H17: 1 | M17: 1 | N17: 1 | AF17: 1 | AG17: 1 | AP17: 1
B18: ёритиш чироқлари (нур) | C18: =D18+E18+F18+G18+H18+I18+J18+K18+L18+M18+N18+O18+P18+Q18+R18+S18+T18+U18+V18+W18+X18+Y18+Z18+AA18+AB18+AC18+AD18+AE18+AF18+AG18+AH18+AI18+AJ18+AK18+AL18+AM18+AN18+AO18+AP18+AQ18+AR18+AS18+AT18+AU18+AV18+AW18+AX18+AY18+AZ18+BA18+BB18+BC18+BD18+BE18+BF18 -> 0
B19: чиқиндиларни олиб чиқиш | C19: =D19+E19+F19+G19+H19+I19+J19+K19+L19+M19+N19+O19+P19+Q19+R19+S19+T19+U19+V19+W19+X19+Y19+Z19+AA19+AB19+AC19+AD19+AE19+AF19+AG19+AH19+AI19+AJ19+AK19+AL19+AM19+AN19+AO19+AP19+AQ19+AR19+AS19+AT19+AU19+AV19+AW19+AX19+AY19+AZ19+BA19+BB19+BC19+BD19+BE19+BF19 -> 0
B20: ободонлаштириш бўйича | C20: =D20+E20+F20+G20+H20+I20+J20+K20+L20+M20+N20+O20+P20+Q20+R20+S20+T20+U20+V20+W20+X20+Y20+Z20+AA20+AB20+AC20+AD20+AE20+AF20+AG20+AH20+AI20+AJ20+AK20+AL20+AM20+AN20+AO20+AP20+AQ20+AR20+AS20+AT20+AU20+AV20+AW20+AX20+AY20+AZ20+BA20+BB20+BC20+BD20+BE20+BF20 -> 0
B21: бошқалар | C21: =D21+E21+F21+G21+H21+I21+J21+K21+L21+M21+N21+O21+P21+Q21+R21+S21+T21+U21+V21+W21+X21+Y21+Z21+AA21+AB21+AC21+AD21+AE21+AF21+AG21+AH21+AI21+AJ21+AK21+AL21+AM21+AN21+AO21+AP21+AQ21+AR21+AS21+AT21+AU21+AV21+AW21+AX21+AY21+AZ21+BA21+BB21+BC21+BD21+BE21+BF21 -> 0
A22: 3. | B22: Совуқ сув қувури таъмирлаш (п/м) | C22: =D22+E22+F22+G22+H22+I22+J22+K22+L22+M22+N22+O22+P22+Q22+R22+S22+T22+U22+V22+W22+X22+Y22+Z22+AA22+AB22+AC22+AD22+AE22+AF22+AG22+AH22+AI22+AJ22+AK22+AL22+AM22+AN22+AO22+AP22+AQ22+AR22+AS22+AT22+AU22+AV22+AW22+AX22+AY22+AZ22+BA22+BB22+BC22+BD22+BE22+BF22 -> 0
A23: 4. | B23: Иссиқ сув қувури таъмирлаш (п/м) | C23: =D23+E23+F23+G23+H23+I23+J23+K23+L23+M23+N23+O23+P23+Q23+R23+S23+T23+U23+V23+W23+X23+Y23+Z23+AA23+AB23+AC23+AD23+AE23+AF23+AG23+AH23+AI23+AJ23+AK23+AL23+AM23+AN23+AO23+AP23+AQ23+AR23+AS23+AT23+AU23+AV23+AW23+AX23+AY23+AZ23+BA23+BB23+BC23+BD23+BE23+BF23 -> 0
A24: 5. | B24: БСК йўналишида кўп қаватли уйларда олиб борилган таъмирлаш ишлари | C24: =D24+E24+F24+G24+H24+I24+J24+K24+L24+M24+N24+O24+P24+Q24+R24+S24+T24+U24+V24+W24+X24+Y24+Z24+AA24+AB24+AC24+AD24+AE24+AF24+AG24+AH24+AI24+AJ24+AK24+AL24+AM24+AN24+AO24+AP24+AQ24+AR24+AS24+AT24+AU24+AV24+AW24+AX24+AY24+AZ24+BA24+BB24+BC24+BD24+BE24+BF24 -> 0
A25: шундан | B25: том таъмирлаш (м2) | C25: =D25+E25+F25+G25+H25+I25+J25+K25+L25+M25+N25+O25+P25+Q25+R25+S25+T25+U25+V25+W25+X25+Y25+Z25+AA25+AB25+AC25+AD25+AE25+AF25+AG25+AH25+AI25+AJ25+AK25+AL25+AM25+AN25+AO25+AP25+AQ25+AR25+AS25+AT25+AU25+AV25+AW25+AX25+AY25+AZ25+BA25+BB25+BC25+BD25+BE25+BF25 -> 200 | AU25: 200
B26: иссиқлик таъминоти | C26: =D26+E26+F26+G26+H26+I26+J26+K26+L26+M26+N26+O26+P26+Q26+R26+S26+T26+U26+V26+W26+X26+Y26+Z26+AA26+AB26+AC26+AD26+AE26+AF26+AG26+AH26+AI26+AJ26+AK26+AL26+AM26+AN26+AO26+AP26+AQ26+AR26+AS26+AT26+AU26+AV26+AW26+AX26+AY26+AZ26+BA26+BB26+BC26+BD26+BE26+BF26 -> 17 | M26: 2 | N26: 4 | AF26: 3 | AG26: 2 | AI26: 2 | AN26: 2 | AO26: 2
B27: лифт таъмири | C27: =D27+E27+F27+G27+H27+I27+J27+K27+L27+M27+N27+O27+P27+Q27+R27+S27+T27+U27+V27+W27+X27+Y27+Z27+AA27+AB27+AC27+AD27+AE27+AF27+AG27+AH27+AI27+AJ27+AK27+AL27+AM27+AN27+AO27+AP27+AQ27+AR27+AS27+AT27+AU27+AV27+AW27+AX27+AY27+AZ27+BA27+BB27+BC27+BD27+BE27+BF27 -> 0
B28: бошқалар | C28: =D28+E28+F28+G28+H28+I28+J28+K28+L28+M28+N28+O28+P28+Q28+R28+S28+T28+U28+V28+W28+X28+Y28+Z28+AA28+AB28+AC28+AD28+AE28+AF28+AG28+AH28+AI28+AJ28+AK28+AL28+AM28+AN28+AO28+AP28+AQ28+AR28+AS28+AT28+AU28+AV28+AW28+AX28+AY28+AZ28+BA28+BB28+BC28+BD28+BE28+BF28 -> 2 | U28: 1 | Y28: 1
A29: 6. | B29: Ўрнатилган янги трансформаторлар | C29: =D29+E29+F29+G29+H29+I29+J29+K29+L29+M29+N29+O29+P29+Q29+R29+S29+T29+U29+V29+W29+X29+Y29+Z29+AA29+AB29+AC29+AD29+AE29+AF29+AG29+AH29+AI29+AJ29+AK29+AL29+AM29+AN29+AO29+AP29+AQ29+AR29+AS29+AT29+AU29+AV29+AW29+AX29+AY29+AZ29+BA29+BB29+BC29+BD29+BE29+BF29 -> 0
A30: 7. | B30: Алмаштирилган ва тортилган электр кабеллари (метр) | C30: =D30+E30+F30+G30+H30+I30+J30+K30+L30+M30+N30+O30+P30+Q30+R30+S30+T30+U30+V30+W30+X30+Y30+Z30+AA30+AB30+AC30+AD30+AE30+AF30+AG30+AH30+AI30+AJ30+AK30+AL30+AM30+AN30+AO30+AP30+AQ30+AR30+AS30+AT30+AU30+AV30+AW30+AX30+AY30+AZ30+BA30+BB30+BC30+BD30+BE30+BF30 -> 0
A31: 8. | B31: Олиб чиқилган чиқиндилар (тонна) | C31: =D31+E31+F31+G31+H31+I31+J31+K31+L31+M31+N31+O31+P31+Q31+R31+S31+T31+U31+V31+W31+X31+Y31+Z31+AA31+AB31+AC31+AD31+AE31+AF31+AG31+AH31+AI31+AJ31+AK31+AL31+AM31+AN31+AO31+AP31+AQ31+AR31+AS31+AT31+AU31+AV31+AW31+AX31+AY31+AZ31+BA31+BB31+BC31+BD31+BE31+BF31 -> 281.1 | D31: 26.4 | E31: 22.4 | F31: 0.1 | I31: 0.3 | J31: 0.2 | K31: 0.5 | L31: 0.2 | M31: 0.2 | O31: 0.1 | P31: 0.5 | R31: 0.4 | T31: 0 | V31: 0.1 | W31: 0.1 | X31: 25.8 | AA31: 0.3 | AB31: 0.1 | AE31: 0.1 | AF31: 0.4 | AG31: 27 | AH31: 31.1 | AI31: 0.1 | AJ31: 27.2 | AK31: 28.1 | AL31: 0.2 | AM31: 27.5 | AN31: 0.1 | AP31: 30.9 | AQ31: 0.5 | AT31: 0.5 | AV31: 0.5 | AW31: 0.4 | AX31: 0.3 | AZ31: 0.4 | BA31: 0.4 | BB31: 0.5 | BD31: 0.1 | BE31: 27 | BF31: 0.1
A32: 9. | B32: Ўрнатилган янги ёритиш чироқлари | C32: =D32+E32+F32+G32+H32+I32+J32+K32+L32+M32+N32+O32+P32+Q32+R32+S32+T32+U32+V32+W32+X32+Y32+Z32+AA32+AB32+AC32+AD32+AE32+AF32+AG32+AH32+AI32+AJ32+AK32+AL32+AM32+AN32+AO32+AP32+AQ32+AR32+AS32+AT32+AU32+AV32+AW32+AX32+AY32+AZ32+BA32+BB32+BC32+BD32+BE32+BF32 -> 0
A33: 10. | B33: Таъмирланган ёритиш чироқлари | C33: =D33+E33+F33+G33+H33+I33+J33+K33+L33+M33+N33+O33+P33+Q33+R33+S33+T33+U33+V33+W33+X33+Y33+Z33+AA33+AB33+AC33+AD33+AE33+AF33+AG33+AH33+AI33+AJ33+AK33+AL33+AM33+AN33+AO33+AP33+AQ33+AR33+AS33+AT33+AU33+AV33+AW33+AX33+AY33+AZ33+BA33+BB33+BC33+BD33+BE33+BF33 -> 2 | W33: 2
AN35: масъул ходим лавозими

Sheet 01.21
A1: № | B1: Кўрсаткич | C1: Жами | D1: Ал-Хоразмий | E1: Бахористон | F1: Бектўпи | G1: Гулистон | H1: Катта Хирмонтепа | I1: Тирсакобод | J1: Хайрабод | K1: Хирмон тепа | L1: Хонтўпи | M1: Шараф | N1: Шарқ | O1: Шарқ тонги | P1: Шухрат | Q1: 1-Чарх Камолон | R1: 2-Чарх Камолон | S1: 3-Чарх Камолон | T1: Бешёғоч | U1: Катта Козиробод | V1: Катта Олмазор | W1: Катта Чилонзор-1 | X1: Катта Чилонзор-2 | Y1: Катта Чилонзор-3 | Z1: Қозиробод | AA1: Новза | AB1: Чилонзор | AC1: 1-Қатортол | AD1: Бешчинор | AE1: Боғзор | AF1: Диёр | AG1: Дилобод | AH1: Катта Навбаҳор | AI1: Кўркам | AJ1: Кўтарма | AK1: Қатортол | AL1: Лутфий | AM1: Навбахор | AN1: Нафосат | AO1: Оқ-тепа | AP1: Халқлар Дўстлиги | AQ1: Чўпон-ота | AR1: 2-Қатортол | AS1: Ботирма | AT1: Бўрижар | AU1: Гавхар | AV1: Дўмбиробод | AW1: Зарқўрғон | AX1: Катта Дўмбиробод | AY1: Кичик Хирмонтепа | AZ1: Мевазор | BA1: Мехржон | BB1: Наққошлик | BC1: Фидокор | BD1: Яккабоғ | BE1: Яккатут | BF1: Бешқўрғон
A2: 1. | B2: Коммунал соҳада келиб тушган жами мурожаатлар | C2: =D2+E2+F2+G2+H2+I2+J2+K2+L2+M2+N2+O2+P2+Q2+R2+S2+T2+U2+V2+W2+X2+Y2+Z2+AA2+AB2+AC2+AD2+AE2+AF2+AG2+AH2+AI2+AJ2+AK2+AL2+AM2+AN2+AO2+AP2+AQ2+AR2+AS2+AT2+AU2+AV2+AW2+AX2+AY2+AZ2+BA2+BB2+BC2+BD2+BE2+BF2 -> 28 | D2: =+SUM(D3:D11) -> 0 | E2: =+SUM(E3:E11) -> 1 | F2: =+SUM(F3:F11) -> 0 | G2: =+SUM(G3:G11) -> 1 | H2: =+SUM(H3:H11) -> 0 | I2: =+SUM(I3:I11) -> 0 | J2: =+SUM(J3:J11) -> 0 | K2: =+SUM(K3:K11) -> 0 | ... BF2: =+SUM(BF3:BF11) -> 2
A3: шундан | B3: БСК йўналишида | C3: =D3+E3+F3+G3+H3+I3+J3+K3+L3+M3+N3+O3+P3+Q3+R3+S3+T3+U3+V3+W3+X3+Y3+Z3+AA3+AB3+AC3+AD3+AE3+AF3+AG3+AH3+AI3+AJ3+AK3+AL3+AM3+AN3+AO3+AP3+AQ3+AR3+AS3+AT3+AU3+AV3+AW3+AX3+AY3+AZ3+BA3+BB3+BC3+BD3+BE3+BF3 -> 9 | N3: 1 | S3: 1 | W3: 3 | X3: 1 | AD3: 1 | AU3: 1 | AX3: 1
B4: электр таъминоти | C4: =D4+E4+F4+G4+H4+I4+J4+K4+L4+M4+N4+O4+P4+Q4+R4+S4+T4+U4+V4+W4+X4+Y4+Z4+AA4+AB4+AC4+AD4+AE4+AF4+AG4+AH4+AI4+AJ4+AK4+AL4+AM4+AN4+AO4+AP4+AQ4+AR4+AS4+AT4+AU4+AV4+AW4+AX4+AY4+AZ4+BA4+BB4+BC4+BD4+BE4+BF4 -> 4 | W4: 1 | AA4: 1 | AV4: 1 | BF4: 1
B5: газ таъминоти | C5: =D5+E5+F5+G5+H5+I5+J5+K5+L5+M5+N5+O5+P5+Q5+R5+S5+T5+U5+V5+W5+X5+Y5+Z5+AA5+AB5+AC5+AD5+AE5+AF5+AG5+AH5+AI5+AJ5+AK5+AL5+AM5+AN5+AO5+AP5+AQ5+AR5+AS5+AT5+AU5+AV5+AW5+AX5+AY5+AZ5+BA5+BB5+BC5+BD5+BE5+BF5 -> 1 | BF5: 1 | BG5: 1
B6: совуқ сув таъминоти | C6: =D6+E6+F6+G6+H6+I6+J6+K6+L6+M6+N6+O6+P6+Q6+R6+S6+T6+U6+V6+W6+X6+Y6+Z6+AA6+AB6+AC6+AD6+AE6+AF6+AG6+AH6+AI6+AJ6+AK6+AL6+AM6+AN6+AO6+AP6+AQ6+AR6+AS6+AT6+AU6+AV6+AW6+AX6+AY6+AZ6+BA6+BB6+BC6+BD6+BE6+BF6 -> 1 | AZ6: 1
B7: иссиқ сув ва иссиқлик таъминоти | C7: =D7+E7+F7+G7+H7+I7+J7+K7+L7+M7+N7+O7+P7+Q7+R7+S7+T7+U7+V7+W7+X7+Y7+Z7+AA7+AB7+AC7+AD7+AE7+AF7+AG7+AH7+AI7+AJ7+AK7+AL7+AM7+AN7+AO7+AP7+AQ7+AR7+AS7+AT7+AU7+AV7+AW7+AX7+AY7+AZ7+BA7+BB7+BC7+BD7+BE7+BF7 -> 11 | E7: 1 | R7: 3 | W7: 2 | AA7: 1 | AE7: 1 | AF7: 1 | AY7: 1 | BE7: 1
B8: ёритиш чироқлари (нур) | C8: =D8+E8+F8+G8+H8+I8+J8+K8+L8+M8+N8+O8+P8+Q8+R8+S8+T8+U8+V8+W8+X8+Y8+Z8+AA8+AB8+AC8+AD8+AE8+AF8+AG8+AH8+AI8+AJ8+AK8+AL8+AM8+AN8+AO8+AP8+AQ8+AR8+AS8+AT8+AU8+AV8+AW8+AX8+AY8+AZ8+BA8+BB8+BC8+BD8+BE8+BF8 -> 0
B9: чиқиндиларни олиб чиқиш | C9: =D9+E9+F9+G9+H9+I9+J9+K9+L9+M9+N9+O9+P9+Q9+R9+S9+T9+U9+V9+W9+X9+Y9+Z9+AA9+AB9+AC9+AD9+AE9+AF9+AG9+AH9+AI9+AJ9+AK9+AL9+AM9+AN9+AO9+AP9+AQ9+AR9+AS9+AT9+AU9+AV9+AW9+AX9+AY9+AZ9+BA9+BB9+BC9+BD9+BE9+BF9 -> 1 | BC9: 1
B10: ободонлаштириш бўйича | C10: =D10+E10+F10+G10+H10+I10+J10+K10+L10+M10+N10+O10+P10+Q10+R10+S10+T10+U10+V10+W10+X10+Y10+Z10+AA10+AB10+AC10+AD10+AE10+AF10+AG10+AH10+AI10+AJ10+AK10+AL10+AM10+AN10+AO10+AP10+AQ10+AR10+AS10+AT10+AU10+AV10+AW10+AX10+AY10+AZ10+BA10+BB10+BC10+BD10+BE10+BF10 -> 0
B11: бошқалар | C11: =D11+E11+F11+G11+H11+I11+J11+K11+L11+M11+N11+O11+P11+Q11+R11+S11+T11+U11+V11+W11+X11+Y11+Z11+AA11+AB11+AC11+AD11+AE11+AF11+AG11+AH11+AI11+AJ11+AK11+AL11+AM11+AN11+AO11+AP11+AQ11+AR11+AS11+AT11+AU11+AV11+AW11+AX11+AY11+AZ11+BA11+BB11+BC11+BD11+BE11+BF11 -> 1 | G11: 1
A12: 2. | B12: Муаммоси ҳал этилган жами мурожаатлар | C12: =D12+E12+F12+G12+H12+I12+J12+K12+L12+M12+N12+O12+P12+Q12+R12+S12+T12+U12+V12+W12+X12+Y12+Z12+AA12+AB12+AC12+AD12+AE12+AF12+AG12+AH12+AI12+AJ12+AK12+AL12+AM12+AN12+AO12+AP12+AQ12+AR12+AS12+AT12+AU12+AV12+AW12+AX12+AY12+AZ12+BA12+BB12+BC12+BD12+BE12+BF12 -> 28 | D12: =+SUM(D13:D21) -> 0 | E12: =+SUM(E13:E21) -> 1 | F12: =+SUM(F13:F21) -> 0 | G12: =+SUM(G13:G21) -> 1 | H12: =+SUM(H13:H21) -> 0 | I12: =+SUM(I13:I21) -> 0 | J12: =+SUM(J13:J21) -> 0 | K12: =+SUM(K13:K21) -> 0 | ... BF12: =+SUM(BF13:BF21) -> 2
A13: шундан | B13: БСК йўналишида | C13: =D13+E13+F13+G13+H13+I13+J13+K13+L13+M13+N13+O13+P13+Q13+R13+S13+T13+U13+V13+W13+X13+Y13+Z13+AA13+AB13+AC13+AD13+AE13+AF13+AG13+AH13+AI13+AJ13+AK13+AL13+AM13+AN13+AO13+AP13+AQ13+AR13+AS13+AT13+AU13+AV13+AW13+AX13+AY13+AZ13+BA13+BB13+BC13+BD13+BE13+BF13 -> 9 | N13: 1 | S13: 1 | W13: 3 | X13: 1 | AD13: 1 | AU13: 1 | AX13: 1
B14: электр таъминоти | C14: =D14+E14+F14+G14+H14+I14+J14+K14+L14+M14+N14+O14+P14+Q14+R14+S14+T14+U14+V14+W14+X14+Y14+Z14+AA14+AB14+AC14+AD14+AE14+AF14+AG14+AH14+AI14+AJ14+AK14+AL14+AM14+AN14+AO14+AP14+AQ14+AR14+AS14+AT14+AU14+AV14+AW14+AX14+AY14+AZ14+BA14+BB14+BC14+BD14+BE14+BF14 -> 4 | W14: 1 | AA14: 1 | AV14: 1 | BF14: 1
B15: газ таъминоти | C15: =D15+E15+F15+G15+H15+I15+J15+K15+L15+M15+N15+O15+P15+Q15+R15+S15+T15+U15+V15+W15+X15+Y15+Z15+AA15+AB15+AC15+AD15+AE15+AF15+AG15+AH15+AI15+AJ15+AK15+AL15+AM15+AN15+AO15+AP15+AQ15+AR15+AS15+AT15+AU15+AV15+AW15+AX15+AY15+AZ15+BA15+BB15+BC15+BD15+BE15+BF15 -> 1 | BF15: 1 | BG15: 1
B16: совуқ сув таъминоти | C16: =D16+E16+F16+G16+H16+I16+J16+K16+L16+M16+N16+O16+P16+Q16+R16+S16+T16+U16+V16+W16+X16+Y16+Z16+AA16+AB16+AC16+AD16+AE16+AF16+AG16+AH16+AI16+AJ16+AK16+AL16+AM16+AN16+AO16+AP16+AQ16+AR16+AS16+AT16+AU16+AV16+AW16+AX16+AY16+AZ16+BA16+BB16+BC16+BD16+BE16+BF16 -> 1 | AZ16: 1
B17: иссиқ сув ва иссиқлик таъминоти | C17: =D17+E17+F17+G17+H17+I17+J17+K17+L17+M17+N17+O17+P17+Q17+R17+S17+T17+U17+V17+W17+X17+Y17+Z17+AA17+AB17+AC17+AD17+AE17+AF17+AG17+AH17+AI17+AJ17+AK17+AL17+AM17+AN17+AO17+AP17+AQ17+AR17+AS17+AT17+AU17+AV17+AW17+AX17+AY17+AZ17+BA17+BB17+BC17+BD17+BE17+BF17 -> 11 | E17: 1 | R17: 3 | W17: 2 | AA17: 1 | AE17: 1 | AF17: 1 | AY17: 1 | BE17: 1
B18: ёритиш чироқлари (нур) | C18: =D18+E18+F18+G18+H18+I18+J18+K18+L18+M18+N18+O18+P18+Q18+R18+S18+T18+U18+V18+W18+X18+Y18+Z18+AA18+AB18+AC18+AD18+AE18+AF18+AG18+AH18+AI18+AJ18+AK18+AL18+AM18+AN18+AO18+AP18+AQ18+AR18+AS18+AT18+AU18+AV18+AW18+AX18+AY18+AZ18+BA18+BB18+BC18+BD18+BE18+BF18 -> 0
B19: чиқиндиларни олиб чиқиш | C19: =D19+E19+F19+G19+H19+I19+J19+K19+L19+M19+N19+O19+P19+Q19+R19+S19+T19+U19+V19+W19+X19+Y19+Z19+AA19+AB19+AC19+AD19+AE19+AF19+AG19+AH19+AI19+AJ19+AK19+AL19+AM19+AN19+AO19+AP19+AQ19+AR19+AS19+AT19+AU19+AV19+AW19+AX19+AY19+AZ19+BA19+BB19+BC19+BD19+BE19+BF19 -> 1 | BC19: 1
B20: ободонлаштириш бўйича | C20: =D20+E20+F20+G20+H20+I20+J20+K20+L20+M20+N20+O20+P20+Q20+R20+S20+T20+U20+V20+W20+X20+Y20+Z20+AA20+AB20+AC20+AD20+AE20+AF20+AG20+AH20+AI20+AJ20+AK20+AL20+AM20+AN20+AO20+AP20+AQ20+AR20+AS20+AT20+AU20+AV20+AW20+AX20+AY20+AZ20+BA20+BB20+BC20+BD20+BE20+BF20 -> 0
B21: бошқалар | C21: =D21+E21+F21+G21+H21+I21+J21+K21+L21+M21+N21+O21+P21+Q21+R21+S21+T21+U21+V21+W21+X21+Y21+Z21+AA21+AB21+AC21+AD21+AE21+AF21+AG21+AH21+AI21+AJ21+AK21+AL21+AM21+AN21+AO21+AP21+AQ21+AR21+AS21+AT21+AU21+AV21+AW21+AX21+AY21+AZ21+BA21+BB21+BC21+BD21+BE21+BF21 -> 1 | G21: 1
A22: 3. | B22: Совуқ сув қувури таъмирлаш (п/м) | C22: =D22+E22+F22+G22+H22+I22+J22+K22+L22+M22+N22+O22+P22+Q22+R22+S22+T22+U22+V22+W22+X22+Y22+Z22+AA22+AB22+AC22+AD22+AE22+AF22+AG22+AH22+AI22+AJ22+AK22+AL22+AM22+AN22+AO22+AP22+AQ22+AR22+AS22+AT22+AU22+AV22+AW22+AX22+AY22+AZ22+BA22+BB22+BC22+BD22+BE22+BF22 -> 0
A23: 4. | B23: Иссиқ сув қувури таъмирлаш (п/м) | C23: =D23+E23+F23+G23+H23+I23+J23+K23+L23+M23+N23+O23+P23+Q23+R23+S23+T23+U23+V23+W23+X23+Y23+Z23+AA23+AB23+AC23+AD23+AE23+AF23+AG23+AH23+AI23+AJ23+AK23+AL23+AM23+AN23+AO23+AP23+AQ23+AR23+AS23+AT23+AU23+AV23+AW23+AX23+AY23+AZ23+BA23+BB23+BC23+BD23+BE23+BF23 -> 0
A24: 5. | B24: БСК йўналишида кўп қаватли уйларда олиб борилган таъмирлаш ишлари | C24: =D24+E24+F24+G24+H24+I24+J24+K24+L24+M24+N24+O24+P24+Q24+R24+S24+T24+U24+V24+W24+X24+Y24+Z24+AA24+AB24+AC24+AD24+AE24+AF24+AG24+AH24+AI24+AJ24+AK24+AL24+AM24+AN24+AO24+AP24+AQ24+AR24+AS24+AT24+AU24+AV24+AW24+AX24+AY24+AZ24+BA24+BB24+BC24+BD24+BE24+BF24 -> 0
A25: шундан | B25: том таъмирлаш (м2) | C25: =D25+E25+F25+G25+H25+I25+J25+K25+L25+M25+N25+O25+P25+Q25+R25+S25+T25+U25+V25+W25+X25+Y25+Z25+AA25+AB25+AC25+AD25+AE25+AF25+AG25+AH25+AI25+AJ25+AK25+AL25+AM25+AN25+AO25+AP25+AQ25+AR25+AS25+AT25+AU25+AV25+AW25+AX25+AY25+AZ25+BA25+BB25+BC25+BD25+BE25+BF25 -> 0
B26: иссиқлик таъминоти | C26: =D26+E26+F26+G26+H26+I26+J26+K26+L26+M26+N26+O26+P26+Q26+R26+S26+T26+U26+V26+W26+X26+Y26+Z26+AA26+AB26+AC26+AD26+AE26+AF26+AG26+AH26+AI26+AJ26+AK26+AL26+AM26+AN26+AO26+AP26+AQ26+AR26+AS26+AT26+AU26+AV26+AW26+AX26+AY26+AZ26+BA26+BB26+BC26+BD26+BE26+BF26 -> 0
B27: лифт таъмири | C27: =D27+E27+F27+G27+H27+I27+J27+K27+L27+M27+N27+O27+P27+Q27+R27+S27+T27+U27+V27+W27+X27+Y27+Z27+AA27+AB27+AC27+AD27+AE27+AF27+AG27+AH27+AI27+AJ27+AK27+AL27+AM27+AN27+AO27+AP27+AQ27+AR27+AS27+AT27+AU27+AV27+AW27+AX27+AY27+AZ27+BA27+BB27+BC27+BD27+BE27+BF27 -> 2 | G27: 1 | N27: 1
B28: бошқалар | C28: =D28+E28+F28+G28+H28+I28+J28+K28+L28+M28+N28+O28+P28+Q28+R28+S28+T28+U28+V28+W28+X28+Y28+Z28+AA28+AB28+AC28+AD28+AE28+AF28+AG28+AH28+AI28+AJ28+AK28+AL28+AM28+AN28+AO28+AP28+AQ28+AR28+AS28+AT28+AU28+AV28+AW28+AX28+AY28+AZ28+BA28+BB28+BC28+BD28+BE28+BF28 -> 0
A29: 6. | B29: Ўрнатилган янги трансформаторлар | C29: =D29+E29+F29+G29+H29+I29+J29+K29+L29+M29+N29+O29+P29+Q29+R29+S29+T29+U29+V29+W29+X29+Y29+Z29+AA29+AB29+AC29+AD29+AE29+AF29+AG29+AH29+AI29+AJ29+AK29+AL29+AM29+AN29+AO29+AP29+AQ29+AR29+AS29+AT29+AU29+AV29+AW29+AX29+AY29+AZ29+BA29+BB29+BC29+BD29+BE29+BF29 -> 0
A30: 7. | B30: Алмаштирилган ва тортилган электр кабеллари (метр) | C30: =D30+E30+F30+G30+H30+I30+J30+K30+L30+M30+N30+O30+P30+Q30+R30+S30+T30+U30+V30+W30+X30+Y30+Z30+AA30+AB30+AC30+AD30+AE30+AF30+AG30+AH30+AI30+AJ30+AK30+AL30+AM30+AN30+AO30+AP30+AQ30+AR30+AS30+AT30+AU30+AV30+AW30+AX30+AY30+AZ30+BA30+BB30+BC30+BD30+BE30+BF30 -> 400 | R30: 250 | Y30: 150
A31: 8. | B31: Олиб чиқилган чиқиндилар (тонна) | C31: =D31+E31+F31+G31+H31+I31+J31+K31+L31+M31+N31+O31+P31+Q31+R31+S31+T31+U31+V31+W31+X31+Y31+Z31+AA31+AB31+AC31+AD31+AE31+AF31+AG31+AH31+AI31+AJ31+AK31+AL31+AM31+AN31+AO31+AP31+AQ31+AR31+AS31+AT31+AU31+AV31+AW31+AX31+AY31+AZ31+BA31+BB31+BC31+BD31+BE31+BF31 -> 289 | D31: 6 | E31: 5.2 | F31: 4.1 | G31: 5.1 | H31: 5.3 | I31: 4.6 | J31: 7.1 | K31: 3.8 | L31: 4.1 | M31: 5.4 | N31: 5.5 | O31: 6.1 | P31: 4.3 | Q31: 2.8 | R31: 9 | S31: 4 | T31: 5.6 | U31: 6.8 | V31: 4.7 | W31: 5.5 | X31: 5.4 | Y31: 6.6 | Z31: 4.8 | AA31: 5 | AB31: 8 | AC31: 4.8 | AD31: 4.9 | AE31: 5.7 | AF31: 4.8 | AG31: 4.5 | AH31: 4 | AI31: 5.3 | AJ31: 8 | AK31: 5.2 | AL31: 5.6 | AM31: 5.8 | AN31: 5.1 | AO31: 4.9 | AP31: 4.9 | AQ31: 5.6 | AR31: 4.4 | AS31: 3.6 | AT31: 3.2 | AU31: 3.7 | AV31: 4.5 | AW31: 4.9 | AX31: 5.4 | AY31: 4.5 | AZ31: 5.4 | BA31: 7.5 | BB31: 5.1 | BC31: 5 | BD31: 5.5 | BE31: 6.8 | BF31: 5.6
A32: 9. | B32: Ўрнатилган янги ёритиш чироқлари | C32: =D32+E32+F32+G32+H32+I32+J32+K32+L32+M32+N32+O32+P32+Q32+R32+S32+T32+U32+V32+W32+X32+Y32+Z32+AA32+AB32+AC32+AD32+AE32+AF32+AG32+AH32+AI32+AJ32+AK32+AL32+AM32+AN32+AO32+AP32+AQ32+AR32+AS32+AT32+AU32+AV32+AW32+AX32+AY32+AZ32+BA32+BB32+BC32+BD32+BE32+BF32 -> 0
A33: 10. | B33: Таъмирланган ёритиш чироқлари | C33: =D33+E33+F33+G33+H33+I33+J33+K33+L33+M33+N33+O33+P33+Q33+R33+S33+T33+U33+V33+W33+X33+Y33+Z33+AA33+AB33+AC33+AD33+AE33+AF33+AG33+AH33+AI33+AJ33+AK33+AL33+AM33+AN33+AO33+AP33+AQ33+AR33+AS33+AT33+AU33+AV33+AW33+AX33+AY33+AZ33+BA33+BB33+BC33+BD33+BE33+BF33 -> 0

Sheet 01.22
A1: № | B1: Кўрсаткич | C1: Жами | D1: Ал-Хоразмий | E1: Бахористон | F1: Бектўпи | G1: Гулистон | H1: Катта Хирмонтепа | I1: Тирсакобод | J1: Хайрабод | K1: Хирмон тепа | L1: Хонтўпи | M1: Шараф | N1: Шарқ | O1: Шарқ тонги | P1: Шухрат | Q1: 1-Чарх Камолон | R1: 2-Чарх Камолон | S1: 3-Чарх Камолон | T1: Бешёғоч | U1: Катта Козиробод | V1: Катта Олмазор | W1: Катта Чилонзор-1 | X1: Катта Чилонзор-2 | Y1: Катта Чилонзор-3 | Z1: Қозиробод | AA1: Новза | AB1: Чилонзор | AC1: 1-Қатортол | AD1: Бешчинор | AE1: Боғзор | AF1: Диёр | AG1: Дилобод | AH1: Катта Навбаҳор | AI1: Кўркам | AJ1: Кўтарма | AK1: Қатортол | AL1: Лутфий | AM1: Навбахор | AN1: Нафосат | AO1: Оқ-тепа | AP1: Халқлар Дўстлиги | AQ1: Чўпон-ота | AR1: 2-Қатортол | AS1: Ботирма | AT1: Бўрижар | AU1: Гавхар | AV1: Дўмбиробод | AW1: Зарқўрғон | AX1: Катта Дўмбиробод | AY1: Кичик Хирмонтепа | AZ1: Мевазор | BA1: Мехржон | BB1: Наққошлик | BC1: Фидокор | BD1: Яккабоғ | BE1: Яккатут | BF1: Бешқўрғон
A2: 1. | B2: Коммунал соҳада келиб тушган жами мурожаатлар | C2: =D2+E2+F2+G2+H2+I2+J2+K2+L2+M2+N2+O2+P2+Q2+R2+S2+T2+U2+V2+W2+X2+Y2+Z2+AA2+AB2+AC2+AD2+AE2+AF2+AG2+AH2+AI2+AJ2+AK2+AL2+AM2+AN2+AO2+AP2+AQ2+AR2+AS2+AT2+AU2+AV2+AW2+AX2+AY2+AZ2+BA2+BB2+BC2+BD2+BE2+BF2 -> 27 | D2: =+SUM(D3:D11) -> 1 | E2: =+SUM(E3:E11) -> 0 | F2: =+SUM(F3:F11) -> 1 | G2: =+SUM(G3:G11) -> 1 | H2: =+SUM(H3:H11) -> 1 | I2: =+SUM(I3:I11) -> 1 | J2: =+SUM(J3:J11) -> 0 | K2: =+SUM(K3:K11) -> 1 | ... BF2: =+SUM(BF3:BF11) -> 1
A3: шундан | B3: БСК йўналишида | C3: =D3+E3+F3+G3+H3+I3+J3+K3+L3+M3+N3+O3+P3+Q3+R3+S3+T3+U3+V3+W3+X3+Y3+Z3+AA3+AB3+AC3+AD3+AE3+AF3+AG3+AH3+AI3+AJ3+AK3+AL3+AM3+AN3+AO3+AP3+AQ3+AR3+AS3+AT3+AU3+AV3+AW3+AX3+AY3+AZ3+BA3+BB3+BC3+BD3+BE3+BF3 -> 12 | D3: 1 | H3: 1 | P3: 2 | W3: 2 | AE3: 1 | AJ3: 1 | AK3: 1 | AU3: 2 | BB3: 1
B4: электр таъминоти | C4: =D4+E4+F4+G4+H4+I4+J4+K4+L4+M4+N4+O4+P4+Q4+R4+S4+T4+U4+V4+W4+X4+Y4+Z4+AA4+AB4+AC4+AD4+AE4+AF4+AG4+AH4+AI4+AJ4+AK4+AL4+AM4+AN4+AO4+AP4+AQ4+AR4+AS4+AT4+AU4+AV4+AW4+AX4+AY4+AZ4+BA4+BB4+BC4+BD4+BE4+BF4 -> 7 | W4: 1 | AO4: 1 | AU4: 1 | AV4: 3 | BF4: 1
B5: газ таъминоти | C5: =D5+E5+F5+G5+H5+I5+J5+K5+L5+M5+N5+O5+P5+Q5+R5+S5+T5+U5+V5+W5+X5+Y5+Z5+AA5+AB5+AC5+AD5+AE5+AF5+AG5+AH5+AI5+AJ5+AK5+AL5+AM5+AN5+AO5+AP5+AQ5+AR5+AS5+AT5+AU5+AV5+AW5+AX5+AY5+AZ5+BA5+BB5+BC5+BD5+BE5+BF5 -> 4 | G5: 1 | I5: 1 | K5: 1 | BD5: 1 | BG5: 1
B6: совуқ сув таъминоти | C6: =D6+E6+F6+G6+H6+I6+J6+K6+L6+M6+N6+O6+P6+Q6+R6+S6+T6+U6+V6+W6+X6+Y6+Z6+AA6+AB6+AC6+AD6+AE6+AF6+AG6+AH6+AI6+AJ6+AK6+AL6+AM6+AN6+AO6+AP6+AQ6+AR6+AS6+AT6+AU6+AV6+AW6+AX6+AY6+AZ6+BA6+BB6+BC6+BD6+BE6+BF6 -> 0
B7: иссиқ сув ва иссиқлик таъминоти | C7: =D7+E7+F7+G7+H7+I7+J7+K7+L7+M7+N7+O7+P7+Q7+R7+S7+T7+U7+V7+W7+X7+Y7+Z7+AA7+AB7+AC7+AD7+AE7+AF7+AG7+AH7+AI7+AJ7+AK7+AL7+AM7+AN7+AO7+AP7+AQ7+AR7+AS7+AT7+AU7+AV7+AW7+AX7+AY7+AZ7+BA7+BB7+BC7+BD7+BE7+BF7 -> 4 | F7: 1 | W7: 1 | AB7: 1 | AP7: 1
B8: ёритиш чироқлари (нур) | C8: =D8+E8+F8+G8+H8+I8+J8+K8+L8+M8+N8+O8+P8+Q8+R8+S8+T8+U8+V8+W8+X8+Y8+Z8+AA8+AB8+AC8+AD8+AE8+AF8+AG8+AH8+AI8+AJ8+AK8+AL8+AM8+AN8+AO8+AP8+AQ8+AR8+AS8+AT8+AU8+AV8+AW8+AX8+AY8+AZ8+BA8+BB8+BC8+BD8+BE8+BF8 -> 0
B9: чиқиндиларни олиб чиқиш | C9: =D9+E9+F9+G9+H9+I9+J9+K9+L9+M9+N9+O9+P9+Q9+R9+S9+T9+U9+V9+W9+X9+Y9+Z9+AA9+AB9+AC9+AD9+AE9+AF9+AG9+AH9+AI9+AJ9+AK9+AL9+AM9+AN9+AO9+AP9+AQ9+AR9+AS9+AT9+AU9+AV9+AW9+AX9+AY9+AZ9+BA9+BB9+BC9+BD9+BE9+BF9 -> 0
B10: ободонлаштириш бўйича | C10: =D10+E10+F10+G10+H10+I10+J10+K10+L10+M10+N10+O10+P10+Q10+R10+S10+T10+U10+V10+W10+X10+Y10+Z10+AA10+AB10+AC10+AD10+AE10+AF10+AG10+AH10+AI10+AJ10+AK10+AL10+AM10+AN10+AO10+AP10+AQ10+AR10+AS10+AT10+AU10+AV10+AW10+AX10+AY10+AZ10+BA10+BB10+BC10+BD10+BE10+BF10 -> 0
B11: бошқалар | C11: =D11+E11+F11+G11+H11+I11+J11+K11+L11+M11+N11+O11+P11+Q11+R11+S11+T11+U11+V11+W11+X11+Y11+Z11+AA11+AB11+AC11+AD11+AE11+AF11+AG11+AH11+AI11+AJ11+AK11+AL11+AM11+AN11+AO11+AP11+AQ11+AR11+AS11+AT11+AU11+AV11+AW11+AX11+AY11+AZ11+BA11+BB11+BC11+BD11+BE11+BF11 -> 0
A12: 2. | B12: Муаммоси ҳал этилган жами мурожаатлар | C12: =D12+E12+F12+G12+H12+I12+J12+K12+L12+M12+N12+O12+P12+Q12+R12+S12+T12+U12+V12+W12+X12+Y12+Z12+AA12+AB12+AC12+AD12+AE12+AF12+AG12+AH12+AI12+AJ12+AK12+AL12+AM12+AN12+AO12+AP12+AQ12+AR12+AS12+AT12+AU12+AV12+AW12+AX12+AY12+AZ12+BA12+BB12+BC12+BD12+BE12+BF12 -> 27 | D12: =+SUM(D13:D21) -> 1 | E12: =+SUM(E13:E21) -> 0 | F12: =+SUM(F13:F21) -> 1 | G12: =+SUM(G13:G21) -> 1 | H12: =+SUM(H13:H21) -> 1 | I12: =+SUM(I13:I21) -> 1 | J12: =+SUM(J13:J21) -> 0 | K12: =+SUM(K13:K21) -> 1 | ... BF12: =+SUM(BF13:BF21) -> 1
A13: шундан | B13: БСК йўналишида | C13: =D13+E13+F13+G13+H13+I13+J13+K13+L13+M13+N13+O13+P13+Q13+R13+S13+T13+U13+V13+W13+X13+Y13+Z13+AA13+AB13+AC13+AD13+AE13+AF13+AG13+AH13+AI13+AJ13+AK13+AL13+AM13+AN13+AO13+AP13+AQ13+AR13+AS13+AT13+AU13+AV13+AW13+AX13+AY13+AZ13+BA13+BB13+BC13+BD13+BE13+BF13 -> 12 | D13: 1 | H13: 1 | P13: 2 | W13: 2 | AE13: 1 | AJ13: 1 | AK13: 1 | AU13: 2 | BB13: 1
B14: электр таъминоти | C14: =D14+E14+F14+G14+H14+I14+J14+K14+L14+M14+N14+O14+P14+Q14+R14+S14+T14+U14+V14+W14+X14+Y14+Z14+AA14+AB14+AC14+AD14+AE14+AF14+AG14+AH14+AI14+AJ14+AK14+AL14+AM14+AN14+AO14+AP14+AQ14+AR14+AS14+AT14+AU14+AV14+AW14+AX14+AY14+AZ14+BA14+BB14+BC14+BD14+BE14+BF14 -> 7 | W14: 1 | AO14: 1 | AU14: 1 | AV14: 3 | BF14: 1
B15: газ таъминоти | C15: =D15+E15+F15+G15+H15+I15+J15+K15+L15+M15+N15+O15+P15+Q15+R15+S15+T15+U15+V15+W15+X15+Y15+Z15+AA15+AB15+AC15+AD15+AE15+AF15+AG15+AH15+AI15+AJ15+AK15+AL15+AM15+AN15+AO15+AP15+AQ15+AR15+AS15+AT15+AU15+AV15+AW15+AX15+AY15+AZ15+BA15+BB15+BC15+BD15+BE15+BF15 -> 4 | G15: 1 | I15: 1 | K15: 1 | BD15: 1 | BG15: 1
B16: совуқ сув таъминоти | C16: =D16+E16+F16+G16+H16+I16+J16+K16+L16+M16+N16+O16+P16+Q16+R16+S16+T16+U16+V16+W16+X16+Y16+Z16+AA16+AB16+AC16+AD16+AE16+AF16+AG16+AH16+AI16+AJ16+AK16+AL16+AM16+AN16+AO16+AP16+AQ16+AR16+AS16+AT16+AU16+AV16+AW16+AX16+AY16+AZ16+BA16+BB16+BC16+BD16+BE16+BF16 -> 0
B17: иссиқ сув ва иссиқлик таъминоти | C17: =D17+E17+F17+G17+H17+I17+J17+K17+L17+M17+N17+O17+P17+Q17+R17+S17+T17+U17+V17+W17+X17+Y17+Z17+AA17+AB17+AC17+AD17+AE17+AF17+AG17+AH17+AI17+AJ17+AK17+AL17+AM17+AN17+AO17+AP17+AQ17+AR17+AS17+AT17+AU17+AV17+AW17+AX17+AY17+AZ17+BA17+BB17+BC17+BD17+BE17+BF17 -> 4 | F17: 1 | W17: 1 | AB17: 1 | AP17: 1
B18: ёритиш чироқлари (нур) | C18: =D18+E18+F18+G18+H18+I18+J18+K18+L18+M18+N18+O18+P18+Q18+R18+S18+T18+U18+V18+W18+X18+Y18+Z18+AA18+AB18+AC18+AD18+AE18+AF18+AG18+AH18+AI18+AJ18+AK18+AL18+AM18+AN18+AO18+AP18+AQ18+AR18+AS18+AT18+AU18+AV18+AW18+AX18+AY18+AZ18+BA18+BB18+BC18+BD18+BE18+BF18 -> 0
B19: чиқиндиларни олиб чиқиш | C19: =D19+E19+F19+G19+H19+I19+J19+K19+L19+M19+N19+O19+P19+Q19+R19+S19+T19+U19+V19+W19+X19+Y19+Z19+AA19+AB19+AC19+AD19+AE19+AF19+AG19+AH19+AI19+AJ19+AK19+AL19+AM19+AN19+AO19+AP19+AQ19+AR19+AS19+AT19+AU19+AV19+AW19+AX19+AY19+AZ19+BA19+BB19+BC19+BD19+BE19+BF19 -> 0
B20: ободонлаштириш бўйича | C20: =D20+E20+F20+G20+H20+I20+J20+K20+L20+M20+N20+O20+P20+Q20+R20+S20+T20+U20+V20+W20+X20+Y20+Z20+AA20+AB20+AC20+AD20+AE20+AF20+AG20+AH20+AI20+AJ20+AK20+AL20+AM20+AN20+AO20+AP20+AQ20+AR20+AS20+AT20+AU20+AV20+AW20+AX20+AY20+AZ20+BA20+BB20+BC20+BD20+BE20+BF20 -> 0
B21: бошқалар | C21: =D21+E21+F21+G21+H21+I21+J21+K21+L21+M21+N21+O21+P21+Q21+R21+S21+T21+U21+V21+W21+X21+Y21+Z21+AA21+AB21+AC21+AD21+AE21+AF21+AG21+AH21+AI21+AJ21+AK21+AL21+AM21+AN21+AO21+AP21+AQ21+AR21+AS21+AT21+AU21+AV21+AW21+AX21+AY21+AZ21+BA21+BB21+BC21+BD21+BE21+BF21 -> 0
A22: 3. | B22: Совуқ сув қувури таъмирлаш (п/м) | C22: =D22+E22+F22+G22+H22+I22+J22+K22+L22+M22+N22+O22+P22+Q22+R22+S22+T22+U22+V22+W22+X22+Y22+Z22+AA22+AB22+AC22+AD22+AE22+AF22+AG22+AH22+AI22+AJ22+AK22+AL22+AM22+AN22+AO22+AP22+AQ22+AR22+AS22+AT22+AU22+AV22+AW22+AX22+AY22+AZ22+BA22+BB22+BC22+BD22+BE22+BF22 -> 0
A23: 4. | B23: Иссиқ сув қувури таъмирлаш (п/м) | C23: =D23+E23+F23+G23+H23+I23+J23+K23+L23+M23+N23+O23+P23+Q23+R23+S23+T23+U23+V23+W23+X23+Y23+Z23+AA23+AB23+AC23+AD23+AE23+AF23+AG23+AH23+AI23+AJ23+AK23+AL23+AM23+AN23+AO23+AP23+AQ23+AR23+AS23+AT23+AU23+AV23+AW23+AX23+AY23+AZ23+BA23+BB23+BC23+BD23+BE23+BF23 -> 0
A24: 5. | B24: БСК йўналишида кўп қаватли уйларда олиб борилган таъмирлаш ишлари | C24: =D24+E24+F24+G24+H24+I24+J24+K24+L24+M24+N24+O24+P24+Q24+R24+S24+T24+U24+V24+W24+X24+Y24+Z24+AA24+AB24+AC24+AD24+AE24+AF24+AG24+AH24+AI24+AJ24+AK24+AL24+AM24+AN24+AO24+AP24+AQ24+AR24+AS24+AT24+AU24+AV24+AW24+AX24+AY24+AZ24+BA24+BB24+BC24+BD24+BE24+BF24 -> 0
A25: шундан | B25: том таъмирлаш (м2) | C25: =D25+E25+F25+G25+H25+I25+J25+K25+L25+M25+N25+O25+P25+Q25+R25+S25+T25+U25+V25+W25+X25+Y25+Z25+AA25+AB25+AC25+AD25+AE25+AF25+AG25+AH25+AI25+AJ25+AK25+AL25+AM25+AN25+AO25+AP25+AQ25+AR25+AS25+AT25+AU25+AV25+AW25+AX25+AY25+AZ25+BA25+BB25+BC25+BD25+BE25+BF25 -> 0
B26: иссиқлик таъминоти | C26: =D26+E26+F26+G26+H26+I26+J26+K26+L26+M26+N26+O26+P26+Q26+R26+S26+T26+U26+V26+W26+X26+Y26+Z26+AA26+AB26+AC26+AD26+AE26+AF26+AG26+AH26+AI26+AJ26+AK26+AL26+AM26+AN26+AO26+AP26+AQ26+AR26+AS26+AT26+AU26+AV26+AW26+AX26+AY26+AZ26+BA26+BB26+BC26+BD26+BE26+BF26 -> 0
B27: лифт таъмири | C27: =D27+E27+F27+G27+H27+I27+J27+K27+L27+M27+N27+O27+P27+Q27+R27+S27+T27+U27+V27+W27+X27+Y27+Z27+AA27+AB27+AC27+AD27+AE27+AF27+AG27+AH27+AI27+AJ27+AK27+AL27+AM27+AN27+AO27+AP27+AQ27+AR27+AS27+AT27+AU27+AV27+AW27+AX27+AY27+AZ27+BA27+BB27+BC27+BD27+BE27+BF27 -> 0
B28: бошқалар | C28: =D28+E28+F28+G28+H28+I28+J28+K28+L28+M28+N28+O28+P28+Q28+R28+S28+T28+U28+V28+W28+X28+Y28+Z28+AA28+AB28+AC28+AD28+AE28+AF28+AG28+AH28+AI28+AJ28+AK28+AL28+AM28+AN28+AO28+AP28+AQ28+AR28+AS28+AT28+AU28+AV28+AW28+AX28+AY28+AZ28+BA28+BB28+BC28+BD28+BE28+BF28 -> 0
A29: 6. | B29: Ўрнатилган янги трансформаторлар | C29: =D29+E29+F29+G29+H29+I29+J29+K29+L29+M29+N29+O29+P29+Q29+R29+S29+T29+U29+V29+W29+X29+Y29+Z29+AA29+AB29+AC29+AD29+AE29+AF29+AG29+AH29+AI29+AJ29+AK29+AL29+AM29+AN29+AO29+AP29+AQ29+AR29+AS29+AT29+AU29+AV29+AW29+AX29+AY29+AZ29+BA29+BB29+BC29+BD29+BE29+BF29 -> 0
A30: 7. | B30: Алмаштирилган ва тортилган электр кабеллари (метр) | C30: =D30+E30+F30+G30+H30+I30+J30+K30+L30+M30+N30+O30+P30+Q30+R30+S30+T30+U30+V30+W30+X30+Y30+Z30+AA30+AB30+AC30+AD30+AE30+AF30+AG30+AH30+AI30+AJ30+AK30+AL30+AM30+AN30+AO30+AP30+AQ30+AR30+AS30+AT30+AU30+AV30+AW30+AX30+AY30+AZ30+BA30+BB30+BC30+BD30+BE30+BF30 -> 0
A31: 8. | B31: Олиб чиқилган чиқиндилар (тонна) | C31: =D31+E31+F31+G31+H31+I31+J31+K31+L31+M31+N31+O31+P31+Q31+R31+S31+T31+U31+V31+W31+X31+Y31+Z31+AA31+AB31+AC31+AD31+AE31+AF31+AG31+AH31+AI31+AJ31+AK31+AL31+AM31+AN31+AO31+AP31+AQ31+AR31+AS31+AT31+AU31+AV31+AW31+AX31+AY31+AZ31+BA31+BB31+BC31+BD31+BE31+BF31 -> 305.8 | D31: 5.5 | E31: 6 | F31: 5.5 | G31: 5.2 | H31: 7.1 | I31: 8.3 | J31: 4.5 | K31: 5.4 | L31: 4.8 | M31: 5.4 | N31: 3.8 | O31: 4.5 | P31: 5.3 | Q31: 5.8 | R31: 6.2 | S31: 11.2 | T31: 5.9 | U31: 6.1 | V31: 6.5 | W31: 6.2 | X31: 5.9 | Y31: 7 | Z31: 5.9 | AA31: 9 | AB31: 7.2 | AC31: 5.9 | AD31: 5.8 | AE31: 5.5 | AF31: 5.9 | AG31: 5.8 | AH31: 6 | AI31: 5.4 | AJ31: 5.9 | AK31: 4.3 | AL31: 4 | AM31: 5 | AN31: 6.2 | AO31: 4.8 | AP31: 6 | AQ31: 3.2 | AR31: 3.5 | AS31: 4.5 | AT31: 4.2 | AU31: 5.4 | AV31: 4.5 | AW31: 4.8 | AX31: 5.9 | AY31: 4.6 | AZ31: 4.5 | BA31: 5.2 | BB31: 4.5 | BC31: 4.5 | BD31: 3.2 | BE31: 4.8 | BF31: 7.8
A32: 9. | B32: Ўрнатилган янги ёритиш чироқлари | C32: =D32+E32+F32+G32+H32+I32+J32+K32+L32+M32+N32+O32+P32+Q32+R32+S32+T32+U32+V32+W32+X32+Y32+Z32+AA32+AB32+AC32+AD32+AE32+AF32+AG32+AH32+AI32+AJ32+AK32+AL32+AM32+AN32+AO32+AP32+AQ32+AR32+AS32+AT32+AU32+AV32+AW32+AX32+AY32+AZ32+BA32+BB32+BC32+BD32+BE32+BF32 -> 0
A33: 10. | B33: Таъмирланган ёритиш чироқлари | C33: =D33+E33+F33+G33+H33+I33+J33+K33+L33+M33+N33+O33+P33+Q33+R33+S33+T33+U33+V33+W33+X33+Y33+Z33+AA33+AB33+AC33+AD33+AE33+AF33+AG33+AH33+AI33+AJ33+AK33+AL33+AM33+AN33+AO33+AP33+AQ33+AR33+AS33+AT33+AU33+AV33+AW33+AX33+AY33+AZ33+BA33+BB33+BC33+BD33+BE33+BF33 -> 0
AN35: масъул ходим лавозими

Sheet 01.23
A1: № | B1: Кўрсаткич | C1: Жами | D1: Ал-Хоразмий | E1: Бахористон | F1: Бектўпи | G1: Гулистон | H1: Катта Хирмонтепа | I1: Тирсакобод | J1: Хайрабод | K1: Хирмон тепа | L1: Хонтўпи | M1: Шараф | N1: Шарқ | O1: Шарқ тонги | P1: Шухрат | Q1: 1-Чарх Камолон | R1: 2-Чарх Камолон | S1: 3-Чарх Камолон | T1: Бешёғоч | U1: Катта Козиробод | V1: Катта Олмазор | W1: Катта Чилонзор-1 | X1: Катта Чилонзор-2 | Y1: Катта Чилонзор-3 | Z1: Қозиробод | AA1: Новза | AB1: Чилонзор | AC1: 1-Қатортол | AD1: Бешчинор | AE1: Боғзор | AF1: Диёр | AG1: Дилобод | AH1: Катта Навбаҳор | AI1: Кўркам | AJ1: Кўтарма | AK1: Қатортол | AL1: Лутфий | AM1: Навбахор | AN1: Нафосат | AO1: Оқ-тепа | AP1: Халқлар Дўстлиги | AQ1: Чўпон-ота | AR1: 2-Қатортол | AS1: Ботирма | AT1: Бўрижар | AU1: Гавхар | AV1: Дўмбиробод | AW1: Зарқўрғон | AX1: Катта Дўмбиробод | AY1: Кичик Хирмонтепа | AZ1: Мевазор | BA1: Мехржон | BB1: Наққошлик | BC1: Фидокор | BD1: Яккабоғ | BE1: Яккатут | BF1: Бешқўрғон
A2: 1. | B2: Коммунал соҳада келиб тушган жами мурожаатлар | C2: =D2+E2+F2+G2+H2+I2+J2+K2+L2+M2+N2+O2+P2+Q2+R2+S2+T2+U2+V2+W2+X2+Y2+Z2+AA2+AB2+AC2+AD2+AE2+AF2+AG2+AH2+AI2+AJ2+AK2+AL2+AM2+AN2+AO2+AP2+AQ2+AR2+AS2+AT2+AU2+AV2+AW2+AX2+AY2+AZ2+BA2+BB2+BC2+BD2+BE2+BF2 -> 35 | D2: =+SUM(D3:D11) -> 0 | E2: =+SUM(E3:E11) -> 1 | F2: =+SUM(F3:F11) -> 0 | G2: =+SUM(G3:G11) -> 1 | H2: =+SUM(H3:H11) -> 1 | I2: =+SUM(I3:I11) -> 0 | J2: =+SUM(J3:J11) -> 0 | K2: =+SUM(K3:K11) -> 1 | ... BF2: =+SUM(BF3:BF11) -> 1
A3: шундан | B3: БСК йўналишида | C3: =D3+E3+F3+G3+H3+I3+J3+K3+L3+M3+N3+O3+P3+Q3+R3+S3+T3+U3+V3+W3+X3+Y3+Z3+AA3+AB3+AC3+AD3+AE3+AF3+AG3+AH3+AI3+AJ3+AK3+AL3+AM3+AN3+AO3+AP3+AQ3+AR3+AS3+AT3+AU3+AV3+AW3+AX3+AY3+AZ3+BA3+BB3+BC3+BD3+BE3+BF3 -> 16 | E3: 1 | G3: 1 | H3: 1 | R3: 1 | Y3: 1 | AG3: 1 | AK3: 1 | AQ3: 2 | AS3: 2 | AT3: 1 | AW3: 2 | BA3: 1 | BE3: 1
B4: электр таъминоти | C4: =D4+E4+F4+G4+H4+I4+J4+K4+L4+M4+N4+O4+P4+Q4+R4+S4+T4+U4+V4+W4+X4+Y4+Z4+AA4+AB4+AC4+AD4+AE4+AF4+AG4+AH4+AI4+AJ4+AK4+AL4+AM4+AN4+AO4+AP4+AQ4+AR4+AS4+AT4+AU4+AV4+AW4+AX4+AY4+AZ4+BA4+BB4+BC4+BD4+BE4+BF4 -> 9 | K4: 1 | L4: 1 | R4: 1 | AA4: 1 | AN4: 1 | AO4: 2 | BC4: 1 | BF4: 1
B5: газ таъминоти | C5: =D5+E5+F5+G5+H5+I5+J5+K5+L5+M5+N5+O5+P5+Q5+R5+S5+T5+U5+V5+W5+X5+Y5+Z5+AA5+AB5+AC5+AD5+AE5+AF5+AG5+AH5+AI5+AJ5+AK5+AL5+AM5+AN5+AO5+AP5+AQ5+AR5+AS5+AT5+AU5+AV5+AW5+AX5+AY5+AZ5+BA5+BB5+BC5+BD5+BE5+BF5 -> 4 | AC5: 1 | AM5: 1 | AW5: 2 | BG5: 1
B6: совуқ сув таъминоти | C6: =D6+E6+F6+G6+H6+I6+J6+K6+L6+M6+N6+O6+P6+Q6+R6+S6+T6+U6+V6+W6+X6+Y6+Z6+AA6+AB6+AC6+AD6+AE6+AF6+AG6+AH6+AI6+AJ6+AK6+AL6+AM6+AN6+AO6+AP6+AQ6+AR6+AS6+AT6+AU6+AV6+AW6+AX6+AY6+AZ6+BA6+BB6+BC6+BD6+BE6+BF6 -> 2 | W6: 1 | AX6: 1
B7: иссиқ сув ва иссиқлик таъминоти | C7: =D7+E7+F7+G7+H7+I7+J7+K7+L7+M7+N7+O7+P7+Q7+R7+S7+T7+U7+V7+W7+X7+Y7+Z7+AA7+AB7+AC7+AD7+AE7+AF7+AG7+AH7+AI7+AJ7+AK7+AL7+AM7+AN7+AO7+AP7+AQ7+AR7+AS7+AT7+AU7+AV7+AW7+AX7+AY7+AZ7+BA7+BB7+BC7+BD7+BE7+BF7 -> 4 | W7: 1 | X7: 1 | AN7: 1 | AW7: 1
B8: ёритиш чироқлари (нур) | C8: =D8+E8+F8+G8+H8+I8+J8+K8+L8+M8+N8+O8+P8+Q8+R8+S8+T8+U8+V8+W8+X8+Y8+Z8+AA8+AB8+AC8+AD8+AE8+AF8+AG8+AH8+AI8+AJ8+AK8+AL8+AM8+AN8+AO8+AP8+AQ8+AR8+AS8+AT8+AU8+AV8+AW8+AX8+AY8+AZ8+BA8+BB8+BC8+BD8+BE8+BF8 -> 0
B9: чиқиндиларни олиб чиқиш | C9: =D9+E9+F9+G9+H9+I9+J9+K9+L9+M9+N9+O9+P9+Q9+R9+S9+T9+U9+V9+W9+X9+Y9+Z9+AA9+AB9+AC9+AD9+AE9+AF9+AG9+AH9+AI9+AJ9+AK9+AL9+AM9+AN9+AO9+AP9+AQ9+AR9+AS9+AT9+AU9+AV9+AW9+AX9+AY9+AZ9+BA9+BB9+BC9+BD9+BE9+BF9 -> 0
B10: ободонлаштириш бўйича | C10: =D10+E10+F10+G10+H10+I10+J10+K10+L10+M10+N10+O10+P10+Q10+R10+S10+T10+U10+V10+W10+X10+Y10+Z10+AA10+AB10+AC10+AD10+AE10+AF10+AG10+AH10+AI10+AJ10+AK10+AL10+AM10+AN10+AO10+AP10+AQ10+AR10+AS10+AT10+AU10+AV10+AW10+AX10+AY10+AZ10+BA10+BB10+BC10+BD10+BE10+BF10 -> 0
B11: бошқалар | C11: =D11+E11+F11+G11+H11+I11+J11+K11+L11+M11+N11+O11+P11+Q11+R11+S11+T11+U11+V11+W11+X11+Y11+Z11+AA11+AB11+AC11+AD11+AE11+AF11+AG11+AH11+AI11+AJ11+AK11+AL11+AM11+AN11+AO11+AP11+AQ11+AR11+AS11+AT11+AU11+AV11+AW11+AX11+AY11+AZ11+BA11+BB11+BC11+BD11+BE11+BF11 -> 0
A12: 2. | B12: Муаммоси ҳал этилган жами мурожаатлар | C12: =D12+E12+F12+G12+H12+I12+J12+K12+L12+M12+N12+O12+P12+Q12+R12+S12+T12+U12+V12+W12+X12+Y12+Z12+AA12+AB12+AC12+AD12+AE12+AF12+AG12+AH12+AI12+AJ12+AK12+AL12+AM12+AN12+AO12+AP12+AQ12+AR12+AS12+AT12+AU12+AV12+AW12+AX12+AY12+AZ12+BA12+BB12+BC12+BD12+BE12+BF12 -> 35 | D12: =+SUM(D13:D21) -> 0 | E12: =+SUM(E13:E21) -> 1 | F12: =+SUM(F13:F21) -> 0 | G12: =+SUM(G13:G21) -> 1 | H12: =+SUM(H13:H21) -> 1 | I12: =+SUM(I13:I21) -> 0 | J12: =+SUM(J13:J21) -> 0 | K12: =+SUM(K13:K21) -> 1 | ... BF12: =+SUM(BF13:BF21) -> 1
A13: шундан | B13: БСК йўналишида | C13: =D13+E13+F13+G13+H13+I13+J13+K13+L13+M13+N13+O13+P13+Q13+R13+S13+T13+U13+V13+W13+X13+Y13+Z13+AA13+AB13+AC13+AD13+AE13+AF13+AG13+AH13+AI13+AJ13+AK13+AL13+AM13+AN13+AO13+AP13+AQ13+AR13+AS13+AT13+AU13+AV13+AW13+AX13+AY13+AZ13+BA13+BB13+BC13+BD13+BE13+BF13 -> 16 | E13: 1 | G13: 1 | H13: 1 | R13: 1 | Y13: 1 | AG13: 1 | AK13: 1 | AQ13: 2 | AS13: 2 | AT13: 1 | AW13: 2 | BA13: 1 | BE13: 1
B14: электр таъминоти | C14: =D14+E14+F14+G14+H14+I14+J14+K14+L14+M14+N14+O14+P14+Q14+R14+S14+T14+U14+V14+W14+X14+Y14+Z14+AA14+AB14+AC14+AD14+AE14+AF14+AG14+AH14+AI14+AJ14+AK14+AL14+AM14+AN14+AO14+AP14+AQ14+AR14+AS14+AT14+AU14+AV14+AW14+AX14+AY14+AZ14+BA14+BB14+BC14+BD14+BE14+BF14 -> 9 | K14: 1 | L14: 1 | R14: 1 | AA14: 1 | AN14: 1 | AO14: 2 | BC14: 1 | BF14: 1
B15: газ таъминоти | C15: =D15+E15+F15+G15+H15+I15+J15+K15+L15+M15+N15+O15+P15+Q15+R15+S15+T15+U15+V15+W15+X15+Y15+Z15+AA15+AB15+AC15+AD15+AE15+AF15+AG15+AH15+AI15+AJ15+AK15+AL15+AM15+AN15+AO15+AP15+AQ15+AR15+AS15+AT15+AU15+AV15+AW15+AX15+AY15+AZ15+BA15+BB15+BC15+BD15+BE15+BF15 -> 4 | AC15: 1 | AM15: 1 | AW15: 2 | BG15: 1
B16: совуқ сув таъминоти | C16: =D16+E16+F16+G16+H16+I16+J16+K16+L16+M16+N16+O16+P16+Q16+R16+S16+T16+U16+V16+W16+X16+Y16+Z16+AA16+AB16+AC16+AD16+AE16+AF16+AG16+AH16+AI16+AJ16+AK16+AL16+AM16+AN16+AO16+AP16+AQ16+AR16+AS16+AT16+AU16+AV16+AW16+AX16+AY16+AZ16+BA16+BB16+BC16+BD16+BE16+BF16 -> 2 | W16: 1 | AX16: 1
B17: иссиқ сув ва иссиқлик таъминоти | C17: =D17+E17+F17+G17+H17+I17+J17+K17+L17+M17+N17+O17+P17+Q17+R17+S17+T17+U17+V17+W17+X17+Y17+Z17+AA17+AB17+AC17+AD17+AE17+AF17+AG17+AH17+AI17+AJ17+AK17+AL17+AM17+AN17+AO17+AP17+AQ17+AR17+AS17+AT17+AU17+AV17+AW17+AX17+AY17+AZ17+BA17+BB17+BC17+BD17+BE17+BF17 -> 4 | W17: 1 | X17: 1 | AN17: 1 | AW17: 1
B18: ёритиш чироқлари (нур) | C18: =D18+E18+F18+G18+H18+I18+J18+K18+L18+M18+N18+O18+P18+Q18+R18+S18+T18+U18+V18+W18+X18+Y18+Z18+AA18+AB18+AC18+AD18+AE18+AF18+AG18+AH18+AI18+AJ18+AK18+AL18+AM18+AN18+AO18+AP18+AQ18+AR18+AS18+AT18+AU18+AV18+AW18+AX18+AY18+AZ18+BA18+BB18+BC18+BD18+BE18+BF18 -> 0
B19: чиқиндиларни олиб чиқиш | C19: =D19+E19+F19+G19+H19+I19+J19+K19+L19+M19+N19+O19+P19+Q19+R19+S19+T19+U19+V19+W19+X19+Y19+Z19+AA19+AB19+AC19+AD19+AE19+AF19+AG19+AH19+AI19+AJ19+AK19+AL19+AM19+AN19+AO19+AP19+AQ19+AR19+AS19+AT19+AU19+AV19+AW19+AX19+AY19+AZ19+BA19+BB19+BC19+BD19+BE19+BF19 -> 0
B20: ободонлаштириш бўйича | C20: =D20+E20+F20+G20+H20+I20+J20+K20+L20+M20+N20+O20+P20+Q20+R20+S20+T20+U20+V20+W20+X20+Y20+Z20+AA20+AB20+AC20+AD20+AE20+AF20+AG20+AH20+AI20+AJ20+AK20+AL20+AM20+AN20+AO20+AP20+AQ20+AR20+AS20+AT20+AU20+AV20+AW20+AX20+AY20+AZ20+BA20+BB20+BC20+BD20+BE20+BF20 -> 0
B21: бошқалар | C21: =D21+E21+F21+G21+H21+I21+J21+K21+L21+M21+N21+O21+P21+Q21+R21+S21+T21+U21+V21+W21+X21+Y21+Z21+AA21+AB21+AC21+AD21+AE21+AF21+AG21+AH21+AI21+AJ21+AK21+AL21+AM21+AN21+AO21+AP21+AQ21+AR21+AS21+AT21+AU21+AV21+AW21+AX21+AY21+AZ21+BA21+BB21+BC21+BD21+BE21+BF21 -> 0
A22: 3. | B22: Совуқ сув қувури таъмирлаш (п/м) | C22: =D22+E22+F22+G22+H22+I22+J22+K22+L22+M22+N22+O22+P22+Q22+R22+S22+T22+U22+V22+W22+X22+Y22+Z22+AA22+AB22+AC22+AD22+AE22+AF22+AG22+AH22+AI22+AJ22+AK22+AL22+AM22+AN22+AO22+AP22+AQ22+AR22+AS22+AT22+AU22+AV22+AW22+AX22+AY22+AZ22+BA22+BB22+BC22+BD22+BE22+BF22 -> 20 | AX22: 20
A23: 4. | B23: Иссиқ сув қувури таъмирлаш (п/м) | C23: =D23+E23+F23+G23+H23+I23+J23+K23+L23+M23+N23+O23+P23+Q23+R23+S23+T23+U23+V23+W23+X23+Y23+Z23+AA23+AB23+AC23+AD23+AE23+AF23+AG23+AH23+AI23+AJ23+AK23+AL23+AM23+AN23+AO23+AP23+AQ23+AR23+AS23+AT23+AU23+AV23+AW23+AX23+AY23+AZ23+BA23+BB23+BC23+BD23+BE23+BF23 -> 0
A24: 5. | B24: БСК йўналишида кўп қаватли уйларда олиб борилган таъмирлаш ишлари | C24: =D24+E24+F24+G24+H24+I24+J24+K24+L24+M24+N24+O24+P24+Q24+R24+S24+T24+U24+V24+W24+X24+Y24+Z24+AA24+AB24+AC24+AD24+AE24+AF24+AG24+AH24+AI24+AJ24+AK24+AL24+AM24+AN24+AO24+AP24+AQ24+AR24+AS24+AT24+AU24+AV24+AW24+AX24+AY24+AZ24+BA24+BB24+BC24+BD24+BE24+BF24 -> 0
A25: шундан | B25: том таъмирлаш (м2) | C25: =D25+E25+F25+G25+H25+I25+J25+K25+L25+M25+N25+O25+P25+Q25+R25+S25+T25+U25+V25+W25+X25+Y25+Z25+AA25+AB25+AC25+AD25+AE25+AF25+AG25+AH25+AI25+AJ25+AK25+AL25+AM25+AN25+AO25+AP25+AQ25+AR25+AS25+AT25+AU25+AV25+AW25+AX25+AY25+AZ25+BA25+BB25+BC25+BD25+BE25+BF25 -> 0
B26: иссиқлик таъминоти | C26: =D26+E26+F26+G26+H26+I26+J26+K26+L26+M26+N26+O26+P26+Q26+R26+S26+T26+U26+V26+W26+X26+Y26+Z26+AA26+AB26+AC26+AD26+AE26+AF26+AG26+AH26+AI26+AJ26+AK26+AL26+AM26+AN26+AO26+AP26+AQ26+AR26+AS26+AT26+AU26+AV26+AW26+AX26+AY26+AZ26+BA26+BB26+BC26+BD26+BE26+BF26 -> 0
B27: лифт таъмири | C27: =D27+E27+F27+G27+H27+I27+J27+K27+L27+M27+N27+O27+P27+Q27+R27+S27+T27+U27+V27+W27+X27+Y27+Z27+AA27+AB27+AC27+AD27+AE27+AF27+AG27+AH27+AI27+AJ27+AK27+AL27+AM27+AN27+AO27+AP27+AQ27+AR27+AS27+AT27+AU27+AV27+AW27+AX27+AY27+AZ27+BA27+BB27+BC27+BD27+BE27+BF27 -> 0
B28: бошқалар | C28: =D28+E28+F28+G28+H28+I28+J28+K28+L28+M28+N28+O28+P28+Q28+R28+S28+T28+U28+V28+W28+X28+Y28+Z28+AA28+AB28+AC28+AD28+AE28+AF28+AG28+AH28+AI28+AJ28+AK28+AL28+AM28+AN28+AO28+AP28+AQ28+AR28+AS28+AT28+AU28+AV28+AW28+AX28+AY28+AZ28+BA28+BB28+BC28+BD28+BE28+BF28 -> 0
A29: 6. | B29: Ўрнатилган янги трансформаторлар | C29: =D29+E29+F29+G29+H29+I29+J29+K29+L29+M29+N29+O29+P29+Q29+R29+S29+T29+U29+V29+W29+X29+Y29+Z29+AA29+AB29+AC29+AD29+AE29+AF29+AG29+AH29+AI29+AJ29+AK29+AL29+AM29+AN29+AO29+AP29+AQ29+AR29+AS29+AT29+AU29+AV29+AW29+AX29+AY29+AZ29+BA29+BB29+BC29+BD29+BE29+BF29 -> 0
A30: 7. | B30: Алмаштирилган ва тортилган электр кабеллари (метр) | C30: =D30+E30+F30+G30+H30+I30+J30+K30+L30+M30+N30+O30+P30+Q30+R30+S30+T30+U30+V30+W30+X30+Y30+Z30+AA30+AB30+AC30+AD30+AE30+AF30+AG30+AH30+AI30+AJ30+AK30+AL30+AM30+AN30+AO30+AP30+AQ30+AR30+AS30+AT30+AU30+AV30+AW30+AX30+AY30+AZ30+BA30+BB30+BC30+BD30+BE30+BF30 -> 600 | W30: 600
A31: 8. | B31: Олиб чиқилган чиқиндилар (тонна) | C31: =D31+E31+F31+G31+H31+I31+J31+K31+L31+M31+N31+O31+P31+Q31+R31+S31+T31+U31+V31+W31+X31+Y31+Z31+AA31+AB31+AC31+AD31+AE31+AF31+AG31+AH31+AI31+AJ31+AK31+AL31+AM31+AN31+AO31+AP31+AQ31+AR31+AS31+AT31+AU31+AV31+AW31+AX31+AY31+AZ31+BA31+BB31+BC31+BD31+BE31+BF31 -> 274 | D31: 4.2 | E31: 3.2 | F31: 2.2 | G31: 4.5 | H31: 4.6 | I31: 4.9 | J31: 5.2 | K31: 5.3 | L31: 5.5 | M31: 5.4 | N31: 4.5 | O31: 5 | P31: 4.5 | Q31: 4.8 | R31: 4.1 | S31: 5.4 | T31: 5.4 | U31: 2.8 | V31: 5.3 | W31: 6.2 | X31: 5.9 | Y31: 5.4 | Z31: 7.2 | AA31: 5.5 | AB31: 4.9 | AC31: 6.2 | AD31: 5.4 | AE31: 5.9 | AF31: 6.2 | AG31: 6.3 | AH31: 4.5 | AI31: 4.6 | AJ31: 3.3 | AK31: 5.2 | AL31: 4.6 | AM31: 5.2 | AN31: 4.6 | AO31: 4.3 | AP31: 5.2 | AQ31: 3.2 | AR31: 4.5 | AS31: 6.2 | AT31: 5.2 | AU31: 4.9 | AV31: 6.5 | AW31: 3.9 | AX31: 4.3 | AY31: 4.9 | AZ31: 6.5 | BA31: 4.9 | BB31: 4.9 | BC31: 5.5 | BD31: 3.2 | BE31: 4.5 | BF31: 7.5
A32: 9. | B32: Ўрнатилган янги ёритиш чироқлари | C32: =D32+E32+F32+G32+H32+I32+J32+K32+L32+M32+N32+O32+P32+Q32+R32+S32+T32+U32+V32+W32+X32+Y32+Z32+AA32+AB32+AC32+AD32+AE32+AF32+AG32+AH32+AI32+AJ32+AK32+AL32+AM32+AN32+AO32+AP32+AQ32+AR32+AS32+AT32+AU32+AV32+AW32+AX32+AY32+AZ32+BA32+BB32+BC32+BD32+BE32+BF32 -> 0
A33: 10. | B33: Таъмирланган ёритиш чироқлари | C33: =D33+E33+F33+G33+H33+I33+J33+K33+L33+M33+N33+O33+P33+Q33+R33+S33+T33+U33+V33+W33+X33+Y33+Z33+AA33+AB33+AC33+AD33+AE33+AF33+AG33+AH33+AI33+AJ33+AK33+AL33+AM33+AN33+AO33+AP33+AQ33+AR33+AS33+AT33+AU33+AV33+AW33+AX33+AY33+AZ33+BA33+BB33+BC33+BD33+BE33+BF33 -> 0
AN35: масъул ходим лавозими

Sheet 01.24
A1: № | B1: Кўрсаткич | C1: Жами | D1: Ал-Хоразмий | E1: Бахористон | F1: Бектўпи | G1: Гулистон | H1: Катта Хирмонтепа | I1: Тирсакобод | J1: Хайрабод | K1: Хирмон тепа | L1: Хонтўпи | M1: Шараф | N1: Шарқ | O1: Шарқ тонги | P1: Шухрат | Q1: 1-Чарх Камолон | R1: 2-Чарх Камолон | S1: 3-Чарх Камолон | T1: Бешёғоч | U1: Катта Козиробод | V1: Катта Олмазор | W1: Катта Чилонзор-1 | X1: Катта Чилонзор-2 | Y1: Катта Чилонзор-3 | Z1: Қозиробод | AA1: Новза | AB1: Чилонзор | AC1: 1-Қатортол | AD1: Бешчинор | AE1: Боғзор | AF1: Диёр | AG1: Дилобод | AH1: Катта Навбаҳор | AI1: Кўркам | AJ1: Кўтарма | AK1: Қатортол | AL1: Лутфий | AM1: Навбахор | AN1: Нафосат | AO1: Оқ-тепа | AP1: Халқлар Дўстлиги | AQ1: Чўпон-ота | AR1: 2-Қатортол | AS1: Ботирма | AT1: Бўрижар | AU1: Гавхар | AV1: Дўмбиробод | AW1: Зарқўрғон | AX1: Катта Дўмбиробод | AY1: Кичик Хирмонтепа | AZ1: Мевазор | BA1: Мехржон | BB1: Наққошлик | BC1: Фидокор | BD1: Яккабоғ | BE1: Яккатут | BF1: Бешқўрғон
A2: 1. | B2: Коммунал соҳада келиб тушган жами мурожаатлар | C2: =D2+E2+F2+G2+H2+I2+J2+K2+L2+M2+N2+O2+P2+Q2+R2+S2+T2+U2+V2+W2+X2+Y2+Z2+AA2+AB2+AC2+AD2+AE2+AF2+AG2+AH2+AI2+AJ2+AK2+AL2+AM2+AN2+AO2+AP2+AQ2+AR2+AS2+AT2+AU2+AV2+AW2+AX2+AY2+AZ2+BA2+BB2+BC2+BD2+BE2+BF2 -> 37 | D2: =+SUM(D3:D11) -> 0 | E2: =+SUM(E3:E11) -> 2 | F2: =+SUM(F3:F11) -> 1 | G2: =+SUM(G3:G11) -> 3 | H2: =+SUM(H3:H11) -> 1 | I2: =+SUM(I3:I11) -> 0 | J2: =+SUM(J3:J11) -> 1 | K2: =+SUM(K3:K11) -> 1 | ... BF2: =+SUM(BF3:BF11) -> 2
A3: шундан | B3: БСК йўналишида | C3: =D3+E3+F3+G3+H3+I3+J3+K3+L3+M3+N3+O3+P3+Q3+R3+S3+T3+U3+V3+W3+X3+Y3+Z3+AA3+AB3+AC3+AD3+AE3+AF3+AG3+AH3+AI3+AJ3+AK3+AL3+AM3+AN3+AO3+AP3+AQ3+AR3+AS3+AT3+AU3+AV3+AW3+AX3+AY3+AZ3+BA3+BB3+BC3+BD3+BE3+BF3 -> 16 | E3: 1 | G3: 3 | H3: 1 | P3: 1 | Y3: 1 | Z3: 1 | AF3: 1 | AJ3: 1 | AW3: 1 | AY3: 2 | BB3: 1 | BC3: 1 | BE3: 1
B4: электр таъминоти | C4: =D4+E4+F4+G4+H4+I4+J4+K4+L4+M4+N4+O4+P4+Q4+R4+S4+T4+U4+V4+W4+X4+Y4+Z4+AA4+AB4+AC4+AD4+AE4+AF4+AG4+AH4+AI4+AJ4+AK4+AL4+AM4+AN4+AO4+AP4+AQ4+AR4+AS4+AT4+AU4+AV4+AW4+AX4+AY4+AZ4+BA4+BB4+BC4+BD4+BE4+BF4 -> 6 | K4: 1 | N4: 1 | R4: 1 | W4: 1 | AV4: 2
B5: газ таъминоти | C5: =D5+E5+F5+G5+H5+I5+J5+K5+L5+M5+N5+O5+P5+Q5+R5+S5+T5+U5+V5+W5+X5+Y5+Z5+AA5+AB5+AC5+AD5+AE5+AF5+AG5+AH5+AI5+AJ5+AK5+AL5+AM5+AN5+AO5+AP5+AQ5+AR5+AS5+AT5+AU5+AV5+AW5+AX5+AY5+AZ5+BA5+BB5+BC5+BD5+BE5+BF5 -> 3 | J5: 1 | AL5: 1 | BF5: 1 | BG5: 1
B6: совуқ сув таъминоти | C6: =D6+E6+F6+G6+H6+I6+J6+K6+L6+M6+N6+O6+P6+Q6+R6+S6+T6+U6+V6+W6+X6+Y6+Z6+AA6+AB6+AC6+AD6+AE6+AF6+AG6+AH6+AI6+AJ6+AK6+AL6+AM6+AN6+AO6+AP6+AQ6+AR6+AS6+AT6+AU6+AV6+AW6+AX6+AY6+AZ6+BA6+BB6+BC6+BD6+BE6+BF6 -> 3 | P6: 1 | AK6: 1 | BF6: 1
B7: иссиқ сув ва иссиқлик таъминоти | C7: =D7+E7+F7+G7+H7+I7+J7+K7+L7+M7+N7+O7+P7+Q7+R7+S7+T7+U7+V7+W7+X7+Y7+Z7+AA7+AB7+AC7+AD7+AE7+AF7+AG7+AH7+AI7+AJ7+AK7+AL7+AM7+AN7+AO7+AP7+AQ7+AR7+AS7+AT7+AU7+AV7+AW7+AX7+AY7+AZ7+BA7+BB7+BC7+BD7+BE7+BF7 -> 9 | E7: 1 | F7: 1 | R7: 1 | W7: 1 | X7: 1 | Y7: 1 | AH7: 1 | AM7: 1 | AQ7: 1
B8: ёритиш чироқлари (нур) | C8: =D8+E8+F8+G8+H8+I8+J8+K8+L8+M8+N8+O8+P8+Q8+R8+S8+T8+U8+V8+W8+X8+Y8+Z8+AA8+AB8+AC8+AD8+AE8+AF8+AG8+AH8+AI8+AJ8+AK8+AL8+AM8+AN8+AO8+AP8+AQ8+AR8+AS8+AT8+AU8+AV8+AW8+AX8+AY8+AZ8+BA8+BB8+BC8+BD8+BE8+BF8 -> 0
B9: чиқиндиларни олиб чиқиш | C9: =D9+E9+F9+G9+H9+I9+J9+K9+L9+M9+N9+O9+P9+Q9+R9+S9+T9+U9+V9+W9+X9+Y9+Z9+AA9+AB9+AC9+AD9+AE9+AF9+AG9+AH9+AI9+AJ9+AK9+AL9+AM9+AN9+AO9+AP9+AQ9+AR9+AS9+AT9+AU9+AV9+AW9+AX9+AY9+AZ9+BA9+BB9+BC9+BD9+BE9+BF9 -> 0
B10: ободонлаштириш бўйича | C10: =D10+E10+F10+G10+H10+I10+J10+K10+L10+M10+N10+O10+P10+Q10+R10+S10+T10+U10+V10+W10+X10+Y10+Z10+AA10+AB10+AC10+AD10+AE10+AF10+AG10+AH10+AI10+AJ10+AK10+AL10+AM10+AN10+AO10+AP10+AQ10+AR10+AS10+AT10+AU10+AV10+AW10+AX10+AY10+AZ10+BA10+BB10+BC10+BD10+BE10+BF10 -> 0
B11: бошқалар | C11: =D11+E11+F11+G11+H11+I11+J11+K11+L11+M11+N11+O11+P11+Q11+R11+S11+T11+U11+V11+W11+X11+Y11+Z11+AA11+AB11+AC11+AD11+AE11+AF11+AG11+AH11+AI11+AJ11+AK11+AL11+AM11+AN11+AO11+AP11+AQ11+AR11+AS11+AT11+AU11+AV11+AW11+AX11+AY11+AZ11+BA11+BB11+BC11+BD11+BE11+BF11 -> 0
A12: 2. | B12: Муаммоси ҳал этилган жами мурожаатлар | C12: =D12+E12+F12+G12+H12+I12+J12+K12+L12+M12+N12+O12+P12+Q12+R12+S12+T12+U12+V12+W12+X12+Y12+Z12+AA12+AB12+AC12+AD12+AE12+AF12+AG12+AH12+AI12+AJ12+AK12+AL12+AM12+AN12+AO12+AP12+AQ12+AR12+AS12+AT12+AU12+AV12+AW12+AX12+AY12+AZ12+BA12+BB12+BC12+BD12+BE12+BF12 -> 37 | D12: =+SUM(D13:D21) -> 0 | E12: =+SUM(E13:E21) -> 2 | F12: =+SUM(F13:F21) -> 1 | G12: =+SUM(G13:G21) -> 3 | H12: =+SUM(H13:H21) -> 1 | I12: =+SUM(I13:I21) -> 0 | J12: =+SUM(J13:J21) -> 1 | K12: =+SUM(K13:K21) -> 1 | ... BF12: =+SUM(BF13:BF21) -> 2
A13: шундан | B13: БСК йўналишида | C13: =D13+E13+F13+G13+H13+I13+J13+K13+L13+M13+N13+O13+P13+Q13+R13+S13+T13+U13+V13+W13+X13+Y13+Z13+AA13+AB13+AC13+AD13+AE13+AF13+AG13+AH13+AI13+AJ13+AK13+AL13+AM13+AN13+AO13+AP13+AQ13+AR13+AS13+AT13+AU13+AV13+AW13+AX13+AY13+AZ13+BA13+BB13+BC13+BD13+BE13+BF13 -> 16 | E13: 1 | G13: 3 | H13: 1 | P13: 1 | Y13: 1 | Z13: 1 | AF13: 1 | AJ13: 1 | AW13: 1 | AY13: 2 | BB13: 1 | BC13: 1 | BE13: 1
B14: электр таъминоти | C14: =D14+E14+F14+G14+H14+I14+J14+K14+L14+M14+N14+O14+P14+Q14+R14+S14+T14+U14+V14+W14+X14+Y14+Z14+AA14+AB14+AC14+AD14+AE14+AF14+AG14+AH14+AI14+AJ14+AK14+AL14+AM14+AN14+AO14+AP14+AQ14+AR14+AS14+AT14+AU14+AV14+AW14+AX14+AY14+AZ14+BA14+BB14+BC14+BD14+BE14+BF14 -> 6 | K14: 1 | N14: 1 | R14: 1 | W14: 1 | AV14: 2
B15: газ таъминоти | C15: =D15+E15+F15+G15+H15+I15+J15+K15+L15+M15+N15+O15+P15+Q15+R15+S15+T15+U15+V15+W15+X15+Y15+Z15+AA15+AB15+AC15+AD15+AE15+AF15+AG15+AH15+AI15+AJ15+AK15+AL15+AM15+AN15+AO15+AP15+AQ15+AR15+AS15+AT15+AU15+AV15+AW15+AX15+AY15+AZ15+BA15+BB15+BC15+BD15+BE15+BF15 -> 3 | J15: 1 | AL15: 1 | BF15: 1 | BG15: 1
B16: совуқ сув таъминоти | C16: =D16+E16+F16+G16+H16+I16+J16+K16+L16+M16+N16+O16+P16+Q16+R16+S16+T16+U16+V16+W16+X16+Y16+Z16+AA16+AB16+AC16+AD16+AE16+AF16+AG16+AH16+AI16+AJ16+AK16+AL16+AM16+AN16+AO16+AP16+AQ16+AR16+AS16+AT16+AU16+AV16+AW16+AX16+AY16+AZ16+BA16+BB16+BC16+BD16+BE16+BF16 -> 3 | P16: 1 | AK16: 1 | BF16: 1
B17: иссиқ сув ва иссиқлик таъминоти | C17: =D17+E17+F17+G17+H17+I17+J17+K17+L17+M17+N17+O17+P17+Q17+R17+S17+T17+U17+V17+W17+X17+Y17+Z17+AA17+AB17+AC17+AD17+AE17+AF17+AG17+AH17+AI17+AJ17+AK17+AL17+AM17+AN17+AO17+AP17+AQ17+AR17+AS17+AT17+AU17+AV17+AW17+AX17+AY17+AZ17+BA17+BB17+BC17+BD17+BE17+BF17 -> 9 | E17: 1 | F17: 1 | R17: 1 | W17: 1 | X17: 1 | Y17: 1 | AH17: 1 | AM17: 1 | AQ17: 1
B18: ёритиш чироқлари (нур) | C18: =D18+E18+F18+G18+H18+I18+J18+K18+L18+M18+N18+O18+P18+Q18+R18+S18+T18+U18+V18+W18+X18+Y18+Z18+AA18+AB18+AC18+AD18+AE18+AF18+AG18+AH18+AI18+AJ18+AK18+AL18+AM18+AN18+AO18+AP18+AQ18+AR18+AS18+AT18+AU18+AV18+AW18+AX18+AY18+AZ18+BA18+BB18+BC18+BD18+BE18+BF18 -> 0
B19: чиқиндиларни олиб чиқиш | C19: =D19+E19+F19+G19+H19+I19+J19+K19+L19+M19+N19+O19+P19+Q19+R19+S19+T19+U19+V19+W19+X19+Y19+Z19+AA19+AB19+AC19+AD19+AE19+AF19+AG19+AH19+AI19+AJ19+AK19+AL19+AM19+AN19+AO19+AP19+AQ19+AR19+AS19+AT19+AU19+AV19+AW19+AX19+AY19+AZ19+BA19+BB19+BC19+BD19+BE19+BF19 -> 0
B20: ободонлаштириш бўйича | C20: =D20+E20+F20+G20+H20+I20+J20+K20+L20+M20+N20+O20+P20+Q20+R20+S20+T20+U20+V20+W20+X20+Y20+Z20+AA20+AB20+AC20+AD20+AE20+AF20+AG20+AH20+AI20+AJ20+AK20+AL20+AM20+AN20+AO20+AP20+AQ20+AR20+AS20+AT20+AU20+AV20+AW20+AX20+AY20+AZ20+BA20+BB20+BC20+BD20+BE20+BF20 -> 0
B21: бошқалар | C21: =D21+E21+F21+G21+H21+I21+J21+K21+L21+M21+N21+O21+P21+Q21+R21+S21+T21+U21+V21+W21+X21+Y21+Z21+AA21+AB21+AC21+AD21+AE21+AF21+AG21+AH21+AI21+AJ21+AK21+AL21+AM21+AN21+AO21+AP21+AQ21+AR21+AS21+AT21+AU21+AV21+AW21+AX21+AY21+AZ21+BA21+BB21+BC21+BD21+BE21+BF21 -> 0
A22: 3. | B22: Совуқ сув қувури таъмирлаш (п/м) | C22: =D22+E22+F22+G22+H22+I22+J22+K22+L22+M22+N22+O22+P22+Q22+R22+S22+T22+U22+V22+W22+X22+Y22+Z22+AA22+AB22+AC22+AD22+AE22+AF22+AG22+AH22+AI22+AJ22+AK22+AL22+AM22+AN22+AO22+AP22+AQ22+AR22+AS22+AT22+AU22+AV22+AW22+AX22+AY22+AZ22+BA22+BB22+BC22+BD22+BE22+BF22 -> 0
A23: 4. | B23: Иссиқ сув қувури таъмирлаш (п/м) | C23: =D23+E23+F23+G23+H23+I23+J23+K23+L23+M23+N23+O23+P23+Q23+R23+S23+T23+U23+V23+W23+X23+Y23+Z23+AA23+AB23+AC23+AD23+AE23+AF23+AG23+AH23+AI23+AJ23+AK23+AL23+AM23+AN23+AO23+AP23+AQ23+AR23+AS23+AT23+AU23+AV23+AW23+AX23+AY23+AZ23+BA23+BB23+BC23+BD23+BE23+BF23 -> 0
A24: 5. | B24: БСК йўналишида кўп қаватли уйларда олиб борилган таъмирлаш ишлари | C24: =D24+E24+F24+G24+H24+I24+J24+K24+L24+M24+N24+O24+P24+Q24+R24+S24+T24+U24+V24+W24+X24+Y24+Z24+AA24+AB24+AC24+AD24+AE24+AF24+AG24+AH24+AI24+AJ24+AK24+AL24+AM24+AN24+AO24+AP24+AQ24+AR24+AS24+AT24+AU24+AV24+AW24+AX24+AY24+AZ24+BA24+BB24+BC24+BD24+BE24+BF24 -> 0
A25: шундан | B25: том таъмирлаш (м2) | C25: =D25+E25+F25+G25+H25+I25+J25+K25+L25+M25+N25+O25+P25+Q25+R25+S25+T25+U25+V25+W25+X25+Y25+Z25+AA25+AB25+AC25+AD25+AE25+AF25+AG25+AH25+AI25+AJ25+AK25+AL25+AM25+AN25+AO25+AP25+AQ25+AR25+AS25+AT25+AU25+AV25+AW25+AX25+AY25+AZ25+BA25+BB25+BC25+BD25+BE25+BF25 -> 0
B26: иссиқлик таъминоти | C26: =D26+E26+F26+G26+H26+I26+J26+K26+L26+M26+N26+O26+P26+Q26+R26+S26+T26+U26+V26+W26+X26+Y26+Z26+AA26+AB26+AC26+AD26+AE26+AF26+AG26+AH26+AI26+AJ26+AK26+AL26+AM26+AN26+AO26+AP26+AQ26+AR26+AS26+AT26+AU26+AV26+AW26+AX26+AY26+AZ26+BA26+BB26+BC26+BD26+BE26+BF26 -> 0
B27: лифт таъмири | C27: =D27+E27+F27+G27+H27+I27+J27+K27+L27+M27+N27+O27+P27+Q27+R27+S27+T27+U27+V27+W27+X27+Y27+Z27+AA27+AB27+AC27+AD27+AE27+AF27+AG27+AH27+AI27+AJ27+AK27+AL27+AM27+AN27+AO27+AP27+AQ27+AR27+AS27+AT27+AU27+AV27+AW27+AX27+AY27+AZ27+BA27+BB27+BC27+BD27+BE27+BF27 -> 0
B28: бошқалар | C28: =D28+E28+F28+G28+H28+I28+J28+K28+L28+M28+N28+O28+P28+Q28+R28+S28+T28+U28+V28+W28+X28+Y28+Z28+AA28+AB28+AC28+AD28+AE28+AF28+AG28+AH28+AI28+AJ28+AK28+AL28+AM28+AN28+AO28+AP28+AQ28+AR28+AS28+AT28+AU28+AV28+AW28+AX28+AY28+AZ28+BA28+BB28+BC28+BD28+BE28+BF28 -> 2 | W28: 2
A29: 6. | B29: Ўрнатилган янги трансформаторлар | C29: =D29+E29+F29+G29+H29+I29+J29+K29+L29+M29+N29+O29+P29+Q29+R29+S29+T29+U29+V29+W29+X29+Y29+Z29+AA29+AB29+AC29+AD29+AE29+AF29+AG29+AH29+AI29+AJ29+AK29+AL29+AM29+AN29+AO29+AP29+AQ29+AR29+AS29+AT29+AU29+AV29+AW29+AX29+AY29+AZ29+BA29+BB29+BC29+BD29+BE29+BF29 -> 0
A30: 7. | B30: Алмаштирилган ва тортилган электр кабеллари (метр) | C30: =D30+E30+F30+G30+H30+I30+J30+K30+L30+M30+N30+O30+P30+Q30+R30+S30+T30+U30+V30+W30+X30+Y30+Z30+AA30+AB30+AC30+AD30+AE30+AF30+AG30+AH30+AI30+AJ30+AK30+AL30+AM30+AN30+AO30+AP30+AQ30+AR30+AS30+AT30+AU30+AV30+AW30+AX30+AY30+AZ30+BA30+BB30+BC30+BD30+BE30+BF30 -> 0
A31: 8. | B31: Олиб чиқилган чиқиндилар (тонна) | C31: =D31+E31+F31+G31+H31+I31+J31+K31+L31+M31+N31+O31+P31+Q31+R31+S31+T31+U31+V31+W31+X31+Y31+Z31+AA31+AB31+AC31+AD31+AE31+AF31+AG31+AH31+AI31+AJ31+AK31+AL31+AM31+AN31+AO31+AP31+AQ31+AR31+AS31+AT31+AU31+AV31+AW31+AX31+AY31+AZ31+BA31+BB31+BC31+BD31+BE31+BF31 -> 261 | D31: 3.2 | E31: 3.4 | F31: 2.8 | G31: 3 | H31: 4.2 | I31: 2.1 | J31: 2.5 | K31: 4.6 | L31: 4.8 | M31: 4 | N31: 3.7 | O31: 3.8 | P31: 5 | Q31: 4.5 | R31: 5 | S31: 3.9 | T31: 3.9 | U31: 5 | V31: 4.3 | W31: 5 | X31: 5 | Y31: 5 | Z31: 5 | AA31: 5.1 | AB31: 5.1 | AC31: 5.3 | AD31: 5.7 | AE31: 5.6 | AF31: 5.7 | AG31: 5.7 | AH31: 5.6 | AI31: 5 | AJ31: 6 | AK31: 6 | AL31: 5.6 | AM31: 6.6 | AN31: 6 | AO31: 6 | AP31: 6 | AQ31: 4 | AR31: 4.6 | AS31: 5.6 | AT31: 5.8 | AU31: 5 | AV31: 5 | AW31: 5 | AX31: 5.1 | AY31: 4 | AZ31: 5.2 | BA31: 5 | BB31: 4 | BC31: 5 | BD31: 6 | BE31: 4 | BF31: 3
A32: 9. | B32: Ўрнатилган янги ёритиш чироқлари | C32: =D32+E32+F32+G32+H32+I32+J32+K32+L32+M32+N32+O32+P32+Q32+R32+S32+T32+U32+V32+W32+X32+Y32+Z32+AA32+AB32+AC32+AD32+AE32+AF32+AG32+AH32+AI32+AJ32+AK32+AL32+AM32+AN32+AO32+AP32+AQ32+AR32+AS32+AT32+AU32+AV32+AW32+AX32+AY32+AZ32+BA32+BB32+BC32+BD32+BE32+BF32 -> 0
A33: 10. | B33: Таъмирланган ёритиш чироқлари | C33: =D33+E33+F33+G33+H33+I33+J33+K33+L33+M33+N33+O33+P33+Q33+R33+S33+T33+U33+V33+W33+X33+Y33+Z33+AA33+AB33+AC33+AD33+AE33+AF33+AG33+AH33+AI33+AJ33+AK33+AL33+AM33+AN33+AO33+AP33+AQ33+AR33+AS33+AT33+AU33+AV33+AW33+AX33+AY33+AZ33+BA33+BB33+BC33+BD33+BE33+BF33 -> 0
AN35: масъул ходим лавозими

Sheet 01.25
A1: № | B1: Кўрсаткич | C1: Жами | D1: Ал-Хоразмий | E1: Бахористон | F1: Бектўпи | G1: Гулистон | H1: Катта Хирмонтепа | I1: Тирсакобод | J1: Хайрабод | K1: Хирмон тепа | L1: Хонтўпи | M1: Шараф | N1: Шарқ | O1: Шарқ тонги | P1: Шухрат | Q1: 1-Чарх Камолон | R1: 2-Чарх Камолон | S1: 3-Чарх Камолон | T1: Бешёғоч | U1: Катта Козиробод | V1: Катта Олмазор | W1: Катта Чилонзор-1 | X1: Катта Чилонзор-2 | Y1: Катта Чилонзор-3 | Z1: Қозиробод | AA1: Новза | AB1: Чилонзор | AC1: 1-Қатортол | AD1: Бешчинор | AE1: Боғзор | AF1: Диёр | AG1: Дилобод | AH1: Катта Навбаҳор | AI1: Кўркам | AJ1: Кўтарма | AK1: Қатортол | AL1: Лутфий | AM1: Навбахор | AN1: Нафосат | AO1: Оқ-тепа | AP1: Халқлар Дўстлиги | AQ1: Чўпон-ота | AR1: 2-Қатортол | AS1: Ботирма | AT1: Бўрижар | AU1: Гавхар | AV1: Дўмбиробод | AW1: Зарқўрғон | AX1: Катта Дўмбиробод | AY1: Кичик Хирмонтепа | AZ1: Мевазор | BA1: Мехржон | BB1: Наққошлик | BC1: Фидокор | BD1: Яккабоғ | BE1: Яккатут | BF1: Бешқўрғон
