Workbook

Sheet 01.20
A1: № | B1: Кўрсаткич | C1: Жами | D1: Ал-Хоразмий | E1: Бахористон | F1: Бектўпи | G1: Гулистон | H1: Катта Хирмонтепа | I1: Тирсакобод | J1: Хайрабод | K1: Хирмон тепа | L1: Хонтўпи | M1: Шараф | N1: Шарқ | O1: Шарқ тонги | P1: Шухрат | Q1: 1-Чарх Камолон | R1: 2-Чарх Камолон | S1: 3-Чарх Камолон | T1: Бешёғоч | U1: Катта Козиробод | V1: Катта Олмазор | W1: Катта Чилонзор-1 | X1: Катта Чилонзор-2 | Y1: Катта Чилонзор-3 | Z1: Қозиробод | AA1: Новза | AB1: Чилонзор | AC1: 1-Қатортол | AD1: Бешчинор | AE1: Боғзор | AF1: Диёр | AG1: Дилобод | AH1: Катта Навбаҳор | AI1: Кўркам | AJ1: Кўтарма | AK1: Қатортол | AL1: Лутфий | AM1: Навбахор | AN1: Нафосат | AO1: Оқ-тепа | AP1: Халқлар Дўстлиги | AQ1: Чўпон-ота | AR1: 2-Қатортол | AS1: Ботирма | AT1: Бўрижар | AU1: Гавхар | AV1: Дўмбиробод | AW1: Зарқўрғон | AX1: Катта Дўмбиробод | AY1: Кичик Хирмонтепа | AZ1: Мевазор | BA1: Мехржон | BB1: Наққошлик | BC1: Фидокор | BD1: Яккабоғ | BE1: Яккатут | BF1: Бешқўрғон | BG1: бошқа ҳудуд
A2: 1. | B2: Фош этилган жиноятлар | C2: =+BG2+D2+E2+F2+G2+H2+I2+J2+K2+L2+M2+N2+O2+P2+Q2+R2+S2+T2+U2+V2+W2+X2+Y2+Z2+AA2+AB2+AC2+AD2+AE2+AF2+AG2+AH2+AI2+AJ2+AK2+AL2+AM2+AN2+AO2+AP2+AQ2+AR2+AS2+AT2+AU2+AV2+AW2+AX2+AY2+AZ2+BA2+BB2+BC2+BD2+BE2+BF2 -> 2 | AL2: 1 | AW2: 1
A3: 2. | B3: Ушланган қидирувдаги шахслар | C3: =+BG3+D3+E3+F3+G3+H3+I3+J3+K3+L3+M3+N3+O3+P3+Q3+R3+S3+T3+U3+V3+W3+X3+Y3+Z3+AA3+AB3+AC3+AD3+AE3+AF3+AG3+AH3+AI3+AJ3+AK3+AL3+AM3+AN3+AO3+AP3+AQ3+AR3+AS3+AT3+AU3+AV3+AW3+AX3+AY3+AZ3+BA3+BB3+BC3+BD3+BE3+BF3 -> 1 | BF3: 1
A4: 3. | B4: Аниқланган бедарак йўқолган шахслар | C4: =+BG4+D4+E4+F4+G4+H4+I4+J4+K4+L4+M4+N4+O4+P4+Q4+R4+S4+T4+U4+V4+W4+X4+Y4+Z4+AA4+AB4+AC4+AD4+AE4+AF4+AG4+AH4+AI4+AJ4+AK4+AL4+AM4+AN4+AO4+AP4+AQ4+AR4+AS4+AT4+AU4+AV4+AW4+AX4+AY4+AZ4+BA4+BB4+BC4+BD4+BE4+BF4 -> 1 | BF4: 1
A5: 4. | B5: Аниқланган жиноятлар | C5: =+BG5+D5+E5+F5+G5+H5+I5+J5+K5+L5+M5+N5+O5+P5+Q5+R5+S5+T5+U5+V5+W5+X5+Y5+Z5+AA5+AB5+AC5+AD5+AE5+AF5+AG5+AH5+AI5+AJ5+AK5+AL5+AM5+AN5+AO5+AP5+AQ5+AR5+AS5+AT5+AU5+AV5+AW5+AX5+AY5+AZ5+BA5+BB5+BC5+BD5+BE5+BF5 -> 1 | U5: 1
A6: 4. | B6: Гиёҳвандлик моддалари билан боғлиқ аниқланган жиноий ҳолатлар | C6: =+BG6+D6+E6+F6+G6+H6+I6+J6+K6+L6+M6+N6+O6+P6+Q6+R6+S6+T6+U6+V6+W6+X6+Y6+Z6+AA6+AB6+AC6+AD6+AE6+AF6+AG6+AH6+AI6+AJ6+AK6+AL6+AM6+AN6+AO6+AP6+AQ6+AR6+AS6+AT6+AU6+AV6+AW6+AX6+AY6+AZ6+BA6+BB6+BC6+BD6+BE6+BF6 -> 1 | U6: 1
A7: 4.1. | B7: Олинган гиёҳвандлик моддари миқдори (грамм ҳисобида) | C7: =+BG7+D7+E7+F7+G7+H7+I7+J7+K7+L7+M7+N7+O7+P7+Q7+R7+S7+T7+U7+V7+W7+X7+Y7+Z7+AA7+AB7+AC7+AD7+AE7+AF7+AG7+AH7+AI7+AJ7+AK7+AL7+AM7+AN7+AO7+AP7+AQ7+AR7+AS7+AT7+AU7+AV7+AW7+AX7+AY7+AZ7+BA7+BB7+BC7+BD7+BE7+BF7 -> 50 | U7: 50
A8: 4.2. | B8: Гиёҳвандлик билан боғлиқ ҳолатлар юзасидан қўзғатилган жиноят ишлари | C8: =+BG8+D8+E8+F8+G8+H8+I8+J8+K8+L8+M8+N8+O8+P8+Q8+R8+S8+T8+U8+V8+W8+X8+Y8+Z8+AA8+AB8+AC8+AD8+AE8+AF8+AG8+AH8+AI8+AJ8+AK8+AL8+AM8+AN8+AO8+AP8+AQ8+AR8+AS8+AT8+AU8+AV8+AW8+AX8+AY8+AZ8+BA8+BB8+BC8+BD8+BE8+BF8 -> 0
A9: 5. | B9: Аниқланган кучли таъсир қилувчи психотроп дори воситалари билан боғлиқ ҳолатлар | C9: =+BG9+D9+E9+F9+G9+H9+I9+J9+K9+L9+M9+N9+O9+P9+Q9+R9+S9+T9+U9+V9+W9+X9+Y9+Z9+AA9+AB9+AC9+AD9+AE9+AF9+AG9+AH9+AI9+AJ9+AK9+AL9+AM9+AN9+AO9+AP9+AQ9+AR9+AS9+AT9+AU9+AV9+AW9+AX9+AY9+AZ9+BA9+BB9+BC9+BD9+BE9+BF9 -> 0
A10: 5.1. | B10: Олинган кучли таъсир қилувчи психотроп воситалари сони (дона ҳисобида) | C10: =+BG10+D10+E10+F10+G10+H10+I10+J10+K10+L10+M10+N10+O10+P10+Q10+R10+S10+T10+U10+V10+W10+X10+Y10+Z10+AA10+AB10+AC10+AD10+AE10+AF10+AG10+AH10+AI10+AJ10+AK10+AL10+AM10+AN10+AO10+AP10+AQ10+AR10+AS10+AT10+AU10+AV10+AW10+AX10+AY10+AZ10+BA10+BB10+BC10+BD10+BE10+BF10 -> 0
A11: 5.2. | B11: Психотроп воситалар билан боғлиқ ҳолатлар юзасидан қўзғатилган жиноят ишлари | C11: =+BG11+D11+E11+F11+G11+H11+I11+J11+K11+L11+M11+N11+O11+P11+Q11+R11+S11+T11+U11+V11+W11+X11+Y11+Z11+AA11+AB11+AC11+AD11+AE11+AF11+AG11+AH11+AI11+AJ11+AK11+AL11+AM11+AN11+AO11+AP11+AQ11+AR11+AS11+AT11+AU11+AV11+AW11+AX11+AY11+AZ11+BA11+BB11+BC11+BD11+BE11+BF11 -> 0
A12: 6. | B12: Аниқланган нарколабораториялар | C12: =+BG12+D12+E12+F12+G12+H12+I12+J12+K12+L12+M12+N12+O12+P12+Q12+R12+S12+T12+U12+V12+W12+X12+Y12+Z12+AA12+AB12+AC12+AD12+AE12+AF12+AG12+AH12+AI12+AJ12+AK12+AL12+AM12+AN12+AO12+AP12+AQ12+AR12+AS12+AT12+AU12+AV12+AW12+AX12+AY12+AZ12+BA12+BB12+BC12+BD12+BE12+BF12 -> 0
A13: 8. | B13: Гиёҳвандлик воситалари ва психотроп моддалар муомаласи олдини олиш юзасидан «маҳалла еттилиги» аъзолари билан ўтказилган қисқа муддатли ўқув семинарлари | C13: =+BG13+D13+E13+F13+G13+H13+I13+J13+K13+L13+M13+N13+O13+P13+Q13+R13+S13+T13+U13+V13+W13+X13+Y13+Z13+AA13+AB13+AC13+AD13+AE13+AF13+AG13+AH13+AI13+AJ13+AK13+AL13+AM13+AN13+AO13+AP13+AQ13+AR13+AS13+AT13+AU13+AV13+AW13+AX13+AY13+AZ13+BA13+BB13+BC13+BD13+BE13+BF13 -> 1 | U13: 1
A14: 9. | B14: Гиёҳвандлик ва психотроп воситаларининг оғир оқибатлари юзасидан таълим муассасалрида ўтказилган профилактик тадбирлар | C14: =+BG14+D14+E14+F14+G14+H14+I14+J14+K14+L14+M14+N14+O14+P14+Q14+R14+S14+T14+U14+V14+W14+X14+Y14+Z14+AA14+AB14+AC14+AD14+AE14+AF14+AG14+AH14+AI14+AJ14+AK14+AL14+AM14+AN14+AO14+AP14+AQ14+AR14+AS14+AT14+AU14+AV14+AW14+AX14+AY14+AZ14+BA14+BB14+BC14+BD14+BE14+BF14 -> 2 | G14: 1 | J14: 1
A15: 10. | B15: ДЭО йўналишида аниқланган маъмурий ҳолатлар | C15: =+BG15+D15+E15+F15+G15+H15+I15+J15+K15+L15+M15+N15+O15+P15+Q15+R15+S15+T15+U15+V15+W15+X15+Y15+Z15+AA15+AB15+AC15+AD15+AE15+AF15+AG15+AH15+AI15+AJ15+AK15+AL15+AM15+AN15+AO15+AP15+AQ15+AR15+AS15+AT15+AU15+AV15+AW15+AX15+AY15+AZ15+BA15+BB15+BC15+BD15+BE15+BF15 -> 0
A16: шундан | B16: ноқонуний диний таълим бериш | C16: =+BG16+D16+E16+F16+G16+H16+I16+J16+K16+L16+M16+N16+O16+P16+Q16+R16+S16+T16+U16+V16+W16+X16+Y16+Z16+AA16+AB16+AC16+AD16+AE16+AF16+AG16+AH16+AI16+AJ16+AK16+AL16+AM16+AN16+AO16+AP16+AQ16+AR16+AS16+AT16+AU16+AV16+AW16+AX16+AY16+AZ16+BA16+BB16+BC16+BD16+BE16+BF16 -> 0
B17: таъқиқланган диний маълумотларни сақлаш ва ташиш | C17: =+BG17+D17+E17+F17+G17+H17+I17+J17+K17+L17+M17+N17+O17+P17+Q17+R17+S17+T17+U17+V17+W17+X17+Y17+Z17+AA17+AB17+AC17+AD17+AE17+AF17+AG17+AH17+AI17+AJ17+AK17+AL17+AM17+AN17+AO17+AP17+AQ17+AR17+AS17+AT17+AU17+AV17+AW17+AX17+AY17+AZ17+BA17+BB17+BC17+BD17+BE17+BF17 -> 0
A18: 11. | B18: ДЭО йўналишида аниқланган жиноий ҳолатлар | C18: =+BG18+D18+E18+F18+G18+H18+I18+J18+K18+L18+M18+N18+O18+P18+Q18+R18+S18+T18+U18+V18+W18+X18+Y18+Z18+AA18+AB18+AC18+AD18+AE18+AF18+AG18+AH18+AI18+AJ18+AK18+AL18+AM18+AN18+AO18+AP18+AQ18+AR18+AS18+AT18+AU18+AV18+AW18+AX18+AY18+AZ18+BA18+BB18+BC18+BD18+BE18+BF18 -> 1 | AR18: 1
A19: шундан | B19: "ҳужралар" | C19: =+BG19+D19+E19+F19+G19+H19+I19+J19+K19+L19+M19+N19+O19+P19+Q19+R19+S19+T19+U19+V19+W19+X19+Y19+Z19+AA19+AB19+AC19+AD19+AE19+AF19+AG19+AH19+AI19+AJ19+AK19+AL19+AM19+AN19+AO19+AP19+AQ19+AR19+AS19+AT19+AU19+AV19+AW19+AX19+AY19+AZ19+BA19+BB19+BC19+BD19+BE19+BF19 -> 1 | AR19: 1
B20: ҳужраларда таълим олган вояга етмаганлар | C20: =+BG20+D20+E20+F20+G20+H20+I20+J20+K20+L20+M20+N20+O20+P20+Q20+R20+S20+T20+U20+V20+W20+X20+Y20+Z20+AA20+AB20+AC20+AD20+AE20+AF20+AG20+AH20+AI20+AJ20+AK20+AL20+AM20+AN20+AO20+AP20+AQ20+AR20+AS20+AT20+AU20+AV20+AW20+AX20+AY20+AZ20+BA20+BB20+BC20+BD20+BE20+BF20 -> 5 | AR20: 5
A21: 12. | B21: Радикаллашувга қарши курашиш борасида олиб борилган тезкор профилактик тадбирлари | C21: =+BG21+D21+E21+F21+G21+H21+I21+J21+K21+L21+M21+N21+O21+P21+Q21+R21+S21+T21+U21+V21+W21+X21+Y21+Z21+AA21+AB21+AC21+AD21+AE21+AF21+AG21+AH21+AI21+AJ21+AK21+AL21+AM21+AN21+AO21+AP21+AQ21+AR21+AS21+AT21+AU21+AV21+AW21+AX21+AY21+AZ21+BA21+BB21+BC21+BD21+BE21+BF21 -> 14 | Y21: 1 | Z21: 2 | AR21: 2 | AT21: 2 | AV21: 2 | AZ21: 4 | BF21: 1
A22: шундан | B22: Қайтарув гуруҳида олиб борилаётган профилактик тушунтириш ишлари | C22: =+BG22+D22+E22+F22+G22+H22+I22+J22+K22+L22+M22+N22+O22+P22+Q22+R22+S22+T22+U22+V22+W22+X22+Y22+Z22+AA22+AB22+AC22+AD22+AE22+AF22+AG22+AH22+AI22+AJ22+AK22+AL22+AM22+AN22+AO22+AP22+AQ22+AR22+AS22+AT22+AU22+AV22+AW22+AX22+AY22+AZ22+BA22+BB22+BC22+BD22+BE22+BF22 -> 12 | Z22: 2 | AR22: 2 | AT22: 2 | AV22: 2 | AZ22: 4
B23: хорижда диструктив ғоя таъсири остига тушган шахслар билан олиб борилаётган филтрь сўров тадбирлари | C23: =+BG23+D23+E23+F23+G23+H23+I23+J23+K23+L23+M23+N23+O23+P23+Q23+R23+S23+T23+U23+V23+W23+X23+Y23+Z23+AA23+AB23+AC23+AD23+AE23+AF23+AG23+AH23+AI23+AJ23+AK23+AL23+AM23+AN23+AO23+AP23+AQ23+AR23+AS23+AT23+AU23+AV23+AW23+AX23+AY23+AZ23+BA23+BB23+BC23+BD23+BE23+BF23 -> 2 | Y23: 1 | Z23: 0 | BF23: 1
A24: 13. | B24: Кибер жиноятлар бўйича келиб тушган мурожаатлар | C24: =+BG24+D24+E24+F24+G24+H24+I24+J24+K24+L24+M24+N24+O24+P24+Q24+R24+S24+T24+U24+V24+W24+X24+Y24+Z24+AA24+AB24+AC24+AD24+AE24+AF24+AG24+AH24+AI24+AJ24+AK24+AL24+AM24+AN24+AO24+AP24+AQ24+AR24+AS24+AT24+AU24+AV24+AW24+AX24+AY24+AZ24+BA24+BB24+BC24+BD24+BE24+BF24 -> 4 | AJ24: 1 | AL24: 1 | AO24: 1 | BF24: 1
A25: 14. | B25: Ҳолат бўйича қўзғатилган жиноят ишлари | C25: =+BG25+D25+E25+F25+G25+H25+I25+J25+K25+L25+M25+N25+O25+P25+Q25+R25+S25+T25+U25+V25+W25+X25+Y25+Z25+AA25+AB25+AC25+AD25+AE25+AF25+AG25+AH25+AI25+AJ25+AK25+AL25+AM25+AN25+AO25+AP25+AQ25+AR25+AS25+AT25+AU25+AV25+AW25+AX25+AY25+AZ25+BA25+BB25+BC25+BD25+BE25+BF25 -> 11 | W25: 1 | AK25: 3 | AL25: 2 | AM25: 1 | BF25: 4
A26: 15. | B26: Фош этилган кибер жиноятлар | C26: =+BG26+D26+E26+F26+G26+H26+I26+J26+K26+L26+M26+N26+O26+P26+Q26+R26+S26+T26+U26+V26+W26+X26+Y26+Z26+AA26+AB26+AC26+AD26+AE26+AF26+AG26+AH26+AI26+AJ26+AK26+AL26+AM26+AN26+AO26+AP26+AQ26+AR26+AS26+AT26+AU26+AV26+AW26+AX26+AY26+AZ26+BA26+BB26+BC26+BD26+BE26+BF26 -> 1 | AL26: 1
A27: 16. | B27: Таълим муассасаларида кибер жиноятларни олдини олиш бўйича амалга оширилган профилактик тарғибот тадбирлари | C27: =+BG27+D27+E27+F27+G27+H27+I27+J27+K27+L27+M27+N27+O27+P27+Q27+R27+S27+T27+U27+V27+W27+X27+Y27+Z27+AA27+AB27+AC27+AD27+AE27+AF27+AG27+AH27+AI27+AJ27+AK27+AL27+AM27+AN27+AO27+AP27+AQ27+AR27+AS27+AT27+AU27+AV27+AW27+AX27+AY27+AZ27+BA27+BB27+BC27+BD27+BE27+BF27 -> 2 | AJ27: 1 | AL27: 1
A28: 17. | B28: Ижтимоий тармоқларда кибер жиноятларни олдини олиш юзасидан амалга оширилган профилактик тадбирлар | C28: =+BG28+D28+E28+F28+G28+H28+I28+J28+K28+L28+M28+N28+O28+P28+Q28+R28+S28+T28+U28+V28+W28+X28+Y28+Z28+AA28+AB28+AC28+AD28+AE28+AF28+AG28+AH28+AI28+AJ28+AK28+AL28+AM28+AN28+AO28+AP28+AQ28+AR28+AS28+AT28+AU28+AV28+AW28+AX28+AY28+AZ28+BA28+BB28+BC28+BD28+BE28+BF28 -> 1 | BG28: 1
A29: 18. | B29: Аҳоли гавжум жойларга ўрнатилган кибер жиноятларни олдини олишга қаратилган баннер, плакат ва бошқа материаллар | C29: =+BG29+D29+E29+F29+G29+H29+I29+J29+K29+L29+M29+N29+O29+P29+Q29+R29+S29+T29+U29+V29+W29+X29+Y29+Z29+AA29+AB29+AC29+AD29+AE29+AF29+AG29+AH29+AI29+AJ29+AK29+AL29+AM29+AN29+AO29+AP29+AQ29+AR29+AS29+AT29+AU29+AV29+AW29+AX29+AY29+AZ29+BA29+BB29+BC29+BD29+BE29+BF29 -> 0

Sheet 01.21
A1: № | B1: Кўрсаткич | C1: Жами | D1: Ал-Хоразмий | E1: Бахористон | F1: Бектўпи | G1: Гулистон | H1: Катта Хирмонтепа | I1: Тирсакобод | J1: Хайрабод | K1: Хирмон тепа | L1: Хонтўпи | M1: Шараф | N1: Шарқ | O1: Шарқ тонги | P1: Шухрат | Q1: 1-Чарх Камолон | R1: 2-Чарх Камолон | S1: 3-Чарх Камолон | T1: Бешёғоч | U1: Катта Козиробод | V1: Катта Олмазор | W1: Катта Чилонзор-1 | X1: Катта Чилонзор-2 | Y1: Катта Чилонзор-3 | Z1: Қозиробод | AA1: Новза | AB1: Чилонзор | AC1: 1-Қатортол | AD1: Бешчинор | AE1: Боғзор | AF1: Диёр | AG1: Дилобод | AH1: Катта Навбаҳор | AI1: Кўркам | AJ1: Кўтарма | AK1: Қатортол | AL1: Лутфий | AM1: Навбахор | AN1: Нафосат | AO1: Оқ-тепа | AP1: Халқлар Дўстлиги | AQ1: Чўпон-ота | AR1: 2-Қатортол | AS1: Ботирма | AT1: Бўрижар | AU1: Гавхар | AV1: Дўмбиробод | AW1: Зарқўрғон | AX1: Катта Дўмбиробод | AY1: Кичик Хирмонтепа | AZ1: Мевазор | BA1: Мехржон | BB1: Наққошлик | BC1: Фидокор | BD1: Яккабоғ | BE1: Яккатут | BF1: Бешқўрғон | BG1: бошқа ҳудуд
A2: 1. | B2: Фош этилган жиноятлар | C2: =+BG2+D2+E2+F2+G2+H2+I2+J2+K2+L2+M2+N2+O2+P2+Q2+R2+S2+T2+U2+V2+W2+X2+Y2+Z2+AA2+AB2+AC2+AD2+AE2+AF2+AG2+AH2+AI2+AJ2+AK2+AL2+AM2+AN2+AO2+AP2+AQ2+AR2+AS2+AT2+AU2+AV2+AW2+AX2+AY2+AZ2+BA2+BB2+BC2+BD2+BE2+BF2 -> 4 | K2: 1 | R2: 1 | AL2: 1 | BF2: 1
A3: 2. | B3: Ушланган қидирувдаги шахслар | C3: =+BG3+D3+E3+F3+G3+H3+I3+J3+K3+L3+M3+N3+O3+P3+Q3+R3+S3+T3+U3+V3+W3+X3+Y3+Z3+AA3+AB3+AC3+AD3+AE3+AF3+AG3+AH3+AI3+AJ3+AK3+AL3+AM3+AN3+AO3+AP3+AQ3+AR3+AS3+AT3+AU3+AV3+AW3+AX3+AY3+AZ3+BA3+BB3+BC3+BD3+BE3+BF3 -> 0
A4: 3. | B4: Аниқланган бедарак йўқолган шахслар | C4: =+BG4+D4+E4+F4+G4+H4+I4+J4+K4+L4+M4+N4+O4+P4+Q4+R4+S4+T4+U4+V4+W4+X4+Y4+Z4+AA4+AB4+AC4+AD4+AE4+AF4+AG4+AH4+AI4+AJ4+AK4+AL4+AM4+AN4+AO4+AP4+AQ4+AR4+AS4+AT4+AU4+AV4+AW4+AX4+AY4+AZ4+BA4+BB4+BC4+BD4+BE4+BF4 -> 0
A5: 4. | B5: Аниқланган жиноятлар | C5: =+BG5+D5+E5+F5+G5+H5+I5+J5+K5+L5+M5+N5+O5+P5+Q5+R5+S5+T5+U5+V5+W5+X5+Y5+Z5+AA5+AB5+AC5+AD5+AE5+AF5+AG5+AH5+AI5+AJ5+AK5+AL5+AM5+AN5+AO5+AP5+AQ5+AR5+AS5+AT5+AU5+AV5+AW5+AX5+AY5+AZ5+BA5+BB5+BC5+BD5+BE5+BF5 -> 5 | I5: 1 | Q5: 1 | AM5: 2 | AX5: 1
A6: 4. | B6: Гиёҳвандлик моддалари билан боғлиқ аниқланган жиноий ҳолатлар | C6: =+BG6+D6+E6+F6+G6+H6+I6+J6+K6+L6+M6+N6+O6+P6+Q6+R6+S6+T6+U6+V6+W6+X6+Y6+Z6+AA6+AB6+AC6+AD6+AE6+AF6+AG6+AH6+AI6+AJ6+AK6+AL6+AM6+AN6+AO6+AP6+AQ6+AR6+AS6+AT6+AU6+AV6+AW6+AX6+AY6+AZ6+BA6+BB6+BC6+BD6+BE6+BF6 -> 3 | I6: 1 | Q6: 1 | AM6: 1
A7: 4.1. | B7: Олинган гиёҳвандлик моддари миқдори (грамм ҳисобида) | C7: =+BG7+D7+E7+F7+G7+H7+I7+J7+K7+L7+M7+N7+O7+P7+Q7+R7+S7+T7+U7+V7+W7+X7+Y7+Z7+AA7+AB7+AC7+AD7+AE7+AF7+AG7+AH7+AI7+AJ7+AK7+AL7+AM7+AN7+AO7+AP7+AQ7+AR7+AS7+AT7+AU7+AV7+AW7+AX7+AY7+AZ7+BA7+BB7+BC7+BD7+BE7+BF7 -> 3.98 | I7: 0.22 | Q7: 3.5 | AM7: 0.26
A8: 4.2. | B8: Гиёҳвандлик билан боғлиқ ҳолатлар юзасидан қўзғатилган жиноят ишлари | C8: =+BG8+D8+E8+F8+G8+H8+I8+J8+K8+L8+M8+N8+O8+P8+Q8+R8+S8+T8+U8+V8+W8+X8+Y8+Z8+AA8+AB8+AC8+AD8+AE8+AF8+AG8+AH8+AI8+AJ8+AK8+AL8+AM8+AN8+AO8+AP8+AQ8+AR8+AS8+AT8+AU8+AV8+AW8+AX8+AY8+AZ8+BA8+BB8+BC8+BD8+BE8+BF8 -> 3 | I8: 1 | Q8: 1 | AM8: 1
A9: 5. | B9: Аниқланган кучли таъсир қилувчи психотроп дори воситалари билан боғлиқ ҳолатлар | C9: =+BG9+D9+E9+F9+G9+H9+I9+J9+K9+L9+M9+N9+O9+P9+Q9+R9+S9+T9+U9+V9+W9+X9+Y9+Z9+AA9+AB9+AC9+AD9+AE9+AF9+AG9+AH9+AI9+AJ9+AK9+AL9+AM9+AN9+AO9+AP9+AQ9+AR9+AS9+AT9+AU9+AV9+AW9+AX9+AY9+AZ9+BA9+BB9+BC9+BD9+BE9+BF9 -> 0
A10: 5.1. | B10: Олинган кучли таъсир қилувчи психотроп воситалари сони (дона ҳисобида) | C10: =+BG10+D10+E10+F10+G10+H10+I10+J10+K10+L10+M10+N10+O10+P10+Q10+R10+S10+T10+U10+V10+W10+X10+Y10+Z10+AA10+AB10+AC10+AD10+AE10+AF10+AG10+AH10+AI10+AJ10+AK10+AL10+AM10+AN10+AO10+AP10+AQ10+AR10+AS10+AT10+AU10+AV10+AW10+AX10+AY10+AZ10+BA10+BB10+BC10+BD10+BE10+BF10 -> 0
A11: 5.2. | B11: Психотроп воситалар билан боғлиқ ҳолатлар юзасидан қўзғатилган жиноят ишлари | C11: =+BG11+D11+E11+F11+G11+H11+I11+J11+K11+L11+M11+N11+O11+P11+Q11+R11+S11+T11+U11+V11+W11+X11+Y11+Z11+AA11+AB11+AC11+AD11+AE11+AF11+AG11+AH11+AI11+AJ11+AK11+AL11+AM11+AN11+AO11+AP11+AQ11+AR11+AS11+AT11+AU11+AV11+AW11+AX11+AY11+AZ11+BA11+BB11+BC11+BD11+BE11+BF11 -> 0
A12: 6. | B12: Аниқланган нарколабораториялар | C12: =+BG12+D12+E12+F12+G12+H12+I12+J12+K12+L12+M12+N12+O12+P12+Q12+R12+S12+T12+U12+V12+W12+X12+Y12+Z12+AA12+AB12+AC12+AD12+AE12+AF12+AG12+AH12+AI12+AJ12+AK12+AL12+AM12+AN12+AO12+AP12+AQ12+AR12+AS12+AT12+AU12+AV12+AW12+AX12+AY12+AZ12+BA12+BB12+BC12+BD12+BE12+BF12 -> 0
A13: 8. | B13: Гиёҳвандлик воситалари ва психотроп моддалар муомаласи олдини олиш юзасидан «маҳалла еттилиги» аъзолари билан ўтказилган қисқа муддатли ўқув семинарлари | C13: =+BG13+D13+E13+F13+G13+H13+I13+J13+K13+L13+M13+N13+O13+P13+Q13+R13+S13+T13+U13+V13+W13+X13+Y13+Z13+AA13+AB13+AC13+AD13+AE13+AF13+AG13+AH13+AI13+AJ13+AK13+AL13+AM13+AN13+AO13+AP13+AQ13+AR13+AS13+AT13+AU13+AV13+AW13+AX13+AY13+AZ13+BA13+BB13+BC13+BD13+BE13+BF13 -> 1 | Q13: 1
A14: 9. | B14: Гиёҳвандлик ва психотроп воситаларининг оғир оқибатлари юзасидан таълим муассасалрида ўтказилган профилактик тадбирлар | C14: =+BG14+D14+E14+F14+G14+H14+I14+J14+K14+L14+M14+N14+O14+P14+Q14+R14+S14+T14+U14+V14+W14+X14+Y14+Z14+AA14+AB14+AC14+AD14+AE14+AF14+AG14+AH14+AI14+AJ14+AK14+AL14+AM14+AN14+AO14+AP14+AQ14+AR14+AS14+AT14+AU14+AV14+AW14+AX14+AY14+AZ14+BA14+BB14+BC14+BD14+BE14+BF14 -> 1 | T14: 1
A15: 10. | B15: ДЭО йўналишида аниқланган маъмурий ҳолатлар | C15: =+BG15+D15+E15+F15+G15+H15+I15+J15+K15+L15+M15+N15+O15+P15+Q15+R15+S15+T15+U15+V15+W15+X15+Y15+Z15+AA15+AB15+AC15+AD15+AE15+AF15+AG15+AH15+AI15+AJ15+AK15+AL15+AM15+AN15+AO15+AP15+AQ15+AR15+AS15+AT15+AU15+AV15+AW15+AX15+AY15+AZ15+BA15+BB15+BC15+BD15+BE15+BF15 -> 0
A16: шундан | B16: ноқонуний диний таълим бериш | C16: =+BG16+D16+E16+F16+G16+H16+I16+J16+K16+L16+M16+N16+O16+P16+Q16+R16+S16+T16+U16+V16+W16+X16+Y16+Z16+AA16+AB16+AC16+AD16+AE16+AF16+AG16+AH16+AI16+AJ16+AK16+AL16+AM16+AN16+AO16+AP16+AQ16+AR16+AS16+AT16+AU16+AV16+AW16+AX16+AY16+AZ16+BA16+BB16+BC16+BD16+BE16+BF16 -> 0
B17: таъқиқланган диний маълумотларни сақлаш ва ташиш | C17: =+BG17+D17+E17+F17+G17+H17+I17+J17+K17+L17+M17+N17+O17+P17+Q17+R17+S17+T17+U17+V17+W17+X17+Y17+Z17+AA17+AB17+AC17+AD17+AE17+AF17+AG17+AH17+AI17+AJ17+AK17+AL17+AM17+AN17+AO17+AP17+AQ17+AR17+AS17+AT17+AU17+AV17+AW17+AX17+AY17+AZ17+BA17+BB17+BC17+BD17+BE17+BF17 -> 0
A18: 11. | B18: ДЭО йўналишида аниқланган жиноий ҳолатлар | C18: =+BG18+D18+E18+F18+G18+H18+I18+J18+K18+L18+M18+N18+O18+P18+Q18+R18+S18+T18+U18+V18+W18+X18+Y18+Z18+AA18+AB18+AC18+AD18+AE18+AF18+AG18+AH18+AI18+AJ18+AK18+AL18+AM18+AN18+AO18+AP18+AQ18+AR18+AS18+AT18+AU18+AV18+AW18+AX18+AY18+AZ18+BA18+BB18+BC18+BD18+BE18+BF18 -> 0
A19: шундан | B19: "ҳужралар" | C19: =+BG19+D19+E19+F19+G19+H19+I19+J19+K19+L19+M19+N19+O19+P19+Q19+R19+S19+T19+U19+V19+W19+X19+Y19+Z19+AA19+AB19+AC19+AD19+AE19+AF19+AG19+AH19+AI19+AJ19+AK19+AL19+AM19+AN19+AO19+AP19+AQ19+AR19+AS19+AT19+AU19+AV19+AW19+AX19+AY19+AZ19+BA19+BB19+BC19+BD19+BE19+BF19 -> 0
B20: ҳужраларда таълим олган вояга етмаганлар | C20: =+BG20+D20+E20+F20+G20+H20+I20+J20+K20+L20+M20+N20+O20+P20+Q20+R20+S20+T20+U20+V20+W20+X20+Y20+Z20+AA20+AB20+AC20+AD20+AE20+AF20+AG20+AH20+AI20+AJ20+AK20+AL20+AM20+AN20+AO20+AP20+AQ20+AR20+AS20+AT20+AU20+AV20+AW20+AX20+AY20+AZ20+BA20+BB20+BC20+BD20+BE20+BF20 -> 0
A21: 12. | B21: Радикаллашувга қарши курашиш борасида олиб борилган тезкор профилактик тадбирлари | C21: =+BG21+D21+E21+F21+G21+H21+I21+J21+K21+L21+M21+N21+O21+P21+Q21+R21+S21+T21+U21+V21+W21+X21+Y21+Z21+AA21+AB21+AC21+AD21+AE21+AF21+AG21+AH21+AI21+AJ21+AK21+AL21+AM21+AN21+AO21+AP21+AQ21+AR21+AS21+AT21+AU21+AV21+AW21+AX21+AY21+AZ21+BA21+BB21+BC21+BD21+BE21+BF21 -> 0
A22: шундан | B22: Қайтарув гуруҳида олиб борилаётган профилактик тушунтириш ишлари | C22: =+BG22+D22+E22+F22+G22+H22+I22+J22+K22+L22+M22+N22+O22+P22+Q22+R22+S22+T22+U22+V22+W22+X22+Y22+Z22+AA22+AB22+AC22+AD22+AE22+AF22+AG22+AH22+AI22+AJ22+AK22+AL22+AM22+AN22+AO22+AP22+AQ22+AR22+AS22+AT22+AU22+AV22+AW22+AX22+AY22+AZ22+BA22+BB22+BC22+BD22+BE22+BF22 -> 14 | Z22: 2 | AR22: 2 | AT22: 2 | AV22: 2 | AX22: 3 | AZ22: 2 | BB22: 1
B23: хорижда диструктив ғоя таъсири остига тушган шахслар билан олиб борилаётган филтрь сўров тадбирлари | C23: =+BG23+D23+E23+F23+G23+H23+I23+J23+K23+L23+M23+N23+O23+P23+Q23+R23+S23+T23+U23+V23+W23+X23+Y23+Z23+AA23+AB23+AC23+AD23+AE23+AF23+AG23+AH23+AI23+AJ23+AK23+AL23+AM23+AN23+AO23+AP23+AQ23+AR23+AS23+AT23+AU23+AV23+AW23+AX23+AY23+AZ23+BA23+BB23+BC23+BD23+BE23+BF23 -> 1 | Z23: 0 | BD23: 1
A24: 13. | B24: Кибер жиноятлар бўйича келиб тушган мурожаатлар | C24: =+BG24+D24+E24+F24+G24+H24+I24+J24+K24+L24+M24+N24+O24+P24+Q24+R24+S24+T24+U24+V24+W24+X24+Y24+Z24+AA24+AB24+AC24+AD24+AE24+AF24+AG24+AH24+AI24+AJ24+AK24+AL24+AM24+AN24+AO24+AP24+AQ24+AR24+AS24+AT24+AU24+AV24+AW24+AX24+AY24+AZ24+BA24+BB24+BC24+BD24+BE24+BF24 -> 9 | E24: 1 | H24: 1 | I24: 1 | L24: 1 | Y24: 1 | AA24: 1 | AB24: 1 | AR24: 1 | BF24: 1
A25: 14. | B25: Ҳолат бўйича қўзғатилган жиноят ишлари | C25: =+BG25+D25+E25+F25+G25+H25+I25+J25+K25+L25+M25+N25+O25+P25+Q25+R25+S25+T25+U25+V25+W25+X25+Y25+Z25+AA25+AB25+AC25+AD25+AE25+AF25+AG25+AH25+AI25+AJ25+AK25+AL25+AM25+AN25+AO25+AP25+AQ25+AR25+AS25+AT25+AU25+AV25+AW25+AX25+AY25+AZ25+BA25+BB25+BC25+BD25+BE25+BF25 -> 0
A26: 15. | B26: Фош этилган кибер жиноятлар | C26: =+BG26+D26+E26+F26+G26+H26+I26+J26+K26+L26+M26+N26+O26+P26+Q26+R26+S26+T26+U26+V26+W26+X26+Y26+Z26+AA26+AB26+AC26+AD26+AE26+AF26+AG26+AH26+AI26+AJ26+AK26+AL26+AM26+AN26+AO26+AP26+AQ26+AR26+AS26+AT26+AU26+AV26+AW26+AX26+AY26+AZ26+BA26+BB26+BC26+BD26+BE26+BF26 -> 0
A27: 16. | B27: Таълим муассасаларида кибер жиноятларни олдини олиш бўйича амалга оширилган профилактик тарғибот тадбирлари | C27: =+BG27+D27+E27+F27+G27+H27+I27+J27+K27+L27+M27+N27+O27+P27+Q27+R27+S27+T27+U27+V27+W27+X27+Y27+Z27+AA27+AB27+AC27+AD27+AE27+AF27+AG27+AH27+AI27+AJ27+AK27+AL27+AM27+AN27+AO27+AP27+AQ27+AR27+AS27+AT27+AU27+AV27+AW27+AX27+AY27+AZ27+BA27+BB27+BC27+BD27+BE27+BF27 -> 2 | AA27: 1 | AQ27: 1
A28: 17. | B28: Ижтимоий тармоқларда кибер жиноятларни олдини олиш юзасидан амалга оширилган профилактик тадбирлар | C28: =+BG28+D28+E28+F28+G28+H28+I28+J28+K28+L28+M28+N28+O28+P28+Q28+R28+S28+T28+U28+V28+W28+X28+Y28+Z28+AA28+AB28+AC28+AD28+AE28+AF28+AG28+AH28+AI28+AJ28+AK28+AL28+AM28+AN28+AO28+AP28+AQ28+AR28+AS28+AT28+AU28+AV28+AW28+AX28+AY28+AZ28+BA28+BB28+BC28+BD28+BE28+BF28 -> 3 | BG28: 3
A29: 18. | B29: Аҳоли гавжум жойларга ўрнатилган кибер жиноятларни олдини олишга қаратилган баннер, плакат ва бошқа материаллар | C29: =+BG29+D29+E29+F29+G29+H29+I29+J29+K29+L29+M29+N29+O29+P29+Q29+R29+S29+T29+U29+V29+W29+X29+Y29+Z29+AA29+AB29+AC29+AD29+AE29+AF29+AG29+AH29+AI29+AJ29+AK29+AL29+AM29+AN29+AO29+AP29+AQ29+AR29+AS29+AT29+AU29+AV29+AW29+AX29+AY29+AZ29+BA29+BB29+BC29+BD29+BE29+BF29 -> 0

Sheet 01.22
A1: № | B1: Кўрсаткич | C1: Жами | D1: Ал-Хоразмий | E1: Бахористон | F1: Бектўпи | G1: Гулистон | H1: Катта Хирмонтепа | I1: Тирсакобод | J1: Хайрабод | K1: Хирмон тепа | L1: Хонтўпи | M1: Шараф | N1: Шарқ | O1: Шарқ тонги | P1: Шухрат | Q1: 1-Чарх Камолон | R1: 2-Чарх Камолон | S1: 3-Чарх Камолон | T1: Бешёғоч | U1: Катта Козиробод | V1: Катта Олмазор | W1: Катта Чилонзор-1 | X1: Катта Чилонзор-2 | Y1: Катта Чилонзор-3 | Z1: Қозиробод | AA1: Новза | AB1: Чилонзор | AC1: 1-Қатортол | AD1: Бешчинор | AE1: Боғзор | AF1: Диёр | AG1: Дилобод | AH1: Катта Навбаҳор | AI1: Кўркам | AJ1: Кўтарма | AK1: Қатортол | AL1: Лутфий | AM1: Навбахор | AN1: Нафосат | AO1: Оқ-тепа | AP1: Халқлар Дўстлиги | AQ1: Чўпон-ота | AR1: 2-Қатортол | AS1: Ботирма | AT1: Бўрижар | AU1: Гавхар | AV1: Дўмбиробод | AW1: Зарқўрғон | AX1: Катта Дўмбиробод | AY1: Кичик Хирмонтепа | AZ1: Мевазор | BA1: Мехржон | BB1: Наққошлик | BC1: Фидокор | BD1: Яккабоғ | BE1: Яккатут | BF1: Бешқўрғон | BG1: бошқа ҳудуд
A2: 1. | B2: Фош этилган жиноятлар | C2: =+BG2+D2+E2+F2+G2+H2+I2+J2+K2+L2+M2+N2+O2+P2+Q2+R2+S2+T2+U2+V2+W2+X2+Y2+Z2+AA2+AB2+AC2+AD2+AE2+AF2+AG2+AH2+AI2+AJ2+AK2+AL2+AM2+AN2+AO2+AP2+AQ2+AR2+AS2+AT2+AU2+AV2+AW2+AX2+AY2+AZ2+BA2+BB2+BC2+BD2+BE2+BF2 -> 4 | R2: 1 | Z2: 1 | AE2: 1 | AS2: 1
A3: 2. | B3: Ушланган қидирувдаги шахслар | C3: =+BG3+D3+E3+F3+G3+H3+I3+J3+K3+L3+M3+N3+O3+P3+Q3+R3+S3+T3+U3+V3+W3+X3+Y3+Z3+AA3+AB3+AC3+AD3+AE3+AF3+AG3+AH3+AI3+AJ3+AK3+AL3+AM3+AN3+AO3+AP3+AQ3+AR3+AS3+AT3+AU3+AV3+AW3+AX3+AY3+AZ3+BA3+BB3+BC3+BD3+BE3+BF3 -> 1 | M3: 1
A4: 3. | B4: Аниқланган бедарак йўқолган шахслар | C4: =+BG4+D4+E4+F4+G4+H4+I4+J4+K4+L4+M4+N4+O4+P4+Q4+R4+S4+T4+U4+V4+W4+X4+Y4+Z4+AA4+AB4+AC4+AD4+AE4+AF4+AG4+AH4+AI4+AJ4+AK4+AL4+AM4+AN4+AO4+AP4+AQ4+AR4+AS4+AT4+AU4+AV4+AW4+AX4+AY4+AZ4+BA4+BB4+BC4+BD4+BE4+BF4 -> 0
A5: 4. | B5: Аниқланган жиноятлар | C5: =+BG5+D5+E5+F5+G5+H5+I5+J5+K5+L5+M5+N5+O5+P5+Q5+R5+S5+T5+U5+V5+W5+X5+Y5+Z5+AA5+AB5+AC5+AD5+AE5+AF5+AG5+AH5+AI5+AJ5+AK5+AL5+AM5+AN5+AO5+AP5+AQ5+AR5+AS5+AT5+AU5+AV5+AW5+AX5+AY5+AZ5+BA5+BB5+BC5+BD5+BE5+BF5 -> 3 | N5: 1 | U5: 1 | AO5: 1 | BG5: 0
A6: 4. | B6: Гиёҳвандлик моддалари билан боғлиқ аниқланган жиноий ҳолатлар | C6: =+BG6+D6+E6+F6+G6+H6+I6+J6+K6+L6+M6+N6+O6+P6+Q6+R6+S6+T6+U6+V6+W6+X6+Y6+Z6+AA6+AB6+AC6+AD6+AE6+AF6+AG6+AH6+AI6+AJ6+AK6+AL6+AM6+AN6+AO6+AP6+AQ6+AR6+AS6+AT6+AU6+AV6+AW6+AX6+AY6+AZ6+BA6+BB6+BC6+BD6+BE6+BF6 -> 3 | N6: 1 | U6: 1 | AO6: 1 | BG6: 0
A7: 4.1. | B7: Олинган гиёҳвандлик моддари миқдори (грамм ҳисобида) | C7: =+BG7+D7+E7+F7+G7+H7+I7+J7+K7+L7+M7+N7+O7+P7+Q7+R7+S7+T7+U7+V7+W7+X7+Y7+Z7+AA7+AB7+AC7+AD7+AE7+AF7+AG7+AH7+AI7+AJ7+AK7+AL7+AM7+AN7+AO7+AP7+AQ7+AR7+AS7+AT7+AU7+AV7+AW7+AX7+AY7+AZ7+BA7+BB7+BC7+BD7+BE7+BF7 -> 512.5 | N7: 510.6 | U7: 1 | AO7: 0.9
A8: 4.2. | B8: Гиёҳвандлик билан боғлиқ ҳолатлар юзасидан қўзғатилган жиноят ишлари | C8: =+BG8+D8+E8+F8+G8+H8+I8+J8+K8+L8+M8+N8+O8+P8+Q8+R8+S8+T8+U8+V8+W8+X8+Y8+Z8+AA8+AB8+AC8+AD8+AE8+AF8+AG8+AH8+AI8+AJ8+AK8+AL8+AM8+AN8+AO8+AP8+AQ8+AR8+AS8+AT8+AU8+AV8+AW8+AX8+AY8+AZ8+BA8+BB8+BC8+BD8+BE8+BF8 -> 3 | N8: 1 | U8: 1 | AO8: 1 | BG8: 0
A9: 5. | B9: Аниқланган кучли таъсир қилувчи психотроп дори воситалари билан боғлиқ ҳолатлар | C9: =+BG9+D9+E9+F9+G9+H9+I9+J9+K9+L9+M9+N9+O9+P9+Q9+R9+S9+T9+U9+V9+W9+X9+Y9+Z9+AA9+AB9+AC9+AD9+AE9+AF9+AG9+AH9+AI9+AJ9+AK9+AL9+AM9+AN9+AO9+AP9+AQ9+AR9+AS9+AT9+AU9+AV9+AW9+AX9+AY9+AZ9+BA9+BB9+BC9+BD9+BE9+BF9 -> 0
A10: 5.1. | B10: Олинган кучли таъсир қилувчи психотроп воситалари сони (дона ҳисобида) | C10: =+BG10+D10+E10+F10+G10+H10+I10+J10+K10+L10+M10+N10+O10+P10+Q10+R10+S10+T10+U10+V10+W10+X10+Y10+Z10+AA10+AB10+AC10+AD10+AE10+AF10+AG10+AH10+AI10+AJ10+AK10+AL10+AM10+AN10+AO10+AP10+AQ10+AR10+AS10+AT10+AU10+AV10+AW10+AX10+AY10+AZ10+BA10+BB10+BC10+BD10+BE10+BF10 -> 0
A11: 5.2. | B11: Психотроп воситалар билан боғлиқ ҳолатлар юзасидан қўзғатилган жиноят ишлари | C11: =+BG11+D11+E11+F11+G11+H11+I11+J11+K11+L11+M11+N11+O11+P11+Q11+R11+S11+T11+U11+V11+W11+X11+Y11+Z11+AA11+AB11+AC11+AD11+AE11+AF11+AG11+AH11+AI11+AJ11+AK11+AL11+AM11+AN11+AO11+AP11+AQ11+AR11+AS11+AT11+AU11+AV11+AW11+AX11+AY11+AZ11+BA11+BB11+BC11+BD11+BE11+BF11 -> 0
A12: 6. | B12: Аниқланган нарколабораториялар | C12: =+BG12+D12+E12+F12+G12+H12+I12+J12+K12+L12+M12+N12+O12+P12+Q12+R12+S12+T12+U12+V12+W12+X12+Y12+Z12+AA12+AB12+AC12+AD12+AE12+AF12+AG12+AH12+AI12+AJ12+AK12+AL12+AM12+AN12+AO12+AP12+AQ12+AR12+AS12+AT12+AU12+AV12+AW12+AX12+AY12+AZ12+BA12+BB12+BC12+BD12+BE12+BF12 -> 0
A13: 8. | B13: Гиёҳвандлик воситалари ва психотроп моддалар муомаласи олдини олиш юзасидан «маҳалла еттилиги» аъзолари билан ўтказилган қисқа муддатли ўқув семинарлари | C13: =+BG13+D13+E13+F13+G13+H13+I13+J13+K13+L13+M13+N13+O13+P13+Q13+R13+S13+T13+U13+V13+W13+X13+Y13+Z13+AA13+AB13+AC13+AD13+AE13+AF13+AG13+AH13+AI13+AJ13+AK13+AL13+AM13+AN13+AO13+AP13+AQ13+AR13+AS13+AT13+AU13+AV13+AW13+AX13+AY13+AZ13+BA13+BB13+BC13+BD13+BE13+BF13 -> 0
A14: 9. | B14: Гиёҳвандлик ва психотроп воситаларининг оғир оқибатлари юзасидан таълим муассасалрида ўтказилган профилактик тадбирлар | C14: =+BG14+D14+E14+F14+G14+H14+I14+J14+K14+L14+M14+N14+O14+P14+Q14+R14+S14+T14+U14+V14+W14+X14+Y14+Z14+AA14+AB14+AC14+AD14+AE14+AF14+AG14+AH14+AI14+AJ14+AK14+AL14+AM14+AN14+AO14+AP14+AQ14+AR14+AS14+AT14+AU14+AV14+AW14+AX14+AY14+AZ14+BA14+BB14+BC14+BD14+BE14+BF14 -> 1 | U14: 1
A15: 10. | B15: ДЭО йўналишида аниқланган маъмурий ҳолатлар | C15: =+BG15+D15+E15+F15+G15+H15+I15+J15+K15+L15+M15+N15+O15+P15+Q15+R15+S15+T15+U15+V15+W15+X15+Y15+Z15+AA15+AB15+AC15+AD15+AE15+AF15+AG15+AH15+AI15+AJ15+AK15+AL15+AM15+AN15+AO15+AP15+AQ15+AR15+AS15+AT15+AU15+AV15+AW15+AX15+AY15+AZ15+BA15+BB15+BC15+BD15+BE15+BF15 -> 0
A16: шундан | B16: ноқонуний диний таълим бериш | C16: =+BG16+D16+E16+F16+G16+H16+I16+J16+K16+L16+M16+N16+O16+P16+Q16+R16+S16+T16+U16+V16+W16+X16+Y16+Z16+AA16+AB16+AC16+AD16+AE16+AF16+AG16+AH16+AI16+AJ16+AK16+AL16+AM16+AN16+AO16+AP16+AQ16+AR16+AS16+AT16+AU16+AV16+AW16+AX16+AY16+AZ16+BA16+BB16+BC16+BD16+BE16+BF16 -> 0
B17: таъқиқланган диний маълумотларни сақлаш ва ташиш | C17: =+BG17+D17+E17+F17+G17+H17+I17+J17+K17+L17+M17+N17+O17+P17+Q17+R17+S17+T17+U17+V17+W17+X17+Y17+Z17+AA17+AB17+AC17+AD17+AE17+AF17+AG17+AH17+AI17+AJ17+AK17+AL17+AM17+AN17+AO17+AP17+AQ17+AR17+AS17+AT17+AU17+AV17+AW17+AX17+AY17+AZ17+BA17+BB17+BC17+BD17+BE17+BF17 -> 0
A18: 11. | B18: ДЭО йўналишида аниқланган жиноий ҳолатлар | C18: =+BG18+D18+E18+F18+G18+H18+I18+J18+K18+L18+M18+N18+O18+P18+Q18+R18+S18+T18+U18+V18+W18+X18+Y18+Z18+AA18+AB18+AC18+AD18+AE18+AF18+AG18+AH18+AI18+AJ18+AK18+AL18+AM18+AN18+AO18+AP18+AQ18+AR18+AS18+AT18+AU18+AV18+AW18+AX18+AY18+AZ18+BA18+BB18+BC18+BD18+BE18+BF18 -> 0
A19: шундан | B19: "ҳужралар" | C19: =+BG19+D19+E19+F19+G19+H19+I19+J19+K19+L19+M19+N19+O19+P19+Q19+R19+S19+T19+U19+V19+W19+X19+Y19+Z19+AA19+AB19+AC19+AD19+AE19+AF19+AG19+AH19+AI19+AJ19+AK19+AL19+AM19+AN19+AO19+AP19+AQ19+AR19+AS19+AT19+AU19+AV19+AW19+AX19+AY19+AZ19+BA19+BB19+BC19+BD19+BE19+BF19 -> 0
B20: ҳужраларда таълим олган вояга етмаганлар | C20: =+BG20+D20+E20+F20+G20+H20+I20+J20+K20+L20+M20+N20+O20+P20+Q20+R20+S20+T20+U20+V20+W20+X20+Y20+Z20+AA20+AB20+AC20+AD20+AE20+AF20+AG20+AH20+AI20+AJ20+AK20+AL20+AM20+AN20+AO20+AP20+AQ20+AR20+AS20+AT20+AU20+AV20+AW20+AX20+AY20+AZ20+BA20+BB20+BC20+BD20+BE20+BF20 -> 0
A21: 12. | B21: Радикаллашувга қарши курашиш борасида олиб борилган тезкор профилактик тадбирлари | C21: =+BG21+D21+E21+F21+G21+H21+I21+J21+K21+L21+M21+N21+O21+P21+Q21+R21+S21+T21+U21+V21+W21+X21+Y21+Z21+AA21+AB21+AC21+AD21+AE21+AF21+AG21+AH21+AI21+AJ21+AK21+AL21+AM21+AN21+AO21+AP21+AQ21+AR21+AS21+AT21+AU21+AV21+AW21+AX21+AY21+AZ21+BA21+BB21+BC21+BD21+BE21+BF21 -> 27 | Q21: 1 | Z21: 2 | AM21: 2 | AN21: 2 | AR21: 2 | AT21: 2 | AU21: 2 | AV21: 2 | AX21: 3 | AZ21: 6 | BB21: 1 | BE21: 2
A22: шундан | B22: Қайтарув гуруҳида олиб борилаётган профилактик тушунтириш ишлари | C22: =+BG22+D22+E22+F22+G22+H22+I22+J22+K22+L22+M22+N22+O22+P22+Q22+R22+S22+T22+U22+V22+W22+X22+Y22+Z22+AA22+AB22+AC22+AD22+AE22+AF22+AG22+AH22+AI22+AJ22+AK22+AL22+AM22+AN22+AO22+AP22+AQ22+AR22+AS22+AT22+AU22+AV22+AW22+AX22+AY22+AZ22+BA22+BB22+BC22+BD22+BE22+BF22 -> 13 | Q22: 1 | AM22: 2 | AN22: 2 | AU22: 2 | AZ22: 4 | BE22: 2
B23: хорижда диструктив ғоя таъсири остига тушган шахслар билан олиб борилаётган филтрь сўров тадбирлари | C23: =+BG23+D23+E23+F23+G23+H23+I23+J23+K23+L23+M23+N23+O23+P23+Q23+R23+S23+T23+U23+V23+W23+X23+Y23+Z23+AA23+AB23+AC23+AD23+AE23+AF23+AG23+AH23+AI23+AJ23+AK23+AL23+AM23+AN23+AO23+AP23+AQ23+AR23+AS23+AT23+AU23+AV23+AW23+AX23+AY23+AZ23+BA23+BB23+BC23+BD23+BE23+BF23 -> 0 | BE23: 0
A24: 13. | B24: Кибер жиноятлар бўйича келиб тушган мурожаатлар | C24: =+BG24+D24+E24+F24+G24+H24+I24+J24+K24+L24+M24+N24+O24+P24+Q24+R24+S24+T24+U24+V24+W24+X24+Y24+Z24+AA24+AB24+AC24+AD24+AE24+AF24+AG24+AH24+AI24+AJ24+AK24+AL24+AM24+AN24+AO24+AP24+AQ24+AR24+AS24+AT24+AU24+AV24+AW24+AX24+AY24+AZ24+BA24+BB24+BC24+BD24+BE24+BF24 -> 10 | I24: 2 | AG24: 1 | AI24: 1 | AJ24: 1 | AM24: 1 | AO24: 1 | AY24: 1 | BA24: 1 | BC24: 1
A25: 14. | B25: Ҳолат бўйича қўзғатилган жиноят ишлари | C25: =+BG25+D25+E25+F25+G25+H25+I25+J25+K25+L25+M25+N25+O25+P25+Q25+R25+S25+T25+U25+V25+W25+X25+Y25+Z25+AA25+AB25+AC25+AD25+AE25+AF25+AG25+AH25+AI25+AJ25+AK25+AL25+AM25+AN25+AO25+AP25+AQ25+AR25+AS25+AT25+AU25+AV25+AW25+AX25+AY25+AZ25+BA25+BB25+BC25+BD25+BE25+BF25 -> 10 | W25: 1 | AA25: 2 | AO25: 3 | AP25: 2 | BB25: 2
A26: 15. | B26: Фош этилган кибер жиноятлар | C26: =+BG26+D26+E26+F26+G26+H26+I26+J26+K26+L26+M26+N26+O26+P26+Q26+R26+S26+T26+U26+V26+W26+X26+Y26+Z26+AA26+AB26+AC26+AD26+AE26+AF26+AG26+AH26+AI26+AJ26+AK26+AL26+AM26+AN26+AO26+AP26+AQ26+AR26+AS26+AT26+AU26+AV26+AW26+AX26+AY26+AZ26+BA26+BB26+BC26+BD26+BE26+BF26 -> 1 | AV26: 1
A27: 16. | B27: Таълим муассасаларида кибер жиноятларни олдини олиш бўйича амалга оширилган профилактик тарғибот тадбирлари | C27: =+BG27+D27+E27+F27+G27+H27+I27+J27+K27+L27+M27+N27+O27+P27+Q27+R27+S27+T27+U27+V27+W27+X27+Y27+Z27+AA27+AB27+AC27+AD27+AE27+AF27+AG27+AH27+AI27+AJ27+AK27+AL27+AM27+AN27+AO27+AP27+AQ27+AR27+AS27+AT27+AU27+AV27+AW27+AX27+AY27+AZ27+BA27+BB27+BC27+BD27+BE27+BF27 -> 4 | L27: 1 | AG27: 1 | AO27: 1 | AQ27: 1
A28: 17. | B28: Ижтимоий тармоқларда кибер жиноятларни олдини олиш юзасидан амалга оширилган профилактик тадбирлар | C28: =+BG28+D28+E28+F28+G28+H28+I28+J28+K28+L28+M28+N28+O28+P28+Q28+R28+S28+T28+U28+V28+W28+X28+Y28+Z28+AA28+AB28+AC28+AD28+AE28+AF28+AG28+AH28+AI28+AJ28+AK28+AL28+AM28+AN28+AO28+AP28+AQ28+AR28+AS28+AT28+AU28+AV28+AW28+AX28+AY28+AZ28+BA28+BB28+BC28+BD28+BE28+BF28 -> 5 | BG28: 5
A29: 18. | B29: Аҳоли гавжум жойларга ўрнатилган кибер жиноятларни олдини олишга қаратилган баннер, плакат ва бошқа материаллар | C29: =+BG29+D29+E29+F29+G29+H29+I29+J29+K29+L29+M29+N29+O29+P29+Q29+R29+S29+T29+U29+V29+W29+X29+Y29+Z29+AA29+AB29+AC29+AD29+AE29+AF29+AG29+AH29+AI29+AJ29+AK29+AL29+AM29+AN29+AO29+AP29+AQ29+AR29+AS29+AT29+AU29+AV29+AW29+AX29+AY29+AZ29+BA29+BB29+BC29+BD29+BE29+BF29 -> 0

Sheet 01.23
A1: № | B1: Кўрсаткич | C1: Жами | D1: Ал-Хоразмий | E1: Бахористон | F1: Бектўпи | G1: Гулистон | H1: Катта Хирмонтепа | I1: Тирсакобод | J1: Хайрабод | K1: Хирмон тепа | L1: Хонтўпи | M1: Шараф | N1: Шарқ | O1: Шарқ тонги | P1: Шухрат | Q1: 1-Чарх Камолон | R1: 2-Чарх Камолон | S1: 3-Чарх Камолон | T1: Бешёғоч | U1: Катта Козиробод | V1: Катта Олмазор | W1: Катта Чилонзор-1 | X1: Катта Чилонзор-2 | Y1: Катта Чилонзор-3 | Z1: Қозиробод | AA1: Новза | AB1: Чилонзор | AC1: 1-Қатортол | AD1: Бешчинор | AE1: Боғзор | AF1: Диёр | AG1: Дилобод | AH1: Катта Навбаҳор | AI1: Кўркам | AJ1: Кўтарма | AK1: Қатортол | AL1: Лутфий | AM1: Навбахор | AN1: Нафосат | AO1: Оқ-тепа | AP1: Халқлар Дўстлиги | AQ1: Чўпон-ота | AR1: 2-Қатортол | AS1: Ботирма | AT1: Бўрижар | AU1: Гавхар | AV1: Дўмбиробод | AW1: Зарқўрғон | AX1: Катта Дўмбиробод | AY1: Кичик Хирмонтепа | AZ1: Мевазор | BA1: Мехржон | BB1: Наққошлик | BC1: Фидокор | BD1: Яккабоғ | BE1: Яккатут | BF1: Бешқўрғон | BG1: бошқа ҳудуд
A2: 1. | B2: Фош этилган жиноятлар | C2: =+BG2+D2+E2+F2+G2+H2+I2+J2+K2+L2+M2+N2+O2+P2+Q2+R2+S2+T2+U2+V2+W2+X2+Y2+Z2+AA2+AB2+AC2+AD2+AE2+AF2+AG2+AH2+AI2+AJ2+AK2+AL2+AM2+AN2+AO2+AP2+AQ2+AR2+AS2+AT2+AU2+AV2+AW2+AX2+AY2+AZ2+BA2+BB2+BC2+BD2+BE2+BF2 -> 2 | Y2: 1 | AA2: 1
A3: 2. | B3: Ушланган қидирувдаги шахслар | C3: =+BG3+D3+E3+F3+G3+H3+I3+J3+K3+L3+M3+N3+O3+P3+Q3+R3+S3+T3+U3+V3+W3+X3+Y3+Z3+AA3+AB3+AC3+AD3+AE3+AF3+AG3+AH3+AI3+AJ3+AK3+AL3+AM3+AN3+AO3+AP3+AQ3+AR3+AS3+AT3+AU3+AV3+AW3+AX3+AY3+AZ3+BA3+BB3+BC3+BD3+BE3+BF3 -> 1 | M3: 1
A4: 3. | B4: Аниқланган бедарак йўқолган шахслар | C4: =+BG4+D4+E4+F4+G4+H4+I4+J4+K4+L4+M4+N4+O4+P4+Q4+R4+S4+T4+U4+V4+W4+X4+Y4+Z4+AA4+AB4+AC4+AD4+AE4+AF4+AG4+AH4+AI4+AJ4+AK4+AL4+AM4+AN4+AO4+AP4+AQ4+AR4+AS4+AT4+AU4+AV4+AW4+AX4+AY4+AZ4+BA4+BB4+BC4+BD4+BE4+BF4 -> 0 | AZ4: 0
A5: 4. | B5: Аниқланган жиноятлар | C5: =+BG5+D5+E5+F5+G5+H5+I5+J5+K5+L5+M5+N5+O5+P5+Q5+R5+S5+T5+U5+V5+W5+X5+Y5+Z5+AA5+AB5+AC5+AD5+AE5+AF5+AG5+AH5+AI5+AJ5+AK5+AL5+AM5+AN5+AO5+AP5+AQ5+AR5+AS5+AT5+AU5+AV5+AW5+AX5+AY5+AZ5+BA5+BB5+BC5+BD5+BE5+BF5 -> 6 | N5: 1 | Q5: 1 | AK5: 1 | AZ5: 1 | BC5: 1 | BF5: 1
A6: 4. | B6: Гиёҳвандлик моддалари билан боғлиқ аниқланган жиноий ҳолатлар | C6: =+BG6+D6+E6+F6+G6+H6+I6+J6+K6+L6+M6+N6+O6+P6+Q6+R6+S6+T6+U6+V6+W6+X6+Y6+Z6+AA6+AB6+AC6+AD6+AE6+AF6+AG6+AH6+AI6+AJ6+AK6+AL6+AM6+AN6+AO6+AP6+AQ6+AR6+AS6+AT6+AU6+AV6+AW6+AX6+AY6+AZ6+BA6+BB6+BC6+BD6+BE6+BF6 -> 3 | N6: 1 | Q6: 1 | BC6: 1
A7: 4.1. | B7: Олинган гиёҳвандлик моддари миқдори (грамм ҳисобида) | C7: =+BG7+D7+E7+F7+G7+H7+I7+J7+K7+L7+M7+N7+O7+P7+Q7+R7+S7+T7+U7+V7+W7+X7+Y7+Z7+AA7+AB7+AC7+AD7+AE7+AF7+AG7+AH7+AI7+AJ7+AK7+AL7+AM7+AN7+AO7+AP7+AQ7+AR7+AS7+AT7+AU7+AV7+AW7+AX7+AY7+AZ7+BA7+BB7+BC7+BD7+BE7+BF7 -> 151.94 | N7: 133.8 | Q7: 0.84 | BC7: 17.3
A8: 4.2. | B8: Гиёҳвандлик билан боғлиқ ҳолатлар юзасидан қўзғатилган жиноят ишлари | C8: =+BG8+D8+E8+F8+G8+H8+I8+J8+K8+L8+M8+N8+O8+P8+Q8+R8+S8+T8+U8+V8+W8+X8+Y8+Z8+AA8+AB8+AC8+AD8+AE8+AF8+AG8+AH8+AI8+AJ8+AK8+AL8+AM8+AN8+AO8+AP8+AQ8+AR8+AS8+AT8+AU8+AV8+AW8+AX8+AY8+AZ8+BA8+BB8+BC8+BD8+BE8+BF8 -> 3 | N8: 1 | Q8: 1 | BC8: 1
A9: 5. | B9: Аниқланган кучли таъсир қилувчи психотроп дори воситалари билан боғлиқ ҳолатлар | C9: =+BG9+D9+E9+F9+G9+H9+I9+J9+K9+L9+M9+N9+O9+P9+Q9+R9+S9+T9+U9+V9+W9+X9+Y9+Z9+AA9+AB9+AC9+AD9+AE9+AF9+AG9+AH9+AI9+AJ9+AK9+AL9+AM9+AN9+AO9+AP9+AQ9+AR9+AS9+AT9+AU9+AV9+AW9+AX9+AY9+AZ9+BA9+BB9+BC9+BD9+BE9+BF9 -> 1 | BF9: 1
A10: 5.1. | B10: Олинган кучли таъсир қилувчи психотроп воситалари сони (дона ҳисобида) | C10: =+BG10+D10+E10+F10+G10+H10+I10+J10+K10+L10+M10+N10+O10+P10+Q10+R10+S10+T10+U10+V10+W10+X10+Y10+Z10+AA10+AB10+AC10+AD10+AE10+AF10+AG10+AH10+AI10+AJ10+AK10+AL10+AM10+AN10+AO10+AP10+AQ10+AR10+AS10+AT10+AU10+AV10+AW10+AX10+AY10+AZ10+BA10+BB10+BC10+BD10+BE10+BF10 -> 398 | BF10: 398
A11: 5.2. | B11: Психотроп воситалар билан боғлиқ ҳолатлар юзасидан қўзғатилган жиноят ишлари | C11: =+BG11+D11+E11+F11+G11+H11+I11+J11+K11+L11+M11+N11+O11+P11+Q11+R11+S11+T11+U11+V11+W11+X11+Y11+Z11+AA11+AB11+AC11+AD11+AE11+AF11+AG11+AH11+AI11+AJ11+AK11+AL11+AM11+AN11+AO11+AP11+AQ11+AR11+AS11+AT11+AU11+AV11+AW11+AX11+AY11+AZ11+BA11+BB11+BC11+BD11+BE11+BF11 -> 0
A12: 6. | B12: Аниқланган нарколабораториялар | C12: =+BG12+D12+E12+F12+G12+H12+I12+J12+K12+L12+M12+N12+O12+P12+Q12+R12+S12+T12+U12+V12+W12+X12+Y12+Z12+AA12+AB12+AC12+AD12+AE12+AF12+AG12+AH12+AI12+AJ12+AK12+AL12+AM12+AN12+AO12+AP12+AQ12+AR12+AS12+AT12+AU12+AV12+AW12+AX12+AY12+AZ12+BA12+BB12+BC12+BD12+BE12+BF12 -> 0
A13: 8. | B13: Гиёҳвандлик воситалари ва психотроп моддалар муомаласи олдини олиш юзасидан «маҳалла еттилиги» аъзолари билан ўтказилган қисқа муддатли ўқув семинарлари | C13: =+BG13+D13+E13+F13+G13+H13+I13+J13+K13+L13+M13+N13+O13+P13+Q13+R13+S13+T13+U13+V13+W13+X13+Y13+Z13+AA13+AB13+AC13+AD13+AE13+AF13+AG13+AH13+AI13+AJ13+AK13+AL13+AM13+AN13+AO13+AP13+AQ13+AR13+AS13+AT13+AU13+AV13+AW13+AX13+AY13+AZ13+BA13+BB13+BC13+BD13+BE13+BF13 -> 2 | N13: 1 | BC13: 1
A14: 9. | B14: Гиёҳвандлик ва психотроп воситаларининг оғир оқибатлари юзасидан таълим муассасалрида ўтказилган профилактик тадбирлар | C14: =+BG14+D14+E14+F14+G14+H14+I14+J14+K14+L14+M14+N14+O14+P14+Q14+R14+S14+T14+U14+V14+W14+X14+Y14+Z14+AA14+AB14+AC14+AD14+AE14+AF14+AG14+AH14+AI14+AJ14+AK14+AL14+AM14+AN14+AO14+AP14+AQ14+AR14+AS14+AT14+AU14+AV14+AW14+AX14+AY14+AZ14+BA14+BB14+BC14+BD14+BE14+BF14 -> 2 | E14: 1 | O14: 1
A15: 10. | B15: ДЭО йўналишида аниқланган маъмурий ҳолатлар | C15: =+BG15+D15+E15+F15+G15+H15+I15+J15+K15+L15+M15+N15+O15+P15+Q15+R15+S15+T15+U15+V15+W15+X15+Y15+Z15+AA15+AB15+AC15+AD15+AE15+AF15+AG15+AH15+AI15+AJ15+AK15+AL15+AM15+AN15+AO15+AP15+AQ15+AR15+AS15+AT15+AU15+AV15+AW15+AX15+AY15+AZ15+BA15+BB15+BC15+BD15+BE15+BF15 -> 1 | BF15: 1
A16: шундан | B16: ноқонуний диний таълим бериш | C16: =+BG16+D16+E16+F16+G16+H16+I16+J16+K16+L16+M16+N16+O16+P16+Q16+R16+S16+T16+U16+V16+W16+X16+Y16+Z16+AA16+AB16+AC16+AD16+AE16+AF16+AG16+AH16+AI16+AJ16+AK16+AL16+AM16+AN16+AO16+AP16+AQ16+AR16+AS16+AT16+AU16+AV16+AW16+AX16+AY16+AZ16+BA16+BB16+BC16+BD16+BE16+BF16 -> 0
B17: таъқиқланган диний маълумотларни сақлаш ва ташиш | C17: =+BG17+D17+E17+F17+G17+H17+I17+J17+K17+L17+M17+N17+O17+P17+Q17+R17+S17+T17+U17+V17+W17+X17+Y17+Z17+AA17+AB17+AC17+AD17+AE17+AF17+AG17+AH17+AI17+AJ17+AK17+AL17+AM17+AN17+AO17+AP17+AQ17+AR17+AS17+AT17+AU17+AV17+AW17+AX17+AY17+AZ17+BA17+BB17+BC17+BD17+BE17+BF17 -> 0
A18: 11. | B18: ДЭО йўналишида аниқланган жиноий ҳолатлар | C18: =+BG18+D18+E18+F18+G18+H18+I18+J18+K18+L18+M18+N18+O18+P18+Q18+R18+S18+T18+U18+V18+W18+X18+Y18+Z18+AA18+AB18+AC18+AD18+AE18+AF18+AG18+AH18+AI18+AJ18+AK18+AL18+AM18+AN18+AO18+AP18+AQ18+AR18+AS18+AT18+AU18+AV18+AW18+AX18+AY18+AZ18+BA18+BB18+BC18+BD18+BE18+BF18 -> 0
A19: шундан | B19: "ҳужралар" | C19: =+BG19+D19+E19+F19+G19+H19+I19+J19+K19+L19+M19+N19+O19+P19+Q19+R19+S19+T19+U19+V19+W19+X19+Y19+Z19+AA19+AB19+AC19+AD19+AE19+AF19+AG19+AH19+AI19+AJ19+AK19+AL19+AM19+AN19+AO19+AP19+AQ19+AR19+AS19+AT19+AU19+AV19+AW19+AX19+AY19+AZ19+BA19+BB19+BC19+BD19+BE19+BF19 -> 0
B20: ҳужраларда таълим олган вояга етмаганлар | C20: =+BG20+D20+E20+F20+G20+H20+I20+J20+K20+L20+M20+N20+O20+P20+Q20+R20+S20+T20+U20+V20+W20+X20+Y20+Z20+AA20+AB20+AC20+AD20+AE20+AF20+AG20+AH20+AI20+AJ20+AK20+AL20+AM20+AN20+AO20+AP20+AQ20+AR20+AS20+AT20+AU20+AV20+AW20+AX20+AY20+AZ20+BA20+BB20+BC20+BD20+BE20+BF20 -> 0
A21: 12. | B21: Радикаллашувга қарши курашиш борасида олиб борилган тезкор профилактик тадбирлари | C21: =+BG21+D21+E21+F21+G21+H21+I21+J21+K21+L21+M21+N21+O21+P21+Q21+R21+S21+T21+U21+V21+W21+X21+Y21+Z21+AA21+AB21+AC21+AD21+AE21+AF21+AG21+AH21+AI21+AJ21+AK21+AL21+AM21+AN21+AO21+AP21+AQ21+AR21+AS21+AT21+AU21+AV21+AW21+AX21+AY21+AZ21+BA21+BB21+BC21+BD21+BE21+BF21 -> 12 | G21: 2 | AU21: 2 | AZ21: 4 | BC21: 2 | BD21: 2
A22: шундан | B22: Қайтарув гуруҳида олиб борилаётган профилактик тушунтириш ишлари | C22: =+BG22+D22+E22+F22+G22+H22+I22+J22+K22+L22+M22+N22+O22+P22+Q22+R22+S22+T22+U22+V22+W22+X22+Y22+Z22+AA22+AB22+AC22+AD22+AE22+AF22+AG22+AH22+AI22+AJ22+AK22+AL22+AM22+AN22+AO22+AP22+AQ22+AR22+AS22+AT22+AU22+AV22+AW22+AX22+AY22+AZ22+BA22+BB22+BC22+BD22+BE22+BF22 -> 10 | G22: 2 | AU22: 2 | AZ22: 4 | BC22: 2
B23: хорижда диструктив ғоя таъсири остига тушган шахслар билан олиб борилаётган филтрь сўров тадбирлари | C23: =+BG23+D23+E23+F23+G23+H23+I23+J23+K23+L23+M23+N23+O23+P23+Q23+R23+S23+T23+U23+V23+W23+X23+Y23+Z23+AA23+AB23+AC23+AD23+AE23+AF23+AG23+AH23+AI23+AJ23+AK23+AL23+AM23+AN23+AO23+AP23+AQ23+AR23+AS23+AT23+AU23+AV23+AW23+AX23+AY23+AZ23+BA23+BB23+BC23+BD23+BE23+BF23 -> 1 | BD23: 1
A24: 13. | B24: Кибер жиноятлар бўйича келиб тушган мурожаатлар | C24: =+BG24+D24+E24+F24+G24+H24+I24+J24+K24+L24+M24+N24+O24+P24+Q24+R24+S24+T24+U24+V24+W24+X24+Y24+Z24+AA24+AB24+AC24+AD24+AE24+AF24+AG24+AH24+AI24+AJ24+AK24+AL24+AM24+AN24+AO24+AP24+AQ24+AR24+AS24+AT24+AU24+AV24+AW24+AX24+AY24+AZ24+BA24+BB24+BC24+BD24+BE24+BF24 -> 5 | D24: 1 | I24: 1 | AD24: 1 | AJ24: 1 | AZ24: 1
A25: 14. | B25: Ҳолат бўйича қўзғатилган жиноят ишлари | C25: =+BG25+D25+E25+F25+G25+H25+I25+J25+K25+L25+M25+N25+O25+P25+Q25+R25+S25+T25+U25+V25+W25+X25+Y25+Z25+AA25+AB25+AC25+AD25+AE25+AF25+AG25+AH25+AI25+AJ25+AK25+AL25+AM25+AN25+AO25+AP25+AQ25+AR25+AS25+AT25+AU25+AV25+AW25+AX25+AY25+AZ25+BA25+BB25+BC25+BD25+BE25+BF25 -> 1 | AD25: 1
A26: 15. | B26: Фош этилган кибер жиноятлар | C26: =+BG26+D26+E26+F26+G26+H26+I26+J26+K26+L26+M26+N26+O26+P26+Q26+R26+S26+T26+U26+V26+W26+X26+Y26+Z26+AA26+AB26+AC26+AD26+AE26+AF26+AG26+AH26+AI26+AJ26+AK26+AL26+AM26+AN26+AO26+AP26+AQ26+AR26+AS26+AT26+AU26+AV26+AW26+AX26+AY26+AZ26+BA26+BB26+BC26+BD26+BE26+BF26 -> 1 | I26: 1
A27: 16. | B27: Таълим муассасаларида кибер жиноятларни олдини олиш бўйича амалга оширилган профилактик тарғибот тадбирлари | C27: =+BG27+D27+E27+F27+G27+H27+I27+J27+K27+L27+M27+N27+O27+P27+Q27+R27+S27+T27+U27+V27+W27+X27+Y27+Z27+AA27+AB27+AC27+AD27+AE27+AF27+AG27+AH27+AI27+AJ27+AK27+AL27+AM27+AN27+AO27+AP27+AQ27+AR27+AS27+AT27+AU27+AV27+AW27+AX27+AY27+AZ27+BA27+BB27+BC27+BD27+BE27+BF27 -> 4 | D27: 1 | AJ27: 1 | AK27: 1 | AQ27: 1
A28: 17. | B28: Ижтимоий тармоқларда кибер жиноятларни олдини олиш юзасидан амалга оширилган профилактик тадбирлар | C28: =+BG28+D28+E28+F28+G28+H28+I28+J28+K28+L28+M28+N28+O28+P28+Q28+R28+S28+T28+U28+V28+W28+X28+Y28+Z28+AA28+AB28+AC28+AD28+AE28+AF28+AG28+AH28+AI28+AJ28+AK28+AL28+AM28+AN28+AO28+AP28+AQ28+AR28+AS28+AT28+AU28+AV28+AW28+AX28+AY28+AZ28+BA28+BB28+BC28+BD28+BE28+BF28 -> 5 | BG28: 5
A29: 18. | B29: Аҳоли гавжум жойларга ўрнатилган кибер жиноятларни олдини олишга қаратилган баннер, плакат ва бошқа материаллар | C29: =+BG29+D29+E29+F29+G29+H29+I29+J29+K29+L29+M29+N29+O29+P29+Q29+R29+S29+T29+U29+V29+W29+X29+Y29+Z29+AA29+AB29+AC29+AD29+AE29+AF29+AG29+AH29+AI29+AJ29+AK29+AL29+AM29+AN29+AO29+AP29+AQ29+AR29+AS29+AT29+AU29+AV29+AW29+AX29+AY29+AZ29+BA29+BB29+BC29+BD29+BE29+BF29 -> 1 | BF29: 1

Sheet 01.24
A1: № | B1: Кўрсаткич | C1: Жами | D1: Ал-Хоразмий | E1: Бахористон | F1: Бектўпи | G1: Гулистон | H1: Катта Хирмонтепа | I1: Тирсакобод | J1: Хайрабод | K1: Хирмон тепа | L1: Хонтўпи | M1: Шараф | N1: Шарқ | O1: Шарқ тонги | P1: Шухрат | Q1: 1-Чарх Камолон | R1: 2-Чарх Камолон | S1: 3-Чарх Камолон | T1: Бешёғоч | U1: Катта Козиробод | V1: Катта Олмазор | W1: Катта Чилонзор-1 | X1: Катта Чилонзор-2 | Y1: Катта Чилонзор-3 | Z1: Қозиробод | AA1: Новза | AB1: Чилонзор | AC1: 1-Қатортол | AD1: Бешчинор | AE1: Боғзор | AF1: Диёр | AG1: Дилобод | AH1: Катта Навбаҳор | AI1: Кўркам | AJ1: Кўтарма | AK1: Қатортол | AL1: Лутфий | AM1: Навбахор | AN1: Нафосат | AO1: Оқ-тепа | AP1: Халқлар Дўстлиги | AQ1: Чўпон-ота | AR1: 2-Қатортол | AS1: Ботирма | AT1: Бўрижар | AU1: Гавхар | AV1: Дўмбиробод | AW1: Зарқўрғон | AX1: Катта Дўмбиробод | AY1: Кичик Хирмонтепа | AZ1: Мевазор | BA1: Мехржон | BB1: Наққошлик | BC1: Фидокор | BD1: Яккабоғ | BE1: Яккатут | BF1: Бешқўрғон | BG1: бошқа ҳудуд
A2: 1. | B2: Фош этилган жиноятлар | C2: =+BG2+D2+E2+F2+G2+H2+I2+J2+K2+L2+M2+N2+O2+P2+Q2+R2+S2+T2+U2+V2+W2+X2+Y2+Z2+AA2+AB2+AC2+AD2+AE2+AF2+AG2+AH2+AI2+AJ2+AK2+AL2+AM2+AN2+AO2+AP2+AQ2+AR2+AS2+AT2+AU2+AV2+AW2+AX2+AY2+AZ2+BA2+BB2+BC2+BD2+BE2+BF2 -> 2 | T2: 1 | AW2: 1
A3: 2. | B3: Ушланган қидирувдаги шахслар | C3: =+BG3+D3+E3+F3+G3+H3+I3+J3+K3+L3+M3+N3+O3+P3+Q3+R3+S3+T3+U3+V3+W3+X3+Y3+Z3+AA3+AB3+AC3+AD3+AE3+AF3+AG3+AH3+AI3+AJ3+AK3+AL3+AM3+AN3+AO3+AP3+AQ3+AR3+AS3+AT3+AU3+AV3+AW3+AX3+AY3+AZ3+BA3+BB3+BC3+BD3+BE3+BF3 -> 0
A4: 3. | B4: Аниқланган бедарак йўқолган шахслар | C4: =+BG4+D4+E4+F4+G4+H4+I4+J4+K4+L4+M4+N4+O4+P4+Q4+R4+S4+T4+U4+V4+W4+X4+Y4+Z4+AA4+AB4+AC4+AD4+AE4+AF4+AG4+AH4+AI4+AJ4+AK4+AL4+AM4+AN4+AO4+AP4+AQ4+AR4+AS4+AT4+AU4+AV4+AW4+AX4+AY4+AZ4+BA4+BB4+BC4+BD4+BE4+BF4 -> 1 | AS4: 1
A5: 4. | B5: Аниқланган жиноятлар | C5: =+BG5+D5+E5+F5+G5+H5+I5+J5+K5+L5+M5+N5+O5+P5+Q5+R5+S5+T5+U5+V5+W5+X5+Y5+Z5+AA5+AB5+AC5+AD5+AE5+AF5+AG5+AH5+AI5+AJ5+AK5+AL5+AM5+AN5+AO5+AP5+AQ5+AR5+AS5+AT5+AU5+AV5+AW5+AX5+AY5+AZ5+BA5+BB5+BC5+BD5+BE5+BF5 -> 2 | AM5: 1 | BF5: 1
A6: 4. | B6: Гиёҳвандлик моддалари билан боғлиқ аниқланган жиноий ҳолатлар | C6: =+BG6+D6+E6+F6+G6+H6+I6+J6+K6+L6+M6+N6+O6+P6+Q6+R6+S6+T6+U6+V6+W6+X6+Y6+Z6+AA6+AB6+AC6+AD6+AE6+AF6+AG6+AH6+AI6+AJ6+AK6+AL6+AM6+AN6+AO6+AP6+AQ6+AR6+AS6+AT6+AU6+AV6+AW6+AX6+AY6+AZ6+BA6+BB6+BC6+BD6+BE6+BF6 -> 1 | BF6: 1
A7: 4.1. | B7: Олинган гиёҳвандлик моддари миқдори (грамм ҳисобида) | C7: =+BG7+D7+E7+F7+G7+H7+I7+J7+K7+L7+M7+N7+O7+P7+Q7+R7+S7+T7+U7+V7+W7+X7+Y7+Z7+AA7+AB7+AC7+AD7+AE7+AF7+AG7+AH7+AI7+AJ7+AK7+AL7+AM7+AN7+AO7+AP7+AQ7+AR7+AS7+AT7+AU7+AV7+AW7+AX7+AY7+AZ7+BA7+BB7+BC7+BD7+BE7+BF7 -> 2.33 | BF7: 2.33
A8: 4.2. | B8: Гиёҳвандлик билан боғлиқ ҳолатлар юзасидан қўзғатилган жиноят ишлари | C8: =+BG8+D8+E8+F8+G8+H8+I8+J8+K8+L8+M8+N8+O8+P8+Q8+R8+S8+T8+U8+V8+W8+X8+Y8+Z8+AA8+AB8+AC8+AD8+AE8+AF8+AG8+AH8+AI8+AJ8+AK8+AL8+AM8+AN8+AO8+AP8+AQ8+AR8+AS8+AT8+AU8+AV8+AW8+AX8+AY8+AZ8+BA8+BB8+BC8+BD8+BE8+BF8 -> 1 | BF8: 1
A9: 5. | B9: Аниқланган кучли таъсир қилувчи психотроп дори воситалари билан боғлиқ ҳолатлар | C9: =+BG9+D9+E9+F9+G9+H9+I9+J9+K9+L9+M9+N9+O9+P9+Q9+R9+S9+T9+U9+V9+W9+X9+Y9+Z9+AA9+AB9+AC9+AD9+AE9+AF9+AG9+AH9+AI9+AJ9+AK9+AL9+AM9+AN9+AO9+AP9+AQ9+AR9+AS9+AT9+AU9+AV9+AW9+AX9+AY9+AZ9+BA9+BB9+BC9+BD9+BE9+BF9 -> 0
A10: 5.1. | B10: Олинган кучли таъсир қилувчи психотроп воситалари сони (дона ҳисобида) | C10: =+BG10+D10+E10+F10+G10+H10+I10+J10+K10+L10+M10+N10+O10+P10+Q10+R10+S10+T10+U10+V10+W10+X10+Y10+Z10+AA10+AB10+AC10+AD10+AE10+AF10+AG10+AH10+AI10+AJ10+AK10+AL10+AM10+AN10+AO10+AP10+AQ10+AR10+AS10+AT10+AU10+AV10+AW10+AX10+AY10+AZ10+BA10+BB10+BC10+BD10+BE10+BF10 -> 0
A11: 5.2. | B11: Психотроп воситалар билан боғлиқ ҳолатлар юзасидан қўзғатилган жиноят ишлари | C11: =+BG11+D11+E11+F11+G11+H11+I11+J11+K11+L11+M11+N11+O11+P11+Q11+R11+S11+T11+U11+V11+W11+X11+Y11+Z11+AA11+AB11+AC11+AD11+AE11+AF11+AG11+AH11+AI11+AJ11+AK11+AL11+AM11+AN11+AO11+AP11+AQ11+AR11+AS11+AT11+AU11+AV11+AW11+AX11+AY11+AZ11+BA11+BB11+BC11+BD11+BE11+BF11 -> 1 | BF11: 1
A12: 6. | B12: Аниқланган нарколабораториялар | C12: =+BG12+D12+E12+F12+G12+H12+I12+J12+K12+L12+M12+N12+O12+P12+Q12+R12+S12+T12+U12+V12+W12+X12+Y12+Z12+AA12+AB12+AC12+AD12+AE12+AF12+AG12+AH12+AI12+AJ12+AK12+AL12+AM12+AN12+AO12+AP12+AQ12+AR12+AS12+AT12+AU12+AV12+AW12+AX12+AY12+AZ12+BA12+BB12+BC12+BD12+BE12+BF12 -> 0
A13: 8. | B13: Гиёҳвандлик воситалари ва психотроп моддалар муомаласи олдини олиш юзасидан «маҳалла еттилиги» аъзолари билан ўтказилган қисқа муддатли ўқув семинарлари | C13: =+BG13+D13+E13+F13+G13+H13+I13+J13+K13+L13+M13+N13+O13+P13+Q13+R13+S13+T13+U13+V13+W13+X13+Y13+Z13+AA13+AB13+AC13+AD13+AE13+AF13+AG13+AH13+AI13+AJ13+AK13+AL13+AM13+AN13+AO13+AP13+AQ13+AR13+AS13+AT13+AU13+AV13+AW13+AX13+AY13+AZ13+BA13+BB13+BC13+BD13+BE13+BF13 -> 1 | G13: 1
A14: 9. | B14: Гиёҳвандлик ва психотроп воситаларининг оғир оқибатлари юзасидан таълим муассасалрида ўтказилган профилактик тадбирлар | C14: =+BG14+D14+E14+F14+G14+H14+I14+J14+K14+L14+M14+N14+O14+P14+Q14+R14+S14+T14+U14+V14+W14+X14+Y14+Z14+AA14+AB14+AC14+AD14+AE14+AF14+AG14+AH14+AI14+AJ14+AK14+AL14+AM14+AN14+AO14+AP14+AQ14+AR14+AS14+AT14+AU14+AV14+AW14+AX14+AY14+AZ14+BA14+BB14+BC14+BD14+BE14+BF14 -> 1 | G14: 1
A15: 10. | B15: ДЭО йўналишида аниқланган маъмурий ҳолатлар | C15: =+BG15+D15+E15+F15+G15+H15+I15+J15+K15+L15+M15+N15+O15+P15+Q15+R15+S15+T15+U15+V15+W15+X15+Y15+Z15+AA15+AB15+AC15+AD15+AE15+AF15+AG15+AH15+AI15+AJ15+AK15+AL15+AM15+AN15+AO15+AP15+AQ15+AR15+AS15+AT15+AU15+AV15+AW15+AX15+AY15+AZ15+BA15+BB15+BC15+BD15+BE15+BF15 -> 0
A16: шундан | B16: ноқонуний диний таълим бериш | C16: =+BG16+D16+E16+F16+G16+H16+I16+J16+K16+L16+M16+N16+O16+P16+Q16+R16+S16+T16+U16+V16+W16+X16+Y16+Z16+AA16+AB16+AC16+AD16+AE16+AF16+AG16+AH16+AI16+AJ16+AK16+AL16+AM16+AN16+AO16+AP16+AQ16+AR16+AS16+AT16+AU16+AV16+AW16+AX16+AY16+AZ16+BA16+BB16+BC16+BD16+BE16+BF16 -> 0
B17: таъқиқланган диний маълумотларни сақлаш ва ташиш | C17: =+BG17+D17+E17+F17+G17+H17+I17+J17+K17+L17+M17+N17+O17+P17+Q17+R17+S17+T17+U17+V17+W17+X17+Y17+Z17+AA17+AB17+AC17+AD17+AE17+AF17+AG17+AH17+AI17+AJ17+AK17+AL17+AM17+AN17+AO17+AP17+AQ17+AR17+AS17+AT17+AU17+AV17+AW17+AX17+AY17+AZ17+BA17+BB17+BC17+BD17+BE17+BF17 -> 0
A18: 11. | B18: ДЭО йўналишида аниқланган жиноий ҳолатлар | C18: =+BG18+D18+E18+F18+G18+H18+I18+J18+K18+L18+M18+N18+O18+P18+Q18+R18+S18+T18+U18+V18+W18+X18+Y18+Z18+AA18+AB18+AC18+AD18+AE18+AF18+AG18+AH18+AI18+AJ18+AK18+AL18+AM18+AN18+AO18+AP18+AQ18+AR18+AS18+AT18+AU18+AV18+AW18+AX18+AY18+AZ18+BA18+BB18+BC18+BD18+BE18+BF18 -> 0
A19: шундан | B19: "ҳужралар" | C19: =+BG19+D19+E19+F19+G19+H19+I19+J19+K19+L19+M19+N19+O19+P19+Q19+R19+S19+T19+U19+V19+W19+X19+Y19+Z19+AA19+AB19+AC19+AD19+AE19+AF19+AG19+AH19+AI19+AJ19+AK19+AL19+AM19+AN19+AO19+AP19+AQ19+AR19+AS19+AT19+AU19+AV19+AW19+AX19+AY19+AZ19+BA19+BB19+BC19+BD19+BE19+BF19 -> 0
B20: ҳужраларда таълим олган вояга етмаганлар | C20: =+BG20+D20+E20+F20+G20+H20+I20+J20+K20+L20+M20+N20+O20+P20+Q20+R20+S20+T20+U20+V20+W20+X20+Y20+Z20+AA20+AB20+AC20+AD20+AE20+AF20+AG20+AH20+AI20+AJ20+AK20+AL20+AM20+AN20+AO20+AP20+AQ20+AR20+AS20+AT20+AU20+AV20+AW20+AX20+AY20+AZ20+BA20+BB20+BC20+BD20+BE20+BF20 -> 0
A21: 12. | B21: Радикаллашувга қарши курашиш борасида олиб борилган тезкор профилактик тадбирлари | C21: =+BG21+D21+E21+F21+G21+H21+I21+J21+K21+L21+M21+N21+O21+P21+Q21+R21+S21+T21+U21+V21+W21+X21+Y21+Z21+AA21+AB21+AC21+AD21+AE21+AF21+AG21+AH21+AI21+AJ21+AK21+AL21+AM21+AN21+AO21+AP21+AQ21+AR21+AS21+AT21+AU21+AV21+AW21+AX21+AY21+AZ21+BA21+BB21+BC21+BD21+BE21+BF21 -> 12 | Q21: 3 | Z21: 2 | AE21: 3 | AK21: 2 | BD21: 1 | BF21: 1
A22: шундан | B22: Қайтарув гуруҳида олиб борилаётган профилактик тушунтириш ишлари | C22: =+BG22+D22+E22+F22+G22+H22+I22+J22+K22+L22+M22+N22+O22+P22+Q22+R22+S22+T22+U22+V22+W22+X22+Y22+Z22+AA22+AB22+AC22+AD22+AE22+AF22+AG22+AH22+AI22+AJ22+AK22+AL22+AM22+AN22+AO22+AP22+AQ22+AR22+AS22+AT22+AU22+AV22+AW22+AX22+AY22+AZ22+BA22+BB22+BC22+BD22+BE22+BF22 -> 10 | Q22: 3 | Z22: 2 | AE22: 3 | AK22: 2
B23: хорижда диструктив ғоя таъсири остига тушган шахслар билан олиб борилаётган филтрь сўров тадбирлари | C23: =+BG23+D23+E23+F23+G23+H23+I23+J23+K23+L23+M23+N23+O23+P23+Q23+R23+S23+T23+U23+V23+W23+X23+Y23+Z23+AA23+AB23+AC23+AD23+AE23+AF23+AG23+AH23+AI23+AJ23+AK23+AL23+AM23+AN23+AO23+AP23+AQ23+AR23+AS23+AT23+AU23+AV23+AW23+AX23+AY23+AZ23+BA23+BB23+BC23+BD23+BE23+BF23 -> 1 | BF23: 1
A24: 13. | B24: Кибер жиноятлар бўйича келиб тушган мурожаатлар | C24: =+BG24+D24+E24+F24+G24+H24+I24+J24+K24+L24+M24+N24+O24+P24+Q24+R24+S24+T24+U24+V24+W24+X24+Y24+Z24+AA24+AB24+AC24+AD24+AE24+AF24+AG24+AH24+AI24+AJ24+AK24+AL24+AM24+AN24+AO24+AP24+AQ24+AR24+AS24+AT24+AU24+AV24+AW24+AX24+AY24+AZ24+BA24+BB24+BC24+BD24+BE24+BF24 -> 6 | D24: 1 | T24: 1 | X24: 1 | AD24: 1 | AT24: 1 | AV24: 1
A25: 14. | B25: Ҳолат бўйича қўзғатилган жиноят ишлари | C25: =+BG25+D25+E25+F25+G25+H25+I25+J25+K25+L25+M25+N25+O25+P25+Q25+R25+S25+T25+U25+V25+W25+X25+Y25+Z25+AA25+AB25+AC25+AD25+AE25+AF25+AG25+AH25+AI25+AJ25+AK25+AL25+AM25+AN25+AO25+AP25+AQ25+AR25+AS25+AT25+AU25+AV25+AW25+AX25+AY25+AZ25+BA25+BB25+BC25+BD25+BE25+BF25 -> 9 | AA25: 1 | AB25: 1 | AG25: 1 | AH25: 1 | AJ25: 1 | AO25: 1 | AW25: 1 | AX25: 1 | BB25: 1
A26: 15. | B26: Фош этилган кибер жиноятлар | C26: =+BG26+D26+E26+F26+G26+H26+I26+J26+K26+L26+M26+N26+O26+P26+Q26+R26+S26+T26+U26+V26+W26+X26+Y26+Z26+AA26+AB26+AC26+AD26+AE26+AF26+AG26+AH26+AI26+AJ26+AK26+AL26+AM26+AN26+AO26+AP26+AQ26+AR26+AS26+AT26+AU26+AV26+AW26+AX26+AY26+AZ26+BA26+BB26+BC26+BD26+BE26+BF26 -> 1 | K26: 1
A27: 16. | B27: Таълим муассасаларида кибер жиноятларни олдини олиш бўйича амалга оширилган профилактик тарғибот тадбирлари | C27: =+BG27+D27+E27+F27+G27+H27+I27+J27+K27+L27+M27+N27+O27+P27+Q27+R27+S27+T27+U27+V27+W27+X27+Y27+Z27+AA27+AB27+AC27+AD27+AE27+AF27+AG27+AH27+AI27+AJ27+AK27+AL27+AM27+AN27+AO27+AP27+AQ27+AR27+AS27+AT27+AU27+AV27+AW27+AX27+AY27+AZ27+BA27+BB27+BC27+BD27+BE27+BF27 -> 3 | W27: 1 | X27: 1 | Y27: 1
A28: 17. | B28: Ижтимоий тармоқларда кибер жиноятларни олдини олиш юзасидан амалга оширилган профилактик тадбирлар | C28: =+BG28+D28+E28+F28+G28+H28+I28+J28+K28+L28+M28+N28+O28+P28+Q28+R28+S28+T28+U28+V28+W28+X28+Y28+Z28+AA28+AB28+AC28+AD28+AE28+AF28+AG28+AH28+AI28+AJ28+AK28+AL28+AM28+AN28+AO28+AP28+AQ28+AR28+AS28+AT28+AU28+AV28+AW28+AX28+AY28+AZ28+BA28+BB28+BC28+BD28+BE28+BF28 -> 3 | BG28: 3
A29: 18. | B29: Аҳоли гавжум жойларга ўрнатилган кибер жиноятларни олдини олишга қаратилган баннер, плакат ва бошқа материаллар | C29: =+BG29+D29+E29+F29+G29+H29+I29+J29+K29+L29+M29+N29+O29+P29+Q29+R29+S29+T29+U29+V29+W29+X29+Y29+Z29+AA29+AB29+AC29+AD29+AE29+AF29+AG29+AH29+AI29+AJ29+AK29+AL29+AM29+AN29+AO29+AP29+AQ29+AR29+AS29+AT29+AU29+AV29+AW29+AX29+AY29+AZ29+BA29+BB29+BC29+BD29+BE29+BF29 -> 0

Sheet 01.25
A1: № | B1: Кўрсаткич | C1: Жами | D1: Ал-Хоразмий | E1: Бахористон | F1: Бектўпи | G1: Гулистон | H1: Катта Хирмонтепа | I1: Тирсакобод | J1: Хайрабод | K1: Хирмон тепа | L1: Хонтўпи | M1: Шараф | N1: Шарқ | O1: Шарқ тонги | P1: Шухрат | Q1: 1-Чарх Камолон | R1: 2-Чарх Камолон | S1: 3-Чарх Камолон | T1: Бешёғоч | U1: Катта Козиробод | V1: Катта Олмазор | W1: Катта Чилонзор-1 | X1: Катта Чилонзор-2 | Y1: Катта Чилонзор-3 | Z1: Қозиробод | AA1: Новза | AB1: Чилонзор | AC1: 1-Қатортол | AD1: Бешчинор | AE1: Боғзор | AF1: Диёр | AG1: Дилобод | AH1: Катта Навбаҳор | AI1: Кўркам | AJ1: Кўтарма | AK1: Қатортол | AL1: Лутфий | AM1: Навбахор | AN1: Нафосат | AO1: Оқ-тепа | AP1: Халқлар Дўстлиги | AQ1: Чўпон-ота | AR1: 2-Қатортол | AS1: Ботирма | AT1: Бўрижар | AU1: Гавхар | AV1: Дўмбиробод | AW1: Зарқўрғон | AX1: Катта Дўмбиробод | AY1: Кичик Хирмонтепа | AZ1: Мевазор | BA1: Мехржон | BB1: Наққошлик | BC1: Фидокор | BD1: Яккабоғ | BE1: Яккатут | BF1: Бешқўрғон | BG1: бошқа ҳудуд
A2: 1. | B2: Фош этилган жиноятлар | C2: =+BG2+D2+E2+F2+G2+H2+I2+J2+K2+L2+M2+N2+O2+P2+Q2+R2+S2+T2+U2+V2+W2+X2+Y2+Z2+AA2+AB2+AC2+AD2+AE2+AF2+AG2+AH2+AI2+AJ2+AK2+AL2+AM2+AN2+AO2+AP2+AQ2+AR2+AS2+AT2+AU2+AV2+AW2+AX2+AY2+AZ2+BA2+BB2+BC2+BD2+BE2+BF2 -> 1 | Z2: 1
A3: 2. | B3: Ушланган қидирувдаги шахслар | C3: =+BG3+D3+E3+F3+G3+H3+I3+J3+K3+L3+M3+N3+O3+P3+Q3+R3+S3+T3+U3+V3+W3+X3+Y3+Z3+AA3+AB3+AC3+AD3+AE3+AF3+AG3+AH3+AI3+AJ3+AK3+AL3+AM3+AN3+AO3+AP3+AQ3+AR3+AS3+AT3+AU3+AV3+AW3+AX3+AY3+AZ3+BA3+BB3+BC3+BD3+BE3+BF3 -> 0
A4: 3. | B4: Аниқланган бедарак йўқолган шахслар | C4: =+BG4+D4+E4+F4+G4+H4+I4+J4+K4+L4+M4+N4+O4+P4+Q4+R4+S4+T4+U4+V4+W4+X4+Y4+Z4+AA4+AB4+AC4+AD4+AE4+AF4+AG4+AH4+AI4+AJ4+AK4+AL4+AM4+AN4+AO4+AP4+AQ4+AR4+AS4+AT4+AU4+AV4+AW4+AX4+AY4+AZ4+BA4+BB4+BC4+BD4+BE4+BF4 -> 2 | N4: 1 | AS4: 1
A5: 4. | B5: Аниқланган жиноятлар | C5: =+BG5+D5+E5+F5+G5+H5+I5+J5+K5+L5+M5+N5+O5+P5+Q5+R5+S5+T5+U5+V5+W5+X5+Y5+Z5+AA5+AB5+AC5+AD5+AE5+AF5+AG5+AH5+AI5+AJ5+AK5+AL5+AM5+AN5+AO5+AP5+AQ5+AR5+AS5+AT5+AU5+AV5+AW5+AX5+AY5+AZ5+BA5+BB5+BC5+BD5+BE5+BF5 -> 3 | F5: 1 | X5: 1 | AJ5: 1
A6: 4. | B6: Гиёҳвандлик моддалари билан боғлиқ аниқланган жиноий ҳолатлар | C6: =+BG6+D6+E6+F6+G6+H6+I6+J6+K6+L6+M6+N6+O6+P6+Q6+R6+S6+T6+U6+V6+W6+X6+Y6+Z6+AA6+AB6+AC6+AD6+AE6+AF6+AG6+AH6+AI6+AJ6+AK6+AL6+AM6+AN6+AO6+AP6+AQ6+AR6+AS6+AT6+AU6+AV6+AW6+AX6+AY6+AZ6+BA6+BB6+BC6+BD6+BE6+BF6 -> 2 | X6: 1 | AJ6: 1
A7: 4.1. | B7: Олинган гиёҳвандлик моддари миқдори (грамм ҳисобида) | C7: =+BG7+D7+E7+F7+G7+H7+I7+J7+K7+L7+M7+N7+O7+P7+Q7+R7+S7+T7+U7+V7+W7+X7+Y7+Z7+AA7+AB7+AC7+AD7+AE7+AF7+AG7+AH7+AI7+AJ7+AK7+AL7+AM7+AN7+AO7+AP7+AQ7+AR7+AS7+AT7+AU7+AV7+AW7+AX7+AY7+AZ7+BA7+BB7+BC7+BD7+BE7+BF7 -> 1 | X7: 0.5 | AJ7: 0.5
A8: 4.2. | B8: Гиёҳвандлик билан боғлиқ ҳолатлар юзасидан қўзғатилган жиноят ишлари | C8: =+BG8+D8+E8+F8+G8+H8+I8+J8+K8+L8+M8+N8+O8+P8+Q8+R8+S8+T8+U8+V8+W8+X8+Y8+Z8+AA8+AB8+AC8+AD8+AE8+AF8+AG8+AH8+AI8+AJ8+AK8+AL8+AM8+AN8+AO8+AP8+AQ8+AR8+AS8+AT8+AU8+AV8+AW8+AX8+AY8+AZ8+BA8+BB8+BC8+BD8+BE8+BF8 -> 2 | X8: 1 | AJ8: 1
A9: 5. | B9: Аниқланган кучли таъсир қилувчи психотроп дори воситалари билан боғлиқ ҳолатлар | C9: =+BG9+D9+E9+F9+G9+H9+I9+J9+K9+L9+M9+N9+O9+P9+Q9+R9+S9+T9+U9+V9+W9+X9+Y9+Z9+AA9+AB9+AC9+AD9+AE9+AF9+AG9+AH9+AI9+AJ9+AK9+AL9+AM9+AN9+AO9+AP9+AQ9+AR9+AS9+AT9+AU9+AV9+AW9+AX9+AY9+AZ9+BA9+BB9+BC9+BD9+BE9+BF9 -> 1 | BC9: 1
A10: 5.1. | B10: Олинган кучли таъсир қилувчи психотроп воситалари сони (дона ҳисобида) | C10: =+BG10+D10+E10+F10+G10+H10+I10+J10+K10+L10+M10+N10+O10+P10+Q10+R10+S10+T10+U10+V10+W10+X10+Y10+Z10+AA10+AB10+AC10+AD10+AE10+AF10+AG10+AH10+AI10+AJ10+AK10+AL10+AM10+AN10+AO10+AP10+AQ10+AR10+AS10+AT10+AU10+AV10+AW10+AX10+AY10+AZ10+BA10+BB10+BC10+BD10+BE10+BF10 -> 200 | BC10: 200
A11: 5.2. | B11: Психотроп воситалар билан боғлиқ ҳолатлар юзасидан қўзғатилган жиноят ишлари | C11: =+BG11+D11+E11+F11+G11+H11+I11+J11+K11+L11+M11+N11+O11+P11+Q11+R11+S11+T11+U11+V11+W11+X11+Y11+Z11+AA11+AB11+AC11+AD11+AE11+AF11+AG11+AH11+AI11+AJ11+AK11+AL11+AM11+AN11+AO11+AP11+AQ11+AR11+AS11+AT11+AU11+AV11+AW11+AX11+AY11+AZ11+BA11+BB11+BC11+BD11+BE11+BF11 -> 1 | BC11: 1
A12: 6. | B12: Аниқланган нарколабораториялар | C12: =+BG12+D12+E12+F12+G12+H12+I12+J12+K12+L12+M12+N12+O12+P12+Q12+R12+S12+T12+U12+V12+W12+X12+Y12+Z12+AA12+AB12+AC12+AD12+AE12+AF12+AG12+AH12+AI12+AJ12+AK12+AL12+AM12+AN12+AO12+AP12+AQ12+AR12+AS12+AT12+AU12+AV12+AW12+AX12+AY12+AZ12+BA12+BB12+BC12+BD12+BE12+BF12 -> 0
A13: 8. | B13: Гиёҳвандлик воситалари ва психотроп моддалар муомаласи олдини олиш юзасидан «маҳалла еттилиги» аъзолари билан ўтказилган қисқа муддатли ўқув семинарлари | C13: =+BG13+D13+E13+F13+G13+H13+I13+J13+K13+L13+M13+N13+O13+P13+Q13+R13+S13+T13+U13+V13+W13+X13+Y13+Z13+AA13+AB13+AC13+AD13+AE13+AF13+AG13+AH13+AI13+AJ13+AK13+AL13+AM13+AN13+AO13+AP13+AQ13+AR13+AS13+AT13+AU13+AV13+AW13+AX13+AY13+AZ13+BA13+BB13+BC13+BD13+BE13+BF13 -> 1 | AD13: 1
A14: 9. | B14: Гиёҳвандлик ва психотроп воситаларининг оғир оқибатлари юзасидан таълим муассасалрида ўтказилган профилактик тадбирлар | C14: =+BG14+D14+E14+F14+G14+H14+I14+J14+K14+L14+M14+N14+O14+P14+Q14+R14+S14+T14+U14+V14+W14+X14+Y14+Z14+AA14+AB14+AC14+AD14+AE14+AF14+AG14+AH14+AI14+AJ14+AK14+AL14+AM14+AN14+AO14+AP14+AQ14+AR14+AS14+AT14+AU14+AV14+AW14+AX14+AY14+AZ14+BA14+BB14+BC14+BD14+BE14+BF14 -> 2 | AD14: 2
A15: 10. | B15: ДЭО йўналишида аниқланган маъмурий ҳолатлар | C15: =+BG15+D15+E15+F15+G15+H15+I15+J15+K15+L15+M15+N15+O15+P15+Q15+R15+S15+T15+U15+V15+W15+X15+Y15+Z15+AA15+AB15+AC15+AD15+AE15+AF15+AG15+AH15+AI15+AJ15+AK15+AL15+AM15+AN15+AO15+AP15+AQ15+AR15+AS15+AT15+AU15+AV15+AW15+AX15+AY15+AZ15+BA15+BB15+BC15+BD15+BE15+BF15 -> 0
A16: шундан | B16: ноқонуний диний таълим бериш | C16: =+BG16+D16+E16+F16+G16+H16+I16+J16+K16+L16+M16+N16+O16+P16+Q16+R16+S16+T16+U16+V16+W16+X16+Y16+Z16+AA16+AB16+AC16+AD16+AE16+AF16+AG16+AH16+AI16+AJ16+AK16+AL16+AM16+AN16+AO16+AP16+AQ16+AR16+AS16+AT16+AU16+AV16+AW16+AX16+AY16+AZ16+BA16+BB16+BC16+BD16+BE16+BF16 -> 0
B17: таъқиқланган диний маълумотларни сақлаш ва ташиш | C17: =+BG17+D17+E17+F17+G17+H17+I17+J17+K17+L17+M17+N17+O17+P17+Q17+R17+S17+T17+U17+V17+W17+X17+Y17+Z17+AA17+AB17+AC17+AD17+AE17+AF17+AG17+AH17+AI17+AJ17+AK17+AL17+AM17+AN17+AO17+AP17+AQ17+AR17+AS17+AT17+AU17+AV17+AW17+AX17+AY17+AZ17+BA17+BB17+BC17+BD17+BE17+BF17 -> 0
