Workbook

Sheet 01.20
A1: № | B1: Кўрсаткич | C1: Жами | D1: Ал-Хоразмий | E1: Бахористон | F1: Бектўпи | G1: Гулистон | H1: Катта Хирмонтепа | I1: Тирсакобод | J1: Хайрабод | K1: Хирмон тепа | L1: Хонтўпи | M1: Шараф | N1: Шарқ | O1: Шарқ тонги | P1: Шухрат | Q1: 1-Чарх Камолон | R1: 2-Чарх Камолон | S1: 3-Чарх Камолон | T1: Бешёғоч | U1: Катта Козиробод | V1: Катта Олмазор | W1: Катта Чилонзор-1 | X1: Катта Чилонзор-2 | Y1: Катта Чилонзор-3 | Z1: Қозиробод | AA1: Новза | AB1: Чилонзор | AC1: 1-Қатортол | AD1: Бешчинор | AE1: Боғзор | AF1: Диёр | AG1: Дилобод | AH1: Катта Навбаҳор | AI1: Кўркам | AJ1: Кўтарма | AK1: Қатортол | AL1: Лутфий | AM1: Навбахор | AN1: Нафосат | AO1: Оқ-тепа | AP1: Халқлар Дўстлиги | AQ1: Чўпон-ота | AR1: 2-Қатортол | AS1: Ботирма | AT1: Бўрижар | AU1: Гавхар | AV1: Дўмбиробод | AW1: Зарқўрғон | AX1: Катта Дўмбиробод | AY1: Кичик Хирмонтепа | AZ1: Мевазор | BA1: Мехржон | BB1: Наққошлик | BC1: Фидокор | BD1: Яккабоғ | BE1: Яккатут | BF1: Бешқўрғон
A2: 1 | B2: Маданий-маърифий тадбирлар | C2: =+D2+E2+F2+G2+H2+I2+J2+K2+L2+M2+N2+O2+P2+Q2+R2+S2+T2+U2+V2+W2+X2+Y2+Z2+AA2+AB2+AC2+AD2+AE2+AF2+AG2+AH2+AI2+AJ2+AK2+AL2+AM2+AN2+AO2+AP2+AQ2+AR2+AS2+AT2+AU2+AV2+AW2+AX2+AY2+AZ2+BA2+BB2+BC2+BD2+BE2+BF2 -> 108 | E2: 3 | F2: 3 | G2: 3 | H2: 1 | I2: 3 | J2: 3 | K2: 3 | L2: 1 | N2: 3 | O2: 1 | P2: 3 | Q2: 3 | R2: 1 | S2: 3 | T2: 1 | U2: 1 | V2: 2 | W2: 2 | X2: 2 | Y2: 1 | Z2: 1 | AA2: 2 | AB2: 2 | AC2: 2 | AD2: 2 | AE2: 1 | AF2: 1 | AG2: 2 | AH2: 2 | AI2: 2 | AJ2: 2 | AK2: 1 | AL2: 4 | AN2: 2 | AO2: 1 | AP2: 4 | AQ2: 2 | AR2: 2 | AS2: 1 | AT2: 4 | AU2: 2 | AV2: 1 | AW2: 2 | AX2: 1 | AY2: 4 | AZ2: 1 | BA2: 2 | BB2: 1 | BC2: 4 | BD2: 2 | BE2: 1 | BF2: 4
B3: иштирок этган ёшлар сони | C3: =+D3+E3+F3+G3+H3+I3+J3+K3+L3+M3+N3+O3+P3+Q3+R3+S3+T3+U3+V3+W3+X3+Y3+Z3+AA3+AB3+AC3+AD3+AE3+AF3+AG3+AH3+AI3+AJ3+AK3+AL3+AM3+AN3+AO3+AP3+AQ3+AR3+AS3+AT3+AU3+AV3+AW3+AX3+AY3+AZ3+BA3+BB3+BC3+BD3+BE3+BF3 -> 326 | E3: 15 | F3: 8 | G3: 9 | H3: 2 | I3: 8 | J3: 8 | K3: 8 | L3: 2 | N3: 9 | O3: 2 | P3: 8 | Q3: 9 | R3: 2 | S3: 8 | T3: 4 | U3: 2 | V3: 6 | W3: 6 | X3: 6 | Y3: 4 | Z3: 2 | AA3: 6 | AB3: 6 | AC3: 6 | AD3: 6 | AE3: 4 | AF3: 2 | AG3: 6 | AH3: 6 | AI3: 6 | AJ3: 6 | AK3: 4 | AL3: 12 | AN3: 6 | AO3: 4 | AP3: 12 | AQ3: 6 | AR3: 6 | AS3: 4 | AT3: 12 | AU3: 6 | AV3: 4 | AW3: 6 | AX3: 4 | AY3: 12 | AZ3: 2 | BA3: 6 | BB3: 4 | BC3: 12 | BD3: 6 | BE3: 4 | BF3: 12
A4: 2 | B4: Ҳарбий ватанпарварлик тадбирлар | C4: =+D4+E4+F4+G4+H4+I4+J4+K4+L4+M4+N4+O4+P4+Q4+R4+S4+T4+U4+V4+W4+X4+Y4+Z4+AA4+AB4+AC4+AD4+AE4+AF4+AG4+AH4+AI4+AJ4+AK4+AL4+AM4+AN4+AO4+AP4+AQ4+AR4+AS4+AT4+AU4+AV4+AW4+AX4+AY4+AZ4+BA4+BB4+BC4+BD4+BE4+BF4 -> 58 | D4: 0 | F4: 1 | G4: 2 | H4: 2 | I4: 1 | J4: 2 | K4: 2 | L4: 1 | O4: 1 | P4: 2 | Q4: 2 | R4: 1 | U4: 1 | V4: 2 | Z4: 2 | AB4: 2 | AF4: 2 | AI4: 2 | AL4: 2 | AN4: 2 | AO4: 2 | AP4: 1 | AR4: 2 | AS4: 2 | AT4: 2 | AU4: 2 | AV4: 2 | AW4: 1 | AY4: 2 | AZ4: 2 | BA4: 2 | BB4: 1 | BD4: 2 | BE4: 2 | BF4: 1
B5: Иштирок этган ёшлар сони | C5: =+D5+E5+F5+G5+H5+I5+J5+K5+L5+M5+N5+O5+P5+Q5+R5+S5+T5+U5+V5+W5+X5+Y5+Z5+AA5+AB5+AC5+AD5+AE5+AF5+AG5+AH5+AI5+AJ5+AK5+AL5+AM5+AN5+AO5+AP5+AQ5+AR5+AS5+AT5+AU5+AV5+AW5+AX5+AY5+AZ5+BA5+BB5+BC5+BD5+BE5+BF5 -> 178 | F5: 2 | G5: 6 | H5: 6 | I5: 4 | J5: 6 | K5: 6 | L5: 4 | O5: 2 | P5: 6 | Q5: 6 | R5: 4 | U5: 2 | V5: 6 | Z5: 6 | AB5: 6 | AF5: 6 | AI5: 6 | AL5: 6 | AN5: 6 | AO5: 6 | AP5: 4 | AR5: 6 | AS5: 6 | AT5: 6 | AU5: 6 | AV5: 6 | AW5: 4 | AY5: 6 | AZ5: 6 | BA5: 6 | BB5: 4 | BD5: 6 | BE5: 6 | BF5: 4
A6: 3 | B6: “Беш ташаббус олимпиадаси” | C6: =+D6+E6+F6+G6+H6+I6+J6+K6+L6+M6+N6+O6+P6+Q6+R6+S6+T6+U6+V6+W6+X6+Y6+Z6+AA6+AB6+AC6+AD6+AE6+AF6+AG6+AH6+AI6+AJ6+AK6+AL6+AM6+AN6+AO6+AP6+AQ6+AR6+AS6+AT6+AU6+AV6+AW6+AX6+AY6+AZ6+BA6+BB6+BC6+BD6+BE6+BF6 -> 0
B7: рўҳатдан ўтган ёшлар сони | C7: =+D7+E7+F7+G7+H7+I7+J7+K7+L7+M7+N7+O7+P7+Q7+R7+S7+T7+U7+V7+W7+X7+Y7+Z7+AA7+AB7+AC7+AD7+AE7+AF7+AG7+AH7+AI7+AJ7+AK7+AL7+AM7+AN7+AO7+AP7+AQ7+AR7+AS7+AT7+AU7+AV7+AW7+AX7+AY7+AZ7+BA7+BB7+BC7+BD7+BE7+BF7 -> 0
B8: иштирок этган ёшлар сони | C8: =+D8+E8+F8+G8+H8+I8+J8+K8+L8+M8+N8+O8+P8+Q8+R8+S8+T8+U8+V8+W8+X8+Y8+Z8+AA8+AB8+AC8+AD8+AE8+AF8+AG8+AH8+AI8+AJ8+AK8+AL8+AM8+AN8+AO8+AP8+AQ8+AR8+AS8+AT8+AU8+AV8+AW8+AX8+AY8+AZ8+BA8+BB8+BC8+BD8+BE8+BF8 -> 0
A9: 4 | B9: Ёшлар дафтари йўналишида кўрсатилган ёрдамлар | C9: =+D9+E9+F9+G9+H9+I9+J9+K9+L9+M9+N9+O9+P9+Q9+R9+S9+T9+U9+V9+W9+X9+Y9+Z9+AA9+AB9+AC9+AD9+AE9+AF9+AG9+AH9+AI9+AJ9+AK9+AL9+AM9+AN9+AO9+AP9+AQ9+AR9+AS9+AT9+AU9+AV9+AW9+AX9+AY9+AZ9+BA9+BB9+BC9+BD9+BE9+BF9 -> 0 | D9: =+D11+D13+D15+D17+D19+D21+D23+D25+D27+D29+D31+D33 -> 0 | E9: =+E11+E13+E15+E17+E19+E21+E23+E25+E27+E29+E31+E33 -> 0 | F9: =+F11+F13+F15+F17+F19+F21+F23+F25+F27+F29+F31+F33 -> 0 | G9: =+G11+G13+G15+G17+G19+G21+G23+G25+G27+G29+G31+G33 -> 0 | H9: =+H11+H13+H15+H17+H19+H21+H23+H25+H27+H29+H31+H33 -> 0 | I9: =+I11+I13+I15+I17+I19+I21+I23+I25+I27+I29+I31+I33 -> 0 | J9: =+J11+J13+J15+J17+J19+J21+J23+J25+J27+J29+J31+J33 -> 0 | K9: =+K11+K13+K15+K17+K19+K21+K23+K25+K27+K29+K31+K33 -> 0 | ... BF9: =+BF11+BF13+BF15+BF17+BF19+BF21+BF23+BF25+BF27+BF29+BF31+BF33 -> 0
B10: Ажратилган маблағлар (сўм) | C10: =+D10+E10+F10+G10+H10+I10+J10+K10+L10+M10+N10+O10+P10+Q10+R10+S10+T10+U10+V10+W10+X10+Y10+Z10+AA10+AB10+AC10+AD10+AE10+AF10+AG10+AH10+AI10+AJ10+AK10+AL10+AM10+AN10+AO10+AP10+AQ10+AR10+AS10+AT10+AU10+AV10+AW10+AX10+AY10+AZ10+BA10+BB10+BC10+BD10+BE10+BF10 -> 0 | D10: =+D12+D14+D16+D18+D20+D22+D24+D26+D28+D30+D32+D34 -> 0 | E10: =+E12+E14+E16+E18+E20+E22+E24+E26+E28+E30+E32+E34 -> 0 | F10: =+F12+F14+F16+F18+F20+F22+F24+F26+F28+F30+F32+F34 -> 0 | G10: =+G12+G14+G16+G18+G20+G22+G24+G26+G28+G30+G32+G34 -> 0 | H10: =+H12+H14+H16+H18+H20+H22+H24+H26+H28+H30+H32+H34 -> 0 | I10: =+I12+I14+I16+I18+I20+I22+I24+I26+I28+I30+I32+I34 -> 0 | J10: =+J12+J14+J16+J18+J20+J22+J24+J26+J28+J30+J32+J34 -> 0 | K10: =+K12+K14+K16+K18+K20+K22+K24+K26+K28+K30+K32+K34 -> 0 | ... BF10: =+BF12+BF14+BF16+BF18+BF20+BF22+BF24+BF26+BF28+BF30+BF32+BF34 -> 0
A11: шундан | B11: Автомототранспорт воситалари ҳайдовчиларини тайёрлаш | C11: =+D11+E11+F11+G11+H11+I11+J11+K11+L11+M11+N11+O11+P11+Q11+R11+S11+T11+U11+V11+W11+X11+Y11+Z11+AA11+AB11+AC11+AD11+AE11+AF11+AG11+AH11+AI11+AJ11+AK11+AL11+AM11+AN11+AO11+AP11+AQ11+AR11+AS11+AT11+AU11+AV11+AW11+AX11+AY11+AZ11+BA11+BB11+BC11+BD11+BE11+BF11 -> 0
B12: Ажратилган маблағлар (сўм) | C12: =+D12+E12+F12+G12+H12+I12+J12+K12+L12+M12+N12+O12+P12+Q12+R12+S12+T12+U12+V12+W12+X12+Y12+Z12+AA12+AB12+AC12+AD12+AE12+AF12+AG12+AH12+AI12+AJ12+AK12+AL12+AM12+AN12+AO12+AP12+AQ12+AR12+AS12+AT12+AU12+AV12+AW12+AX12+AY12+AZ12+BA12+BB12+BC12+BD12+BE12+BF12 -> 0
B13: Тўлов-контракт | C13: =+D13+E13+F13+G13+H13+I13+J13+K13+L13+M13+N13+O13+P13+Q13+R13+S13+T13+U13+V13+W13+X13+Y13+Z13+AA13+AB13+AC13+AD13+AE13+AF13+AG13+AH13+AI13+AJ13+AK13+AL13+AM13+AN13+AO13+AP13+AQ13+AR13+AS13+AT13+AU13+AV13+AW13+AX13+AY13+AZ13+BA13+BB13+BC13+BD13+BE13+BF13 -> 0
B14: Ажратилган маблағлар (сўм) | C14: =+D14+E14+F14+G14+H14+I14+J14+K14+L14+M14+N14+O14+P14+Q14+R14+S14+T14+U14+V14+W14+X14+Y14+Z14+AA14+AB14+AC14+AD14+AE14+AF14+AG14+AH14+AI14+AJ14+AK14+AL14+AM14+AN14+AO14+AP14+AQ14+AR14+AS14+AT14+AU14+AV14+AW14+AX14+AY14+AZ14+BA14+BB14+BC14+BD14+BE14+BF14 -> 0
B15: Илм-фан, спорт, санъат ва маданият йўналишларидаги олти ойгача муддатли ўқув курслари | C15: =+D15+E15+F15+G15+H15+I15+J15+K15+L15+M15+N15+O15+P15+Q15+R15+S15+T15+U15+V15+W15+X15+Y15+Z15+AA15+AB15+AC15+AD15+AE15+AF15+AG15+AH15+AI15+AJ15+AK15+AL15+AM15+AN15+AO15+AP15+AQ15+AR15+AS15+AT15+AU15+AV15+AW15+AX15+AY15+AZ15+BA15+BB15+BC15+BD15+BE15+BF15 -> 0
B16: Ажратилган маблағлар (сўм) | C16: =+D16+E16+F16+G16+H16+I16+J16+K16+L16+M16+N16+O16+P16+Q16+R16+S16+T16+U16+V16+W16+X16+Y16+Z16+AA16+AB16+AC16+AD16+AE16+AF16+AG16+AH16+AI16+AJ16+AK16+AL16+AM16+AN16+AO16+AP16+AQ16+AR16+AS16+AT16+AU16+AV16+AW16+AX16+AY16+AZ16+BA16+BB16+BC16+BD16+BE16+BF16 -> 0
B17: Олимпиада, танлов ва мусобақаларнинг маҳаллий босқичларида қатнашиш харажатлари | C17: =+D17+E17+F17+G17+H17+I17+J17+K17+L17+M17+N17+O17+P17+Q17+R17+S17+T17+U17+V17+W17+X17+Y17+Z17+AA17+AB17+AC17+AD17+AE17+AF17+AG17+AH17+AI17+AJ17+AK17+AL17+AM17+AN17+AO17+AP17+AQ17+AR17+AS17+AT17+AU17+AV17+AW17+AX17+AY17+AZ17+BA17+BB17+BC17+BD17+BE17+BF17 -> 0
B18: Ажратилган маблағлар (сўм) | C18: =+D18+E18+F18+G18+H18+I18+J18+K18+L18+M18+N18+O18+P18+Q18+R18+S18+T18+U18+V18+W18+X18+Y18+Z18+AA18+AB18+AC18+AD18+AE18+AF18+AG18+AH18+AI18+AJ18+AK18+AL18+AM18+AN18+AO18+AP18+AQ18+AR18+AS18+AT18+AU18+AV18+AW18+AX18+AY18+AZ18+BA18+BB18+BC18+BD18+BE18+BF18 -> 0
B19: Мамлакатда ёки хорижий давлатларда даволаниш билан боғлиқ харажатлар | C19: =+D19+E19+F19+G19+H19+I19+J19+K19+L19+M19+N19+O19+P19+Q19+R19+S19+T19+U19+V19+W19+X19+Y19+Z19+AA19+AB19+AC19+AD19+AE19+AF19+AG19+AH19+AI19+AJ19+AK19+AL19+AM19+AN19+AO19+AP19+AQ19+AR19+AS19+AT19+AU19+AV19+AW19+AX19+AY19+AZ19+BA19+BB19+BC19+BD19+BE19+BF19 -> 0
B20: Ажратилган маблағлар (сўм) | C20: =+D20+E20+F20+G20+H20+I20+J20+K20+L20+M20+N20+O20+P20+Q20+R20+S20+T20+U20+V20+W20+X20+Y20+Z20+AA20+AB20+AC20+AD20+AE20+AF20+AG20+AH20+AI20+AJ20+AK20+AL20+AM20+AN20+AO20+AP20+AQ20+AR20+AS20+AT20+AU20+AV20+AW20+AX20+AY20+AZ20+BA20+BB20+BC20+BD20+BE20+BF20 -> 0
B21: Сафарбарлик чақируви резервидаги хизматни ўташ бадали | C21: =+D21+E21+F21+G21+H21+I21+J21+K21+L21+M21+N21+O21+P21+Q21+R21+S21+T21+U21+V21+W21+X21+Y21+Z21+AA21+AB21+AC21+AD21+AE21+AF21+AG21+AH21+AI21+AJ21+AK21+AL21+AM21+AN21+AO21+AP21+AQ21+AR21+AS21+AT21+AU21+AV21+AW21+AX21+AY21+AZ21+BA21+BB21+BC21+BD21+BE21+BF21 -> 0
B22: Ажратилган маблағлар (сўм) | C22: =+D22+E22+F22+G22+H22+I22+J22+K22+L22+M22+N22+O22+P22+Q22+R22+S22+T22+U22+V22+W22+X22+Y22+Z22+AA22+AB22+AC22+AD22+AE22+AF22+AG22+AH22+AI22+AJ22+AK22+AL22+AM22+AN22+AO22+AP22+AQ22+AR22+AS22+AT22+AU22+AV22+AW22+AX22+AY22+AZ22+BA22+BB22+BC22+BD22+BE22+BF22 -> 0
B23: 12 ойгача турар жой ижараси | C23: =+D23+E23+F23+G23+H23+I23+J23+K23+L23+M23+N23+O23+P23+Q23+R23+S23+T23+U23+V23+W23+X23+Y23+Z23+AA23+AB23+AC23+AD23+AE23+AF23+AG23+AH23+AI23+AJ23+AK23+AL23+AM23+AN23+AO23+AP23+AQ23+AR23+AS23+AT23+AU23+AV23+AW23+AX23+AY23+AZ23+BA23+BB23+BC23+BD23+BE23+BF23 -> 0
... B34: Ажратилган маблағлар (сўм) | C34: =+D34+E34+F34+G34+H34+I34+J34+K34+L34+M34+N34+O34+P34+Q34+R34+S34+T34+U34+V34+W34+X34+Y34+Z34+AA34+AB34+AC34+AD34+AE34+AF34+AG34+AH34+AI34+AJ34+AK34+AL34+AM34+AN34+AO34+AP34+AQ34+AR34+AS34+AT34+AU34+AV34+AW34+AX34+AY34+AZ34+BA34+BB34+BC34+BD34+BE34+BF34 -> 0
A35: 5 | B35: Оталиққа олинган ёшлар билан ўрганилганлар сони | C35: =+D35+E35+F35+G35+H35+I35+J35+K35+L35+M35+N35+O35+P35+Q35+R35+S35+T35+U35+V35+W35+X35+Y35+Z35+AA35+AB35+AC35+AD35+AE35+AF35+AG35+AH35+AI35+AJ35+AK35+AL35+AM35+AN35+AO35+AP35+AQ35+AR35+AS35+AT35+AU35+AV35+AW35+AX35+AY35+AZ35+BA35+BB35+BC35+BD35+BE35+BF35 -> 25 | L35: 1 | P35: 1 | R35: 1 | U35: 1 | X35: 1 | AA35: 1 | AB35: 1 | AO35: 2 | AR35: 2 | AS35: 1 | AT35: 1 | AU35: 2 | AV35: 2 | AX35: 1 | AZ35: 2 | BB35: 2 | BC35: 1 | BE35: 1 | BF35: 1
B36: аниқланган муаммолар | C36: =+D36+E36+F36+G36+H36+I36+J36+K36+L36+M36+N36+O36+P36+Q36+R36+S36+T36+U36+V36+W36+X36+Y36+Z36+AA36+AB36+AC36+AD36+AE36+AF36+AG36+AH36+AI36+AJ36+AK36+AL36+AM36+AN36+AO36+AP36+AQ36+AR36+AS36+AT36+AU36+AV36+AW36+AX36+AY36+AZ36+BA36+BB36+BC36+BD36+BE36+BF36 -> 5 | U36: 1 | AT36: 1 | AU36: 1 | BC36: 1 | BE36: 1
B37: ҳал этилганлари | C37: =+D37+E37+F37+G37+H37+I37+J37+K37+L37+M37+N37+O37+P37+Q37+R37+S37+T37+U37+V37+W37+X37+Y37+Z37+AA37+AB37+AC37+AD37+AE37+AF37+AG37+AH37+AI37+AJ37+AK37+AL37+AM37+AN37+AO37+AP37+AQ37+AR37+AS37+AT37+AU37+AV37+AW37+AX37+AY37+AZ37+BA37+BB37+BC37+BD37+BE37+BF37 -> 0
A38: 6 | B38: Чет элда миграцияга ўқиш, яшаш ёки ишлаш учун бўлиб турган ёшлар йўналиши | C38: =+D38+E38+F38+G38+H38+I38+J38+K38+L38+M38+N38+O38+P38+Q38+R38+S38+T38+U38+V38+W38+X38+Y38+Z38+AA38+AB38+AC38+AD38+AE38+AF38+AG38+AH38+AI38+AJ38+AK38+AL38+AM38+AN38+AO38+AP38+AQ38+AR38+AS38+AT38+AU38+AV38+AW38+AX38+AY38+AZ38+BA38+BB38+BC38+BD38+BE38+BF38 -> 0
A39: 7 | B39: "Раҳбар ва ёшлар" учрашуви | C39: =+D39+E39+F39+G39+H39+I39+J39+K39+L39+M39+N39+O39+P39+Q39+R39+S39+T39+U39+V39+W39+X39+Y39+Z39+AA39+AB39+AC39+AD39+AE39+AF39+AG39+AH39+AI39+AJ39+AK39+AL39+AM39+AN39+AO39+AP39+AQ39+AR39+AS39+AT39+AU39+AV39+AW39+AX39+AY39+AZ39+BA39+BB39+BC39+BD39+BE39+BF39 -> 9 | U39: 1 | X39: 1 | AG39: 1 | AT39: 1 | AU39: 1 | AV39: 1 | BC39: 1 | BE39: 1 | BF39: 1
B40: Иштирок этган ёшлар сони | C40: =+D40+E40+F40+G40+H40+I40+J40+K40+L40+M40+N40+O40+P40+Q40+R40+S40+T40+U40+V40+W40+X40+Y40+Z40+AA40+AB40+AC40+AD40+AE40+AF40+AG40+AH40+AI40+AJ40+AK40+AL40+AM40+AN40+AO40+AP40+AQ40+AR40+AS40+AT40+AU40+AV40+AW40+AX40+AY40+AZ40+BA40+BB40+BC40+BD40+BE40+BF40 -> 54 | U40: 5 | X40: 11 | AG40: 6 | AT40: 5 | AU40: 6 | AV40: 3 | BC40: 3 | BE40: 3 | BF40: 12
B41: Ёшларнинг муаммолари | C41: =+D41+E41+F41+G41+H41+I41+J41+K41+L41+M41+N41+O41+P41+Q41+R41+S41+T41+U41+V41+W41+X41+Y41+Z41+AA41+AB41+AC41+AD41+AE41+AF41+AG41+AH41+AI41+AJ41+AK41+AL41+AM41+AN41+AO41+AP41+AQ41+AR41+AS41+AT41+AU41+AV41+AW41+AX41+AY41+AZ41+BA41+BB41+BC41+BD41+BE41+BF41 -> 5 | U41: 1 | AT41: 1 | AU41: 1 | BC41: 1 | BE41: 1
B42: Ҳал этилганлик ҳолати | C42: =+D42+E42+F42+G42+H42+I42+J42+K42+L42+M42+N42+O42+P42+Q42+R42+S42+T42+U42+V42+W42+X42+Y42+Z42+AA42+AB42+AC42+AD42+AE42+AF42+AG42+AH42+AI42+AJ42+AK42+AL42+AM42+AN42+AO42+AP42+AQ42+AR42+AS42+AT42+AU42+AV42+AW42+AX42+AY42+AZ42+BA42+BB42+BC42+BD42+BE42+BF42 -> 0
A43: 8 | B43: Мактаб ўқувчилар давомати | C43: =+D43+E43+F43+G43+H43+I43+J43+K43+L43+M43+N43+O43+P43+Q43+R43+S43+T43+U43+V43+W43+X43+Y43+Z43+AA43+AB43+AC43+AD43+AE43+AF43+AG43+AH43+AI43+AJ43+AK43+AL43+AM43+AN43+AO43+AP43+AQ43+AR43+AS43+AT43+AU43+AV43+AW43+AX43+AY43+AZ43+BA43+BB43+BC43+BD43+BE43+BF43 -> 0
A44: 9 | B44: Ёшларни тадбиркорликка жалб этиш (ПҚ-60-61-62-қарорлар ижроси) йўналишида кредит берилган ёшлар сони | C44: =+D44+E44+F44+G44+H44+I44+J44+K44+L44+M44+N44+O44+P44+Q44+R44+S44+T44+U44+V44+W44+X44+Y44+Z44+AA44+AB44+AC44+AD44+AE44+AF44+AG44+AH44+AI44+AJ44+AK44+AL44+AM44+AN44+AO44+AP44+AQ44+AR44+AS44+AT44+AU44+AV44+AW44+AX44+AY44+AZ44+BA44+BB44+BC44+BD44+BE44+BF44 -> 0
B45: Ажратилган кредит маблағлари (млн) | C45: =+D45+E45+F45+G45+H45+I45+J45+K45+L45+M45+N45+O45+P45+Q45+R45+S45+T45+U45+V45+W45+X45+Y45+Z45+AA45+AB45+AC45+AD45+AE45+AF45+AG45+AH45+AI45+AJ45+AK45+AL45+AM45+AN45+AO45+AP45+AQ45+AR45+AS45+AT45+AU45+AV45+AW45+AX45+AY45+AZ45+BA45+BB45+BC45+BD45+BE45+BF45 -> 0
A46: 10 | B46: Битирувчи (мактаб, профессионал таълим, ОТМ) ёшларни бандлигини таъминлаш | C46: =+D46+E46+F46+G46+H46+I46+J46+K46+L46+M46+N46+O46+P46+Q46+R46+S46+T46+U46+V46+W46+X46+Y46+Z46+AA46+AB46+AC46+AD46+AE46+AF46+AG46+AH46+AI46+AJ46+AK46+AL46+AM46+AN46+AO46+AP46+AQ46+AR46+AS46+AT46+AU46+AV46+AW46+AX46+AY46+AZ46+BA46+BB46+BC46+BD46+BE46+BF46 -> 0
A47: 11 | B47: "Ibrat farzandlar" лойиҳасини тарғибот қилиш | C47: =+D47+E47+F47+G47+H47+I47+J47+K47+L47+M47+N47+O47+P47+Q47+R47+S47+T47+U47+V47+W47+X47+Y47+Z47+AA47+AB47+AC47+AD47+AE47+AF47+AG47+AH47+AI47+AJ47+AK47+AL47+AM47+AN47+AO47+AP47+AQ47+AR47+AS47+AT47+AU47+AV47+AW47+AX47+AY47+AZ47+BA47+BB47+BC47+BD47+BE47+BF47 -> 73 | E47: 1 | F47: 2 | G47: 2 | H47: 1 | I47: 2 | J47: 2 | K47: 1 | N47: 1 | O47: 1 | P47: 2 | Q47: 1 | R47: 1 | S47: 2 | T47: 2 | U47: 1 | V47: 2 | W47: 2 | X47: 1 | AA47: 1 | AB47: 2 | AC47: 2 | AD47: 1 | AE47: 2 | AF47: 2 | AG47: 1 | AI47: 1 | AJ47: 2 | AK47: 2 | AL47: 1 | AM47: 2 | AN47: 2 | AO47: 1 | AP47: 2 | AQ47: 2 | AR47: 1 | AS47: 2 | AT47: 2 | AU47: 1 | AW47: 1 | AX47: 2 | AY47: 1 | AZ47: 2 | BA47: 2 | BB47: 1 | BC47: 2 | BD47: 2 | BE47: 1
A48: 12 | B48: "Ustoz AI" лойиҳасини тарғибот қилиш | C48: =+D48+E48+F48+G48+H48+I48+J48+K48+L48+M48+N48+O48+P48+Q48+R48+S48+T48+U48+V48+W48+X48+Y48+Z48+AA48+AB48+AC48+AD48+AE48+AF48+AG48+AH48+AI48+AJ48+AK48+AL48+AM48+AN48+AO48+AP48+AQ48+AR48+AS48+AT48+AU48+AV48+AW48+AX48+AY48+AZ48+BA48+BB48+BC48+BD48+BE48+BF48 -> 74 | E48: 1 | F48: 1 | G48: 2 | H48: 1 | I48: 2 | J48: 2 | K48: 1 | L48: 1 | N48: 1 | O48: 1 | P48: 2 | Q48: 1 | R48: 1 | S48: 2 | T48: 2 | U48: 1 | V48: 2 | W48: 2 | X48: 1 | Y48: 1 | AA48: 1 | AB48: 2 | AC48: 2 | AD48: 1 | AE48: 2 | AF48: 2 | AG48: 1 | AI48: 1 | AJ48: 2 | AK48: 2 | AL48: 1 | AM48: 2 | AN48: 2 | AO48: 1 | AP48: 2 | AQ48: 2 | AR48: 1 | AS48: 2 | AT48: 2 | AU48: 1 | AW48: 1 | AX48: 2 | AY48: 1 | AZ48: 2 | BA48: 2 | BB48: 1 | BC48: 2 | BD48: 2 | BE48: 1
A49: 13 | B49: "UzChees" лойиҳасини тарғибот қилиш | C49: =+D49+E49+F49+G49+H49+I49+J49+K49+L49+M49+N49+O49+P49+Q49+R49+S49+T49+U49+V49+W49+X49+Y49+Z49+AA49+AB49+AC49+AD49+AE49+AF49+AG49+AH49+AI49+AJ49+AK49+AL49+AM49+AN49+AO49+AP49+AQ49+AR49+AS49+AT49+AU49+AV49+AW49+AX49+AY49+AZ49+BA49+BB49+BC49+BD49+BE49+BF49 -> 66 | E49: 1 | F49: 2 | G49: 2 | H49: 1 | I49: 2 | J49: 2 | K49: 1 | N49: 1 | O49: 1 | P49: 1 | Q49: 1 | R49: 1 | S49: 1 | T49: 1 | U49: 1 | V49: 1 | W49: 1 | X49: 1 | Y49: 1 | Z49: 1 | AA49: 1 | AB49: 1 | AC49: 2 | AD49: 1 | AE49: 2 | AF49: 2 | AG49: 1 | AI49: 1 | AJ49: 1 | AK49: 1 | AL49: 1 | AM49: 2 | AN49: 2 | AO49: 1 | AP49: 1 | AQ49: 1 | AR49: 1 | AS49: 2 | AT49: 2 | AU49: 1 | AV49: 1 | AW49: 1 | AX49: 2 | AY49: 1 | AZ49: 2 | BA49: 2 | BB49: 1 | BC49: 2 | BD49: 2 | BE49: 1
A50: 14 | B50: "Mutolaa" лойиҳасини тарғибот қилиш | C50: =+D50+E50+F50+G50+H50+I50+J50+K50+L50+M50+N50+O50+P50+Q50+R50+S50+T50+U50+V50+W50+X50+Y50+Z50+AA50+AB50+AC50+AD50+AE50+AF50+AG50+AH50+AI50+AJ50+AK50+AL50+AM50+AN50+AO50+AP50+AQ50+AR50+AS50+AT50+AU50+AV50+AW50+AX50+AY50+AZ50+BA50+BB50+BC50+BD50+BE50+BF50 -> 75 | E50: 1 | F50: 2 | G50: 2 | H50: 1 | I50: 2 | J50: 2 | K50: 1 | L50: 1 | N50: 1 | O50: 2 | P50: 2 | Q50: 1 | R50: 1 | S50: 2 | T50: 1 | U50: 1 | V50: 2 | W50: 2 | X50: 1 | Z50: 1 | AA50: 1 | AB50: 2 | AC50: 2 | AD50: 1 | AE50: 2 | AF50: 2 | AG50: 1 | AI50: 1 | AJ50: 2 | AK50: 2 | AL50: 1 | AM50: 2 | AN50: 2 | AO50: 1 | AP50: 2 | AQ50: 2 | AR50: 1 | AS50: 2 | AT50: 2 | AU50: 1 | AW50: 1 | AX50: 2 | AY50: 1 | AZ50: 2 | BA50: 2 | BB50: 1 | BC50: 2 | BD50: 2 | BE50: 1
...

Sheet 01.21
A1: № | B1: Кўрсаткич | C1: Жами | D1: Ал-Хоразмий | E1: Бахористон | F1: Бектўпи | G1: Гулистон | H1: Катта Хирмонтепа | I1: Тирсакобод | J1: Хайрабод | K1: Хирмон тепа | L1: Хонтўпи | M1: Шараф | N1: Шарқ | O1: Шарқ тонги | P1: Шухрат | Q1: 1-Чарх Камолон | R1: 2-Чарх Камолон | S1: 3-Чарх Камолон | T1: Бешёғоч | U1: Катта Козиробод | V1: Катта Олмазор | W1: Катта Чилонзор-1 | X1: Катта Чилонзор-2 | Y1: Катта Чилонзор-3 | Z1: Қозиробод | AA1: Новза | AB1: Чилонзор | AC1: 1-Қатортол | AD1: Бешчинор | AE1: Боғзор | AF1: Диёр | AG1: Дилобод | AH1: Катта Навбаҳор | AI1: Кўркам | AJ1: Кўтарма | AK1: Қатортол | AL1: Лутфий | AM1: Навбахор | AN1: Нафосат | AO1: Оқ-тепа | AP1: Халқлар Дўстлиги | AQ1: Чўпон-ота | AR1: 2-Қатортол | AS1: Ботирма | AT1: Бўрижар | AU1: Гавхар | AV1: Дўмбиробод | AW1: Зарқўрғон | AX1: Катта Дўмбиробод | AY1: Кичик Хирмонтепа | AZ1: Мевазор | BA1: Мехржон | BB1: Наққошлик | BC1: Фидокор | BD1: Яккабоғ | BE1: Яккатут | BF1: Бешқўрғон
A2: 1 | B2: Маданий-маърифий тадбирлар | C2: =+D2+E2+F2+G2+H2+I2+J2+K2+L2+M2+N2+O2+P2+Q2+R2+S2+T2+U2+V2+W2+X2+Y2+Z2+AA2+AB2+AC2+AD2+AE2+AF2+AG2+AH2+AI2+AJ2+AK2+AL2+AM2+AN2+AO2+AP2+AQ2+AR2+AS2+AT2+AU2+AV2+AW2+AX2+AY2+AZ2+BA2+BB2+BC2+BD2+BE2+BF2 -> 5 | F2: 1 | I2: 1 | T2: 1 | AB2: 1 | AR2: 1
B3: иштирок этган ёшлар сони | C3: =+D3+E3+F3+G3+H3+I3+J3+K3+L3+M3+N3+O3+P3+Q3+R3+S3+T3+U3+V3+W3+X3+Y3+Z3+AA3+AB3+AC3+AD3+AE3+AF3+AG3+AH3+AI3+AJ3+AK3+AL3+AM3+AN3+AO3+AP3+AQ3+AR3+AS3+AT3+AU3+AV3+AW3+AX3+AY3+AZ3+BA3+BB3+BC3+BD3+BE3+BF3 -> 48 | F3: 7 | I3: 12 | T3: 20 | AB3: 5 | AR3: 4
A4: 2 | B4: Ҳарбий ватанпарварлик тадбирлар | C4: =+D4+E4+F4+G4+H4+I4+J4+K4+L4+M4+N4+O4+P4+Q4+R4+S4+T4+U4+V4+W4+X4+Y4+Z4+AA4+AB4+AC4+AD4+AE4+AF4+AG4+AH4+AI4+AJ4+AK4+AL4+AM4+AN4+AO4+AP4+AQ4+AR4+AS4+AT4+AU4+AV4+AW4+AX4+AY4+AZ4+BA4+BB4+BC4+BD4+BE4+BF4 -> 4 | X4: 1 | AB4: 1 | AE4: 1 | AO4: 1
B5: Иштирок этган ёшлар сони | C5: =+D5+E5+F5+G5+H5+I5+J5+K5+L5+M5+N5+O5+P5+Q5+R5+S5+T5+U5+V5+W5+X5+Y5+Z5+AA5+AB5+AC5+AD5+AE5+AF5+AG5+AH5+AI5+AJ5+AK5+AL5+AM5+AN5+AO5+AP5+AQ5+AR5+AS5+AT5+AU5+AV5+AW5+AX5+AY5+AZ5+BA5+BB5+BC5+BD5+BE5+BF5 -> 52 | X5: 12 | AB5: 10 | AE5: 10 | AO5: 20
A6: 3 | B6: “Беш ташаббус олимпиадаси” | C6: =+D6+E6+F6+G6+H6+I6+J6+K6+L6+M6+N6+O6+P6+Q6+R6+S6+T6+U6+V6+W6+X6+Y6+Z6+AA6+AB6+AC6+AD6+AE6+AF6+AG6+AH6+AI6+AJ6+AK6+AL6+AM6+AN6+AO6+AP6+AQ6+AR6+AS6+AT6+AU6+AV6+AW6+AX6+AY6+AZ6+BA6+BB6+BC6+BD6+BE6+BF6 -> 0
B7: рўҳатдан ўтган ёшлар сони | C7: =+D7+E7+F7+G7+H7+I7+J7+K7+L7+M7+N7+O7+P7+Q7+R7+S7+T7+U7+V7+W7+X7+Y7+Z7+AA7+AB7+AC7+AD7+AE7+AF7+AG7+AH7+AI7+AJ7+AK7+AL7+AM7+AN7+AO7+AP7+AQ7+AR7+AS7+AT7+AU7+AV7+AW7+AX7+AY7+AZ7+BA7+BB7+BC7+BD7+BE7+BF7 -> 0
B8: иштирок этган ёшлар сони | C8: =+D8+E8+F8+G8+H8+I8+J8+K8+L8+M8+N8+O8+P8+Q8+R8+S8+T8+U8+V8+W8+X8+Y8+Z8+AA8+AB8+AC8+AD8+AE8+AF8+AG8+AH8+AI8+AJ8+AK8+AL8+AM8+AN8+AO8+AP8+AQ8+AR8+AS8+AT8+AU8+AV8+AW8+AX8+AY8+AZ8+BA8+BB8+BC8+BD8+BE8+BF8 -> 0
A9: 4 | B9: Ёшлар дафтари йўналишида кўрсатилган ёрдамлар | C9: =+D9+E9+F9+G9+H9+I9+J9+K9+L9+M9+N9+O9+P9+Q9+R9+S9+T9+U9+V9+W9+X9+Y9+Z9+AA9+AB9+AC9+AD9+AE9+AF9+AG9+AH9+AI9+AJ9+AK9+AL9+AM9+AN9+AO9+AP9+AQ9+AR9+AS9+AT9+AU9+AV9+AW9+AX9+AY9+AZ9+BA9+BB9+BC9+BD9+BE9+BF9 -> 0 | D9: =+D11+D13+D15+D17+D19+D21+D23+D25+D27+D29+D31+D33 -> 0 | E9: =+E11+E13+E15+E17+E19+E21+E23+E25+E27+E29+E31+E33 -> 0 | F9: =+F11+F13+F15+F17+F19+F21+F23+F25+F27+F29+F31+F33 -> 0 | G9: =+G11+G13+G15+G17+G19+G21+G23+G25+G27+G29+G31+G33 -> 0 | H9: =+H11+H13+H15+H17+H19+H21+H23+H25+H27+H29+H31+H33 -> 0 | I9: =+I11+I13+I15+I17+I19+I21+I23+I25+I27+I29+I31+I33 -> 0 | J9: =+J11+J13+J15+J17+J19+J21+J23+J25+J27+J29+J31+J33 -> 0 | K9: =+K11+K13+K15+K17+K19+K21+K23+K25+K27+K29+K31+K33 -> 0 | ... BF9: =+BF11+BF13+BF15+BF17+BF19+BF21+BF23+BF25+BF27+BF29+BF31+BF33 -> 0
B10: Ажратилган маблағлар (сўм) | C10: =+D10+E10+F10+G10+H10+I10+J10+K10+L10+M10+N10+O10+P10+Q10+R10+S10+T10+U10+V10+W10+X10+Y10+Z10+AA10+AB10+AC10+AD10+AE10+AF10+AG10+AH10+AI10+AJ10+AK10+AL10+AM10+AN10+AO10+AP10+AQ10+AR10+AS10+AT10+AU10+AV10+AW10+AX10+AY10+AZ10+BA10+BB10+BC10+BD10+BE10+BF10 -> 0 | D10: =+D12+D14+D16+D18+D20+D22+D24+D26+D28+D30+D32+D34 -> 0 | E10: =+E12+E14+E16+E18+E20+E22+E24+E26+E28+E30+E32+E34 -> 0 | F10: =+F12+F14+F16+F18+F20+F22+F24+F26+F28+F30+F32+F34 -> 0 | G10: =+G12+G14+G16+G18+G20+G22+G24+G26+G28+G30+G32+G34 -> 0 | H10: =+H12+H14+H16+H18+H20+H22+H24+H26+H28+H30+H32+H34 -> 0 | I10: =+I12+I14+I16+I18+I20+I22+I24+I26+I28+I30+I32+I34 -> 0 | J10: =+J12+J14+J16+J18+J20+J22+J24+J26+J28+J30+J32+J34 -> 0 | K10: =+K12+K14+K16+K18+K20+K22+K24+K26+K28+K30+K32+K34 -> 0 | ... BF10: =+BF12+BF14+BF16+BF18+BF20+BF22+BF24+BF26+BF28+BF30+BF32+BF34 -> 0
A11: шундан | B11: Автомототранспорт воситалари ҳайдовчиларини тайёрлаш | C11: =+D11+E11+F11+G11+H11+I11+J11+K11+L11+M11+N11+O11+P11+Q11+R11+S11+T11+U11+V11+W11+X11+Y11+Z11+AA11+AB11+AC11+AD11+AE11+AF11+AG11+AH11+AI11+AJ11+AK11+AL11+AM11+AN11+AO11+AP11+AQ11+AR11+AS11+AT11+AU11+AV11+AW11+AX11+AY11+AZ11+BA11+BB11+BC11+BD11+BE11+BF11 -> 0
B12: Ажратилган маблағлар (сўм) | C12: =+D12+E12+F12+G12+H12+I12+J12+K12+L12+M12+N12+O12+P12+Q12+R12+S12+T12+U12+V12+W12+X12+Y12+Z12+AA12+AB12+AC12+AD12+AE12+AF12+AG12+AH12+AI12+AJ12+AK12+AL12+AM12+AN12+AO12+AP12+AQ12+AR12+AS12+AT12+AU12+AV12+AW12+AX12+AY12+AZ12+BA12+BB12+BC12+BD12+BE12+BF12 -> 0
B13: Тўлов-контракт | C13: =+D13+E13+F13+G13+H13+I13+J13+K13+L13+M13+N13+O13+P13+Q13+R13+S13+T13+U13+V13+W13+X13+Y13+Z13+AA13+AB13+AC13+AD13+AE13+AF13+AG13+AH13+AI13+AJ13+AK13+AL13+AM13+AN13+AO13+AP13+AQ13+AR13+AS13+AT13+AU13+AV13+AW13+AX13+AY13+AZ13+BA13+BB13+BC13+BD13+BE13+BF13 -> 0
B14: Ажратилган маблағлар (сўм) | C14: =+D14+E14+F14+G14+H14+I14+J14+K14+L14+M14+N14+O14+P14+Q14+R14+S14+T14+U14+V14+W14+X14+Y14+Z14+AA14+AB14+AC14+AD14+AE14+AF14+AG14+AH14+AI14+AJ14+AK14+AL14+AM14+AN14+AO14+AP14+AQ14+AR14+AS14+AT14+AU14+AV14+AW14+AX14+AY14+AZ14+BA14+BB14+BC14+BD14+BE14+BF14 -> 0
B15: Илм-фан, спорт, санъат ва маданият йўналишларидаги олти ойгача муддатли ўқув курслари | C15: =+D15+E15+F15+G15+H15+I15+J15+K15+L15+M15+N15+O15+P15+Q15+R15+S15+T15+U15+V15+W15+X15+Y15+Z15+AA15+AB15+AC15+AD15+AE15+AF15+AG15+AH15+AI15+AJ15+AK15+AL15+AM15+AN15+AO15+AP15+AQ15+AR15+AS15+AT15+AU15+AV15+AW15+AX15+AY15+AZ15+BA15+BB15+BC15+BD15+BE15+BF15 -> 0
B16: Ажратилган маблағлар (сўм) | C16: =+D16+E16+F16+G16+H16+I16+J16+K16+L16+M16+N16+O16+P16+Q16+R16+S16+T16+U16+V16+W16+X16+Y16+Z16+AA16+AB16+AC16+AD16+AE16+AF16+AG16+AH16+AI16+AJ16+AK16+AL16+AM16+AN16+AO16+AP16+AQ16+AR16+AS16+AT16+AU16+AV16+AW16+AX16+AY16+AZ16+BA16+BB16+BC16+BD16+BE16+BF16 -> 0
B17: Олимпиада, танлов ва мусобақаларнинг маҳаллий босқичларида қатнашиш харажатлари | C17: =+D17+E17+F17+G17+H17+I17+J17+K17+L17+M17+N17+O17+P17+Q17+R17+S17+T17+U17+V17+W17+X17+Y17+Z17+AA17+AB17+AC17+AD17+AE17+AF17+AG17+AH17+AI17+AJ17+AK17+AL17+AM17+AN17+AO17+AP17+AQ17+AR17+AS17+AT17+AU17+AV17+AW17+AX17+AY17+AZ17+BA17+BB17+BC17+BD17+BE17+BF17 -> 0
B18: Ажратилган маблағлар (сўм) | C18: =+D18+E18+F18+G18+H18+I18+J18+K18+L18+M18+N18+O18+P18+Q18+R18+S18+T18+U18+V18+W18+X18+Y18+Z18+AA18+AB18+AC18+AD18+AE18+AF18+AG18+AH18+AI18+AJ18+AK18+AL18+AM18+AN18+AO18+AP18+AQ18+AR18+AS18+AT18+AU18+AV18+AW18+AX18+AY18+AZ18+BA18+BB18+BC18+BD18+BE18+BF18 -> 0
B19: Мамлакатда ёки хорижий давлатларда даволаниш билан боғлиқ харажатлар | C19: =+D19+E19+F19+G19+H19+I19+J19+K19+L19+M19+N19+O19+P19+Q19+R19+S19+T19+U19+V19+W19+X19+Y19+Z19+AA19+AB19+AC19+AD19+AE19+AF19+AG19+AH19+AI19+AJ19+AK19+AL19+AM19+AN19+AO19+AP19+AQ19+AR19+AS19+AT19+AU19+AV19+AW19+AX19+AY19+AZ19+BA19+BB19+BC19+BD19+BE19+BF19 -> 0
B20: Ажратилган маблағлар (сўм) | C20: =+D20+E20+F20+G20+H20+I20+J20+K20+L20+M20+N20+O20+P20+Q20+R20+S20+T20+U20+V20+W20+X20+Y20+Z20+AA20+AB20+AC20+AD20+AE20+AF20+AG20+AH20+AI20+AJ20+AK20+AL20+AM20+AN20+AO20+AP20+AQ20+AR20+AS20+AT20+AU20+AV20+AW20+AX20+AY20+AZ20+BA20+BB20+BC20+BD20+BE20+BF20 -> 0
B21: Сафарбарлик чақируви резервидаги хизматни ўташ бадали | C21: =+D21+E21+F21+G21+H21+I21+J21+K21+L21+M21+N21+O21+P21+Q21+R21+S21+T21+U21+V21+W21+X21+Y21+Z21+AA21+AB21+AC21+AD21+AE21+AF21+AG21+AH21+AI21+AJ21+AK21+AL21+AM21+AN21+AO21+AP21+AQ21+AR21+AS21+AT21+AU21+AV21+AW21+AX21+AY21+AZ21+BA21+BB21+BC21+BD21+BE21+BF21 -> 0
B22: Ажратилган маблағлар (сўм) | C22: =+D22+E22+F22+G22+H22+I22+J22+K22+L22+M22+N22+O22+P22+Q22+R22+S22+T22+U22+V22+W22+X22+Y22+Z22+AA22+AB22+AC22+AD22+AE22+AF22+AG22+AH22+AI22+AJ22+AK22+AL22+AM22+AN22+AO22+AP22+AQ22+AR22+AS22+AT22+AU22+AV22+AW22+AX22+AY22+AZ22+BA22+BB22+BC22+BD22+BE22+BF22 -> 0
B23: 12 ойгача турар жой ижараси | C23: =+D23+E23+F23+G23+H23+I23+J23+K23+L23+M23+N23+O23+P23+Q23+R23+S23+T23+U23+V23+W23+X23+Y23+Z23+AA23+AB23+AC23+AD23+AE23+AF23+AG23+AH23+AI23+AJ23+AK23+AL23+AM23+AN23+AO23+AP23+AQ23+AR23+AS23+AT23+AU23+AV23+AW23+AX23+AY23+AZ23+BA23+BB23+BC23+BD23+BE23+BF23 -> 0
... B34: Ажратилган маблағлар (сўм) | C34: =+D34+E34+F34+G34+H34+I34+J34+K34+L34+M34+N34+O34+P34+Q34+R34+S34+T34+U34+V34+W34+X34+Y34+Z34+AA34+AB34+AC34+AD34+AE34+AF34+AG34+AH34+AI34+AJ34+AK34+AL34+AM34+AN34+AO34+AP34+AQ34+AR34+AS34+AT34+AU34+AV34+AW34+AX34+AY34+AZ34+BA34+BB34+BC34+BD34+BE34+BF34 -> 0
A35: 5 | B35: Оталиққа олинган ёшлар билан ўрганилганлар сони | C35: =+D35+E35+F35+G35+H35+I35+J35+K35+L35+M35+N35+O35+P35+Q35+R35+S35+T35+U35+V35+W35+X35+Y35+Z35+AA35+AB35+AC35+AD35+AE35+AF35+AG35+AH35+AI35+AJ35+AK35+AL35+AM35+AN35+AO35+AP35+AQ35+AR35+AS35+AT35+AU35+AV35+AW35+AX35+AY35+AZ35+BA35+BB35+BC35+BD35+BE35+BF35 -> 54 | F35: 1 | G35: 1 | H35: 4 | I35: 1 | J35: 1 | K35: 1 | R35: 5 | S35: 1 | T35: 2 | U35: 2 | W35: 1 | AB35: 1 | AC35: 3 | AD35: 1 | AE35: 1 | AF35: 1 | AG35: 1 | AI35: 1 | AJ35: 2 | AK35: 2 | AL35: 1 | AS35: 2 | AT35: 1 | AU35: 1 | AV35: 4 | AY35: 5 | BA35: 1 | BB35: 1 | BC35: 2 | BD35: 1 | BF35: 2
B36: аниқланган муаммолар | C36: =+D36+E36+F36+G36+H36+I36+J36+K36+L36+M36+N36+O36+P36+Q36+R36+S36+T36+U36+V36+W36+X36+Y36+Z36+AA36+AB36+AC36+AD36+AE36+AF36+AG36+AH36+AI36+AJ36+AK36+AL36+AM36+AN36+AO36+AP36+AQ36+AR36+AS36+AT36+AU36+AV36+AW36+AX36+AY36+AZ36+BA36+BB36+BC36+BD36+BE36+BF36 -> 0
B37: ҳал этилганлари | C37: =+D37+E37+F37+G37+H37+I37+J37+K37+L37+M37+N37+O37+P37+Q37+R37+S37+T37+U37+V37+W37+X37+Y37+Z37+AA37+AB37+AC37+AD37+AE37+AF37+AG37+AH37+AI37+AJ37+AK37+AL37+AM37+AN37+AO37+AP37+AQ37+AR37+AS37+AT37+AU37+AV37+AW37+AX37+AY37+AZ37+BA37+BB37+BC37+BD37+BE37+BF37 -> 0
A38: 6 | B38: Чет элда миграцияга ўқиш, яшаш ёки ишлаш учун бўлиб турган ёшлар йўналиши | C38: =+D38+E38+F38+G38+H38+I38+J38+K38+L38+M38+N38+O38+P38+Q38+R38+S38+T38+U38+V38+W38+X38+Y38+Z38+AA38+AB38+AC38+AD38+AE38+AF38+AG38+AH38+AI38+AJ38+AK38+AL38+AM38+AN38+AO38+AP38+AQ38+AR38+AS38+AT38+AU38+AV38+AW38+AX38+AY38+AZ38+BA38+BB38+BC38+BD38+BE38+BF38 -> 0
A39: 7 | B39: "Раҳбар ва ёшлар" учрашуви | C39: =+D39+E39+F39+G39+H39+I39+J39+K39+L39+M39+N39+O39+P39+Q39+R39+S39+T39+U39+V39+W39+X39+Y39+Z39+AA39+AB39+AC39+AD39+AE39+AF39+AG39+AH39+AI39+AJ39+AK39+AL39+AM39+AN39+AO39+AP39+AQ39+AR39+AS39+AT39+AU39+AV39+AW39+AX39+AY39+AZ39+BA39+BB39+BC39+BD39+BE39+BF39 -> 3 | I39: 1 | R39: 1 | AV39: 1
B40: Иштирок этган ёшлар сони | C40: =+D40+E40+F40+G40+H40+I40+J40+K40+L40+M40+N40+O40+P40+Q40+R40+S40+T40+U40+V40+W40+X40+Y40+Z40+AA40+AB40+AC40+AD40+AE40+AF40+AG40+AH40+AI40+AJ40+AK40+AL40+AM40+AN40+AO40+AP40+AQ40+AR40+AS40+AT40+AU40+AV40+AW40+AX40+AY40+AZ40+BA40+BB40+BC40+BD40+BE40+BF40 -> 54 | I40: 14 | R40: 20 | AV40: 20
B41: Ёшларнинг муаммолари | C41: =+D41+E41+F41+G41+H41+I41+J41+K41+L41+M41+N41+O41+P41+Q41+R41+S41+T41+U41+V41+W41+X41+Y41+Z41+AA41+AB41+AC41+AD41+AE41+AF41+AG41+AH41+AI41+AJ41+AK41+AL41+AM41+AN41+AO41+AP41+AQ41+AR41+AS41+AT41+AU41+AV41+AW41+AX41+AY41+AZ41+BA41+BB41+BC41+BD41+BE41+BF41 -> 0
B42: Ҳал этилганлик ҳолати | C42: =+D42+E42+F42+G42+H42+I42+J42+K42+L42+M42+N42+O42+P42+Q42+R42+S42+T42+U42+V42+W42+X42+Y42+Z42+AA42+AB42+AC42+AD42+AE42+AF42+AG42+AH42+AI42+AJ42+AK42+AL42+AM42+AN42+AO42+AP42+AQ42+AR42+AS42+AT42+AU42+AV42+AW42+AX42+AY42+AZ42+BA42+BB42+BC42+BD42+BE42+BF42 -> 0
A43: 8 | B43: Мактаб ўқувчилар давомати | C43: =+D43+E43+F43+G43+H43+I43+J43+K43+L43+M43+N43+O43+P43+Q43+R43+S43+T43+U43+V43+W43+X43+Y43+Z43+AA43+AB43+AC43+AD43+AE43+AF43+AG43+AH43+AI43+AJ43+AK43+AL43+AM43+AN43+AO43+AP43+AQ43+AR43+AS43+AT43+AU43+AV43+AW43+AX43+AY43+AZ43+BA43+BB43+BC43+BD43+BE43+BF43 -> 0
A44: 9 | B44: Ёшларни тадбиркорликка жалб этиш (ПҚ-60-61-62-қарорлар ижроси) йўналишида кредит берилган ёшлар сони | C44: =+D44+E44+F44+G44+H44+I44+J44+K44+L44+M44+N44+O44+P44+Q44+R44+S44+T44+U44+V44+W44+X44+Y44+Z44+AA44+AB44+AC44+AD44+AE44+AF44+AG44+AH44+AI44+AJ44+AK44+AL44+AM44+AN44+AO44+AP44+AQ44+AR44+AS44+AT44+AU44+AV44+AW44+AX44+AY44+AZ44+BA44+BB44+BC44+BD44+BE44+BF44 -> 0
B45: Ажратилган кредит маблағлари (млн) | C45: =+D45+E45+F45+G45+H45+I45+J45+K45+L45+M45+N45+O45+P45+Q45+R45+S45+T45+U45+V45+W45+X45+Y45+Z45+AA45+AB45+AC45+AD45+AE45+AF45+AG45+AH45+AI45+AJ45+AK45+AL45+AM45+AN45+AO45+AP45+AQ45+AR45+AS45+AT45+AU45+AV45+AW45+AX45+AY45+AZ45+BA45+BB45+BC45+BD45+BE45+BF45 -> 0
A46: 10 | B46: Битирувчи (мактаб, профессионал таълим, ОТМ) ёшларни бандлигини таъминлаш | C46: =+D46+E46+F46+G46+H46+I46+J46+K46+L46+M46+N46+O46+P46+Q46+R46+S46+T46+U46+V46+W46+X46+Y46+Z46+AA46+AB46+AC46+AD46+AE46+AF46+AG46+AH46+AI46+AJ46+AK46+AL46+AM46+AN46+AO46+AP46+AQ46+AR46+AS46+AT46+AU46+AV46+AW46+AX46+AY46+AZ46+BA46+BB46+BC46+BD46+BE46+BF46 -> 0
A47: 11 | B47: "Ibrat farzandlar" лойиҳасини тарғибот қилиш | C47: =+D47+E47+F47+G47+H47+I47+J47+K47+L47+M47+N47+O47+P47+Q47+R47+S47+T47+U47+V47+W47+X47+Y47+Z47+AA47+AB47+AC47+AD47+AE47+AF47+AG47+AH47+AI47+AJ47+AK47+AL47+AM47+AN47+AO47+AP47+AQ47+AR47+AS47+AT47+AU47+AV47+AW47+AX47+AY47+AZ47+BA47+BB47+BC47+BD47+BE47+BF47 -> 9 | E47: 1 | L47: 1 | Q47: 1 | W47: 1 | Z47: 1 | AH47: 1 | AO47: 1 | BF47: 2
A48: 12 | B48: "Ustoz AI" лойиҳасини тарғибот қилиш | C48: =+D48+E48+F48+G48+H48+I48+J48+K48+L48+M48+N48+O48+P48+Q48+R48+S48+T48+U48+V48+W48+X48+Y48+Z48+AA48+AB48+AC48+AD48+AE48+AF48+AG48+AH48+AI48+AJ48+AK48+AL48+AM48+AN48+AO48+AP48+AQ48+AR48+AS48+AT48+AU48+AV48+AW48+AX48+AY48+AZ48+BA48+BB48+BC48+BD48+BE48+BF48 -> 7 | I48: 1 | AR48: 4 | BF48: 2
A49: 13 | B49: "UzChees" лойиҳасини тарғибот қилиш | C49: =+D49+E49+F49+G49+H49+I49+J49+K49+L49+M49+N49+O49+P49+Q49+R49+S49+T49+U49+V49+W49+X49+Y49+Z49+AA49+AB49+AC49+AD49+AE49+AF49+AG49+AH49+AI49+AJ49+AK49+AL49+AM49+AN49+AO49+AP49+AQ49+AR49+AS49+AT49+AU49+AV49+AW49+AX49+AY49+AZ49+BA49+BB49+BC49+BD49+BE49+BF49 -> 7 | N49: 2 | AL49: 1 | BC49: 4
A50: 14 | B50: "Mutolaa" лойиҳасини тарғибот қилиш | C50: =+D50+E50+F50+G50+H50+I50+J50+K50+L50+M50+N50+O50+P50+Q50+R50+S50+T50+U50+V50+W50+X50+Y50+Z50+AA50+AB50+AC50+AD50+AE50+AF50+AG50+AH50+AI50+AJ50+AK50+AL50+AM50+AN50+AO50+AP50+AQ50+AR50+AS50+AT50+AU50+AV50+AW50+AX50+AY50+AZ50+BA50+BB50+BC50+BD50+BE50+BF50 -> 12 | S50: 1 | AN50: 1 | AO50: 10
...

Sheet 01.22
A1: № | B1: Кўрсаткич | C1: Жами | D1: Ал-Хоразмий | E1: Бахористон | F1: Бектўпи | G1: Гулистон | H1: Катта Хирмонтепа | I1: Тирсакобод | J1: Хайрабод | K1: Хирмон тепа | L1: Хонтўпи | M1: Шараф | N1: Шарқ | O1: Шарқ тонги | P1: Шухрат | Q1: 1-Чарх Камолон | R1: 2-Чарх Камолон | S1: 3-Чарх Камолон | T1: Бешёғоч | U1: Катта Козиробод | V1: Катта Олмазор | W1: Катта Чилонзор-1 | X1: Катта Чилонзор-2 | Y1: Катта Чилонзор-3 | Z1: Қозиробод | AA1: Новза | AB1: Чилонзор | AC1: 1-Қатортол | AD1: Бешчинор | AE1: Боғзор | AF1: Диёр | AG1: Дилобод | AH1: Катта Навбаҳор | AI1: Кўркам | AJ1: Кўтарма | AK1: Қатортол | AL1: Лутфий | AM1: Навбахор | AN1: Нафосат | AO1: Оқ-тепа | AP1: Халқлар Дўстлиги | AQ1: Чўпон-ота | AR1: 2-Қатортол | AS1: Ботирма | AT1: Бўрижар | AU1: Гавхар | AV1: Дўмбиробод | AW1: Зарқўрғон | AX1: Катта Дўмбиробод | AY1: Кичик Хирмонтепа | AZ1: Мевазор | BA1: Мехржон | BB1: Наққошлик | BC1: Фидокор | BD1: Яккабоғ | BE1: Яккатут | BF1: Бешқўрғон
A2: 1 | B2: Маданий-маърифий тадбирлар | C2: =+D2+E2+F2+G2+H2+I2+J2+K2+L2+M2+N2+O2+P2+Q2+R2+S2+T2+U2+V2+W2+X2+Y2+Z2+AA2+AB2+AC2+AD2+AE2+AF2+AG2+AH2+AI2+AJ2+AK2+AL2+AM2+AN2+AO2+AP2+AQ2+AR2+AS2+AT2+AU2+AV2+AW2+AX2+AY2+AZ2+BA2+BB2+BC2+BD2+BE2+BF2 -> 16 | K2: 1 | O2: 1 | U2: 1 | Z2: 1 | AG2: 1 | AM2: 1 | AO2: 1 | AT2: 4 | AV2: 1 | AZ2: 1 | BB2: 1 | BE2: 1 | BF2: 1
B3: иштирок этган ёшлар сони | C3: =+D3+E3+F3+G3+H3+I3+J3+K3+L3+M3+N3+O3+P3+Q3+R3+S3+T3+U3+V3+W3+X3+Y3+Z3+AA3+AB3+AC3+AD3+AE3+AF3+AG3+AH3+AI3+AJ3+AK3+AL3+AM3+AN3+AO3+AP3+AQ3+AR3+AS3+AT3+AU3+AV3+AW3+AX3+AY3+AZ3+BA3+BB3+BC3+BD3+BE3+BF3 -> 66 | K3: 7 | O3: 6 | U3: 4 | Z3: 6 | AG3: 6 | AM3: 5 | AO3: 4 | AT3: 4 | AV3: 6 | AZ3: 3 | BB3: 5 | BE3: 5 | BF3: 5
A4: 2 | B4: Ҳарбий ватанпарварлик тадбирлар | C4: =+D4+E4+F4+G4+H4+I4+J4+K4+L4+M4+N4+O4+P4+Q4+R4+S4+T4+U4+V4+W4+X4+Y4+Z4+AA4+AB4+AC4+AD4+AE4+AF4+AG4+AH4+AI4+AJ4+AK4+AL4+AM4+AN4+AO4+AP4+AQ4+AR4+AS4+AT4+AU4+AV4+AW4+AX4+AY4+AZ4+BA4+BB4+BC4+BD4+BE4+BF4 -> 12 | E4: 1 | G4: 1 | N4: 1 | S4: 1 | T4: 1 | AA4: 1 | AD4: 1 | AH4: 1 | AK4: 1 | AQ4: 1 | AX4: 1 | BC4: 1
B5: Иштирок этган ёшлар сони | C5: =+D5+E5+F5+G5+H5+I5+J5+K5+L5+M5+N5+O5+P5+Q5+R5+S5+T5+U5+V5+W5+X5+Y5+Z5+AA5+AB5+AC5+AD5+AE5+AF5+AG5+AH5+AI5+AJ5+AK5+AL5+AM5+AN5+AO5+AP5+AQ5+AR5+AS5+AT5+AU5+AV5+AW5+AX5+AY5+AZ5+BA5+BB5+BC5+BD5+BE5+BF5 -> 62 | E5: 6 | G5: 6 | N5: 4 | S5: 4 | T5: 8 | AA5: 4 | AD5: 4 | AH5: 4 | AK5: 8 | AQ5: 4 | AX5: 5 | BC5: 5
A6: 3 | B6: “Беш ташаббус олимпиадаси” | C6: =+D6+E6+F6+G6+H6+I6+J6+K6+L6+M6+N6+O6+P6+Q6+R6+S6+T6+U6+V6+W6+X6+Y6+Z6+AA6+AB6+AC6+AD6+AE6+AF6+AG6+AH6+AI6+AJ6+AK6+AL6+AM6+AN6+AO6+AP6+AQ6+AR6+AS6+AT6+AU6+AV6+AW6+AX6+AY6+AZ6+BA6+BB6+BC6+BD6+BE6+BF6 -> 0
B7: рўҳатдан ўтган ёшлар сони | C7: =+D7+E7+F7+G7+H7+I7+J7+K7+L7+M7+N7+O7+P7+Q7+R7+S7+T7+U7+V7+W7+X7+Y7+Z7+AA7+AB7+AC7+AD7+AE7+AF7+AG7+AH7+AI7+AJ7+AK7+AL7+AM7+AN7+AO7+AP7+AQ7+AR7+AS7+AT7+AU7+AV7+AW7+AX7+AY7+AZ7+BA7+BB7+BC7+BD7+BE7+BF7 -> 0
B8: иштирок этган ёшлар сони | C8: =+D8+E8+F8+G8+H8+I8+J8+K8+L8+M8+N8+O8+P8+Q8+R8+S8+T8+U8+V8+W8+X8+Y8+Z8+AA8+AB8+AC8+AD8+AE8+AF8+AG8+AH8+AI8+AJ8+AK8+AL8+AM8+AN8+AO8+AP8+AQ8+AR8+AS8+AT8+AU8+AV8+AW8+AX8+AY8+AZ8+BA8+BB8+BC8+BD8+BE8+BF8 -> 0
A9: 4 | B9: Ёшлар дафтари йўналишида кўрсатилган ёрдамлар | C9: =+D9+E9+F9+G9+H9+I9+J9+K9+L9+M9+N9+O9+P9+Q9+R9+S9+T9+U9+V9+W9+X9+Y9+Z9+AA9+AB9+AC9+AD9+AE9+AF9+AG9+AH9+AI9+AJ9+AK9+AL9+AM9+AN9+AO9+AP9+AQ9+AR9+AS9+AT9+AU9+AV9+AW9+AX9+AY9+AZ9+BA9+BB9+BC9+BD9+BE9+BF9 -> 0 | D9: =+D11+D13+D15+D17+D19+D21+D23+D25+D27+D29+D31+D33 -> 0 | E9: =+E11+E13+E15+E17+E19+E21+E23+E25+E27+E29+E31+E33 -> 0 | F9: =+F11+F13+F15+F17+F19+F21+F23+F25+F27+F29+F31+F33 -> 0 | G9: =+G11+G13+G15+G17+G19+G21+G23+G25+G27+G29+G31+G33 -> 0 | H9: =+H11+H13+H15+H17+H19+H21+H23+H25+H27+H29+H31+H33 -> 0 | I9: =+I11+I13+I15+I17+I19+I21+I23+I25+I27+I29+I31+I33 -> 0 | J9: =+J11+J13+J15+J17+J19+J21+J23+J25+J27+J29+J31+J33 -> 0 | K9: =+K11+K13+K15+K17+K19+K21+K23+K25+K27+K29+K31+K33 -> 0 | ... BF9: =+BF11+BF13+BF15+BF17+BF19+BF21+BF23+BF25+BF27+BF29+BF31+BF33 -> 0
B10: Ажратилган маблағлар (сўм) | C10: =+D10+E10+F10+G10+H10+I10+J10+K10+L10+M10+N10+O10+P10+Q10+R10+S10+T10+U10+V10+W10+X10+Y10+Z10+AA10+AB10+AC10+AD10+AE10+AF10+AG10+AH10+AI10+AJ10+AK10+AL10+AM10+AN10+AO10+AP10+AQ10+AR10+AS10+AT10+AU10+AV10+AW10+AX10+AY10+AZ10+BA10+BB10+BC10+BD10+BE10+BF10 -> 0 | D10: =+D12+D14+D16+D18+D20+D22+D24+D26+D28+D30+D32+D34 -> 0 | E10: =+E12+E14+E16+E18+E20+E22+E24+E26+E28+E30+E32+E34 -> 0 | F10: =+F12+F14+F16+F18+F20+F22+F24+F26+F28+F30+F32+F34 -> 0 | G10: =+G12+G14+G16+G18+G20+G22+G24+G26+G28+G30+G32+G34 -> 0 | H10: =+H12+H14+H16+H18+H20+H22+H24+H26+H28+H30+H32+H34 -> 0 | I10: =+I12+I14+I16+I18+I20+I22+I24+I26+I28+I30+I32+I34 -> 0 | J10: =+J12+J14+J16+J18+J20+J22+J24+J26+J28+J30+J32+J34 -> 0 | K10: =+K12+K14+K16+K18+K20+K22+K24+K26+K28+K30+K32+K34 -> 0 | ... BF10: =+BF12+BF14+BF16+BF18+BF20+BF22+BF24+BF26+BF28+BF30+BF32+BF34 -> 0
A11: шундан | B11: Автомототранспорт воситалари ҳайдовчиларини тайёрлаш | C11: =+D11+E11+F11+G11+H11+I11+J11+K11+L11+M11+N11+O11+P11+Q11+R11+S11+T11+U11+V11+W11+X11+Y11+Z11+AA11+AB11+AC11+AD11+AE11+AF11+AG11+AH11+AI11+AJ11+AK11+AL11+AM11+AN11+AO11+AP11+AQ11+AR11+AS11+AT11+AU11+AV11+AW11+AX11+AY11+AZ11+BA11+BB11+BC11+BD11+BE11+BF11 -> 0
B12: Ажратилган маблағлар (сўм) | C12: =+D12+E12+F12+G12+H12+I12+J12+K12+L12+M12+N12+O12+P12+Q12+R12+S12+T12+U12+V12+W12+X12+Y12+Z12+AA12+AB12+AC12+AD12+AE12+AF12+AG12+AH12+AI12+AJ12+AK12+AL12+AM12+AN12+AO12+AP12+AQ12+AR12+AS12+AT12+AU12+AV12+AW12+AX12+AY12+AZ12+BA12+BB12+BC12+BD12+BE12+BF12 -> 0
B13: Тўлов-контракт | C13: =+D13+E13+F13+G13+H13+I13+J13+K13+L13+M13+N13+O13+P13+Q13+R13+S13+T13+U13+V13+W13+X13+Y13+Z13+AA13+AB13+AC13+AD13+AE13+AF13+AG13+AH13+AI13+AJ13+AK13+AL13+AM13+AN13+AO13+AP13+AQ13+AR13+AS13+AT13+AU13+AV13+AW13+AX13+AY13+AZ13+BA13+BB13+BC13+BD13+BE13+BF13 -> 0
B14: Ажратилган маблағлар (сўм) | C14: =+D14+E14+F14+G14+H14+I14+J14+K14+L14+M14+N14+O14+P14+Q14+R14+S14+T14+U14+V14+W14+X14+Y14+Z14+AA14+AB14+AC14+AD14+AE14+AF14+AG14+AH14+AI14+AJ14+AK14+AL14+AM14+AN14+AO14+AP14+AQ14+AR14+AS14+AT14+AU14+AV14+AW14+AX14+AY14+AZ14+BA14+BB14+BC14+BD14+BE14+BF14 -> 0
B15: Илм-фан, спорт, санъат ва маданият йўналишларидаги олти ойгача муддатли ўқув курслари | C15: =+D15+E15+F15+G15+H15+I15+J15+K15+L15+M15+N15+O15+P15+Q15+R15+S15+T15+U15+V15+W15+X15+Y15+Z15+AA15+AB15+AC15+AD15+AE15+AF15+AG15+AH15+AI15+AJ15+AK15+AL15+AM15+AN15+AO15+AP15+AQ15+AR15+AS15+AT15+AU15+AV15+AW15+AX15+AY15+AZ15+BA15+BB15+BC15+BD15+BE15+BF15 -> 0
B16: Ажратилган маблағлар (сўм) | C16: =+D16+E16+F16+G16+H16+I16+J16+K16+L16+M16+N16+O16+P16+Q16+R16+S16+T16+U16+V16+W16+X16+Y16+Z16+AA16+AB16+AC16+AD16+AE16+AF16+AG16+AH16+AI16+AJ16+AK16+AL16+AM16+AN16+AO16+AP16+AQ16+AR16+AS16+AT16+AU16+AV16+AW16+AX16+AY16+AZ16+BA16+BB16+BC16+BD16+BE16+BF16 -> 0
B17: Олимпиада, танлов ва мусобақаларнинг маҳаллий босқичларида қатнашиш харажатлари | C17: =+D17+E17+F17+G17+H17+I17+J17+K17+L17+M17+N17+O17+P17+Q17+R17+S17+T17+U17+V17+W17+X17+Y17+Z17+AA17+AB17+AC17+AD17+AE17+AF17+AG17+AH17+AI17+AJ17+AK17+AL17+AM17+AN17+AO17+AP17+AQ17+AR17+AS17+AT17+AU17+AV17+AW17+AX17+AY17+AZ17+BA17+BB17+BC17+BD17+BE17+BF17 -> 0
B18: Ажратилган маблағлар (сўм) | C18: =+D18+E18+F18+G18+H18+I18+J18+K18+L18+M18+N18+O18+P18+Q18+R18+S18+T18+U18+V18+W18+X18+Y18+Z18+AA18+AB18+AC18+AD18+AE18+AF18+AG18+AH18+AI18+AJ18+AK18+AL18+AM18+AN18+AO18+AP18+AQ18+AR18+AS18+AT18+AU18+AV18+AW18+AX18+AY18+AZ18+BA18+BB18+BC18+BD18+BE18+BF18 -> 0
B19: Мамлакатда ёки хорижий давлатларда даволаниш билан боғлиқ харажатлар | C19: =+D19+E19+F19+G19+H19+I19+J19+K19+L19+M19+N19+O19+P19+Q19+R19+S19+T19+U19+V19+W19+X19+Y19+Z19+AA19+AB19+AC19+AD19+AE19+AF19+AG19+AH19+AI19+AJ19+AK19+AL19+AM19+AN19+AO19+AP19+AQ19+AR19+AS19+AT19+AU19+AV19+AW19+AX19+AY19+AZ19+BA19+BB19+BC19+BD19+BE19+BF19 -> 0
B20: Ажратилган маблағлар (сўм) | C20: =+D20+E20+F20+G20+H20+I20+J20+K20+L20+M20+N20+O20+P20+Q20+R20+S20+T20+U20+V20+W20+X20+Y20+Z20+AA20+AB20+AC20+AD20+AE20+AF20+AG20+AH20+AI20+AJ20+AK20+AL20+AM20+AN20+AO20+AP20+AQ20+AR20+AS20+AT20+AU20+AV20+AW20+AX20+AY20+AZ20+BA20+BB20+BC20+BD20+BE20+BF20 -> 0
B21: Сафарбарлик чақируви резервидаги хизматни ўташ бадали | C21: =+D21+E21+F21+G21+H21+I21+J21+K21+L21+M21+N21+O21+P21+Q21+R21+S21+T21+U21+V21+W21+X21+Y21+Z21+AA21+AB21+AC21+AD21+AE21+AF21+AG21+AH21+AI21+AJ21+AK21+AL21+AM21+AN21+AO21+AP21+AQ21+AR21+AS21+AT21+AU21+AV21+AW21+AX21+AY21+AZ21+BA21+BB21+BC21+BD21+BE21+BF21 -> 0
B22: Ажратилган маблағлар (сўм) | C22: =+D22+E22+F22+G22+H22+I22+J22+K22+L22+M22+N22+O22+P22+Q22+R22+S22+T22+U22+V22+W22+X22+Y22+Z22+AA22+AB22+AC22+AD22+AE22+AF22+AG22+AH22+AI22+AJ22+AK22+AL22+AM22+AN22+AO22+AP22+AQ22+AR22+AS22+AT22+AU22+AV22+AW22+AX22+AY22+AZ22+BA22+BB22+BC22+BD22+BE22+BF22 -> 0
B23: 12 ойгача турар жой ижараси | C23: =+D23+E23+F23+G23+H23+I23+J23+K23+L23+M23+N23+O23+P23+Q23+R23+S23+T23+U23+V23+W23+X23+Y23+Z23+AA23+AB23+AC23+AD23+AE23+AF23+AG23+AH23+AI23+AJ23+AK23+AL23+AM23+AN23+AO23+AP23+AQ23+AR23+AS23+AT23+AU23+AV23+AW23+AX23+AY23+AZ23+BA23+BB23+BC23+BD23+BE23+BF23 -> 0
... B34: Ажратилган маблағлар (сўм) | C34: =+D34+E34+F34+G34+H34+I34+J34+K34+L34+M34+N34+O34+P34+Q34+R34+S34+T34+U34+V34+W34+X34+Y34+Z34+AA34+AB34+AC34+AD34+AE34+AF34+AG34+AH34+AI34+AJ34+AK34+AL34+AM34+AN34+AO34+AP34+AQ34+AR34+AS34+AT34+AU34+AV34+AW34+AX34+AY34+AZ34+BA34+BB34+BC34+BD34+BE34+BF34 -> 0
A35: 5 | B35: Оталиққа олинган ёшлар билан ўрганилганлар сони | C35: =+D35+E35+F35+G35+H35+I35+J35+K35+L35+M35+N35+O35+P35+Q35+R35+S35+T35+U35+V35+W35+X35+Y35+Z35+AA35+AB35+AC35+AD35+AE35+AF35+AG35+AH35+AI35+AJ35+AK35+AL35+AM35+AN35+AO35+AP35+AQ35+AR35+AS35+AT35+AU35+AV35+AW35+AX35+AY35+AZ35+BA35+BB35+BC35+BD35+BE35+BF35 -> 0
B36: аниқланган муаммолар | C36: =+D36+E36+F36+G36+H36+I36+J36+K36+L36+M36+N36+O36+P36+Q36+R36+S36+T36+U36+V36+W36+X36+Y36+Z36+AA36+AB36+AC36+AD36+AE36+AF36+AG36+AH36+AI36+AJ36+AK36+AL36+AM36+AN36+AO36+AP36+AQ36+AR36+AS36+AT36+AU36+AV36+AW36+AX36+AY36+AZ36+BA36+BB36+BC36+BD36+BE36+BF36 -> 0
B37: ҳал этилганлари | C37: =+D37+E37+F37+G37+H37+I37+J37+K37+L37+M37+N37+O37+P37+Q37+R37+S37+T37+U37+V37+W37+X37+Y37+Z37+AA37+AB37+AC37+AD37+AE37+AF37+AG37+AH37+AI37+AJ37+AK37+AL37+AM37+AN37+AO37+AP37+AQ37+AR37+AS37+AT37+AU37+AV37+AW37+AX37+AY37+AZ37+BA37+BB37+BC37+BD37+BE37+BF37 -> 0
A38: 6 | B38: Чет элда миграцияга ўқиш, яшаш ёки ишлаш учун бўлиб турган ёшлар йўналиши | C38: =+D38+E38+F38+G38+H38+I38+J38+K38+L38+M38+N38+O38+P38+Q38+R38+S38+T38+U38+V38+W38+X38+Y38+Z38+AA38+AB38+AC38+AD38+AE38+AF38+AG38+AH38+AI38+AJ38+AK38+AL38+AM38+AN38+AO38+AP38+AQ38+AR38+AS38+AT38+AU38+AV38+AW38+AX38+AY38+AZ38+BA38+BB38+BC38+BD38+BE38+BF38 -> 0
A39: 7 | B39: "Раҳбар ва ёшлар" учрашуви | C39: =+D39+E39+F39+G39+H39+I39+J39+K39+L39+M39+N39+O39+P39+Q39+R39+S39+T39+U39+V39+W39+X39+Y39+Z39+AA39+AB39+AC39+AD39+AE39+AF39+AG39+AH39+AI39+AJ39+AK39+AL39+AM39+AN39+AO39+AP39+AQ39+AR39+AS39+AT39+AU39+AV39+AW39+AX39+AY39+AZ39+BA39+BB39+BC39+BD39+BE39+BF39 -> 0
B40: Иштирок этган ёшлар сони | C40: =+D40+E40+F40+G40+H40+I40+J40+K40+L40+M40+N40+O40+P40+Q40+R40+S40+T40+U40+V40+W40+X40+Y40+Z40+AA40+AB40+AC40+AD40+AE40+AF40+AG40+AH40+AI40+AJ40+AK40+AL40+AM40+AN40+AO40+AP40+AQ40+AR40+AS40+AT40+AU40+AV40+AW40+AX40+AY40+AZ40+BA40+BB40+BC40+BD40+BE40+BF40 -> 0
B41: Ёшларнинг муаммолари | C41: =+D41+E41+F41+G41+H41+I41+J41+K41+L41+M41+N41+O41+P41+Q41+R41+S41+T41+U41+V41+W41+X41+Y41+Z41+AA41+AB41+AC41+AD41+AE41+AF41+AG41+AH41+AI41+AJ41+AK41+AL41+AM41+AN41+AO41+AP41+AQ41+AR41+AS41+AT41+AU41+AV41+AW41+AX41+AY41+AZ41+BA41+BB41+BC41+BD41+BE41+BF41 -> 0
B42: Ҳал этилганлик ҳолати | C42: =+D42+E42+F42+G42+H42+I42+J42+K42+L42+M42+N42+O42+P42+Q42+R42+S42+T42+U42+V42+W42+X42+Y42+Z42+AA42+AB42+AC42+AD42+AE42+AF42+AG42+AH42+AI42+AJ42+AK42+AL42+AM42+AN42+AO42+AP42+AQ42+AR42+AS42+AT42+AU42+AV42+AW42+AX42+AY42+AZ42+BA42+BB42+BC42+BD42+BE42+BF42 -> 0
A43: 8 | B43: Мактаб ўқувчилар давомати | C43: =+D43+E43+F43+G43+H43+I43+J43+K43+L43+M43+N43+O43+P43+Q43+R43+S43+T43+U43+V43+W43+X43+Y43+Z43+AA43+AB43+AC43+AD43+AE43+AF43+AG43+AH43+AI43+AJ43+AK43+AL43+AM43+AN43+AO43+AP43+AQ43+AR43+AS43+AT43+AU43+AV43+AW43+AX43+AY43+AZ43+BA43+BB43+BC43+BD43+BE43+BF43 -> 52 | E43: 1 | F43: 1 | G43: 1 | H43: 1 | I43: 1 | J43: 1 | K43: 1 | L43: 1 | N43: 1 | O43: 1 | P43: 1 | Q43: 1 | R43: 1 | S43: 1 | T43: 1 | U43: 1 | V43: 1 | W43: 1 | X43: 1 | Y43: 1 | Z43: 1 | AA43: 1 | AB43: 1 | AC43: 1 | AD43: 1 | AE43: 1 | AG43: 1 | AH43: 1 | AI43: 1 | AJ43: 1 | AK43: 1 | AL43: 1 | AM43: 1 | AN43: 1 | AO43: 1 | AP43: 1 | AQ43: 1 | AR43: 1 | AS43: 1 | AT43: 1 | AU43: 1 | AV43: 1 | AW43: 1 | AX43: 1 | AY43: 1 | AZ43: 1 | BA43: 1 | BB43: 1 | BC43: 1 | BD43: 1 | BE43: 1 | BF43: 1
A44: 9 | B44: Ёшларни тадбиркорликка жалб этиш (ПҚ-60-61-62-қарорлар ижроси) йўналишида кредит берилган ёшлар сони | C44: =+D44+E44+F44+G44+H44+I44+J44+K44+L44+M44+N44+O44+P44+Q44+R44+S44+T44+U44+V44+W44+X44+Y44+Z44+AA44+AB44+AC44+AD44+AE44+AF44+AG44+AH44+AI44+AJ44+AK44+AL44+AM44+AN44+AO44+AP44+AQ44+AR44+AS44+AT44+AU44+AV44+AW44+AX44+AY44+AZ44+BA44+BB44+BC44+BD44+BE44+BF44 -> 0
B45: Ажратилган кредит маблағлари (млн) | C45: =+D45+E45+F45+G45+H45+I45+J45+K45+L45+M45+N45+O45+P45+Q45+R45+S45+T45+U45+V45+W45+X45+Y45+Z45+AA45+AB45+AC45+AD45+AE45+AF45+AG45+AH45+AI45+AJ45+AK45+AL45+AM45+AN45+AO45+AP45+AQ45+AR45+AS45+AT45+AU45+AV45+AW45+AX45+AY45+AZ45+BA45+BB45+BC45+BD45+BE45+BF45 -> 0
A46: 10 | B46: Битирувчи (мактаб, профессионал таълим, ОТМ) ёшларни бандлигини таъминлаш | C46: =+D46+E46+F46+G46+H46+I46+J46+K46+L46+M46+N46+O46+P46+Q46+R46+S46+T46+U46+V46+W46+X46+Y46+Z46+AA46+AB46+AC46+AD46+AE46+AF46+AG46+AH46+AI46+AJ46+AK46+AL46+AM46+AN46+AO46+AP46+AQ46+AR46+AS46+AT46+AU46+AV46+AW46+AX46+AY46+AZ46+BA46+BB46+BC46+BD46+BE46+BF46 -> 0
A47: 11 | B47: "Ibrat farzandlar" лойиҳасини тарғибот қилиш | C47: =+D47+E47+F47+G47+H47+I47+J47+K47+L47+M47+N47+O47+P47+Q47+R47+S47+T47+U47+V47+W47+X47+Y47+Z47+AA47+AB47+AC47+AD47+AE47+AF47+AG47+AH47+AI47+AJ47+AK47+AL47+AM47+AN47+AO47+AP47+AQ47+AR47+AS47+AT47+AU47+AV47+AW47+AX47+AY47+AZ47+BA47+BB47+BC47+BD47+BE47+BF47 -> 52 | E47: 1 | F47: 1 | G47: 1 | H47: 1 | I47: 1 | J47: 1 | K47: 1 | L47: 1 | N47: 1 | O47: 1 | P47: 1 | Q47: 1 | R47: 1 | S47: 1 | T47: 1 | U47: 1 | V47: 1 | W47: 1 | X47: 1 | Y47: 1 | Z47: 1 | AA47: 1 | AB47: 1 | AC47: 1 | AD47: 1 | AE47: 1 | AG47: 1 | AH47: 1 | AI47: 1 | AJ47: 1 | AK47: 1 | AL47: 1 | AM47: 1 | AN47: 1 | AO47: 1 | AP47: 1 | AQ47: 1 | AR47: 1 | AS47: 1 | AT47: 1 | AU47: 1 | AV47: 1 | AW47: 1 | AX47: 1 | AY47: 1 | AZ47: 1 | BA47: 1 | BB47: 1 | BC47: 1 | BD47: 1 | BE47: 1 | BF47: 1
A48: 12 | B48: "Ustoz AI" лойиҳасини тарғибот қилиш | C48: =+D48+E48+F48+G48+H48+I48+J48+K48+L48+M48+N48+O48+P48+Q48+R48+S48+T48+U48+V48+W48+X48+Y48+Z48+AA48+AB48+AC48+AD48+AE48+AF48+AG48+AH48+AI48+AJ48+AK48+AL48+AM48+AN48+AO48+AP48+AQ48+AR48+AS48+AT48+AU48+AV48+AW48+AX48+AY48+AZ48+BA48+BB48+BC48+BD48+BE48+BF48 -> 52 | E48: 1 | F48: 1 | G48: 1 | H48: 1 | I48: 1 | J48: 1 | K48: 1 | L48: 1 | N48: 1 | O48: 1 | P48: 1 | Q48: 1 | R48: 1 | S48: 1 | T48: 1 | U48: 1 | V48: 1 | W48: 1 | X48: 1 | Y48: 1 | Z48: 1 | AA48: 1 | AB48: 1 | AC48: 1 | AD48: 1 | AE48: 1 | AG48: 1 | AH48: 1 | AI48: 1 | AJ48: 1 | AK48: 1 | AL48: 1 | AM48: 1 | AN48: 1 | AO48: 1 | AP48: 1 | AQ48: 1 | AR48: 1 | AS48: 1 | AT48: 1 | AU48: 1 | AV48: 1 | AW48: 1 | AX48: 1 | AY48: 1 | AZ48: 1 | BA48: 1 | BB48: 1 | BC48: 1 | BD48: 1 | BE48: 1 | BF48: 1
A49: 13 | B49: "UzChees" лойиҳасини тарғибот қилиш | C49: =+D49+E49+F49+G49+H49+I49+J49+K49+L49+M49+N49+O49+P49+Q49+R49+S49+T49+U49+V49+W49+X49+Y49+Z49+AA49+AB49+AC49+AD49+AE49+AF49+AG49+AH49+AI49+AJ49+AK49+AL49+AM49+AN49+AO49+AP49+AQ49+AR49+AS49+AT49+AU49+AV49+AW49+AX49+AY49+AZ49+BA49+BB49+BC49+BD49+BE49+BF49 -> 52 | E49: 1 | F49: 1 | G49: 1 | H49: 1 | I49: 1 | J49: 1 | K49: 1 | L49: 1 | N49: 1 | O49: 1 | P49: 1 | Q49: 1 | R49: 1 | S49: 1 | T49: 1 | U49: 1 | V49: 1 | W49: 1 | X49: 1 | Y49: 1 | Z49: 1 | AA49: 1 | AB49: 1 | AC49: 1 | AD49: 1 | AE49: 1 | AG49: 1 | AH49: 1 | AI49: 1 | AJ49: 1 | AK49: 1 | AL49: 1 | AM49: 1 | AN49: 1 | AO49: 1 | AP49: 1 | AQ49: 1 | AR49: 1 | AS49: 1 | AT49: 1 | AU49: 1 | AV49: 1 | AW49: 1 | AX49: 1 | AY49: 1 | AZ49: 1 | BA49: 1 | BB49: 1 | BC49: 1 | BD49: 1 | BE49: 1 | BF49: 1
A50: 14 | B50: "Mutolaa" лойиҳасини тарғибот қилиш | C50: =+D50+E50+F50+G50+H50+I50+J50+K50+L50+M50+N50+O50+P50+Q50+R50+S50+T50+U50+V50+W50+X50+Y50+Z50+AA50+AB50+AC50+AD50+AE50+AF50+AG50+AH50+AI50+AJ50+AK50+AL50+AM50+AN50+AO50+AP50+AQ50+AR50+AS50+AT50+AU50+AV50+AW50+AX50+AY50+AZ50+BA50+BB50+BC50+BD50+BE50+BF50 -> 52 | E50: 1 | F50: 1 | G50: 1 | H50: 1 | I50: 1 | J50: 1 | K50: 1 | L50: 1 | N50: 1 | O50: 1 | P50: 1 | Q50: 1 | R50: 1 | S50: 1 | T50: 1 | U50: 1 | V50: 1 | W50: 1 | X50: 1 | Y50: 1 | Z50: 1 | AA50: 1 | AB50: 1 | AC50: 1 | AD50: 1 | AE50: 1 | AG50: 1 | AH50: 1 | AI50: 1 | AJ50: 1 | AK50: 1 | AL50: 1 | AM50: 1 | AN50: 1 | AO50: 1 | AP50: 1 | AQ50: 1 | AR50: 1 | AS50: 1 | AT50: 1 | AU50: 1 | AV50: 1 | AW50: 1 | AX50: 1 | AY50: 1 | AZ50: 1 | BA50: 1 | BB50: 1 | BC50: 1 | BD50: 1 | BE50: 1 | BF50: 1
...

Sheet 01.23
A1: № | B1: Кўрсаткич | C1: Жами | D1: Ал-Хоразмий | E1: Бахористон | F1: Бектўпи | G1: Гулистон | H1: Катта Хирмонтепа | I1: Тирсакобод | J1: Хайрабод | K1: Хирмон тепа | L1: Хонтўпи | M1: Шараф | N1: Шарқ | O1: Шарқ тонги | P1: Шухрат | Q1: 1-Чарх Камолон | R1: 2-Чарх Камолон | S1: 3-Чарх Камолон | T1: Бешёғоч | U1: Катта Козиробод | V1: Катта Олмазор | W1: Катта Чилонзор-1 | X1: Катта Чилонзор-2 | Y1: Катта Чилонзор-3 | Z1: Қозиробод | AA1: Новза | AB1: Чилонзор | AC1: 1-Қатортол | AD1: Бешчинор | AE1: Боғзор | AF1: Диёр | AG1: Дилобод | AH1: Катта Навбаҳор | AI1: Кўркам | AJ1: Кўтарма | AK1: Қатортол | AL1: Лутфий | AM1: Навбахор | AN1: Нафосат | AO1: Оқ-тепа | AP1: Халқлар Дўстлиги | AQ1: Чўпон-ота | AR1: 2-Қатортол | AS1: Ботирма | AT1: Бўрижар | AU1: Гавхар | AV1: Дўмбиробод | AW1: Зарқўрғон | AX1: Катта Дўмбиробод | AY1: Кичик Хирмонтепа | AZ1: Мевазор | BA1: Мехржон | BB1: Наққошлик | BC1: Фидокор | BD1: Яккабоғ | BE1: Яккатут | BF1: Бешқўрғон
A2: 1 | B2: Маданий-маърифий тадбирлар | C2: =+D2+E2+F2+G2+H2+I2+J2+K2+L2+M2+N2+O2+P2+Q2+R2+S2+T2+U2+V2+W2+X2+Y2+Z2+AA2+AB2+AC2+AD2+AE2+AF2+AG2+AH2+AI2+AJ2+AK2+AL2+AM2+AN2+AO2+AP2+AQ2+AR2+AS2+AT2+AU2+AV2+AW2+AX2+AY2+AZ2+BA2+BB2+BC2+BD2+BE2+BF2 -> 10 | G2: 1 | H2: 2 | L2: 1 | R2: 1 | AE2: 1 | AF2: 1 | AK2: 1 | AS2: 1 | AX2: 1
B3: иштирок этган ёшлар сони | C3: =+D3+E3+F3+G3+H3+I3+J3+K3+L3+M3+N3+O3+P3+Q3+R3+S3+T3+U3+V3+W3+X3+Y3+Z3+AA3+AB3+AC3+AD3+AE3+AF3+AG3+AH3+AI3+AJ3+AK3+AL3+AM3+AN3+AO3+AP3+AQ3+AR3+AS3+AT3+AU3+AV3+AW3+AX3+AY3+AZ3+BA3+BB3+BC3+BD3+BE3+BF3 -> 46 | G3: 4 | H3: 6 | L3: 5 | R3: 4 | AE3: 5 | AF3: 4 | AK3: 5 | AS3: 8 | AX3: 5
A4: 2 | B4: Ҳарбий ватанпарварлик тадбирлар | C4: =+D4+E4+F4+G4+H4+I4+J4+K4+L4+M4+N4+O4+P4+Q4+R4+S4+T4+U4+V4+W4+X4+Y4+Z4+AA4+AB4+AC4+AD4+AE4+AF4+AG4+AH4+AI4+AJ4+AK4+AL4+AM4+AN4+AO4+AP4+AQ4+AR4+AS4+AT4+AU4+AV4+AW4+AX4+AY4+AZ4+BA4+BB4+BC4+BD4+BE4+BF4 -> 9 | N4: 1 | O4: 1 | W4: 1 | Y4: 1 | AC4: 1 | AG4: 1 | AJ4: 1 | AM4: 1 | BB4: 1
B5: Иштирок этган ёшлар сони | C5: =+D5+E5+F5+G5+H5+I5+J5+K5+L5+M5+N5+O5+P5+Q5+R5+S5+T5+U5+V5+W5+X5+Y5+Z5+AA5+AB5+AC5+AD5+AE5+AF5+AG5+AH5+AI5+AJ5+AK5+AL5+AM5+AN5+AO5+AP5+AQ5+AR5+AS5+AT5+AU5+AV5+AW5+AX5+AY5+AZ5+BA5+BB5+BC5+BD5+BE5+BF5 -> 30 | N5: 3 | O5: 4 | W5: 3 | Y5: 5 | AC5: 3 | AG5: 3 | AJ5: 3 | AM5: 3 | BB5: 3
A6: 3 | B6: “Беш ташаббус олимпиадаси” | C6: =+D6+E6+F6+G6+H6+I6+J6+K6+L6+M6+N6+O6+P6+Q6+R6+S6+T6+U6+V6+W6+X6+Y6+Z6+AA6+AB6+AC6+AD6+AE6+AF6+AG6+AH6+AI6+AJ6+AK6+AL6+AM6+AN6+AO6+AP6+AQ6+AR6+AS6+AT6+AU6+AV6+AW6+AX6+AY6+AZ6+BA6+BB6+BC6+BD6+BE6+BF6 -> 0
B7: рўҳатдан ўтган ёшлар сони | C7: =+D7+E7+F7+G7+H7+I7+J7+K7+L7+M7+N7+O7+P7+Q7+R7+S7+T7+U7+V7+W7+X7+Y7+Z7+AA7+AB7+AC7+AD7+AE7+AF7+AG7+AH7+AI7+AJ7+AK7+AL7+AM7+AN7+AO7+AP7+AQ7+AR7+AS7+AT7+AU7+AV7+AW7+AX7+AY7+AZ7+BA7+BB7+BC7+BD7+BE7+BF7 -> 0
B8: иштирок этган ёшлар сони | C8: =+D8+E8+F8+G8+H8+I8+J8+K8+L8+M8+N8+O8+P8+Q8+R8+S8+T8+U8+V8+W8+X8+Y8+Z8+AA8+AB8+AC8+AD8+AE8+AF8+AG8+AH8+AI8+AJ8+AK8+AL8+AM8+AN8+AO8+AP8+AQ8+AR8+AS8+AT8+AU8+AV8+AW8+AX8+AY8+AZ8+BA8+BB8+BC8+BD8+BE8+BF8 -> 0
A9: 4 | B9: Ёшлар дафтари йўналишида кўрсатилган ёрдамлар | C9: =+D9+E9+F9+G9+H9+I9+J9+K9+L9+M9+N9+O9+P9+Q9+R9+S9+T9+U9+V9+W9+X9+Y9+Z9+AA9+AB9+AC9+AD9+AE9+AF9+AG9+AH9+AI9+AJ9+AK9+AL9+AM9+AN9+AO9+AP9+AQ9+AR9+AS9+AT9+AU9+AV9+AW9+AX9+AY9+AZ9+BA9+BB9+BC9+BD9+BE9+BF9 -> 0 | D9: =+D11+D13+D15+D17+D19+D21+D23+D25+D27+D29+D31+D33 -> 0 | E9: =+E11+E13+E15+E17+E19+E21+E23+E25+E27+E29+E31+E33 -> 0 | F9: =+F11+F13+F15+F17+F19+F21+F23+F25+F27+F29+F31+F33 -> 0 | G9: =+G11+G13+G15+G17+G19+G21+G23+G25+G27+G29+G31+G33 -> 0 | H9: =+H11+H13+H15+H17+H19+H21+H23+H25+H27+H29+H31+H33 -> 0 | I9: =+I11+I13+I15+I17+I19+I21+I23+I25+I27+I29+I31+I33 -> 0 | J9: =+J11+J13+J15+J17+J19+J21+J23+J25+J27+J29+J31+J33 -> 0 | K9: =+K11+K13+K15+K17+K19+K21+K23+K25+K27+K29+K31+K33 -> 0 | ... BF9: =+BF11+BF13+BF15+BF17+BF19+BF21+BF23+BF25+BF27+BF29+BF31+BF33 -> 0
B10: Ажратилган маблағлар (сўм) | C10: =+D10+E10+F10+G10+H10+I10+J10+K10+L10+M10+N10+O10+P10+Q10+R10+S10+T10+U10+V10+W10+X10+Y10+Z10+AA10+AB10+AC10+AD10+AE10+AF10+AG10+AH10+AI10+AJ10+AK10+AL10+AM10+AN10+AO10+AP10+AQ10+AR10+AS10+AT10+AU10+AV10+AW10+AX10+AY10+AZ10+BA10+BB10+BC10+BD10+BE10+BF10 -> 0 | D10: =+D12+D14+D16+D18+D20+D22+D24+D26+D28+D30+D32+D34 -> 0 | E10: =+E12+E14+E16+E18+E20+E22+E24+E26+E28+E30+E32+E34 -> 0 | F10: =+F12+F14+F16+F18+F20+F22+F24+F26+F28+F30+F32+F34 -> 0 | G10: =+G12+G14+G16+G18+G20+G22+G24+G26+G28+G30+G32+G34 -> 0 | H10: =+H12+H14+H16+H18+H20+H22+H24+H26+H28+H30+H32+H34 -> 0 | I10: =+I12+I14+I16+I18+I20+I22+I24+I26+I28+I30+I32+I34 -> 0 | J10: =+J12+J14+J16+J18+J20+J22+J24+J26+J28+J30+J32+J34 -> 0 | K10: =+K12+K14+K16+K18+K20+K22+K24+K26+K28+K30+K32+K34 -> 0 | ... BF10: =+BF12+BF14+BF16+BF18+BF20+BF22+BF24+BF26+BF28+BF30+BF32+BF34 -> 0
A11: шундан | B11: Автомототранспорт воситалари ҳайдовчиларини тайёрлаш | C11: =+D11+E11+F11+G11+H11+I11+J11+K11+L11+M11+N11+O11+P11+Q11+R11+S11+T11+U11+V11+W11+X11+Y11+Z11+AA11+AB11+AC11+AD11+AE11+AF11+AG11+AH11+AI11+AJ11+AK11+AL11+AM11+AN11+AO11+AP11+AQ11+AR11+AS11+AT11+AU11+AV11+AW11+AX11+AY11+AZ11+BA11+BB11+BC11+BD11+BE11+BF11 -> 0
B12: Ажратилган маблағлар (сўм) | C12: =+D12+E12+F12+G12+H12+I12+J12+K12+L12+M12+N12+O12+P12+Q12+R12+S12+T12+U12+V12+W12+X12+Y12+Z12+AA12+AB12+AC12+AD12+AE12+AF12+AG12+AH12+AI12+AJ12+AK12+AL12+AM12+AN12+AO12+AP12+AQ12+AR12+AS12+AT12+AU12+AV12+AW12+AX12+AY12+AZ12+BA12+BB12+BC12+BD12+BE12+BF12 -> 0
B13: Тўлов-контракт | C13: =+D13+E13+F13+G13+H13+I13+J13+K13+L13+M13+N13+O13+P13+Q13+R13+S13+T13+U13+V13+W13+X13+Y13+Z13+AA13+AB13+AC13+AD13+AE13+AF13+AG13+AH13+AI13+AJ13+AK13+AL13+AM13+AN13+AO13+AP13+AQ13+AR13+AS13+AT13+AU13+AV13+AW13+AX13+AY13+AZ13+BA13+BB13+BC13+BD13+BE13+BF13 -> 0
B14: Ажратилган маблағлар (сўм) | C14: =+D14+E14+F14+G14+H14+I14+J14+K14+L14+M14+N14+O14+P14+Q14+R14+S14+T14+U14+V14+W14+X14+Y14+Z14+AA14+AB14+AC14+AD14+AE14+AF14+AG14+AH14+AI14+AJ14+AK14+AL14+AM14+AN14+AO14+AP14+AQ14+AR14+AS14+AT14+AU14+AV14+AW14+AX14+AY14+AZ14+BA14+BB14+BC14+BD14+BE14+BF14 -> 0
B15: Илм-фан, спорт, санъат ва маданият йўналишларидаги олти ойгача муддатли ўқув курслари | C15: =+D15+E15+F15+G15+H15+I15+J15+K15+L15+M15+N15+O15+P15+Q15+R15+S15+T15+U15+V15+W15+X15+Y15+Z15+AA15+AB15+AC15+AD15+AE15+AF15+AG15+AH15+AI15+AJ15+AK15+AL15+AM15+AN15+AO15+AP15+AQ15+AR15+AS15+AT15+AU15+AV15+AW15+AX15+AY15+AZ15+BA15+BB15+BC15+BD15+BE15+BF15 -> 0
B16: Ажратилган маблағлар (сўм) | C16: =+D16+E16+F16+G16+H16+I16+J16+K16+L16+M16+N16+O16+P16+Q16+R16+S16+T16+U16+V16+W16+X16+Y16+Z16+AA16+AB16+AC16+AD16+AE16+AF16+AG16+AH16+AI16+AJ16+AK16+AL16+AM16+AN16+AO16+AP16+AQ16+AR16+AS16+AT16+AU16+AV16+AW16+AX16+AY16+AZ16+BA16+BB16+BC16+BD16+BE16+BF16 -> 0
B17: Олимпиада, танлов ва мусобақаларнинг маҳаллий босқичларида қатнашиш харажатлари | C17: =+D17+E17+F17+G17+H17+I17+J17+K17+L17+M17+N17+O17+P17+Q17+R17+S17+T17+U17+V17+W17+X17+Y17+Z17+AA17+AB17+AC17+AD17+AE17+AF17+AG17+AH17+AI17+AJ17+AK17+AL17+AM17+AN17+AO17+AP17+AQ17+AR17+AS17+AT17+AU17+AV17+AW17+AX17+AY17+AZ17+BA17+BB17+BC17+BD17+BE17+BF17 -> 0
B18: Ажратилган маблағлар (сўм) | C18: =+D18+E18+F18+G18+H18+I18+J18+K18+L18+M18+N18+O18+P18+Q18+R18+S18+T18+U18+V18+W18+X18+Y18+Z18+AA18+AB18+AC18+AD18+AE18+AF18+AG18+AH18+AI18+AJ18+AK18+AL18+AM18+AN18+AO18+AP18+AQ18+AR18+AS18+AT18+AU18+AV18+AW18+AX18+AY18+AZ18+BA18+BB18+BC18+BD18+BE18+BF18 -> 0
B19: Мамлакатда ёки хорижий давлатларда даволаниш билан боғлиқ харажатлар | C19: =+D19+E19+F19+G19+H19+I19+J19+K19+L19+M19+N19+O19+P19+Q19+R19+S19+T19+U19+V19+W19+X19+Y19+Z19+AA19+AB19+AC19+AD19+AE19+AF19+AG19+AH19+AI19+AJ19+AK19+AL19+AM19+AN19+AO19+AP19+AQ19+AR19+AS19+AT19+AU19+AV19+AW19+AX19+AY19+AZ19+BA19+BB19+BC19+BD19+BE19+BF19 -> 0
B20: Ажратилган маблағлар (сўм) | C20: =+D20+E20+F20+G20+H20+I20+J20+K20+L20+M20+N20+O20+P20+Q20+R20+S20+T20+U20+V20+W20+X20+Y20+Z20+AA20+AB20+AC20+AD20+AE20+AF20+AG20+AH20+AI20+AJ20+AK20+AL20+AM20+AN20+AO20+AP20+AQ20+AR20+AS20+AT20+AU20+AV20+AW20+AX20+AY20+AZ20+BA20+BB20+BC20+BD20+BE20+BF20 -> 0
B21: Сафарбарлик чақируви резервидаги хизматни ўташ бадали | C21: =+D21+E21+F21+G21+H21+I21+J21+K21+L21+M21+N21+O21+P21+Q21+R21+S21+T21+U21+V21+W21+X21+Y21+Z21+AA21+AB21+AC21+AD21+AE21+AF21+AG21+AH21+AI21+AJ21+AK21+AL21+AM21+AN21+AO21+AP21+AQ21+AR21+AS21+AT21+AU21+AV21+AW21+AX21+AY21+AZ21+BA21+BB21+BC21+BD21+BE21+BF21 -> 0
B22: Ажратилган маблағлар (сўм) | C22: =+D22+E22+F22+G22+H22+I22+J22+K22+L22+M22+N22+O22+P22+Q22+R22+S22+T22+U22+V22+W22+X22+Y22+Z22+AA22+AB22+AC22+AD22+AE22+AF22+AG22+AH22+AI22+AJ22+AK22+AL22+AM22+AN22+AO22+AP22+AQ22+AR22+AS22+AT22+AU22+AV22+AW22+AX22+AY22+AZ22+BA22+BB22+BC22+BD22+BE22+BF22 -> 0
B23: 12 ойгача турар жой ижараси | C23: =+D23+E23+F23+G23+H23+I23+J23+K23+L23+M23+N23+O23+P23+Q23+R23+S23+T23+U23+V23+W23+X23+Y23+Z23+AA23+AB23+AC23+AD23+AE23+AF23+AG23+AH23+AI23+AJ23+AK23+AL23+AM23+AN23+AO23+AP23+AQ23+AR23+AS23+AT23+AU23+AV23+AW23+AX23+AY23+AZ23+BA23+BB23+BC23+BD23+BE23+BF23 -> 0
... B34: Ажратилган маблағлар (сўм) | C34: =+D34+E34+F34+G34+H34+I34+J34+K34+L34+M34+N34+O34+P34+Q34+R34+S34+T34+U34+V34+W34+X34+Y34+Z34+AA34+AB34+AC34+AD34+AE34+AF34+AG34+AH34+AI34+AJ34+AK34+AL34+AM34+AN34+AO34+AP34+AQ34+AR34+AS34+AT34+AU34+AV34+AW34+AX34+AY34+AZ34+BA34+BB34+BC34+BD34+BE34+BF34 -> 0
A35: 5 | B35: Оталиққа олинган ёшлар билан ўрганилганлар сони | C35: =+D35+E35+F35+G35+H35+I35+J35+K35+L35+M35+N35+O35+P35+Q35+R35+S35+T35+U35+V35+W35+X35+Y35+Z35+AA35+AB35+AC35+AD35+AE35+AF35+AG35+AH35+AI35+AJ35+AK35+AL35+AM35+AN35+AO35+AP35+AQ35+AR35+AS35+AT35+AU35+AV35+AW35+AX35+AY35+AZ35+BA35+BB35+BC35+BD35+BE35+BF35 -> 5 | N35: 1 | O35: 1 | P35: 1 | Y35: 1 | Z35: 1
B36: аниқланган муаммолар | C36: =+D36+E36+F36+G36+H36+I36+J36+K36+L36+M36+N36+O36+P36+Q36+R36+S36+T36+U36+V36+W36+X36+Y36+Z36+AA36+AB36+AC36+AD36+AE36+AF36+AG36+AH36+AI36+AJ36+AK36+AL36+AM36+AN36+AO36+AP36+AQ36+AR36+AS36+AT36+AU36+AV36+AW36+AX36+AY36+AZ36+BA36+BB36+BC36+BD36+BE36+BF36 -> 0
B37: ҳал этилганлари | C37: =+D37+E37+F37+G37+H37+I37+J37+K37+L37+M37+N37+O37+P37+Q37+R37+S37+T37+U37+V37+W37+X37+Y37+Z37+AA37+AB37+AC37+AD37+AE37+AF37+AG37+AH37+AI37+AJ37+AK37+AL37+AM37+AN37+AO37+AP37+AQ37+AR37+AS37+AT37+AU37+AV37+AW37+AX37+AY37+AZ37+BA37+BB37+BC37+BD37+BE37+BF37 -> 0
A38: 6 | B38: Чет элда миграцияга ўқиш, яшаш ёки ишлаш учун бўлиб турган ёшлар йўналиши | C38: =+D38+E38+F38+G38+H38+I38+J38+K38+L38+M38+N38+O38+P38+Q38+R38+S38+T38+U38+V38+W38+X38+Y38+Z38+AA38+AB38+AC38+AD38+AE38+AF38+AG38+AH38+AI38+AJ38+AK38+AL38+AM38+AN38+AO38+AP38+AQ38+AR38+AS38+AT38+AU38+AV38+AW38+AX38+AY38+AZ38+BA38+BB38+BC38+BD38+BE38+BF38 -> 0
A39: 7 | B39: "Раҳбар ва ёшлар" учрашуви | C39: =+D39+E39+F39+G39+H39+I39+J39+K39+L39+M39+N39+O39+P39+Q39+R39+S39+T39+U39+V39+W39+X39+Y39+Z39+AA39+AB39+AC39+AD39+AE39+AF39+AG39+AH39+AI39+AJ39+AK39+AL39+AM39+AN39+AO39+AP39+AQ39+AR39+AS39+AT39+AU39+AV39+AW39+AX39+AY39+AZ39+BA39+BB39+BC39+BD39+BE39+BF39 -> 0
